Workbook

Sheet README
A1: Grupo Bimbo (BIMBO A) - consolidated DCF v1 (assistant proposal, 2026-10-19)
A2: Built from the team's three models: v3 (valuation/), Alejandro and Diego (valuation/team-models/). Target price and rating stay with the team.
A4: What this is | B4: One DCF on averaged judgments. Facts (debt, cash, shares) take one sourced value and mechanics (valuation date, lease reinvestment, bridge) take one convention, because averaging a data error with a correct figure only halves the error.
A5: Why 50/50 | B5: Alejandro's model carries the v3 inputs (his FCFF and WACC equal v3), so there are two input sets, not three. Set Inputs!D6 to 0.6667 to give each model one third.
A6: Sheets | B6: Inputs (decision cells in yellow) -> IS, BS, CF and History (audited FY2021-FY2025, from data/financials.csv) -> WACC -> DCF -> Sensitivity. Compare, Walks, Risk_ESG and Football explain the numbers; Checks ties everything to the Python replica and the statements to their reported totals.
A7: Colour code | B7: Blue = typed value; black = formula; yellow = decision cell; green = key result.
A8: Rebuild | B8: python -I valuation/build/consolidate_models.py --project . ; python -I valuation/build/build_consolidated_workbook.py --project . ; recalc_excel.ps1 ; scan_errors.py
A10: Key results (live)
A11: WACC | B11: =WACC!B16 -> 0.10378242
A12: Cost of equity | B12: =WACC!B11 -> 0.13039389
A13: Exit EV/EBITDA | B13: =Inputs!D40 -> 5.9172897
A14: Terminal growth | B14: =Inputs!D42 -> 0.04125
A15: Value per share today - exit multiple | B15: =DCF!B43 -> 46.417141
A16: Value per share today - Gordon, RONIC-consistent | B16: =DCF!B56 -> 30.756774
A17: Value per share today - Gordon, template style (reference) | B17: =DCF!B60 -> 41.645673
A18: 12-month value, exit (guide convention) | B18: =DCF!C66 -> 51.419652
A19: Expected return, exit (guide convention) | B19: =DCF!D66 -> -0.10461344
A20: Value today needed for the HOLD floor | B20: =DCF!D72 -> 46.656303
A21: All checks | B21: =Checks!E35 -> OK

Sheet Inputs
A1: Consolidated DCF inputs - Grupo Bimbo (BIMBO A)
A2: MXN millions unless stated. Valuation date 16-Oct-2026; balance sheet and cash-flow anchor 30-Jun-2026. Blue = typed value; black = formula; yellow = decision cell the team can change.
A3: Rule: facts take one sourced value; mechanics take one convention (the technically correct one); only judgments are averaged, with weight w on the v3 set. Alejandro's model carries the v3 inputs, so it is not a third independent set.
A5: Input | B5: v3 / Alejandro | C5: Diego | D5: Consolidated (used) | E5: Tag | F5: Bucket | G5: Rule and source
A6: Weight on the v3 input set (w) | D6: 0.5 | E6: [assumption] | F6: Method | G6: 0.5 = two independent input sets (recommended). 0.6667 = one third per model, which gives v3 two thirds because Alejandro's model carries the v3 inputs.
A7: Diego exit-multiple basis (clean / raw) | D7: clean | E7: [assumption] | F7: Method | G7: clean = Diego's own rule (median of his four core peers) on the lease-consistent peer table (v3); raw = his 6.4x, built on US GAAP multiples with operating-lease cost inside EBITDA and Gruma's CIQ EBITDA.
A8: NCI treatment (market / book) | D8: market | E8: [assumption] | F8: Mechanic (provisional) | G8: market = NCI income / (ke - NCI growth): BBU independent operators withdraw more than their book equity every year (valuation.md section 5). book = 721.7 at 30-Jun-2026. Open team decision.
A10: A. Facts (one sourced value; not averaged)
A11: Share price, 16-Oct-2026 (MXN) | B11: 58.6 | C11: 58.6 | D11: 58.6 | E11: [sourced] | F11: Fact | G11: BMV official close (PPP) 16-Oct-2026
A12: Shares outstanding (millions) | B12: 4294.9437 | C12: 4296.2842 | D12: 4294.9437 | E12: [sourced] | F12: Fact | G12: BMV notice 29-Jul-2026 (4,294.9m, after the April-2026 cancellation). Diego: Capital IQ 30-Jun-2026
A13: Financial debt, 30-Jun-2026 | B13: 153660 | D13: 153660 | E13: [sourced] | F13: Fact | G13: 2Q26 release p.6; ties to Capital IQ debt ex leases and derivatives (wiki ciq-debt-stack-and-maturity-ladder)
A14: Lease liabilities (IFRS 16), 30-Jun-2026 | B14: 33361 | D14: 33361 | E14: [sourced] | F14: Fact | G14: Capital IQ balance sheet 2026 FQ2 (7,113 + 26,248)
A15: Debt incl. leases | B15: 187021 | C15: 194918.3 | D15: =D13+D14 -> 187021 | E15: [calc] | F15: Fact | G15: [calc] reconciliation, for Diego to confirm: CIQ total debt is MXN 189,679 = 153,660 + 33,361 + 2,658 derivative adjustments (wiki ciq-debt-stack-and-maturity-ladder). CIQ's peso and dollar figures imply 17.47 MXN/US$; Diego reconverted US$10,855m at 17.96 (+5,239), the rate that wiki bimbo-wacc-market-inputs-capiq-2026-10 says CIQ used. Evidence for 17.47: US$948m cash x 17.47 = 16,565 vs company 16,563
A16: Cash and equivalents, 30-Jun-2026 | B16: 16563 | C16: 17022.805 | D16: 16563 | E16: [sourced] | F16: Fact | G16: Company 16,563 (net debt 137,097, 2Q26 release p.6). Diego's 17,023 = US$948m at 17.96 (+460)
A17: NCI annual income | B17: 1814 | D17: 1814 | E17: [sourced] | F17: Fact | G17: 1H26 x 2 (Alejandro Datos_Bimbo D18; valuation.md section 5)
A18: NCI income growth (for the market value) | B18: 0.03 | D18: 0.03 | E18: [assumption] | F18: Judgment (v3) | G18: Tied to North America (about 3% in pesos); valuation/inputs/spg_inputs.yaml nci_claim
A19: NCI at book | B19: 721.7 | C19: 743 | D19: 721.7 | E19: [sourced] | F19: Fact | G19: 30-Jun-2026 (Diego: Dec-2025 book 743)
A20: Investments in associates | B20: 6497.5 | C20: 0 | D20: 6497.5 | E20: [sourced] | F20: Mechanic | G20: Non-operating asset; its results sit below EBIT, so the DCF does not capture it. Diego omits it
A21: Seasonal income tax payable (1H26, paid in 2H26) | B21: 4538.05 | C21: 0 | D21: 4538.05 | E21: [sourced] | F21: Mechanic | G21: The 2H26 flow is counted in full, so the tax accrued in 1H26 that inflates June cash is deducted
A22: Other debt-like claims (Gordon only) | B22: 18135 | C22: 0 | D22: 18135 | E22: [sourced] | F22: Mechanic | G22: Pensions, provisions incl. uncertain tax positions, derivatives (Alejandro Datos_Bimbo D21). Peer EVs exclude them, so the exit method does not deduct them (v3 rule)
A23: FY2025 revenue | B23: 426952 | C23: 426952 | D23: 426952 | E23: [sourced] | F23: Fact | G23: EEFF25; data/financials.csv
A24: Lease principal paid / revenue | B24: 0.0139 | C24: 0.013872754 | D24: 0.0139 | E24: [calc] | F24: Mechanic | G24: FY2025 5,923 / 426,952 (model/drivers.yaml rounds to 1.39%)
A25: Lease liability / revenue (held) | B25: 0.08148457 | D25: 0.08148457 | E25: [calc] | F25: Mechanic | G25: FY2025 34,790 / 426,952. New leases = principal + growth in the liability (v3 published basis). Diego's principal-only basis keeps the liability flat while revenue grows, so it understates reinvestment
A26: Stub days (30-Jun to 31-Dec-2026) | B26: 184 | C26: 76 | D26: 184 | E26: [calc] | F26: Mechanic | G26: Cash flows and the balance sheet on the same date (30-Jun). Diego discounts from 16-Oct with a 76-day stub but keeps the 30-Jun balance sheet, which drops about 3.5 months of cash flow
A27: Days from 30-Jun to 16-Oct-2026 (roll-forward at ke) | B27: 108 | C27: 0 | D27: 108 | E27: [calc] | F27: Mechanic | G27: No dividend was paid between the two dates (the 2026 dividend was paid 13-May-2026)
A28: Next unpaid dividend per share | B28: 1.05 | D28: 1.05 | E28: [sourced] | F28: Fact | G28: Consensus DPS FY2027E (CIQ 20-Sep-2026); valuation-outputs.yaml
A30: B. Cost of capital (same sources in all three models; only the beta and the debt figure differ)
A31: Risk-free: M-Bono 10y 9.26% - Mexico default spread 1.75% | B31: 0.075101188 | C31: 0.075101188 | D31: 0.075101188 | E31: [sourced]/[calc] | F31: Fact | G31: Capital IQ 16-Oct-2026; Damodaran July 2026 (Baa3)
A32: Equity risk premium (mature market) | B32: 0.042 | C32: 0.042 | D32: 0.042 | E32: [sourced] | F32: Fact | G32: Damodaran implied ERP
A33: Country risk premium, weighted by FY2025 Adj. EBITDA | B33: 0.020496339 | C33: 0.020496778 | D33: 0.020496339 | E33: [calc] | F33: Fact | G33: Same method and weights in all three models (NA 28.8%, Mexico 55.4%, EAA 9.8%, LatAm 6.0%); added once to ke
A34: Pre-tax cost of debt: M-Bono + 45 bp (BIMBO 26) | B34: 0.0971 | C34: 0.0971 | D34: 0.0971 | E34: [sourced]/[calc] | F34: Fact | G34: Issue spread of the Feb-2026 bond
A35: Marginal tax rate (tax shield, relevering) | B35: 0.3 | C35: 0.3 | D35: 0.3 | E35: [sourced] | F35: Fact | G35: Mexican statutory rate
A36: D/E, market value, debt incl. leases | B36: 0.7430795 | C36: 0.77421573 | D36: =D15/(D11*D12) -> 0.7430795 | E36: [calc] | F36: Fact | G36: Both chose the current market structure; Diego's differs only through his debt figure (row 15)
A37: Unlevered beta | B37: 0.53 | C37: 0.56 | D37: =$D$6*B37+(1-$D$6)*C37 -> 0.545 | E37: [sourced] | F37: Judgment | G37: Damodaran Food Processing (Global): v3 0.53 (Jan-2026 file); Diego 0.56 (cash-corrected)
A39: C. Terminal value and tax on operating profit (judgments, averaged)
A40: Exit EV/EBITDA on FY2030 EBITDA | B40: 6 | C40: 6.4 | D40: =$D$6*B40+(1-$D$6)*IF($D$7="raw",C40,C41) -> 5.9172897 | E40: [assumption] | F40: Judgment | G40: v3: judgment above the core bakery median (5.53x) for the Mexico mix. Diego: median of his core four (Flowers, Gruma, Yamazaki, Aryzta) = 6.37x on his table
A41: Diego's rule on the lease-consistent peer table (row 52) | C41: =B52 -> 5.8345794 | E41: [calc] | F41: Data basis | G41: Same four peers, EV/EBITDA LTM on one claim basis (valuation/inputs/peers.yaml)
A42: Terminal growth g (nominal MXN) | B42: 0.0425 | C42: 0.04 | D42: =$D$6*B42+(1-$D$6)*C42 -> 0.04125 | E42: [assumption] | F42: Judgment | G42: v3 4.25% (regional mix, below 5% nominal GDP). Diego 4.0% (2% real + ~3% inflation, USD-linked mix)
A43: Tax on EBIT (cash flows) | B43: 0.34 | C43: 0.3 | D43: =$D$6*B43+(1-$D$6)*C43 -> 0.32 | E43: [assumption] | F43: Judgment (flagged) | G43: v3 34% (effective rate 33-36% ex-2022: non-deductibles, foreign rates). Diego 30% (statutory). The effective rate is the better estimate of cash taxes; the average is shown because the user asked for averages
A44: Return on new capital after 2030 (Gordon) | B44: 0.146184 | D44: =B44 -> 0.146184 | E44: [assumption] | F44: Judgment (v3 only) | G44: RONIC implied by the published v3 terminal value (valuation-outputs.yaml tv_ronic). Diego has no Gordon or reinvestment judgment, so nothing to average
...

Sheet IS
A1: Income statement, FY2021A-FY2025A (audited, MXN millions)
A2: Continuing operations. Blue = typed from the filings (data/financials.csv); black = formula. FY2021 is restated for Ricolino (sold 1-Nov-2022), which sits in 'other financial result' as discontinued operations after tax.
A4: MXN m | B4: FY2021A | C4: FY2022A | D4: FY2023A | E4: FY2024A | F4: FY2025A | G4: Tag | H4: Source / note
A5: Net sales | B5: 338792 | C5: 398706 | D5: 399879 | E5: 408335 | F5: 426952 | G5: [sourced] | H5: RA23 XBRL p.257 (FY21-22); IA25-EEFF p.13 (FY23-25)
A6: Cost of sales | B6: 157703 | C6: 193325 | D6: 194369 | E6: 193407 | F6: 203465 | G6: [sourced] | H6: RA23 XBRL p.257 (FY21-22); IA25-EEFF p.13 (FY23-25)
A7: Gross profit | B7: =B5-B6 -> 181089 | C7: =C5-C6 -> 205381 | D7: =D5-D6 -> 205510 | E7: =E5-E6 -> 214928 | F7: =F5-F6 -> 223487 | G7: [calc]
A8: Operating expenses, net | B8: 148509 | C8: 151685 | D8: 170055 | E8: 181779 | F8: 189341 | G8: [sourced] | H8: RA23 XBRL p.257 (FY21-22); IA25-EEFF p.13 (FY23-25). Distribution and selling + administration + integration + other (income) expenses, net
A9: EBIT (operating income) | B9: =B7-B8 -> 32580 | C9: =C7-C8 -> 53696 | D9: =D7-D8 -> 35455 | E9: =E7-E8 -> 33149 | F9: =F7-F8 -> 34146 | G9: [calc] | H9: FY2022 includes a non-cash gain on multi-employer pension plans of about 19,010 (RA23 EEFF notes 21-22)
A10: Interest expense | B10: 7823 | C10: 8049 | D10: 10006 | E10: 13100 | F10: 14464 | G10: [sourced] | H10: RA23 XBRL p.257 (FY21-22); IA25-EEFF p.13 (FY23-25)
A11: Interest income | B11: 363 | C11: 740 | D11: 809 | E11: 924 | F11: 897 | G11: [sourced] | H11: RA23 XBRL p.257 (FY21-22); IA25-EEFF p.13 (FY23-25)
A12: Other financial result, net | B12: 988 | C12: 16479 | D12: -950 | E12: -133 | F12: -436 | G12: [sourced] | H12: RA23 XBRL p.257 (FY21-22); IA25-EEFF p.13 (FY23-25). Associates + FX + monetary position + discontinued operations after tax (Ricolino: 1,254 in FY2021; 16,988 in FY2022)
A13: Pre-tax income (incl. discontinued operations after tax) | B13: =B9-B10+B11+B12 -> 26108 | C13: =C9-C10+C11+C12 -> 62866 | D13: =D9-D10+D11+D12 -> 25308 | E13: =E9-E10+E11+E12 -> 20840 | F13: =F9-F10+F11+F12 -> 20143 | G13: [calc]
A14: Income tax | B14: 8726 | C14: 14381 | D14: 8386 | E14: 6797 | F14: 7197 | G14: [sourced] | H14: RA23 XBRL p.257 (FY21-22); IA25-EEFF p.13 (FY23-25). Continuing operations
A15: Net income | B15: =B13-B14 -> 17382 | C15: =C13-C14 -> 48485 | D15: =D13-D14 -> 16922 | E15: =E13-E14 -> 14043 | F15: =F13-F14 -> 12946 | G15: [calc]
A16: Net income as reported | B16: 17382 | C16: 48485 | D16: 16922 | E16: 14043 | F16: 12946 | G16: [sourced] | H16: RA23 XBRL p.257 (FY21-22); IA25-EEFF p.13 (FY23-25). Consolidated, before the NCI split
A17: Check: computed - reported | B17: =B15-B16 -> 0 | C17: =C15-C16 -> 0 | D17: =D15-D16 -> 0 | E17: =E15-E16 -> 0 | F17: =F15-F16 -> 0 | G17: [calc]
A18: Attributable to non-controlling interests | B18: 1466 | C18: 1575 | D18: 1445 | E18: 1499 | F18: 1813 | G18: [sourced] | H18: RA23 XBRL p.257 (FY21-22); IA25-EEFF p.13 (FY23-25). FY2021-22 include the NCI share of discontinued operations
A19: Net income to shareholders | B19: =B15-B18 -> 15916 | C19: =C15-C18 -> 46910 | D19: =D15-D18 -> 15477 | E19: =E15-E18 -> 12544 | F19: =F15-F18 -> 11133 | G19: [calc]
A20: Diluted shares (millions) | B20: 4487.268 | C20: 4448.693 | D20: 4418.137 | E20: 4357.25 | F20: 4310.531 | G20: [sourced] | H20: RA23 XBRL p.257 (FY21-22); IA25-EEFF p.13 (FY23-25)
A21: Diluted EPS (MXN) | B21: =B19/B20 -> 3.5469243 | C21: =C19/C20 -> 10.54467 | D21: =D19/D20 -> 3.5030602 | E21: =E19/E20 -> 2.87888 | F21: =F19/F20 -> 2.5827444 | G21: [calc]
A22: D&A (continuing) | B22: 16126 | C22: 18038 | D22: 18929 | E22: 23051 | F22: 24838 | G22: [sourced] | H22: RA23 XBRL p.359 (FY21); RA23 XBRL p.358 (FY22); IA25-EEFF p.86 (FY23-24); IA25-EEFF p.85 (FY25). Segment note, consistent with EBIT
A23: EBITDA (EBIT + D&A, IFRS 16) | B23: =B9+B22 -> 48706 | C23: =C9+C22 -> 71734 | D23: =D9+D22 -> 54384 | E23: =E9+E22 -> 56200 | F23: =F9+F22 -> 58984 | G23: [calc]
A24: Adjusted EBITDA (company definition) | B24: 47372 | C24: 53446 | D24: 54942 | E24: 55473 | F24: 59456 | G24: [sourced] | H24: RA22 p.313 (FY21 restated); RA23 p.358 (FY22); IA25-EEFF p.85-86 (FY23-25). Operating income + D&A + impairment + non-cash items (mainly multi-employer pension plans)

Sheet BS
A1: Balance sheet, FY2021A-FY2025A (audited, MXN millions, year-end)
A2: Blue = typed from the filings (data/financials.csv); black = formula. Lines are grouped as in the model; net debt includes lease liabilities.
A4: MXN m | B4: FY2021A | C4: FY2022A | D4: FY2023A | E4: FY2024A | F4: FY2025A | G4: Tag | H4: Source / note
A5: Cash and equivalents | B5: 8748 | C5: 12313 | D5: 6353 | E5: 8057 | F5: 8535 | G5: [sourced] | H5: RA23 XBRL p.256 (FY21-22); IA25-EEFF p.12 (FY23-25)
A6: Accounts receivable | B6: 19184 | C6: 21600 | D6: 21268 | E6: 23555 | F6: 23784 | G6: [sourced] | H6: RA23 XBRL p.292 (FY21-22); IA25-EEFF p.36 (FY23-25)
A7: Inventories | B7: 13710 | C7: 16989 | D7: 16120 | E7: 18832 | F7: 17151 | G7: [sourced] | H7: RA23 XBRL p.256 (FY21-22); IA25-EEFF p.12 (FY23-25)
A8: Other current assets | B8: 11769 | C8: 12568 | D8: 15173 | E8: 16736 | F8: 15201 | G8: [sourced] | H8: RA23 XBRL p.256 (FY21-22); IA25-EEFF p.12 (FY23-25)
A9: Total current assets | B9: =SUM(B5:B8) -> 53411 | C9: =SUM(C5:C8) -> 63470 | D9: =SUM(D5:D8) -> 58914 | E9: =SUM(E5:E8) -> 67180 | F9: =SUM(F5:F8) -> 64671 | G9: [calc]
A10: PP&E and right-of-use assets, net | B10: 134645 | C10: 141982 | D10: 155004 | E10: 189596 | F10: 190180 | G10: [sourced] | H10: RA23 XBRL p.256 (FY21-22); IA25-EEFF p.12 (FY23-25)
A11: Intangibles and goodwill | B11: 131530 | C11: 127147 | D11: 117101 | E11: 140908 | F11: 135515 | G11: [sourced] | H11: RA23 XBRL p.256 (FY21-22); IA25-EEFF p.12 (FY23-25)
A12: Other non-current assets | B12: 18054 | C12: 15165 | D12: 17083 | E12: 19120 | F12: 19439 | G12: [sourced] | H12: RA23 XBRL p.256 (FY21-22); IA25-EEFF p.12 (FY23-25)
A13: Total assets | B13: =B9+B10+B11+B12 -> 337640 | C13: =C9+C10+C11+C12 -> 347764 | D13: =D9+D10+D11+D12 -> 348102 | E13: =E9+E10+E11+E12 -> 416804 | F13: =F9+F10+F11+F12 -> 409805 | G13: [calc]
A14: Total assets as reported | B14: 337640 | C14: 347764 | D14: 348102 | E14: 416804 | F14: 409805 | G14: [sourced] | H14: RA23 XBRL p.256 (FY21-22); IA25-EEFF p.12 (FY23-25)
A15: Check: lines - reported | B15: =B13-B14 -> 0 | C15: =C13-C14 -> 0 | D15: =D13-D14 -> 0 | E15: =E13-E14 -> 0 | F15: =F13-F14 -> 0 | G15: [calc]
A16: Accounts payable | B16: 35752 | C16: 44058 | D16: 40409 | E16: 40815 | F16: 39074 | G16: [sourced] | H16: RA23 XBRL p.256 (FY21-22); IA25-EEFF p.12 (FY23-25)
A17: Other current liabilities | B17: 28590 | C17: 33311 | D17: 28100 | E17: 32338 | F17: 31788 | G17: [sourced] | H17: RA23 XBRL p.256 (FY21-22); IA25-EEFF p.12 (FY23-25)
A18: Short-term debt (current portion) | B18: 10625 | C18: 6435 | D18: 12932 | E18: 4862 | F18: 12635 | G18: [sourced] | H18: RA23 XBRL p.256 (FY21-22); IA25-EEFF p.12 (FY23-25)
A19: Total current liabilities | B19: =SUM(B16:B18) -> 74967 | C19: =SUM(C16:C18) -> 83804 | D19: =SUM(D16:D18) -> 81441 | E19: =SUM(E16:E18) -> 78015 | F19: =SUM(F16:F18) -> 83497 | G19: [calc]
A20: Long-term debt | B20: 82230 | C20: 77619 | D20: 97003 | E20: 146043 | F20: 141028 | G20: [sourced] | H20: RA23 XBRL p.256 (FY21-22); IA25-EEFF p.12 (FY23-25)
A21: Lease liabilities (IFRS 16, current + non-current) | B21: 31149 | C21: 29185 | D21: 26815 | E21: 35801 | F21: 34790 | G21: [sourced] | H21: RA23 XBRL p.256 (FY21-22); IA25-EEFF p.12 (FY23-25)
A22: Other non-current liabilities | B22: 47688 | C22: 29554 | D22: 31215 | E22: 29247 | F22: 30235 | G22: [sourced] | H22: RA23 XBRL p.256 (FY21-22); IA25-EEFF p.12 (FY23-25)
A23: Total liabilities | B23: =B19+B20+B21+B22 -> 236034 | C23: =C19+C20+C21+C22 -> 220162 | D23: =D19+D20+D21+D22 -> 236474 | E23: =E19+E20+E21+E22 -> 289106 | F23: =F19+F20+F21+F22 -> 289550 | G23: [calc]
A24: Shareholders' equity (parent) | B24: 97100 | C24: 124111 | D24: 108322 | E24: 125944 | F24: 119512 | G24: [sourced] | H24: RA23 XBRL p.256 (FY21-22); IA25-EEFF p.12 (FY23-25). FY2021-22 include perpetual notes classed as equity (8,867; 8,098)
A25: Non-controlling interests | B25: 4506 | C25: 3491 | D25: 3306 | E25: 1754 | F25: 743 | G25: [sourced] | H25: RA23 XBRL p.256 (FY21-22); IA25-EEFF p.12 (FY23-25)
A26: Total equity | B26: =B24+B25 -> 101606 | C26: =C24+C25 -> 127602 | D26: =D24+D25 -> 111628 | E26: =E24+E25 -> 127698 | F26: =F24+F25 -> 120255 | G26: [calc]
A27: Total liabilities and equity | B27: =B23+B26 -> 337640 | C27: =C23+C26 -> 347764 | D27: =D23+D26 -> 348102 | E27: =E23+E26 -> 416804 | F27: =F23+F26 -> 409805 | G27: [calc]
A28: Check: assets - (liabilities + equity) | B28: =B13-B27 -> 0 | C28: =C13-C27 -> 0 | D28: =D13-D27 -> 0 | E28: =E13-E27 -> 0 | F28: =F13-F27 -> 0 | G28: [calc]
A29: Financial debt incl. leases | B29: =B18+B20+B21 -> 124004 | C29: =C18+C20+C21 -> 113239 | D29: =D18+D20+D21 -> 136750 | E29: =E18+E20+E21 -> 186706 | F29: =F18+F20+F21 -> 188453 | G29: [calc]
A30: Net debt incl. leases | B30: =B29-B5 -> 115256 | C30: =C29-C5 -> 100926 | D30: =D29-D5 -> 130397 | E30: =E29-E5 -> 178649 | F30: =F29-F5 -> 179918 | G30: [calc]
A31: Net debt / Adjusted EBITDA (x) | B31: =B30/IS!B24 -> 2.4329984 | C31: =C30/IS!C24 -> 1.8883733 | D31: =D30/IS!D24 -> 2.3733574 | E31: =E30/IS!E24 -> 3.2204676 | F31: =F30/IS!F24 -> 3.0260697 | G31: [calc]
A32: Operating working capital (receivables + inventories + other current assets - payables - other current liabilities) | B32: =B6+B7+B8-B16-B17 -> -19679 | C32: =C6+C7+C8-C16-C17 -> -26212 | D32: =D6+D7+D8-D16-D17 -> -15948 | E32: =E6+E7+E8-E16-E17 -> -14030 | F32: =F6+F7+F8-F16-F17 -> -14726 | G32: [calc] | H32: Balance-sheet basis, same definition as the forecast driver; data/adjustments.md uses a narrower one (excludes financing and tax items)

Sheet CF
A1: Cash flow, FY2021A-FY2025A (audited, MXN millions; abridged)
A2: Only the lines the valuation uses. Blue = typed from the filings; black = formula. FY2021-22 CFO includes Ricolino until its sale.
A4: MXN m | B4: FY2021A | C4: FY2022A | D4: FY2023A | E4: FY2024A | F4: FY2025A | G4: Tag | H4: Source / note
A5: Cash flow from operations | B5: 45776 | C5: 38851 | D5: 31411 | E5: 39907 | F5: 47753 | G5: [sourced] | H5: RA23 XBRL p.260 (FY21-22); IA25-EEFF p.16 (FY23-25)
A6: Capex, cash basis (PP&E + intangibles) | B6: 21293 | C6: 29467 | D6: 35672 | E6: 30174 | F6: 22841 | G6: [sourced] | H6: RA23 XBRL p.260 (FY21-22); IA25-EEFF p.16 (FY23-25)
A7: Lease principal paid (IFRS 16) | B7: 4117 | C7: 5056 | D7: 4802 | E7: 5321 | F7: 5923 | G7: [calc] | H7: RA23 XBRL p.260 (FY21-22); IA25-EEFF p.16 (FY23-25). Financing line 'lease payments' less lease interest accrued
A8: Free cash flow (CFO - capex - lease principal) | B8: =B5-B6-B7 -> 20366 | C8: =C5-C6-C7 -> 4328 | D8: =D5-D6-D7 -> -9063 | E8: =E5-E6-E7 -> 4412 | F8: =F5-F6-F7 -> 18989 | G8: [calc]
A9: Dividends paid (to the parent) | B9: 4502 | C9: 5791 | D9: 3458 | E9: 4125 | F9: 4316 | G9: [sourced] | H9: RA23 XBRL p.259 (FY21-22); IA25-EEFF p.15 (FY23-25)
A10: FCF margin (% of net sales) | B10: =B8/IS!B5 -> 0.06011358 | C10: =C8/IS!C5 -> 0.010855116 | D10: =D8/IS!D5 -> -0.022664356 | E10: =E8/IS!E5 -> 0.010804854 | F10: =F8/IS!F5 -> 0.044475726 | G10: [calc]
A11: Capex, PP&E acquired (segment note; the basis of the capex guidance) | B11: 20671 | C11: 28669 | D11: 34754 | E11: 29402 | F11: 22530 | G11: [sourced] | H11: RA22 p.313 (FY21 restated); RA23 p.358 (FY22); IA25-EEFF p.85-86 (FY23-25)
A12: Capex, PP&E acquired / net sales | B12: =B11/IS!B5 -> 0.061013837 | C12: =C11/IS!C5 -> 0.071905113 | D12: =D11/IS!D5 -> 0.086911291 | E12: =E11/IS!E5 -> 0.072004604 | F12: =F11/IS!F5 -> 0.052769398 | G12: [calc]
A13: Change in operating working capital (+ releases cash) | C13: =BS!B32-BS!C32 -> 6533 | D13: =BS!C32-BS!D32 -> -10264 | E13: =BS!D32-BS!E32 -> -1918 | F13: =BS!E32-BS!F32 -> 696 | G13: [calc] | H13: Decrease in operating working capital on the balance sheet (BS row 32)

Sheet History
A1: Historical growth, margins, returns and segments, FY2021A-FY2025A
A2: Formulas on the IS, BS and CF sheets; blue = typed from the filings or releases. FY2021 is restated for Ricolino, so FY2021 growth rates are not available on the same basis.
A4: MXN m | B4: FY2021A | C4: FY2022A | D4: FY2023A | E4: FY2024A | F4: FY2025A | G4: Tag | H4: Source / note
A5: A. Growth, % y/y
A6: Net sales (MXN) | C6: =IS!C5/IS!B5-1 -> 0.17684597 | D6: =IS!D5/IS!C5-1 -> 0.0029420174 | E6: =IS!E5/IS!D5-1 -> 0.021146397 | F6: =IS!F5/IS!E5-1 -> 0.045592467 | G6: [calc]
A7: Adjusted EBITDA (MXN) | C7: =IS!C24/IS!B24-1 -> 0.1282192 | D7: =IS!D24/IS!C24-1 -> 0.027990869 | E7: =IS!E24/IS!D24-1 -> 0.0096647374 | F7: =IS!F24/IS!E24-1 -> 0.071800696 | G7: [calc]
A8: EBIT | C8: =IS!C9/IS!B9-1 -> 0.64812769 | D8: =IS!D9/IS!C9-1 -> -0.33970873 | E8: =IS!E9/IS!D9-1 -> -0.065040192 | F8: =IS!F9/IS!E9-1 -> 0.030076322 | G8: [calc] | H8: FY2022 EBIT and net income include the pension and Ricolino one-offs
A9: Net income to shareholders | C9: =IS!C19/IS!B19-1 -> 1.9473486 | D9: =IS!D19/IS!C19-1 -> -0.67007035 | E9: =IS!E19/IS!D19-1 -> -0.18950701 | F9: =IS!F19/IS!E19-1 -> -0.11248406 | G9: [calc]
A10: Diluted EPS | C10: =IS!C21/IS!B21-1 -> 1.9729053 | D10: =IS!D21/IS!C21-1 -> -0.66778854 | E10: =IS!E21/IS!D21-1 -> -0.17818141 | F10: =IS!F21/IS!E21-1 -> -0.10286486 | G10: [calc]
A11: Net sales ex-FX (company) | B11: 0.093 | C11: 0.206 | D11: 0.107 | E11: 0.005 | F11: 0.016 | G11: [sourced] | H11: 4T21 p.2 (FY21, as originally reported, incl. Ricolino); 4T22 p.4; 4T23 p.1; 4T24 p.2; 4T25 p.3
A13: B. Compound annual growth (CAGR) and simple average
A14: Net sales CAGR FY2021-FY2025 (4 years) | B14: =(IS!F5/IS!B5)^(1/4)-1 -> 0.059525653 | G14: [calc]
A15: Net sales CAGR FY2022-FY2025 (3 years) | B15: =(IS!F5/IS!C5)^(1/3)-1 -> 0.023078034 | G15: [calc]
A16: Adjusted EBITDA CAGR FY2021-FY2025 (4 years) | B16: =(IS!F24/IS!B24)^(1/4)-1 -> 0.058445478 | G16: [calc]
A17: Adjusted EBITDA CAGR FY2022-FY2025 (3 years) | B17: =(IS!F24/IS!C24)^(1/3)-1 -> 0.03616001 | G17: [calc]
A18: Net sales: simple average of the annual rates FY2022-FY2025 | B18: =AVERAGE(C6:F6) -> 0.061631713 | G18: [calc] | H18: FY2022 (+17.7%) lifts the average; see the CAGR from FY2022
A20: C. Margins, % of net sales
A21: Gross margin | B21: =IS!B7/IS!B5 -> 0.5345138 | C21: =IS!C7/IS!C5 -> 0.51511891 | D21: =IS!D7/IS!D5 -> 0.51393046 | E21: =IS!E7/IS!E5 -> 0.52635214 | F21: =IS!F7/IS!F5 -> 0.5234476 | G21: [calc]
A22: EBIT margin | B22: =IS!B9/IS!B5 -> 0.096165199 | C22: =IS!C9/IS!C5 -> 0.13467568 | D22: =IS!D9/IS!D5 -> 0.088664321 | E22: =IS!E9/IS!E5 -> 0.081180893 | F22: =IS!F9/IS!F5 -> 0.079976203 | G22: [calc]
A23: EBITDA margin (EBIT + D&A) | B23: =IS!B23/IS!B5 -> 0.14376373 | C23: =IS!C23/IS!C5 -> 0.17991703 | D23: =IS!D23/IS!D5 -> 0.13600114 | E23: =IS!E23/IS!E5 -> 0.13763209 | F23: =IS!F23/IS!F5 -> 0.13815136 | G23: [calc]
A24: Adjusted EBITDA margin | B24: =IS!B24/IS!B5 -> 0.13982621 | C24: =IS!C24/IS!C5 -> 0.13404865 | D24: =IS!D24/IS!D5 -> 0.13739656 | E24: =IS!E24/IS!E5 -> 0.13585169 | F24: =IS!F24/IS!F5 -> 0.13925687 | G24: [calc]
A25: Net margin (to shareholders) | B25: =IS!B19/IS!B5 -> 0.046978677 | C25: =IS!C19/IS!C5 -> 0.11765562 | D25: =IS!D19/IS!D5 -> 0.038704208 | E25: =IS!E19/IS!E5 -> 0.030719875 | F25: =IS!F19/IS!F5 -> 0.026075531 | G25: [calc] | H25: FY2022 includes the Ricolino gain
A26: FCF margin | B26: =CF!B10 -> 0.06011358 | C26: =CF!C10 -> 0.010855116 | D26: =CF!D10 -> -0.022664356 | E26: =CF!E10 -> 0.010804854 | F26: =CF!F10 -> 0.044475726 | G26: [calc]
A27: D&A / net sales | B27: =IS!B22/IS!B5 -> 0.047598527 | C27: =IS!C22/IS!C5 -> 0.045241356 | D27: =IS!D22/IS!D5 -> 0.047336819 | E27: =IS!E22/IS!E5 -> 0.056451198 | F27: =IS!F22/IS!F5 -> 0.058175158 | G27: [calc]
A28: Capex (PP&E acquired) / net sales | B28: =CF!B12 -> 0.061013837 | C28: =CF!C12 -> 0.071905113 | D28: =CF!D12 -> 0.086911291 | E28: =CF!E12 -> 0.072004604 | F28: =CF!F12 -> 0.052769398 | G28: [calc]
A30: D. Returns, leverage and liquidity
A31: Return on average equity (parent) | C31: =IS!C19/AVERAGE(BS!B24,BS!C24) -> 0.42411996 | D31: =IS!D19/AVERAGE(BS!C24,BS!D24) -> 0.13317386 | E31: =IS!E19/AVERAGE(BS!D24,BS!E24) -> 0.10709194 | F31: =IS!F19/AVERAGE(BS!E24,BS!F24) -> 0.090712796 | G31: [calc] | H31: FY2022 includes the one-offs
A32: ROIC = EBIT x (1 - effective tax rate) / opening (equity + net debt) | C32: =IS!C9*(1-IS!C14/IS!C13)/(BS!B26+BS!B30) -> 0.19096336 | D32: =IS!D9*(1-IS!D14/IS!D13)/(BS!C26+BS!C30) -> 0.10373658 | E32: =IS!E9*(1-IS!E14/IS!E13)/(BS!D26+BS!D30) -> 0.09229377 | F32: =IS!F9*(1-IS!F14/IS!F13)/(BS!E26+BS!E30) -> 0.071637044 | G32: [calc]
A33: Effective tax rate | B33: =IS!B14/IS!B13 -> 0.33422706 | C33: =IS!C14/IS!C13 -> 0.2287564 | D33: =IS!D14/IS!D13 -> 0.33135767 | E33: =IS!E14/IS!E13 -> 0.32615163 | F33: =IS!F14/IS!F13 -> 0.35729534 | G33: [calc]
A34: Net debt incl. leases / Adjusted EBITDA (x) | B34: =BS!B31 -> 2.4329984 | C34: =BS!C31 -> 1.8883733 | D34: =BS!D31 -> 2.3733574 | E34: =BS!E31 -> 3.2204676 | F34: =BS!F31 -> 3.0260697 | G34: [calc]
A35: Interest cover: EBIT / interest expense (x) | B35: =IS!B9/IS!B10 -> 4.1646427 | C35: =IS!C9/IS!C10 -> 6.6711393 | D35: =IS!D9/IS!D10 -> 3.543374 | E35: =IS!E9/IS!E10 -> 2.530458 | F35: =IS!F9/IS!F10 -> 2.3607577 | G35: [calc]
A36: Current ratio (x) | B36: =BS!B9/BS!B19 -> 0.71246015 | C36: =BS!C9/BS!C19 -> 0.75736242 | D36: =BS!D9/BS!D19 -> 0.72339485 | E36: =BS!E9/BS!E19 -> 0.86111645 | F36: =BS!F9/BS!F19 -> 0.77453082 | G36: [calc]
A38: E. Net sales by region before eliminations, MXN m
A39: North America | B39: 175369 | C39: 205674 | D39: 192534 | E39: 189330 | F39: 190211 | G39: [sourced] | H39: RA23 XBRL p.359 (FY21); RA23 XBRL p.358 (FY22); IA25-EEFF p.86 (FY23-24); IA25-EEFF p.85 (FY25)
A40: Mexico | B40: 109089 | C40: 130401 | D40: 145387 | E40: 151164 | F40: 154809 | G40: [sourced] | H40: RA23 XBRL p.359 (FY21); RA23 XBRL p.358 (FY22); IA25-EEFF p.86 (FY23-24); IA25-EEFF p.85 (FY25)
A41: Europe, Asia and Africa | B41: 34195 | C41: 37536 | D41: 40545 | E41: 45044 | F41: 54214 | G41: [sourced] | H41: RA23 XBRL p.359 (FY21); RA23 XBRL p.358 (FY22); IA25-EEFF p.86 (FY23-24); IA25-EEFF p.85 (FY25)
A42: Latin America | B42: 31109 | C42: 38411 | D42: 36647 | E42: 39879 | F42: 44120 | G42: [sourced] | H42: RA23 XBRL p.359 (FY21); RA23 XBRL p.358 (FY22); IA25-EEFF p.86 (FY23-24); IA25-EEFF p.85 (FY25)
A43: Eliminations | B43: -10970 | C43: -13316 | D43: -15234 | E43: -17082 | F43: -16402 | G43: [sourced] | H43: RA23 XBRL p.359 (FY21); RA23 XBRL p.358 (FY22); IA25-EEFF p.86 (FY23-24); IA25-EEFF p.85 (FY25)
A44: Consolidated net sales | B44: =SUM(B39:B43) -> 338792 | C44: =SUM(C39:C43) -> 398706 | D44: =SUM(D39:D43) -> 399879 | E44: =SUM(E39:E43) -> 408335 | F44: =SUM(F39:F43) -> 426952 | G44: [calc]
A45: Check: segments - income statement | B45: =B44-IS!B5 -> 0 | C45: =C44-IS!C5 -> 0 | D45: =D44-IS!D5 -> 0 | E45: =E44-IS!E5 -> 0 | F45: =F44-IS!F5 -> 0 | G45: [calc]
...

Sheet WACC
A1: Consolidated cost of capital
A2: ke = rf + beta_levered x ERP + CRP; beta_levered = beta_unlevered x (1 + (1 - t) x D/E)
A3: Item | B3: Value | C3: Formula or source
A4: Unlevered beta | B4: =Inputs!D37 -> 0.545 | C4: Inputs row 37 (w-weighted)
A5: D/E (market, debt incl. leases) | B5: =Inputs!D36 -> 0.7430795 | C5: Inputs row 36
A6: Marginal tax rate | B6: =Inputs!D35 -> 0.3 | C6: Inputs row 35
A7: Levered beta | B7: =B4*(1+(1-B6)*B5) -> 0.82848483 | C7: Hamada
A8: Risk-free | B8: =Inputs!D31 -> 0.075101188
A9: Equity risk premium | B9: =Inputs!D32 -> 0.042
A10: Country risk premium | B10: =Inputs!D33 -> 0.020496339 | C10: Added once, not multiplied by beta
A11: Cost of equity (ke) | B11: =B8+B7*B9+B10 -> 0.13039389
A12: Pre-tax cost of debt | B12: =Inputs!D34 -> 0.0971
A13: After-tax cost of debt | B13: =B12*(1-B6) -> 0.06797
A14: Weight of debt D/(D+E) | B14: =B5/(1+B5) -> 0.4263027
A15: Weight of equity | B15: =1-B14 -> 0.5736973
A16: WACC | B16: =B15*B11+B14*B13 -> 0.10378242
A18: How the three WACCs compare
A19: v3 published (valuation-outputs.yaml) | B19: 0.10323276 | C19: Same inputs as Alejandro
A20: Alejandro (WACC!C87 of his workbook) | B20: 0.10323299 | C20: beta 0.53, D/E 0.743
A21: Diego (WACC!C87 of his workbook) | B21: 0.1039829 | C21: beta 0.56, D/E 0.774 (CIQ debt at the LTM FX rate)
A22: Simple average of the two input sets | B22: =(B20+B21)/2 -> 0.10360794
A23: Simple average of the three models | B23: =(B19+B20+B21)/3 -> 0.10348288
A24: Consolidated (this sheet) | B24: =B16 -> 0.10378242 | C24: beta averaged, D/E reconciled to the company debt
A26: All three use the same risk-free, ERP, EBITDA-weighted country risk premium and cost of debt, so the WACCs differ by less than 10 bp: there is little to average.

Sheet DCF
A1: Consolidated DCF - FCFF, exit multiple and Gordon
A2: S&P template mechanics: FY2026 stub from 30-Jun (184 days), mid-period discounting, terminal value at end-2030; value rolled to 16-Oct-2026 at ke. MXN millions.
A3: FY2025A = base year: reported revenue, Adjusted EBITDA, D&A, capex, lease principal paid (new leases) and working capital (Inputs rows 76-81). Tax on EBIT, NOPAT and FCFF in grey are pro forma at the DCF's tax rate, for comparison only. The valuation counts cash flows from 30-Jun-2026.
A4: MXN m | B4: FY2025A | C4: FY2026E | D4: FY2027E | E4: FY2028E | F4: FY2029E | G4: FY2030E
A5: Revenue | B5: =Inputs!D23 -> 426952 | C5: =B5*(1+C6) -> 424878.67 | D5: =C5*(1+D6) -> 444001.22 | E5: =D5*(1+E6) -> 465320.88 | F5: =E5*(1+F6) -> 486542.73 | G5: =F5*(1+G6) -> 507796.5
A6: growth | B6: =B5/Inputs!D76-1 -> 0.045592467 | C6: =Inputs!B58 -> -0.0048561143 | D6: =Inputs!C58 -> 0.04500708 | E6: =Inputs!D58 -> 0.048017122 | F6: =Inputs!E58 -> 0.045606917 | G6: =Inputs!F58 -> 0.043683258
A7: EBITDA margin | B7: =B8/B5 -> 0.13925687 | C7: =Inputs!B61 -> 0.14636015 | D7: =Inputs!C61 -> 0.14536383 | E7: =Inputs!D61 -> 0.14814867 | F7: =Inputs!E61 -> 0.14914867 | G7: =Inputs!F61 -> 0.15014867
A8: EBITDA (IFRS 16) | B8: =Inputs!D77 -> 59456 | C8: =C5*C7 -> 62185.308 | D8: =D5*D7 -> 64541.718 | E8: =E5*E7 -> 68936.668 | F8: =F5*F7 -> 72567.2 | G8: =G5*G7 -> 76244.968
A9: D&A / revenue | B9: =B10/B5 -> 0.058175158 | C9: =Inputs!B64 -> 0.059 | D9: =Inputs!C64 -> 0.059 | E9: =Inputs!D64 -> 0.059 | F9: =Inputs!E64 -> 0.0585 | G9: =Inputs!F64 -> 0.0585
A10: D&A | B10: =Inputs!D78 -> 24838 | C10: =C5*C9 -> 25067.842 | D10: =D5*D9 -> 26196.072 | E10: =E5*E9 -> 27453.932 | F10: =F5*F9 -> 28462.75 | G10: =G5*G9 -> 29706.096
A11: EBIT | B11: =B8-B10 -> 34618 | C11: =C8-C10 -> 37117.466 | D11: =D8-D10 -> 38345.646 | E11: =E8-E10 -> 41482.736 | F11: =F8-F10 -> 44104.45 | G11: =G8-G10 -> 46538.872
A12: Tax on EBIT | B12: =B11*Inputs!$D$43 -> 11077.76 | C12: =C11*Inputs!$D$43 -> 11877.589 | D12: =D11*Inputs!$D$43 -> 12270.607 | E12: =E11*Inputs!$D$43 -> 13274.475 | F12: =F11*Inputs!$D$43 -> 14113.424 | G12: =G11*Inputs!$D$43 -> 14892.439
A13: NOPAT | B13: =B11-B12 -> 23540.24 | C13: =C11-C12 -> 25239.877 | D13: =D11-D12 -> 26075.039 | E13: =E11-E12 -> 28208.26 | F13: =F11-F12 -> 29991.026 | G13: =G11-G12 -> 31646.433
A14: capex ex leases / revenue | B14: =B15/B5 -> 0.052769398 | C14: =Inputs!B67 -> 0.048780047 | D14: =Inputs!C67 -> 0.050086358 | E14: =Inputs!D67 -> 0.05047906 | F14: =Inputs!E67 -> 0.05122906 | G14: =Inputs!F67 -> 0.05147906
A15: Capex ex leases | B15: =Inputs!D79 -> 22530 | C15: =C5*C14 -> 20725.602 | D15: =D5*D14 -> 22238.404 | E15: =E5*E14 -> 23488.961 | F15: =F5*F14 -> 24925.127 | G15: =G5*G14 -> 26140.887
A16: New leases (principal + growth in the liability) | B16: =Inputs!D80 -> 5923 | C16: =Inputs!$D$24*C5+Inputs!$D$25*(C5-B5) -> 5736.8693 | D16: =Inputs!$D$24*D5+Inputs!$D$25*(D5-C5) -> 7729.8096 | E16: =Inputs!$D$24*E5+Inputs!$D$25*(E5-D5) -> 8205.1836 | F16: =Inputs!$D$24*F5+Inputs!$D$25*(F5-E5) -> 8492.1974 | G16: =Inputs!$D$24*G5+Inputs!$D$25*(G5-F5) -> 8790.2259
A17: change in WC / revenue | B17: =B18/B5 -> 0.0016301598 | C17: =Inputs!B70 -> -6.6033733e-05 | D17: =Inputs!C70 -> 0.0014313829 | E17: =Inputs!D70 -> 0.00098956485 | F17: =Inputs!E70 -> 0.0009843316 | G17: =Inputs!F70 -> 0.0010254467
A18: Change in working capital (+ releases cash) | B18: =Inputs!D81 -> 696 | C18: =C5*C17 -> -28.056325 | D18: =D5*D17 -> 635.53575 | E18: =E5*E17 -> 460.46519 | F18: =F5*F17 -> 478.91939 | G18: =G5*G17 -> 520.71823
A19: Free cash flow to the firm (FCFF) | B19: =B13+B10-B15-B16+B18 -> 20621.24 | C19: =C13+C10-C15-C16+C18 -> 23817.191 | D19: =D13+D10-D15-D16+D18 -> 22938.433 | E19: =E13+E10-E15-E16+E18 -> 24428.513 | F19: =F13+F10-F15-F16+F18 -> 25515.371 | G19: =G13+G10-G15-G16+G18 -> 26942.134
A20: Share of the year counted | C20: =Inputs!$D$26/365 -> 0.50410959 | D20: 1 | E20: 1 | F20: 1 | G20: 1
A21: Discount exponent (years from 30-Jun-2026) | C21: =Inputs!$D$26/365/2 -> 0.25205479 | D21: =Inputs!$D$26/365+0.5 -> 1.0041096 | E21: =D21+1 -> 2.0041096 | F21: =E21+1 -> 3.0041096 | G21: =F21+1 -> 4.0041096
A22: Discount factor | C22: =1/(1+WACC!$B$16)^C21 -> 0.97541856 | D22: =1/(1+WACC!$B$16)^D21 -> 0.90560809 | E22: =1/(1+WACC!$B$16)^E21 -> 0.82045889 | F22: =1/(1+WACC!$B$16)^F21 -> 0.74331578 | G22: =1/(1+WACC!$B$16)^G21 -> 0.673426
A23: PV of FCFF | C23: =C19*C20*C22 -> 11711.338 | D23: =D19*D20*D22 -> 20773.231 | E23: =E19*E20*E22 -> 20042.591 | F23: =F19*F20*F22 -> 18965.978 | G23: =G19*G20*G22 -> 18143.534
A25: Valuation at 30-Jun-2026, rolled to 16-Oct-2026
A26: PV of FCFF, 2H26-FY2030 | B26: =SUM(C23:G23) -> 89636.671
A27: Years from 30-Jun-2026 to end-2030 (terminal value) | B27: =Inputs!D26/365+4 -> 4.5041096
A28: Exit multiple method
A29: Exit EV/EBITDA | B29: =Inputs!D40 -> 5.9172897
A30: Terminal value (FY2030 EBITDA x multiple) | B30: =G8*B29 -> 451163.56
A31: PV of terminal value | B31: =B30/(1+WACC!B16)^B27 -> 289189.26
A32: Enterprise value (exit) | B32: =B26+B31 -> 378825.93
A33: Terminal value / EV | B33: =B31/B32 -> 0.76338296
A34: Perpetual FCFF growth implied by the multiple (template formula) | B34: =(B30*WACC!B16-G19)/(B30+G19) -> 0.04158225
A35: Equity bridge at 30-Jun-2026 (each claim once)
A36: (-) Debt incl. leases | B36: =-Inputs!D15 -> -187021
A37: (+) Cash | B37: =Inputs!D16 -> 16563
A38: (-) Non-controlling interests | B38: =-IF(Inputs!D8="book",Inputs!D19,Inputs!D17/(WACC!B11-Inputs!D18)) -> -18068.829
A39: (+) Associates - seasonal tax payable | B39: =Inputs!D20-Inputs!D21 -> 1959.45
A40: Equity value, exit, 30-Jun-2026 | B40: =B32+SUM(B36:B39) -> 192258.55
A41: Per share, 30-Jun-2026 | B41: =B40/Inputs!D12 -> 44.763929
...

Sheet Sensitivity
A1: Sensitivity of the consolidated value per share today (MXN)
A2: Live formulas. NCI claim and the roll-forward factor held at the base ke, as in the S&P template grids.
A4: Exit method: WACC (rows) x exit EV/EBITDA (columns)
A5: WACC \ multiple | B5: 5 | C5: 5.5 | D5: =Inputs!D40 -> 5.9172897 | E5: 6.5 | F5: 7
A6: =WACC!$B$16-0.01 -> 0.093782417 | B6: =(SUMPRODUCT(DCF!$C$19:$G$19*DCF!$C$20:$G$20/(1+$A6)^DCF!$C$21:$G$21)+DCF!$G$8*B$5/(1+$A6)^DCF!$B$27+SUM(DCF!$B$36:$B$39))/Inputs!$D$12*DCF!$B$42 -> 38.493584 | C6: =(SUMPRODUCT(DCF!$C$19:$G$19*DCF!$C$20:$G$20/(1+$A6)^DCF!$C$21:$G$21)+DCF!$G$8*C$5/(1+$A6)^DCF!$B$27+SUM(DCF!$B$36:$B$39))/Inputs!$D$12*DCF!$B$42 -> 44.640039 | D6: =(SUMPRODUCT(DCF!$C$19:$G$19*DCF!$C$20:$G$20/(1+$A6)^DCF!$C$21:$G$21)+DCF!$G$8*D$5/(1+$A6)^DCF!$B$27+SUM(DCF!$B$36:$B$39))/Inputs!$D$12*DCF!$B$42 -> 49.769744 | E6: =(SUMPRODUCT(DCF!$C$19:$G$19*DCF!$C$20:$G$20/(1+$A6)^DCF!$C$21:$G$21)+DCF!$G$8*E$5/(1+$A6)^DCF!$B$27+SUM(DCF!$B$36:$B$39))/Inputs!$D$12*DCF!$B$42 -> 56.932948 | F6: =(SUMPRODUCT(DCF!$C$19:$G$19*DCF!$C$20:$G$20/(1+$A6)^DCF!$C$21:$G$21)+DCF!$G$8*F$5/(1+$A6)^DCF!$B$27+SUM(DCF!$B$36:$B$39))/Inputs!$D$12*DCF!$B$42 -> 63.079403
A7: =WACC!$B$16-0.005 -> 0.098782417 | B7: =(SUMPRODUCT(DCF!$C$19:$G$19*DCF!$C$20:$G$20/(1+$A7)^DCF!$C$21:$G$21)+DCF!$G$8*B$5/(1+$A7)^DCF!$B$27+SUM(DCF!$B$36:$B$39))/Inputs!$D$12*DCF!$B$42 -> 37.026347 | C7: =(SUMPRODUCT(DCF!$C$19:$G$19*DCF!$C$20:$G$20/(1+$A7)^DCF!$C$21:$G$21)+DCF!$G$8*C$5/(1+$A7)^DCF!$B$27+SUM(DCF!$B$36:$B$39))/Inputs!$D$12*DCF!$B$42 -> 43.047825 | D7: =(SUMPRODUCT(DCF!$C$19:$G$19*DCF!$C$20:$G$20/(1+$A7)^DCF!$C$21:$G$21)+DCF!$G$8*D$5/(1+$A7)^DCF!$B$27+SUM(DCF!$B$36:$B$39))/Inputs!$D$12*DCF!$B$42 -> 48.073227 | E7: =(SUMPRODUCT(DCF!$C$19:$G$19*DCF!$C$20:$G$20/(1+$A7)^DCF!$C$21:$G$21)+DCF!$G$8*E$5/(1+$A7)^DCF!$B$27+SUM(DCF!$B$36:$B$39))/Inputs!$D$12*DCF!$B$42 -> 55.090782 | F7: =(SUMPRODUCT(DCF!$C$19:$G$19*DCF!$C$20:$G$20/(1+$A7)^DCF!$C$21:$G$21)+DCF!$G$8*F$5/(1+$A7)^DCF!$B$27+SUM(DCF!$B$36:$B$39))/Inputs!$D$12*DCF!$B$42 -> 61.11226
A8: =WACC!$B$16 -> 0.10378242 | B8: =(SUMPRODUCT(DCF!$C$19:$G$19*DCF!$C$20:$G$20/(1+$A8)^DCF!$C$21:$G$21)+DCF!$G$8*B$5/(1+$A8)^DCF!$B$27+SUM(DCF!$B$36:$B$39))/Inputs!$D$12*DCF!$B$42 -> 35.593869 | C8: =(SUMPRODUCT(DCF!$C$19:$G$19*DCF!$C$20:$G$20/(1+$A8)^DCF!$C$21:$G$21)+DCF!$G$8*C$5/(1+$A8)^DCF!$B$27+SUM(DCF!$B$36:$B$39))/Inputs!$D$12*DCF!$B$42 -> 41.493462 | D8: =(SUMPRODUCT(DCF!$C$19:$G$19*DCF!$C$20:$G$20/(1+$A8)^DCF!$C$21:$G$21)+DCF!$G$8*D$5/(1+$A8)^DCF!$B$27+SUM(DCF!$B$36:$B$39))/Inputs!$D$12*DCF!$B$42 -> 46.417141 | E8: =(SUMPRODUCT(DCF!$C$19:$G$19*DCF!$C$20:$G$20/(1+$A8)^DCF!$C$21:$G$21)+DCF!$G$8*E$5/(1+$A8)^DCF!$B$27+SUM(DCF!$B$36:$B$39))/Inputs!$D$12*DCF!$B$42 -> 53.292648 | F8: =(SUMPRODUCT(DCF!$C$19:$G$19*DCF!$C$20:$G$20/(1+$A8)^DCF!$C$21:$G$21)+DCF!$G$8*F$5/(1+$A8)^DCF!$B$27+SUM(DCF!$B$36:$B$39))/Inputs!$D$12*DCF!$B$42 -> 59.19224
A9: =WACC!$B$16+0.005 -> 0.10878242 | B9: =(SUMPRODUCT(DCF!$C$19:$G$19*DCF!$C$20:$G$20/(1+$A9)^DCF!$C$21:$G$21)+DCF!$G$8*B$5/(1+$A9)^DCF!$B$27+SUM(DCF!$B$36:$B$39))/Inputs!$D$12*DCF!$B$42 -> 34.195159 | C9: =(SUMPRODUCT(DCF!$C$19:$G$19*DCF!$C$20:$G$20/(1+$A9)^DCF!$C$21:$G$21)+DCF!$G$8*C$5/(1+$A9)^DCF!$B$27+SUM(DCF!$B$36:$B$39))/Inputs!$D$12*DCF!$B$42 -> 39.975868 | D9: =(SUMPRODUCT(DCF!$C$19:$G$19*DCF!$C$20:$G$20/(1+$A9)^DCF!$C$21:$G$21)+DCF!$G$8*D$5/(1+$A9)^DCF!$B$27+SUM(DCF!$B$36:$B$39))/Inputs!$D$12*DCF!$B$42 -> 44.800329 | E9: =(SUMPRODUCT(DCF!$C$19:$G$19*DCF!$C$20:$G$20/(1+$A9)^DCF!$C$21:$G$21)+DCF!$G$8*E$5/(1+$A9)^DCF!$B$27+SUM(DCF!$B$36:$B$39))/Inputs!$D$12*DCF!$B$42 -> 51.537286 | F9: =(SUMPRODUCT(DCF!$C$19:$G$19*DCF!$C$20:$G$20/(1+$A9)^DCF!$C$21:$G$21)+DCF!$G$8*F$5/(1+$A9)^DCF!$B$27+SUM(DCF!$B$36:$B$39))/Inputs!$D$12*DCF!$B$42 -> 57.317996
A10: =WACC!$B$16+0.01 -> 0.11378242 | B10: =(SUMPRODUCT(DCF!$C$19:$G$19*DCF!$C$20:$G$20/(1+$A10)^DCF!$C$21:$G$21)+DCF!$G$8*B$5/(1+$A10)^DCF!$B$27+SUM(DCF!$B$36:$B$39))/Inputs!$D$12*DCF!$B$42 -> 32.829262 | C10: =(SUMPRODUCT(DCF!$C$19:$G$19*DCF!$C$20:$G$20/(1+$A10)^DCF!$C$21:$G$21)+DCF!$G$8*C$5/(1+$A10)^DCF!$B$27+SUM(DCF!$B$36:$B$39))/Inputs!$D$12*DCF!$B$42 -> 38.494002 | D10: =(SUMPRODUCT(DCF!$C$19:$G$19*DCF!$C$20:$G$20/(1+$A10)^DCF!$C$21:$G$21)+DCF!$G$8*D$5/(1+$A10)^DCF!$B$27+SUM(DCF!$B$36:$B$39))/Inputs!$D$12*DCF!$B$42 -> 43.221677 | E10: =(SUMPRODUCT(DCF!$C$19:$G$19*DCF!$C$20:$G$20/(1+$A10)^DCF!$C$21:$G$21)+DCF!$G$8*E$5/(1+$A10)^DCF!$B$27+SUM(DCF!$B$36:$B$39))/Inputs!$D$12*DCF!$B$42 -> 49.823481 | F10: =(SUMPRODUCT(DCF!$C$19:$G$19*DCF!$C$20:$G$20/(1+$A10)^DCF!$C$21:$G$21)+DCF!$G$8*F$5/(1+$A10)^DCF!$B$27+SUM(DCF!$B$36:$B$39))/Inputs!$D$12*DCF!$B$42 -> 55.488221
A13: Gordon (RONIC-consistent): WACC (rows) x terminal growth g (columns)
A14: WACC \ g | B14: =Inputs!$D$42-0.01 -> 0.03125 | C14: =Inputs!$D$42-0.005 -> 0.03625 | D14: =Inputs!$D$42 -> 0.04125 | E14: =Inputs!$D$42+0.005 -> 0.04625 | F14: =Inputs!$D$42+0.01 -> 0.05125
A15: =WACC!$B$16-0.01 -> 0.093782417 | B15: =(SUMPRODUCT(DCF!$C$19:$G$19*DCF!$C$20:$G$20/(1+$A15)^DCF!$C$21:$G$21)+DCF!$G$13*(1+B$14)*(1-B$14/Inputs!$D$44)/($A15-B$14)/(1+$A15)^DCF!$B$27+SUM(DCF!$B$36:$B$39)+DCF!$B$54)/Inputs!$D$12*DCF!$B$42 -> 38.807672 | C15: =(SUMPRODUCT(DCF!$C$19:$G$19*DCF!$C$20:$G$20/(1+$A15)^DCF!$C$21:$G$21)+DCF!$G$13*(1+C$14)*(1-C$14/Inputs!$D$44)/($A15-C$14)/(1+$A15)^DCF!$B$27+SUM(DCF!$B$36:$B$39)+DCF!$B$54)/Inputs!$D$12*DCF!$B$42 -> 41.762517 | D15: =(SUMPRODUCT(DCF!$C$19:$G$19*DCF!$C$20:$G$20/(1+$A15)^DCF!$C$21:$G$21)+DCF!$G$13*(1+D$14)*(1-D$14/Inputs!$D$44)/($A15-D$14)/(1+$A15)^DCF!$B$27+SUM(DCF!$B$36:$B$39)+DCF!$B$54)/Inputs!$D$12*DCF!$B$42 -> 45.246621 | E15: =(SUMPRODUCT(DCF!$C$19:$G$19*DCF!$C$20:$G$20/(1+$A15)^DCF!$C$21:$G$21)+DCF!$G$13*(1+E$14)*(1-E$14/Inputs!$D$44)/($A15-E$14)/(1+$A15)^DCF!$B$27+SUM(DCF!$B$36:$B$39)+DCF!$B$54)/Inputs!$D$12*DCF!$B$42 -> 49.427005 | F15: =(SUMPRODUCT(DCF!$C$19:$G$19*DCF!$C$20:$G$20/(1+$A15)^DCF!$C$21:$G$21)+DCF!$G$13*(1+F$14)*(1-F$14/Inputs!$D$44)/($A15-F$14)/(1+$A15)^DCF!$B$27+SUM(DCF!$B$36:$B$39)+DCF!$B$54)/Inputs!$D$12*DCF!$B$42 -> 54.549227
A16: =WACC!$B$16-0.005 -> 0.098782417 | B16: =(SUMPRODUCT(DCF!$C$19:$G$19*DCF!$C$20:$G$20/(1+$A16)^DCF!$C$21:$G$21)+DCF!$G$13*(1+B$14)*(1-B$14/Inputs!$D$44)/($A16-B$14)/(1+$A16)^DCF!$B$27+SUM(DCF!$B$36:$B$39)+DCF!$B$54)/Inputs!$D$12*DCF!$B$42 -> 32.446453 | C16: =(SUMPRODUCT(DCF!$C$19:$G$19*DCF!$C$20:$G$20/(1+$A16)^DCF!$C$21:$G$21)+DCF!$G$13*(1+C$14)*(1-C$14/Inputs!$D$44)/($A16-C$14)/(1+$A16)^DCF!$B$27+SUM(DCF!$B$36:$B$39)+DCF!$B$54)/Inputs!$D$12*DCF!$B$42 -> 34.726069 | D16: =(SUMPRODUCT(DCF!$C$19:$G$19*DCF!$C$20:$G$20/(1+$A16)^DCF!$C$21:$G$21)+DCF!$G$13*(1+D$14)*(1-D$14/Inputs!$D$44)/($A16-D$14)/(1+$A16)^DCF!$B$27+SUM(DCF!$B$36:$B$39)+DCF!$B$54)/Inputs!$D$12*DCF!$B$42 -> 37.3722 | E16: =(SUMPRODUCT(DCF!$C$19:$G$19*DCF!$C$20:$G$20/(1+$A16)^DCF!$C$21:$G$21)+DCF!$G$13*(1+E$14)*(1-E$14/Inputs!$D$44)/($A16-E$14)/(1+$A16)^DCF!$B$27+SUM(DCF!$B$36:$B$39)+DCF!$B$54)/Inputs!$D$12*DCF!$B$42 -> 40.489499 | F16: =(SUMPRODUCT(DCF!$C$19:$G$19*DCF!$C$20:$G$20/(1+$A16)^DCF!$C$21:$G$21)+DCF!$G$13*(1+F$14)*(1-F$14/Inputs!$D$44)/($A16-F$14)/(1+$A16)^DCF!$B$27+SUM(DCF!$B$36:$B$39)+DCF!$B$54)/Inputs!$D$12*DCF!$B$42 -> 44.226654
A17: =WACC!$B$16 -> 0.10378242 | B17: =(SUMPRODUCT(DCF!$C$19:$G$19*DCF!$C$20:$G$20/(1+$A17)^DCF!$C$21:$G$21)+DCF!$G$13*(1+B$14)*(1-B$14/Inputs!$D$44)/($A17-B$14)/(1+$A17)^DCF!$B$27+SUM(DCF!$B$36:$B$39)+DCF!$B$54)/Inputs!$D$12*DCF!$B$42 -> 26.9648 | C17: =(SUMPRODUCT(DCF!$C$19:$G$19*DCF!$C$20:$G$20/(1+$A17)^DCF!$C$21:$G$21)+DCF!$G$13*(1+C$14)*(1-C$14/Inputs!$D$44)/($A17-C$14)/(1+$A17)^DCF!$B$27+SUM(DCF!$B$36:$B$39)+DCF!$B$54)/Inputs!$D$12*DCF!$B$42 -> 28.732813 | D17: =(SUMPRODUCT(DCF!$C$19:$G$19*DCF!$C$20:$G$20/(1+$A17)^DCF!$C$21:$G$21)+DCF!$G$13*(1+D$14)*(1-D$14/Inputs!$D$44)/($A17-D$14)/(1+$A17)^DCF!$B$27+SUM(DCF!$B$36:$B$39)+DCF!$B$54)/Inputs!$D$12*DCF!$B$42 -> 30.756774 | E17: =(SUMPRODUCT(DCF!$C$19:$G$19*DCF!$C$20:$G$20/(1+$A17)^DCF!$C$21:$G$21)+DCF!$G$13*(1+E$14)*(1-E$14/Inputs!$D$44)/($A17-E$14)/(1+$A17)^DCF!$B$27+SUM(DCF!$B$36:$B$39)+DCF!$B$54)/Inputs!$D$12*DCF!$B$42 -> 33.103413 | F17: =(SUMPRODUCT(DCF!$C$19:$G$19*DCF!$C$20:$G$20/(1+$A17)^DCF!$C$21:$G$21)+DCF!$G$13*(1+F$14)*(1-F$14/Inputs!$D$44)/($A17-F$14)/(1+$A17)^DCF!$B$27+SUM(DCF!$B$36:$B$39)+DCF!$B$54)/Inputs!$D$12*DCF!$B$42 -> 35.86487
A18: =WACC!$B$16+0.005 -> 0.10878242 | B18: =(SUMPRODUCT(DCF!$C$19:$G$19*DCF!$C$20:$G$20/(1+$A18)^DCF!$C$21:$G$21)+DCF!$G$13*(1+B$14)*(1-B$14/Inputs!$D$44)/($A18-B$14)/(1+$A18)^DCF!$B$27+SUM(DCF!$B$36:$B$39)+DCF!$B$54)/Inputs!$D$12*DCF!$B$42 -> 22.192419 | C18: =(SUMPRODUCT(DCF!$C$19:$G$19*DCF!$C$20:$G$20/(1+$A18)^DCF!$C$21:$G$21)+DCF!$G$13*(1+C$14)*(1-C$14/Inputs!$D$44)/($A18-C$14)/(1+$A18)^DCF!$B$27+SUM(DCF!$B$36:$B$39)+DCF!$B$54)/Inputs!$D$12*DCF!$B$42 -> 23.566915 | D18: =(SUMPRODUCT(DCF!$C$19:$G$19*DCF!$C$20:$G$20/(1+$A18)^DCF!$C$21:$G$21)+DCF!$G$13*(1+D$14)*(1-D$14/Inputs!$D$44)/($A18-D$14)/(1+$A18)^DCF!$B$27+SUM(DCF!$B$36:$B$39)+DCF!$B$54)/Inputs!$D$12*DCF!$B$42 -> 25.120638 | E18: =(SUMPRODUCT(DCF!$C$19:$G$19*DCF!$C$20:$G$20/(1+$A18)^DCF!$C$21:$G$21)+DCF!$G$13*(1+E$14)*(1-E$14/Inputs!$D$44)/($A18-E$14)/(1+$A18)^DCF!$B$27+SUM(DCF!$B$36:$B$39)+DCF!$B$54)/Inputs!$D$12*DCF!$B$42 -> 26.896579 | F18: =(SUMPRODUCT(DCF!$C$19:$G$19*DCF!$C$20:$G$20/(1+$A18)^DCF!$C$21:$G$21)+DCF!$G$13*(1+F$14)*(1-F$14/Inputs!$D$44)/($A18-F$14)/(1+$A18)^DCF!$B$27+SUM(DCF!$B$36:$B$39)+DCF!$B$54)/Inputs!$D$12*DCF!$B$42 -> 28.952678
A19: =WACC!$B$16+0.01 -> 0.11378242 | B19: =(SUMPRODUCT(DCF!$C$19:$G$19*DCF!$C$20:$G$20/(1+$A19)^DCF!$C$21:$G$21)+DCF!$G$13*(1+B$14)*(1-B$14/Inputs!$D$44)/($A19-B$14)/(1+$A19)^DCF!$B$27+SUM(DCF!$B$36:$B$39)+DCF!$B$54)/Inputs!$D$12*DCF!$B$42 -> 18.000287 | C19: =(SUMPRODUCT(DCF!$C$19:$G$19*DCF!$C$20:$G$20/(1+$A19)^DCF!$C$21:$G$21)+DCF!$G$13*(1+C$14)*(1-C$14/Inputs!$D$44)/($A19-C$14)/(1+$A19)^DCF!$B$27+SUM(DCF!$B$36:$B$39)+DCF!$B$54)/Inputs!$D$12*DCF!$B$42 -> 19.068221 | D19: =(SUMPRODUCT(DCF!$C$19:$G$19*DCF!$C$20:$G$20/(1+$A19)^DCF!$C$21:$G$21)+DCF!$G$13*(1+D$14)*(1-D$14/Inputs!$D$44)/($A19-D$14)/(1+$A19)^DCF!$B$27+SUM(DCF!$B$36:$B$39)+DCF!$B$54)/Inputs!$D$12*DCF!$B$42 -> 20.261216 | E19: =(SUMPRODUCT(DCF!$C$19:$G$19*DCF!$C$20:$G$20/(1+$A19)^DCF!$C$21:$G$21)+DCF!$G$13*(1+E$14)*(1-E$14/Inputs!$D$44)/($A19-E$14)/(1+$A19)^DCF!$B$27+SUM(DCF!$B$36:$B$39)+DCF!$B$54)/Inputs!$D$12*DCF!$B$42 -> 21.607049 | F19: =(SUMPRODUCT(DCF!$C$19:$G$19*DCF!$C$20:$G$20/(1+$A19)^DCF!$C$21:$G$21)+DCF!$G$13*(1+F$14)*(1-F$14/Inputs!$D$44)/($A19-F$14)/(1+$A19)^DCF!$B$27+SUM(DCF!$B$36:$B$39)+DCF!$B$54)/Inputs!$D$12*DCF!$B$42 -> 23.142383
A21: Centre cells (green) equal DCF!B43 and DCF!B56 (see Checks).

Sheet Compare
A1: The three models side by side
A2: Values read from each workbook (cached results); consolidated = this workbook at the base settings. Per-share values are for 16-Oct-2026.
A4: Item | B4: v3 (valuation/) | C4: Alejandro | D4: Diego | E4: Consolidated | F4: Bucket | G4: What differs and the rule used
A5: Provenance
A6: Workbook | B6: BIMBOA_DCF_v3.xlsx | C6: Bimbo_DCF_Alejandro.xlsm | D6: SPG_DCF_independent_Diego.xlsm | E6: BIMBOA_DCF_consolidated_v1.xlsx | G6: valuation/ and valuation/team-models/
A7: Forecast source | B7: v3 drivers (regional build) | C7: v3 drivers, copied (controls: FCFF = v3) | D7: Capital IQ consensus FY26-28 + fade | E7: Average of the two sets | F7: Judgment | G7: Alejandro is not an independent set: his FCFF FY2026-30 equal v3 to the peso
A8: Horizon | B8: 10 years (FY2026-35) | C8: 5 years (2H26-FY2030) | D8: 5 years (76-day stub-FY2030) | E8: 5 years (2H26-FY2030) | F8: Mechanic | G8: Template horizon for both teammates; v3 kept as a reference row
A9: Valuation date mechanics | B9: Fiscal-year-end roll (0.79 y) | C9: 30-Jun anchor, rolled at ke | D9: 16-Oct, 30-Jun balance sheet | E9: 30-Jun anchor, rolled at ke | F9: Mechanic | G9: Diego's mix of dates drops about 3.5 months of cash flow (Walks: -0.75)
A10: Cost of capital
A11: Risk-free | B11: 0.075101 | C11: 0.075101188 | D11: 0.075101188 | E11: 0.075101188 | F11: Fact | G11: Same in all three
A12: Country risk premium (EBITDA-weighted) | B12: 0.020496 | C12: 0.020496339 | D12: 0.020496778 | E12: 0.020496339 | F12: Fact | G12: Same method and weights
A13: Unlevered beta | B13: 0.53 | C13: 0.53 | D13: 0.56 | E13: 0.545 | F13: Judgment | G13: Averaged
A14: D/E | B14: 0.7431 | C14: 0.7430795 | D14: 0.77421573 | E14: 0.7430795 | F14: Fact | G14: Company debt; Diego's CIQ debt figure is reconverted at the wrong FX rate
A15: Levered beta | B15: 0.806 | C15: 0.8056825 | D15: 0.86349257 | E15: 0.82848483
A16: Cost of equity | B16: 0.12943651 | C16: 0.12943619 | D16: 0.13186465 | E16: 0.13039389
A17: WACC | B17: 0.10323276 | C17: 0.10323299 | D17: 0.1039829 | E17: 0.10378242 | G17: Less than 10 bp apart
A18: Forecast
A19: Revenue FY2030 (MXN m) | B19: n/a | C19: 504070.15 | D19: 511536.39 | E19: 507796.5 | F19: Judgment
A20: Revenue CAGR FY2025-30 | B20: n/a | C20: 0.033766338 | D20: 0.03681076 | E20: 0.035290266 | F20: Judgment
A21: EBITDA margin FY2030 | B21: n/a | C21: 0.153 | D21: 0.14729733 | E21: 0.15014867 | F21: Judgment | G21: The largest judgment gap (Walks: -3.3 per share)
A22: Capex + new leases / revenue FY2030 | B22: n/a | C22: 0.072361607 | D22: 0.061830874 | E22: 0.068789588 | F22: Judgment + mechanic | G22: Capex averaged; leases recomputed with the v3 mechanics
A23: Tax on EBIT | B23: 0.34 | C23: 0.34 | D23: 0.3 | E23: 0.32 | F23: Judgment (flagged) | G23: Averaged
A24: FCFF FY2026-30, sum (MXN m) | B24: n/a | C24: 117350.41 | D24: 137620.96 | E24: 123641.64
A25: Terminal value
A26: Exit EV/EBITDA | B26: 6 | C26: 6 | D26: 6.4 | E26: 5.9172897 | F26: Judgment | G26: Diego's rule on clean data gives 5.83x; average with v3 6.0x
A27: Perpetual growth implied by the multiple | B27: 0.050788 | C27: 0.047195239 | D27: 0.036618228 | E27: 0.04158225
A28: Terminal growth g (Gordon) | B28: 0.0425 | C28: 0.0425 | D28: 0.04 | E28: 0.04125 | F28: Judgment | G28: Diego: his reverse-DCF g
A29: RONIC behind the Gordon value | B29: 0.146184 | C29: 0.20011852 | D29: n/a | E29: 0.146184 | F29: Judgment | G29: Alejandro's template-style Gordon implies 20%
A30: Equity bridge (MXN m)
A31: Debt incl. leases | B31: n/a | C31: 187021 | D31: 194918.3 | E31: 187021 | F31: Fact | G31: See Inputs row 15
A32: Cash | B32: n/a | C32: 16563 | D32: 17022.805 | E32: 16563 | F32: Fact
A33: Non-controlling interests | B33: n/a | C33: 18242.855 | D33: 743 | E33: 18068.829 | F33: Mechanic (provisional) | G33: Market value in v3 and Alejandro; book in Diego
A34: Associates - seasonal tax | B34: n/a | C34: 1959.45 | D34: 0 | E34: 1959.45 | F34: Mechanic
A35: Other debt-like claims (Gordon only) | B35: n/a | C35: 18135 | D35: 0 | E35: 18135 | F35: Mechanic
A36: Shares (millions) | B36: 4294.9 | C36: 4294.9437 | D36: 4296.2842 | E36: 4294.9437 | F36: Fact
A37: Results (MXN per share, 16-Oct-2026)
A38: Exit multiple | B38: 45.715085 | C38: 47.134224 | D38: 54.938043 | E38: 46.417141
A39: Gordon (as each model computes it) | B39: 33.551593 | C39: 36.912947 | D39: n/a | E39: 30.756774 | G39: Consolidated: RONIC-consistent
A40: Exit vs price | B40: -0.2198791 | C40: -0.19566171 | D40: -0.062490739 | E40: -0.20789862

Sheet Walks
A1: Why the values differ
A2: Values from the Python replica (valuation/build/consolidate_models.py), which reproduces both workbooks to the centavo (Checks). One change at a time, in order.
A4: Walk 1 - Alejandro to Diego, exit method (MXN per share, 16-Oct-2026)
A5: Step | B5: Value | C5: Change | D5: Type
A6: Alejandro: v3 inputs on the S&P template (30-Jun anchor, rolled to 16-Oct at ke) | B6: 47.134224 | D6: Start
A7: Valuation date: 76-day stub discounted from 16-Oct, balance sheet still 30-Jun (no roll-forward) | B7: 46.38199 | C7: -0.75223409 | D7: Mechanic
A8: Debt: add derivative liabilities that sit inside Capital IQ total debt (+2,658) | B8: 45.763029 | C8: -0.61896038 | D8: Fact
A9: Debt and cash: US$ figures reconverted at 17.96 MXN/US$; CIQ's own peso and dollar figures imply 17.47 | B9: 44.650304 | C9: -1.1127254 | D9: Fact (FX reconversion, to confirm)
A10: Shares: Capital IQ 4,296.3m instead of the BMV notice 4,294.9m | B10: 44.636372 | C10: -0.013931511 | D10: Fact
A11: Bridge: drop associates (+6,498) and the seasonal tax payable (-4,538) | B11: 44.180292 | C11: -0.45608016 | D11: Mechanic
A12: NCI at book (743) instead of market value (18,243) | B12: 48.253546 | C12: 4.0732535 | D12: Mechanic (provisional)
A13: WACC 10.32% -> 10.40% (unlevered beta 0.53 -> 0.56; D/E 0.743 -> 0.774) | B13: 48.024794 | C13: -0.22875142 | D13: Judgment (beta) + fact (debt)
A14: Revenue path: v3 regional build -> Capital IQ consensus + fade | B14: 49.299074 | C14: 1.2742801 | D14: Judgment
A15: EBITDA margin path: v3 (to 15.3%) -> consensus (held at 14.7%) | B15: 46.014117 | C15: -3.284957 | D15: Judgment
A16: D&A path: v3 (5.85-5.9% of sales) -> template mechanics (D&A rises to 100% of capex + leases) | B16: 46.171812 | C16: 0.15769504 | D16: Mechanic (template D&A)
A17: Capex excluding leases: v3 (4.6% -> 5.5%) -> consensus (5.2% -> 4.8%) | B17: 47.386457 | C17: 1.2146452 | D17: Judgment
A18: New leases: principal + growth in the liability -> principal only (1.39%) | B18: 48.628699 | C18: 1.2422412 | D18: Mechanic
... A21: Exit multiple 6.0x -> 6.4x | B21: 54.938043 | C21: 4.6264027 | D21: Judgment + data basis
A22: Diego's workbook (SPG_DCF_independent_Diego.xlsm, DCF!I155) | B22: 54.938043 | C22: =B22-B21 -> 0 | D22: gap must be 0.00
A24: Walk 2 - v3 set to Diego's set on the same facts and mechanics (where the analysts really differ)
A25: Step | B25: Exit | C25: Change | D25: Gordon (RONIC) | E25: Change
A26: v3 set on reconciled facts and mechanics (= Alejandro) | B26: 47.134224 | D26: 30.356137
A27: Unlevered beta 0.53 -> 0.56 (WACC 10.32% -> 10.43%) | B27: 46.876761 | C27: -0.2574629 | D27: 29.095173 | E27: -1.2609636
A28: Revenue path: v3 regional build -> consensus + fade | B28: 48.0848 | C28: 1.2080396 | D28: 30.104702 | E28: 1.0095286
A29: EBITDA margin path: v3 (to 15.3%) -> consensus (held at 14.7%) | B29: 44.754078 | C29: -3.3307228 | D29: 25.921295 | E29: -4.1834066
A30: Capex excluding leases: v3 (4.6% -> 5.5%) -> consensus (5.2% -> 4.8%) | B30: 45.809708 | C30: 1.0556306 | D30: 26.976926 | E30: 1.0556306
A31: Working capital path | B31: 46.18268 | C31: 0.37297211 | D31: 27.349898 | E31: 0.37297211
A32: Tax on EBIT 34% -> 30% | B32: 47.630505 | C32: 1.4478251 | D32: 32.153464 | E32: 4.8035661
A33: Exit multiple 6.0x -> 5.83x (Diego's core-median rule on lease-consistent peer data) | B33: 45.705477 | C33: -1.9250284 | D33: 32.153464 | E33: 0
A34: Terminal growth 4.25% -> 4.00% (Gordon only) | B34: 45.705477 | C34: 0 | D34: 31.09366 | E34: -1.0598037
A36: Reading: once facts and mechanics are reconciled the two sets are only about Ps 1.3 apart on the exit method. Margin is the main disagreement (v3 higher); revenue, capex and the tax rate offset it (Diego higher).

Sheet Risk_ESG
A1: Risks and ESG translated into value (consolidated base)
A2: Each row changes one input against the base. Values from the Python replica. ESG evidence from Diego's General ESG Report v2 (team-models/BIMBOA_ESG_Report_EN_Diego.pdf); figures he tagged [unverified] are not used.
A4: Lever | B4: Theme and evidence | C4: Exit (MXN/share) | D4: Gordon RONIC (MXN/share)
A5: EBITDA margin -50 bp every year | B5: Wheat is the main input: raw materials ~64% of cost of sales [sourced/calc]; the CFO tied 60 bp of 2022 EBITDA margin to the wheat cycle [guidance]; the 2026 wheat move (+17%) is [unverified] | C5: -3.7175227 | D5: -4.5860846
A6: EBITDA margin +50 bp every year | B6: Productivity plan delivers more | C6: 3.7175227 | D6: 4.5860846
A7: Capex +50 bp of revenue every year | B7: 101 work centres in high or extremely high water stress [sourced]; withdrawal +15.1% since FY2019 [calc]; a separate sustainability capex envelope since 2025, amount not disclosed [sourced] | C7: -2.047824 | D7: -2.047824
A8: Revenue growth -50 bp every year | B8: Front-of-pack labelling phase 3 from 2028-01-01 and school-food rules from 2025-03-29 [sourced]; consumer shifts on sugar and refined flour | C8: -1.8433948 | D8: -1.5735242
A9: Exit multiple -0.5x | B9: Controlled company: 72.03% control group and 38.9% independent directors [sourced]; minority protection 1 of 10 on his compiled rubric [assumption]; governance is the weak pillar in every rating source | C9: -5.8995929 | D9: 0
A10: WACC +50 bp | B10: Country and currency risk (not ESG) | C10: -1.6168114 | D10: -5.636136
A11: One-off claim of MXN 1bn | B11: Canada Bread price-fixing class actions open with no provision; the CAD 50m fine was paid in 2023 [sourced]; uncertain tax positions 8,537 [sourced] already deducted in Gordon | C11: -0.24143082 | D11: -0.24143082
A12: Recurring cost of MXN 1bn a year from FY2027 (pre-tax) | B12: Mexican carbon market, pilot 2020-25, rules unpublished [sourced]; extended producer responsibility under the law of 2026-01-19 [sourced] | C12: -1.4316863 | D12: -1.7737769
A13: Bimbo 23L coupon step-up (Scope 3 target missed in 2030) | B13: +25 bp on MXN 12,000m from 21-Nov-2031 to 20-May-2033 if the -28% Scope 3 target is not verified [sourced]; 2025 Scope 3 +46.7% vs the bond base [calc] | C13: -0.0043042728 | D13: -0.0043042728
A15: Rules of thumb (live)
A16: Each MXN 1bn of claim at 30-Jun-2026, per share today | C16: =-1000/Inputs!D12*DCF!B42 -> -0.24143082
A17: No ESG adjustment to the discount rate: Diego's report finds no source that links Bimbo's ESG scores to its cost of debt or equity, and the 23L step-up is about 0.05% of FY2025 EBITDA. Adding a premium would double-count risks already in the cash flows.

Sheet Football
A1: Football field (MXN per share, 16-Oct-2026)
A2: Price MXN 58.60. Ranges: consolidated grids at +/-0.5 pp of WACC and +/-0.5x or +/-0.5 pp of g. The team sets the target.
A4: Method | B4: Low | C4: Point | D4: High | E4: Note
A5: 52-week range | B5: 53.03 | D5: 68.67 | E5: Capital IQ, 06-Oct-2026
A6: Consolidated - exit multiple | B6: 39.975868 | C6: 46.417141 | D6: 55.090782 | E6: 5.92x; range: WACC +/-0.5 pp and 5.5x-6.5x
A7: Consolidated - Gordon, RONIC 14.6% | B7: 23.566915 | C7: 30.756774 | D7: 40.489499 | E7: g 4.125%; range: WACC and g +/-0.5 pp
A8: Consolidated - Gordon, template style | C8: 41.645673 | E8: Implies RONIC of about 33%: not credible
A9: v3 (10 years) - exit 6.0x / Gordon | B9: 33.551593 | D9: 45.715085 | E9: Published v3
A10: Alejandro - exit 6.0x / Gordon | B10: 36.912947 | D10: 47.134224 | E10: v3 inputs, 5 years
A11: Diego - exit 6.4x | C11: 54.938043 | E11: Before fixing facts and mechanics
A12: Comps (v3 table) - core 5.53x / all eligible 8.27x | B12: 35.95 | D12: 74.87 | E12: LTM EBITDA 60,919; peer-EV claims
A13: Current price | C13: 58.6

Sheet Checks
A1: Checks
