Workbook

Sheet TearSheet
B2: Financials & Peer Analysis
B4: Company set-up (static values: the CIQ Excel plugin is not used)
B5: Step 1. Company identifier | E5: BMV:BIMBO A | H5: Notes:
H6: Layout after the S&P Capital IQ Pro 'Financials & Peer Analysis' template. Numbers are static and tagged; detail and sources are in Detail_TearSheet and Inputs_Sources.
H7: A = actual (CIQ quarterly sums or company filings); E = consensus mean (CIQ, 20-Sep-2026). Shaded blank = not in the local data; pending a CIQ refresh.
B8: Step 2. Latest completed year | E8: FY2025
B11: Step 3. As-of date | E11: 2026-10-16
B14: Step 4. Currency | E14: Mexican peso (MXN)
B16: Step 5. Magnitude | E16: Millions
B18: Step 6. Source | E18: Company filings and CIQ (A); S&P Capital IQ consensus mean (E)
B21: Step 7. Refresh | E21: Not linked to CIQ: re-run valuation/build/build_peer_workbook.py
B25: Grupo Bimbo, S.A.B. de C.V. | K25: Data in (MXN m), except per share
E26: A | F26: A | G26: A | H26: E | I26: E | J26: E | K26: E
B27: Income Statement | E27: FY2023 | F27: FY2024 | G27: FY2025 | H27: FY2026 | I27: FY2027 | J27: FY2028 | K27: FY2029 | L27: Tag / source
B28: Sales | C28: Total revenue | E28: =IF(ISNUMBER(Detail_TearSheet!E7),Detail_TearSheet!E7,"n/a") -> 399879 | F28: =IF(ISNUMBER(Detail_TearSheet!F7),Detail_TearSheet!F7,"n/a") -> 408335 | G28: =IF(ISNUMBER(Detail_TearSheet!G7),Detail_TearSheet!G7,"n/a") -> 426963 | H28: =IF(ISNUMBER(Detail_TearSheet!H7),Detail_TearSheet!H7,"n/a") -> 426274.7 | I28: =IF(ISNUMBER(Detail_TearSheet!I7),Detail_TearSheet!I7,"n/a") -> 445288 | J28: =IF(ISNUMBER(Detail_TearSheet!J7),Detail_TearSheet!J7,"n/a") -> 468430.9 | K28: =Inputs_Sources!$D$705 -> 477018 | L28: [sourced] A: Detail_TearSheet (CIQ / filings); E: CIQ consensus mean
B29: - growth YoY | E29: =IFERROR(E28/Detail_TearSheet!D7-1,"n/a") -> 0.0029420174 | F29: =IFERROR(F28/E28-1,"n/a") -> 0.021146397 | G29: =IFERROR(G28/F28-1,"n/a") -> 0.045619406 | H29: =IFERROR(H28/G28-1,"n/a") -> -0.0016120835 | I29: =IFERROR(I28/H28-1,"n/a") -> 0.044603398 | J29: =IFERROR(J28/I28-1,"n/a") -> 0.05197288 | K29: =IFERROR(K28/J28-1,"n/a") -> 0.018331626 | L29: [calc]
B30: Gross Profit | C30: Gross Profit / (loss) | E30: =IF(ISNUMBER(Detail_TearSheet!E9),Detail_TearSheet!E9,"n/a") -> 206159.5 | F30: =IF(ISNUMBER(Detail_TearSheet!F9),Detail_TearSheet!F9,"n/a") -> 214928 | G30: =IF(ISNUMBER(Detail_TearSheet!G9),Detail_TearSheet!G9,"n/a") -> 224241.7 | H30: =IFERROR(H28*Detail_TearSheet!H11/100,"n/a") -> 222941.67 | I30: =IFERROR(I28*Detail_TearSheet!I11/100,"n/a") -> 231549.76 | J30: =IFERROR(J28*Detail_TearSheet!J11/100,"n/a") -> 243818.28 | K30: =IFERROR(K28*Inputs_Sources!$D$715/100,"n/a") -> 248526.38 | L30: [sourced] A: Detail_TearSheet (CIQ / filings); E: CIQ consensus mean; E = revenue x consensus gross margin [calc]
B31: SG&A | C31: Selling, general and administrative expenses | E31: =IF(ISNUMBER(Detail_TearSheet!E12),Detail_TearSheet!E12,"n/a") -> 165748 | F31: =IF(ISNUMBER(Detail_TearSheet!F12),Detail_TearSheet!F12,"n/a") -> 175164 | G31: =IF(ISNUMBER(Detail_TearSheet!G12),Detail_TearSheet!G12,"n/a") -> 184186 | H31: =IF(ISNUMBER(Detail_TearSheet!H12),Detail_TearSheet!H12,"n/a") -> 177262 | I31: =IF(ISNUMBER(Detail_TearSheet!I12),Detail_TearSheet!I12,"n/a") -> 189938 | J31: =IF(ISNUMBER(Detail_TearSheet!J12),Detail_TearSheet!J12,"n/a") -> 197030 | K31: =Inputs_Sources!$D$716 -> 216662 | L31: [sourced] A: Detail_TearSheet (CIQ / filings); E: CIQ consensus mean
B32: Operating Expenses | C32: Total operating expenses | E32: =IF(ISNUMBER(Detail_TearSheet!E14),Detail_TearSheet!E14,"n/a") -> 168704.7 | F32: =IF(ISNUMBER(Detail_TearSheet!F14),Detail_TearSheet!F14,"n/a") -> 181779 | G32: =IF(ISNUMBER(Detail_TearSheet!G14),Detail_TearSheet!G14,"n/a") -> 187970.1 | H32: =IFERROR(H30-H33,"n/a") -> 185495.67 | I32: =IFERROR(I30-I33,"n/a") -> 192770.76 | J32: =IFERROR(J30-J33,"n/a") -> 201892.28 | K32: =IFERROR(K30-K33,"n/a") -> 208504.38 | L32: [sourced] A: Detail_TearSheet (CIQ / filings); E: CIQ consensus mean; E = gross profit - EBIT [calc]
B33: EBIT | C33: Operating income/(loss), company basis | E33: =IF(ISNUMBER(Detail_TearSheet!E16),Detail_TearSheet!E16,"n/a") -> 35455 | F33: =IF(ISNUMBER(Detail_TearSheet!F16),Detail_TearSheet!F16,"n/a") -> 33149 | G33: =IF(ISNUMBER(Detail_TearSheet!G16),Detail_TearSheet!G16,"n/a") -> 34146 | H33: =IF(ISNUMBER(Detail_TearSheet!H16),Detail_TearSheet!H16,"n/a") -> 37446 | I33: =IF(ISNUMBER(Detail_TearSheet!I16),Detail_TearSheet!I16,"n/a") -> 38779 | J33: =IF(ISNUMBER(Detail_TearSheet!J16),Detail_TearSheet!J16,"n/a") -> 41926 | K33: =Inputs_Sources!$D$707 -> 40022 | L33: [sourced] A: Detail_TearSheet (CIQ / filings); E: CIQ consensus mean
B34: EBITDA | C34: Adjusted EBITDA, company (IFRS 16) | E34: =IF(ISNUMBER(Detail_TearSheet!E19),Detail_TearSheet!E19,"n/a") -> 54942 | F34: =IF(ISNUMBER(Detail_TearSheet!F19),Detail_TearSheet!F19,"n/a") -> 55473 | G34: =IF(ISNUMBER(Detail_TearSheet!G19),Detail_TearSheet!G19,"n/a") -> 59456 | H34: =IF(ISNUMBER(Detail_TearSheet!H19),Detail_TearSheet!H19,"n/a") -> 62117 | I34: =IF(ISNUMBER(Detail_TearSheet!I19),Detail_TearSheet!I19,"n/a") -> 64891 | J34: =IF(ISNUMBER(Detail_TearSheet!J19),Detail_TearSheet!J19,"n/a") -> 68999 | K34: =Inputs_Sources!$D$706 -> 70667.5 | L34: [sourced] A: Detail_TearSheet (CIQ / filings); E: CIQ consensus mean
B35: Pre tax profit | C35: Income from continuing operations before taxes | E35: =IF(ISNUMBER(Detail_TearSheet!E21),Detail_TearSheet!E21,"n/a") -> 25324 | F35: =IF(ISNUMBER(Detail_TearSheet!F21),Detail_TearSheet!F21,"n/a") -> 21034 | G35: =IF(ISNUMBER(Detail_TearSheet!G21),Detail_TearSheet!G21,"n/a") -> 20143 | H35: =IF(ISNUMBER(Detail_TearSheet!H21),Detail_TearSheet!H21,"n/a") -> 23597 | I35: =IF(ISNUMBER(Detail_TearSheet!I21),Detail_TearSheet!I21,"n/a") -> 25677 | J35: =IF(ISNUMBER(Detail_TearSheet!J21),Detail_TearSheet!J21,"n/a") -> 30308 | L35: [sourced] A: Detail_TearSheet (CIQ / filings); E: CIQ consensus mean; E: not in CIQ consensus
B36: NPAT | C36: Net income to majority | E36: =IF(ISNUMBER(Detail_TearSheet!E22),Detail_TearSheet!E22,"n/a") -> 15477 | F36: =IF(ISNUMBER(Detail_TearSheet!F22),Detail_TearSheet!F22,"n/a") -> 12544 | G36: =IF(ISNUMBER(Detail_TearSheet!G22),Detail_TearSheet!G22,"n/a") -> 11133 | H36: =IF(ISNUMBER(Detail_TearSheet!H22),Detail_TearSheet!H22,"n/a") -> 13688 | I36: =IF(ISNUMBER(Detail_TearSheet!I22),Detail_TearSheet!I22,"n/a") -> 15011 | J36: =IF(ISNUMBER(Detail_TearSheet!J22),Detail_TearSheet!J22,"n/a") -> 17371 | K36: =Inputs_Sources!$D$708 -> 16735 | L36: [sourced] A: Detail_TearSheet (CIQ / filings); E: CIQ consensus mean
B37: EPS | C37: EPS, basic, total (E: normalised) | E37: =IF(ISNUMBER(Detail_TearSheet!E24),Detail_TearSheet!E24,"n/a") -> 3.5 | F37: =IF(ISNUMBER(Detail_TearSheet!F24),Detail_TearSheet!F24,"n/a") -> 2.88 | G37: =IF(ISNUMBER(Detail_TearSheet!G24),Detail_TearSheet!G24,"n/a") -> 2.58 | H37: =IF(ISNUMBER(Detail_TearSheet!H24),Detail_TearSheet!H24,"n/a") -> 3.07 | I37: =IF(ISNUMBER(Detail_TearSheet!I24),Detail_TearSheet!I24,"n/a") -> 3.35 | J37: =IF(ISNUMBER(Detail_TearSheet!J24),Detail_TearSheet!J24,"n/a") -> 3.8 | K37: =Inputs_Sources!$D$709 -> 4.02 | L37: [sourced] A: Detail_TearSheet (CIQ / filings); E: CIQ consensus mean
B38: - growth YoY | E38: =IFERROR(E37/Detail_TearSheet!D24-1,"n/a") -> -0.66793169 | F38: =IFERROR(F37/E37-1,"n/a") -> -0.17714286 | G38: =IFERROR(G37/F37-1,"n/a") -> -0.10416667 | H38: =IFERROR(H37/G37-1,"n/a") -> 0.18992248 | I38: =IFERROR(I37/H37-1,"n/a") -> 0.091205212 | J38: =IFERROR(J37/I37-1,"n/a") -> 0.13432836 | K38: =IFERROR(K37/J37-1,"n/a") -> 0.057894737 | L38: [calc]
B39: DPS | C39: Dividend per share | E39: =IF(ISNUMBER(Detail_TearSheet!E25),Detail_TearSheet!E25,"n/a") -> 0.78 | F39: =IF(ISNUMBER(Detail_TearSheet!F25),Detail_TearSheet!F25,"n/a") -> 0.94 | G39: =IF(ISNUMBER(Detail_TearSheet!G25),Detail_TearSheet!G25,"n/a") -> 1 | H39: =IF(ISNUMBER(Detail_TearSheet!H25),Detail_TearSheet!H25,"n/a") -> 1.01 | I39: =IF(ISNUMBER(Detail_TearSheet!I25),Detail_TearSheet!I25,"n/a") -> 1.05 | J39: =IF(ISNUMBER(Detail_TearSheet!J25),Detail_TearSheet!J25,"n/a") -> 1.24 | K39: =Inputs_Sources!$D$710 -> 1.24 | L39: [sourced] A: Detail_TearSheet (CIQ / filings); E: CIQ consensus mean
B41: Balance Sheet
B42: Cash and Equivalents | C42: Cash and short-term investments | E42: =IF(ISNUMBER(Detail_TearSheet!E28),Detail_TearSheet!E28,"n/a") -> 6353 | F42: =IF(ISNUMBER(Detail_TearSheet!F28),Detail_TearSheet!F28,"n/a") -> 8057 | G42: =IF(ISNUMBER(Detail_TearSheet!G28),Detail_TearSheet!G28,"n/a") -> 8535 | L42: [sourced] A: Detail_TearSheet (CIQ / filings); E: CIQ consensus mean; E: not in CIQ consensus
B43: Current Assets | C43: Total current assets | E43: =IF(ISNUMBER(Detail_TearSheet!E29),Detail_TearSheet!E29,"n/a") -> 58914 | F43: =IF(ISNUMBER(Detail_TearSheet!F29),Detail_TearSheet!F29,"n/a") -> 67180 | G43: =IF(ISNUMBER(Detail_TearSheet!G29),Detail_TearSheet!G29,"n/a") -> 64671 | L43: [sourced] A: Detail_TearSheet (CIQ / filings); E: CIQ consensus mean; E: not in CIQ consensus
B44: Non-Current Assets | C44: Total non-current assets | E44: =IF(ISNUMBER(Detail_TearSheet!E31),Detail_TearSheet!E31,"n/a") -> 289188 | F44: =IF(ISNUMBER(Detail_TearSheet!F31),Detail_TearSheet!F31,"n/a") -> 349624 | G44: =IF(ISNUMBER(Detail_TearSheet!G31),Detail_TearSheet!G31,"n/a") -> 345134 | L44: [sourced] A: Detail_TearSheet (CIQ / filings); E: CIQ consensus mean; E: not in CIQ consensus
B45: Current Liabilities | C45: Total current liabilities | E45: =IF(ISNUMBER(Detail_TearSheet!E32),Detail_TearSheet!E32,"n/a") -> 87192 | F45: =IF(ISNUMBER(Detail_TearSheet!F32),Detail_TearSheet!F32,"n/a") -> 85155 | G45: =IF(ISNUMBER(Detail_TearSheet!G32),Detail_TearSheet!G32,"n/a") -> 90573 | L45: [sourced] A: Detail_TearSheet (CIQ / filings); E: CIQ consensus mean; E: not in CIQ consensus
B46: Non-Current Liabilities | C46: Total non-current liabilities | E46: =IF(ISNUMBER(Detail_TearSheet!E34),Detail_TearSheet!E34,"n/a") -> 149282 | F46: =IF(ISNUMBER(Detail_TearSheet!F34),Detail_TearSheet!F34,"n/a") -> 203951 | G46: =IF(ISNUMBER(Detail_TearSheet!G34),Detail_TearSheet!G34,"n/a") -> 198977 | L46: [sourced] A: Detail_TearSheet (CIQ / filings); E: CIQ consensus mean; E: not in CIQ consensus
B47: Net Debt | C47: Net debt (A: CIQ incl. IFRS 16 leases; E: consensus) | E47: =IF(ISNUMBER(Detail_TearSheet!E37),Detail_TearSheet!E37,"n/a") -> 133186 | F47: =IF(ISNUMBER(Detail_TearSheet!F37),Detail_TearSheet!F37,"n/a") -> 179338 | G47: =IF(ISNUMBER(Detail_TearSheet!G37),Detail_TearSheet!G37,"n/a") -> 182232 | H47: =Inputs_Sources!$D$678 -> 146911.02 | I47: =Inputs_Sources!$D$690 -> 133766.76 | J47: =Inputs_Sources!$D$702 -> 119433.54 | K47: =Inputs_Sources!$D$714 -> 109707 | L47: [sourced] A: Detail_TearSheet (CIQ / filings); E: CIQ consensus mean; E = consensus net debt (broker definition; FY25A 149,031 vs 182,232 incl. leases)
B49: Cash Flow
B50: Capex | C50: Capital expenditures | E50: =IF(ISNUMBER(Detail_TearSheet!E42),Detail_TearSheet!E42,"n/a") -> -34754 | F50: =IF(ISNUMBER(Detail_TearSheet!F42),Detail_TearSheet!F42,"n/a") -> -29402 | G50: =IF(ISNUMBER(Detail_TearSheet!G42),Detail_TearSheet!G42,"n/a") -> -22530 | H50: =IF(ISNUMBER(Detail_TearSheet!H42),Detail_TearSheet!H42,"n/a") -> -21978.8 | I50: =IF(ISNUMBER(Detail_TearSheet!I42),Detail_TearSheet!I42,"n/a") -> -22341.3 | J50: =IF(ISNUMBER(Detail_TearSheet!J42),Detail_TearSheet!J42,"n/a") -> -22933.5 | K50: =-Inputs_Sources!$D$711 -> -19308 | L50: [sourced] A: Detail_TearSheet (CIQ / filings); E: CIQ consensus mean
B51: Change in working capital | C51: (Increase)/decrease in working capital | E51: =IF(ISNUMBER(Detail_TearSheet!E46),Detail_TearSheet!E46,"n/a") -> 11165 | F51: =IF(ISNUMBER(Detail_TearSheet!F46),Detail_TearSheet!F46,"n/a") -> 1017 | G51: =IF(ISNUMBER(Detail_TearSheet!G46),Detail_TearSheet!G46,"n/a") -> -696 | L51: [sourced] A: Detail_TearSheet (CIQ / filings); E: CIQ consensus mean; E: not in CIQ consensus
B52: Net cash flow from operations | C52: Net cash flows from operating activities | E52: =IF(ISNUMBER(Detail_TearSheet!E41),Detail_TearSheet!E41,"n/a") -> 31411 | F52: =IF(ISNUMBER(Detail_TearSheet!F41),Detail_TearSheet!F41,"n/a") -> 39907 | G52: =IF(ISNUMBER(Detail_TearSheet!G41),Detail_TearSheet!G41,"n/a") -> 47753 | H52: =Inputs_Sources!$D$676 -> 35594.5 | I52: =Inputs_Sources!$D$688 -> 38165 | J52: =Inputs_Sources!$D$700 -> 43566 | L52: [sourced] A: Detail_TearSheet (CIQ / filings); E: CIQ consensus mean
B53: Net cash flow from investing activities | C53: Net cash flows from investing activities | E53: =IF(ISNUMBER(Detail_TearSheet!E44),Detail_TearSheet!E44,"n/a") -> -42440 | F53: =IF(ISNUMBER(Detail_TearSheet!F44),Detail_TearSheet!F44,"n/a") -> -36138 | G53: =IF(ISNUMBER(Detail_TearSheet!G44),Detail_TearSheet!G44,"n/a") -> -34652 | L53: [sourced] A: Detail_TearSheet (CIQ / filings); E: CIQ consensus mean; E: not in CIQ consensus
B54: Net cash flow from financing activities | C54: Net cash flows from financing activities | E54: =IF(ISNUMBER(Detail_TearSheet!E45),Detail_TearSheet!E45,"n/a") -> 5904 | F54: =IF(ISNUMBER(Detail_TearSheet!F45),Detail_TearSheet!F45,"n/a") -> n/a | G54: =IF(ISNUMBER(Detail_TearSheet!G45),Detail_TearSheet!G45,"n/a") -> -11908 | L54: [sourced] A: Detail_TearSheet (CIQ / filings); E: CIQ consensus mean; E: not in CIQ consensus
B56: Margins / Ratios
...

Sheet PeerAnalysis
B2: Performance Valuation - Grupo Bimbo and peers
B4: Notes:
B5: Pricing date 16-Oct-2026. USD m; MXN figures converted at the pricing-date rate, MXN 18.479 per USD (Bimbo's own multiples are computed in MXN).
B6: Enterprise value on one claim basis for every company: financial debt + lease liabilities + NCI at book - cash (pensions, MEPP and derivatives excluded); US GAAP EBITDA + operating lease cost.
B7: Shaded blank = not available (peers' 52-week range and 1-day change were not returned by Capital IQ). Price changes over 1, 2, 3 and 5 years are month-end approximations (base 31-Oct); QTD and YTD are exact.
B8: NTM and STM: CIQ consensus calendarised from the pricing date with fiscal-year day weights (STM = the 12 months after NTM).
B9: Data in ($M)
F10: Market Data
F11: Share Price ($) | G11: Price High ($) | H11: Price Low ($) | I11: Market Cap. ($M) | J11: Enterprise Value ($M) | K11: Price Performance (%) | R11: Dividends per share
B12: Company Name | D12: Group | E12: Exchange:Ticker | G12: 52W | H12: 52W | K12: 1D | L12: 1Y | M12: 2Y | N12: 3Y | O12: 5Y | P12: QTD | Q12: YTD
B13: =Detail_PeerAnalysis!A12 -> Flowers Foods, Inc. | D13: Core | E13: =Detail_PeerAnalysis!B12 -> NYSE:FLO | F13: =IFERROR(Detail_PeerAnalysis!F12*Detail_PeerAnalysis!H12,"n/a") -> 6.1089109 | L13: =IF(AND(ISNUMBER(Inputs_Sources!$D$346),ISNUMBER(Inputs_Sources!$D$349)),Inputs_Sources!$D$346/Inputs_Sources!$D$349-1,"n/a") -> -0.48784577 | M13: =IF(AND(ISNUMBER(Inputs_Sources!$D$346),ISNUMBER(Inputs_Sources!$D$350)),Inputs_Sources!$D$346/Inputs_Sources!$D$350-1,"n/a") -> -0.7251462 | N13: =IF(AND(ISNUMBER(Inputs_Sources!$D$346),ISNUMBER(Inputs_Sources!$D$351)),Inputs_Sources!$D$346/Inputs_Sources!$D$351-1,"n/a") -> -0.72138623 | O13: =IF(AND(ISNUMBER(Inputs_Sources!$D$346),ISNUMBER(Inputs_Sources!$D$352)),Inputs_Sources!$D$346/Inputs_Sources!$D$352-1,"n/a") -> -0.75313131 | P13: =IF(AND(ISNUMBER(Inputs_Sources!$D$346),ISNUMBER(Inputs_Sources!$D$347)),Inputs_Sources!$D$346/Inputs_Sources!$D$347-1,"n/a") -> 0.1009009 | Q13: =IF(AND(ISNUMBER(Inputs_Sources!$D$346),ISNUMBER(Inputs_Sources!$D$348)),Inputs_Sources!$D$346/Inputs_Sources!$D$348-1,"n/a") -> -0.43841912 | R13: =IF(ISNUMBER(Inputs_Sources!$D$353),Inputs_Sources!$D$353,"n/a") -> 0.87
B14: =Detail_PeerAnalysis!A13 -> Gruma, S.A.B. de C.V. | D14: Core | E14: =Detail_PeerAnalysis!B13 -> BMV:GRUMA B | F14: =IFERROR(Detail_PeerAnalysis!F13*Detail_PeerAnalysis!H13,"n/a") -> 13.097029 | L14: =IF(AND(ISNUMBER(Inputs_Sources!$D$383),ISNUMBER(Inputs_Sources!$D$386)),Inputs_Sources!$D$383/Inputs_Sources!$D$386-1,"n/a") -> -0.22954679 | M14: =IF(AND(ISNUMBER(Inputs_Sources!$D$383),ISNUMBER(Inputs_Sources!$D$387)),Inputs_Sources!$D$383/Inputs_Sources!$D$387-1,"n/a") -> -0.24071926 | N14: =IF(AND(ISNUMBER(Inputs_Sources!$D$383),ISNUMBER(Inputs_Sources!$D$388)),Inputs_Sources!$D$383/Inputs_Sources!$D$388-1,"n/a") -> -0.24553314 | O14: =IF(AND(ISNUMBER(Inputs_Sources!$D$383),ISNUMBER(Inputs_Sources!$D$389)),Inputs_Sources!$D$383/Inputs_Sources!$D$389-1,"n/a") -> 0.11309524 | P14: =IF(AND(ISNUMBER(Inputs_Sources!$D$383),ISNUMBER(Inputs_Sources!$D$384)),Inputs_Sources!$D$383/Inputs_Sources!$D$384-1,"n/a") -> 0.0046047583 | Q14: =IF(AND(ISNUMBER(Inputs_Sources!$D$383),ISNUMBER(Inputs_Sources!$D$385)),Inputs_Sources!$D$383/Inputs_Sources!$D$385-1,"n/a") -> -0.24027858 | R14: =IF(ISNUMBER(Inputs_Sources!$D$390),Inputs_Sources!$D$390,"n/a") -> 0.32
B15: =Detail_PeerAnalysis!A14 -> Yamazaki Baking Co., Ltd. | D15: Core | E15: =Detail_PeerAnalysis!B14 -> TSE:2212 | F15: =IFERROR(Detail_PeerAnalysis!F14*Detail_PeerAnalysis!H14,"n/a") -> 24.153886 | L15: =IF(AND(ISNUMBER(Inputs_Sources!$D$420),ISNUMBER(Inputs_Sources!$D$423)),Inputs_Sources!$D$420/Inputs_Sources!$D$423-1,"n/a") -> 0.23379275 | M15: =IF(AND(ISNUMBER(Inputs_Sources!$D$420),ISNUMBER(Inputs_Sources!$D$424)),Inputs_Sources!$D$420/Inputs_Sources!$D$424-1,"n/a") -> 0.18364349 | N15: =IF(AND(ISNUMBER(Inputs_Sources!$D$420),ISNUMBER(Inputs_Sources!$D$425)),Inputs_Sources!$D$420/Inputs_Sources!$D$425-1,"n/a") -> 0.1427896 | O15: =IF(AND(ISNUMBER(Inputs_Sources!$D$420),ISNUMBER(Inputs_Sources!$D$426)),Inputs_Sources!$D$420/Inputs_Sources!$D$426-1,"n/a") -> 0.5932762 | P15: =IF(AND(ISNUMBER(Inputs_Sources!$D$420),ISNUMBER(Inputs_Sources!$D$421)),Inputs_Sources!$D$420/Inputs_Sources!$D$421-1,"n/a") -> 0.053159041 | Q15: =IF(AND(ISNUMBER(Inputs_Sources!$D$420),ISNUMBER(Inputs_Sources!$D$422)),Inputs_Sources!$D$420/Inputs_Sources!$D$422-1,"n/a") -> 0.14712862 | R15: =IF(ISNUMBER(Inputs_Sources!$D$427),Inputs_Sources!$D$427,"n/a") -> 0.39
B16: =Detail_PeerAnalysis!A15 -> ARYZTA AG | D16: Core | E16: =Detail_PeerAnalysis!B15 -> SWX:ARYN | F16: =IFERROR(Detail_PeerAnalysis!F15*Detail_PeerAnalysis!H15,"n/a") -> 49.145161 | L16: =IF(AND(ISNUMBER(Inputs_Sources!$D$457),ISNUMBER(Inputs_Sources!$D$460)),Inputs_Sources!$D$457/Inputs_Sources!$D$460-1,"n/a") -> -0.23412884 | M16: =IF(AND(ISNUMBER(Inputs_Sources!$D$457),ISNUMBER(Inputs_Sources!$D$461)),Inputs_Sources!$D$457/Inputs_Sources!$D$461-1,"n/a") -> -0.30423693 | N16: =IF(AND(ISNUMBER(Inputs_Sources!$D$457),ISNUMBER(Inputs_Sources!$D$462)),Inputs_Sources!$D$457/Inputs_Sources!$D$462-1,"n/a") -> -0.32850109 | O16: =IF(AND(ISNUMBER(Inputs_Sources!$D$457),ISNUMBER(Inputs_Sources!$D$463)),Inputs_Sources!$D$457/Inputs_Sources!$D$463-1,"n/a") -> -0.059747223 | P16: =IF(AND(ISNUMBER(Inputs_Sources!$D$457),ISNUMBER(Inputs_Sources!$D$458)),Inputs_Sources!$D$457/Inputs_Sources!$D$458-1,"n/a") -> 0.079358101 | Q16: =IF(AND(ISNUMBER(Inputs_Sources!$D$457),ISNUMBER(Inputs_Sources!$D$459)),Inputs_Sources!$D$457/Inputs_Sources!$D$459-1,"n/a") -> -0.24693252 | R16: =IF(ISNUMBER(Inputs_Sources!$D$464),Inputs_Sources!$D$464,"n/a") -> 0
B17: =Detail_PeerAnalysis!A16 -> The J. M. Smucker Company | D17: Secondary | E17: =Detail_PeerAnalysis!B16 -> NYSE:SJM | F17: =IFERROR(Detail_PeerAnalysis!F16*Detail_PeerAnalysis!H16,"n/a") -> 127.45787 | L17: =IF(AND(ISNUMBER(Inputs_Sources!$D$494),ISNUMBER(Inputs_Sources!$D$497)),Inputs_Sources!$D$494/Inputs_Sources!$D$497-1,"n/a") -> 0.23061323 | M17: =IF(AND(ISNUMBER(Inputs_Sources!$D$494),ISNUMBER(Inputs_Sources!$D$498)),Inputs_Sources!$D$494/Inputs_Sources!$D$498-1,"n/a") -> 0.12263237 | N17: =IF(AND(ISNUMBER(Inputs_Sources!$D$494),ISNUMBER(Inputs_Sources!$D$499)),Inputs_Sources!$D$494/Inputs_Sources!$D$499-1,"n/a") -> 0.11937807 | O17: =IF(AND(ISNUMBER(Inputs_Sources!$D$494),ISNUMBER(Inputs_Sources!$D$500)),Inputs_Sources!$D$494/Inputs_Sources!$D$500-1,"n/a") -> 0.037196809 | P17: =IF(AND(ISNUMBER(Inputs_Sources!$D$494),ISNUMBER(Inputs_Sources!$D$495)),Inputs_Sources!$D$494/Inputs_Sources!$D$495-1,"n/a") -> 0.071650828 | Q17: =IF(AND(ISNUMBER(Inputs_Sources!$D$494),ISNUMBER(Inputs_Sources!$D$496)),Inputs_Sources!$D$494/Inputs_Sources!$D$496-1,"n/a") -> 0.30283202 | R17: =IF(ISNUMBER(Inputs_Sources!$D$501),Inputs_Sources!$D$501,"n/a") -> 4.42
B18: =Detail_PeerAnalysis!A17 -> The Campbell's Company | D18: Secondary | E18: =Detail_PeerAnalysis!B17 -> NasdaqGS:CPB | F18: =IFERROR(Detail_PeerAnalysis!F17*Detail_PeerAnalysis!H17,"n/a") -> 19.872233 | L18: =IF(AND(ISNUMBER(Inputs_Sources!$D$531),ISNUMBER(Inputs_Sources!$D$534)),Inputs_Sources!$D$531/Inputs_Sources!$D$534-1,"n/a") -> -0.34052439 | M18: =IF(AND(ISNUMBER(Inputs_Sources!$D$531),ISNUMBER(Inputs_Sources!$D$535)),Inputs_Sources!$D$531/Inputs_Sources!$D$535-1,"n/a") -> -0.57406217 | N18: =IF(AND(ISNUMBER(Inputs_Sources!$D$531),ISNUMBER(Inputs_Sources!$D$536)),Inputs_Sources!$D$531/Inputs_Sources!$D$536-1,"n/a") -> -0.50829003 | O18: =IF(AND(ISNUMBER(Inputs_Sources!$D$531),ISNUMBER(Inputs_Sources!$D$537)),Inputs_Sources!$D$531/Inputs_Sources!$D$537-1,"n/a") -> -0.50262829 | P18: =IF(AND(ISNUMBER(Inputs_Sources!$D$531),ISNUMBER(Inputs_Sources!$D$532)),Inputs_Sources!$D$531/Inputs_Sources!$D$532-1,"n/a") -> 0.0020171457 | Q18: =IF(AND(ISNUMBER(Inputs_Sources!$D$531),ISNUMBER(Inputs_Sources!$D$533)),Inputs_Sources!$D$531/Inputs_Sources!$D$533-1,"n/a") -> -0.287047 | R18: =IF(ISNUMBER(Inputs_Sources!$D$538),Inputs_Sources!$D$538,"n/a") -> 1.56
B19: =Detail_PeerAnalysis!A18 -> Mondelez International, Inc. | D19: Secondary | E19: =Detail_PeerAnalysis!B18 -> NasdaqGS:MDLZ | F19: =IFERROR(Detail_PeerAnalysis!F18*Detail_PeerAnalysis!H18,"n/a") -> 63.910366 | L19: =IF(AND(ISNUMBER(Inputs_Sources!$D$568),ISNUMBER(Inputs_Sources!$D$571)),Inputs_Sources!$D$568/Inputs_Sources!$D$571-1,"n/a") -> 0.112252 | M19: =IF(AND(ISNUMBER(Inputs_Sources!$D$568),ISNUMBER(Inputs_Sources!$D$572)),Inputs_Sources!$D$568/Inputs_Sources!$D$572-1,"n/a") -> -0.066734813 | N19: =IF(AND(ISNUMBER(Inputs_Sources!$D$568),ISNUMBER(Inputs_Sources!$D$573)),Inputs_Sources!$D$568/Inputs_Sources!$D$573-1,"n/a") -> -0.034737955 | O19: =IF(AND(ISNUMBER(Inputs_Sources!$D$568),ISNUMBER(Inputs_Sources!$D$574)),Inputs_Sources!$D$568/Inputs_Sources!$D$574-1,"n/a") -> 0.052189661 | P19: =IF(AND(ISNUMBER(Inputs_Sources!$D$568),ISNUMBER(Inputs_Sources!$D$569)),Inputs_Sources!$D$568/Inputs_Sources!$D$569-1,"n/a") -> 0.10532688 | Q19: =IF(AND(ISNUMBER(Inputs_Sources!$D$568),ISNUMBER(Inputs_Sources!$D$570)),Inputs_Sources!$D$568/Inputs_Sources!$D$570-1,"n/a") -> 0.18725618 | R19: =IF(ISNUMBER(Inputs_Sources!$D$575),Inputs_Sources!$D$575,"n/a") -> 2
B20: =Detail_PeerAnalysis!A19 -> Arca Continental, S.A.B. de C.V. | D20: Secondary | E20: =Detail_PeerAnalysis!B19 -> BMV:AC | F20: =IFERROR(Detail_PeerAnalysis!F19*Detail_PeerAnalysis!H19,"n/a") -> 11.345852 | L20: =IF(AND(ISNUMBER(Inputs_Sources!$D$605),ISNUMBER(Inputs_Sources!$D$608)),Inputs_Sources!$D$605/Inputs_Sources!$D$608-1,"n/a") -> 0.17027864 | M20: =IF(AND(ISNUMBER(Inputs_Sources!$D$605),ISNUMBER(Inputs_Sources!$D$609)),Inputs_Sources!$D$605/Inputs_Sources!$D$609-1,"n/a") -> 0.32631579 | N20: =IF(AND(ISNUMBER(Inputs_Sources!$D$605),ISNUMBER(Inputs_Sources!$D$610)),Inputs_Sources!$D$605/Inputs_Sources!$D$610-1,"n/a") -> 0.26845638 | O20: =IF(AND(ISNUMBER(Inputs_Sources!$D$605),ISNUMBER(Inputs_Sources!$D$611)),Inputs_Sources!$D$605/Inputs_Sources!$D$611-1,"n/a") -> 0.85597381 | P20: =IF(AND(ISNUMBER(Inputs_Sources!$D$605),ISNUMBER(Inputs_Sources!$D$606)),Inputs_Sources!$D$605/Inputs_Sources!$D$606-1,"n/a") -> 0.055865922 | Q20: =IF(AND(ISNUMBER(Inputs_Sources!$D$605),ISNUMBER(Inputs_Sources!$D$607)),Inputs_Sources!$D$605/Inputs_Sources!$D$607-1,"n/a") -> 0.04805915 | R20: =IF(ISNUMBER(Inputs_Sources!$D$612),Inputs_Sources!$D$612,"n/a") -> 0.24
B21: =Detail_PeerAnalysis!A20 -> PepsiCo, Inc. | D21: Secondary | E21: =Detail_PeerAnalysis!B20 -> NasdaqGS:PEP | F21: =IFERROR(Detail_PeerAnalysis!F20*Detail_PeerAnalysis!H20,"n/a") -> 131.504 | L21: =IF(AND(ISNUMBER(Inputs_Sources!$D$642),ISNUMBER(Inputs_Sources!$D$645)),Inputs_Sources!$D$642/Inputs_Sources!$D$645-1,"n/a") -> -0.099938394 | M21: =IF(AND(ISNUMBER(Inputs_Sources!$D$642),ISNUMBER(Inputs_Sources!$D$646)),Inputs_Sources!$D$642/Inputs_Sources!$D$646-1,"n/a") -> -0.20827312 | N21: =IF(AND(ISNUMBER(Inputs_Sources!$D$642),ISNUMBER(Inputs_Sources!$D$647)),Inputs_Sources!$D$642/Inputs_Sources!$D$647-1,"n/a") -> -0.19469623 | O21: =IF(AND(ISNUMBER(Inputs_Sources!$D$642),ISNUMBER(Inputs_Sources!$D$648)),Inputs_Sources!$D$642/Inputs_Sources!$D$648-1,"n/a") -> -0.18632426 | P21: =IF(AND(ISNUMBER(Inputs_Sources!$D$642),ISNUMBER(Inputs_Sources!$D$643)),Inputs_Sources!$D$642/Inputs_Sources!$D$643-1,"n/a") -> 0.037642045 | Q21: =IF(AND(ISNUMBER(Inputs_Sources!$D$642),ISNUMBER(Inputs_Sources!$D$644)),Inputs_Sources!$D$642/Inputs_Sources!$D$644-1,"n/a") -> -0.08382107 | R21: =IF(ISNUMBER(Inputs_Sources!$D$649),Inputs_Sources!$D$649,"n/a") -> 5.81
B22: =Detail_PeerAnalysis!A11 -> Grupo Bimbo, S.A.B. de C.V. (subject) | D22: Subject Company >> | E22: =Detail_PeerAnalysis!B11 -> BMV:BIMBO A | F22: =IFERROR(Detail_PeerAnalysis!F11*Detail_PeerAnalysis!H11,"n/a") -> 3.1711673 | G22: =Inputs_Sources!$D$717/Inputs_Sources!$D$10 -> 3.7161102 | H22: =Inputs_Sources!$D$718/Inputs_Sources!$D$10 -> 2.869744 | K22: =IF(ISNUMBER(Inputs_Sources!$D$719),Inputs_Sources!$D$719,"n/a") -> 0.010868 | L22: =IF(AND(ISNUMBER(Inputs_Sources!$D$720),ISNUMBER(Inputs_Sources!$D$723)),Inputs_Sources!$D$720/Inputs_Sources!$D$723-1,"n/a") -> -0.086658354 | M22: =IF(AND(ISNUMBER(Inputs_Sources!$D$720),ISNUMBER(Inputs_Sources!$D$724)),Inputs_Sources!$D$720/Inputs_Sources!$D$724-1,"n/a") -> -0.054381152 | N22: =IF(AND(ISNUMBER(Inputs_Sources!$D$720),ISNUMBER(Inputs_Sources!$D$725)),Inputs_Sources!$D$720/Inputs_Sources!$D$725-1,"n/a") -> -0.19923476 | O22: =IF(AND(ISNUMBER(Inputs_Sources!$D$720),ISNUMBER(Inputs_Sources!$D$726)),Inputs_Sources!$D$720/Inputs_Sources!$D$726-1,"n/a") -> -0.038398425 | P22: =IF(AND(ISNUMBER(Inputs_Sources!$D$720),ISNUMBER(Inputs_Sources!$D$721)),Inputs_Sources!$D$720/Inputs_Sources!$D$721-1,"n/a") -> 0.067395264 | Q22: =IF(AND(ISNUMBER(Inputs_Sources!$D$720),ISNUMBER(Inputs_Sources!$D$722)),Inputs_Sources!$D$720/Inputs_Sources!$D$722-1,"n/a") -> -0.006779661 | R22: =Inputs_Sources!$D$727/Inputs_Sources!$D$10 -> 0.058174144
R27: EBITDA, YoY (%)
F28: Financials ($M) | R28: Ratios & Margins
F29: FY2024 | G29: FY2025 | H29: FY2026 | I29: LTM | J29: NTM | K29: STM | L29: FY2024 | M29: FY2025 | N29: FY2026 | O29: LTM | P29: NTM | Q29: STM | R29: FY2024 | S29: FY2025 | T29: FY2026 | U29: LTM | V29: NTM | W29: STM
B30: Company Name | D30: Group | E30: Exchange:Ticker | F30: Total revenue | L30: Gross Profit / (loss) | R30: EBITDA, YoY (%)
B31: =Detail_PeerAnalysis!A12 -> Flowers Foods, Inc. | D31: Core | E31: =Detail_PeerAnalysis!B12 -> NYSE:FLO | F31: =Detail_PeerAnalysis!B26 -> 5103.5 | G31: =Detail_PeerAnalysis!C26 -> 5256.5 | H31: =IF(ISNUMBER(Inputs_Sources!$D$337),Inputs_Sources!$D$337,"n/a") -> 5075.8 | I31: =Detail_PeerAnalysis!D26 -> 5223.9 | J31: =IF(ISNUMBER(Detail_PeerAnalysis!E26),Detail_PeerAnalysis!E26,"n/a") -> 5062.0877 | K31: =IF(AND(ISNUMBER(Inputs_Sources!$D$246),ISNUMBER(Inputs_Sources!$D$339)),Detail_PeerAnalysis!D61*Inputs_Sources!$D$246+Detail_PeerAnalysis!E61*Inputs_Sources!$D$339,"n/a") -> 5038.1625 | L31: =IF(ISNUMBER(Inputs_Sources!$D$356),Inputs_Sources!$D$356,"n/a") -> 2526.3 | M31: =IF(ISNUMBER(Inputs_Sources!$D$357),Inputs_Sources!$D$357,"n/a") -> 2568.9 | N31: =IF(AND(ISNUMBER(Inputs_Sources!$D$337),ISNUMBER(Inputs_Sources!$D$358)),Inputs_Sources!$D$337*Inputs_Sources!$D$358/100,"n/a") -> 2424.7097 | O31: =IF(ISNUMBER(Detail_PeerAnalysis!M26),Detail_PeerAnalysis!M26,"n/a") -> 2540.4 | P31: =IF(AND(ISNUMBER(Inputs_Sources!$D$244),ISNUMBER(Inputs_Sources!$D$246),ISNUMBER(Inputs_Sources!$D$358),ISNUMBER(Inputs_Sources!$D$359)),(Detail_PeerAnalysis!D61*Inputs_Sources!$D$244*Inputs_Sources!$D$358+Detail_PeerAnalysis!E61*Inputs_Sources!$D$246*Inputs_Sources!$D$359)/100,"n/a") -> 2394.3783 | Q31: =IF(AND(ISNUMBER(Inputs_Sources!$D$246),ISNUMBER(Inputs_Sources!$D$339),ISNUMBER(Inputs_Sources!$D$359),ISNUMBER(Inputs_Sources!$D$360)),(Detail_PeerAnalysis!D61*Inputs_Sources!$D$246*Inputs_Sources!$D$359+Detail_PeerAnalysis!E61*Inputs_Sources!$D$339*Inputs_Sources!$D$360)/100,"n/a") -> 2413.1744 | R31: =IF(ISNUMBER(Inputs_Sources!$D$336),IFERROR(Detail_PeerAnalysis!F26/Inputs_Sources!$D$336-1,"n/a"),"n/a") -> 0.065479844 | S31: =IFERROR(Detail_PeerAnalysis!G26/Detail_PeerAnalysis!F26-1,"n/a") -> -0.011330901 | T31: =IF(ISNUMBER(Inputs_Sources!$D$338),IFERROR(Inputs_Sources!$D$338/Detail_PeerAnalysis!G26-1,"n/a"),"n/a") -> -0.10916861 | V31: =IFERROR(Detail_PeerAnalysis!K26/Detail_PeerAnalysis!H26-1,"n/a") -> -0.10398749 | W31: =IF(AND(ISNUMBER(Inputs_Sources!$D$245),ISNUMBER(Inputs_Sources!$D$340)),IFERROR((Detail_PeerAnalysis!D61*Inputs_Sources!$D$245+Detail_PeerAnalysis!E61*Inputs_Sources!$D$340)/Detail_PeerAnalysis!K26-1,"n/a"),"n/a") -> -0.010008289
B32: =Detail_PeerAnalysis!A13 -> Gruma, S.A.B. de C.V. | D32: Core | E32: =Detail_PeerAnalysis!B13 -> BMV:GRUMA B | F32: =Detail_PeerAnalysis!B27 -> 6486.9 | G32: =Detail_PeerAnalysis!C27 -> 6374.6 | H32: =IF(ISNUMBER(Inputs_Sources!$D$374),Inputs_Sources!$D$374,"n/a") -> 6648.35 | I32: =Detail_PeerAnalysis!D27 -> 6500.1 | J32: =IF(ISNUMBER(Detail_PeerAnalysis!E27),Detail_PeerAnalysis!E27,"n/a") -> 6487.4487 | K32: =IF(AND(ISNUMBER(Inputs_Sources!$D$331),ISNUMBER(Inputs_Sources!$D$376)),Detail_PeerAnalysis!D62*Inputs_Sources!$D$331+Detail_PeerAnalysis!E62*Inputs_Sources!$D$376,"n/a") -> 6579.5375 | L32: =IF(ISNUMBER(Inputs_Sources!$D$393),Inputs_Sources!$D$393,"n/a") -> 2498.6 | M32: =IF(ISNUMBER(Inputs_Sources!$D$394),Inputs_Sources!$D$394,"n/a") -> 2492.7 | N32: =IF(AND(ISNUMBER(Inputs_Sources!$D$374),ISNUMBER(Inputs_Sources!$D$395)),Inputs_Sources!$D$374*Inputs_Sources!$D$395/100,"n/a") -> 2562.9389 | O32: =IF(ISNUMBER(Detail_PeerAnalysis!M27),Detail_PeerAnalysis!M27,"n/a") -> 2522.2 | P32: =IF(AND(ISNUMBER(Inputs_Sources!$D$330),ISNUMBER(Inputs_Sources!$D$331),ISNUMBER(Inputs_Sources!$D$395),ISNUMBER(Inputs_Sources!$D$396)),(Detail_PeerAnalysis!D62*Inputs_Sources!$D$330*Inputs_Sources!$D$395+Detail_PeerAnalysis!E62*Inputs_Sources!$D$331*Inputs_Sources!$D$396)/100,"n/a") -> 2500.9115 | Q32: =IF(AND(ISNUMBER(Inputs_Sources!$D$331),ISNUMBER(Inputs_Sources!$D$376),ISNUMBER(Inputs_Sources!$D$396),ISNUMBER(Inputs_Sources!$D$397)),(Detail_PeerAnalysis!D62*Inputs_Sources!$D$331*Inputs_Sources!$D$396+Detail_PeerAnalysis!E62*Inputs_Sources!$D$376*Inputs_Sources!$D$397)/100,"n/a") -> 2539.0217 | R32: =IF(ISNUMBER(Inputs_Sources!$D$373),IFERROR(Detail_PeerAnalysis!F27/Inputs_Sources!$D$373-1,"n/a"),"n/a") -> n/a | S32: =IFERROR(Detail_PeerAnalysis!G27/Detail_PeerAnalysis!F27-1,"n/a") -> 0.0043320661 | T32: =IF(ISNUMBER(Inputs_Sources!$D$375),IFERROR(Inputs_Sources!$D$375/Detail_PeerAnalysis!G27-1,"n/a"),"n/a") -> -0.021681338 | V32: =IFERROR(Detail_PeerAnalysis!K27/Detail_PeerAnalysis!H27-1,"n/a") -> -0.034908517 | W32: =IF(AND(ISNUMBER(Inputs_Sources!$D$332),ISNUMBER(Inputs_Sources!$D$377)),IFERROR((Detail_PeerAnalysis!D62*Inputs_Sources!$D$332+Detail_PeerAnalysis!E62*Inputs_Sources!$D$377)/Detail_PeerAnalysis!K27-1,"n/a"),"n/a") -> 0.020722605
B33: =Detail_PeerAnalysis!A14 -> Yamazaki Baking Co., Ltd. | D33: Core | E33: =Detail_PeerAnalysis!B14 -> TSE:2212 | F33: =Detail_PeerAnalysis!B28 -> 8224.6 | G33: =Detail_PeerAnalysis!C28 -> 8773.2 | H33: =IF(ISNUMBER(Inputs_Sources!$D$411),Inputs_Sources!$D$411,"n/a") -> 8564.4 | I33: =Detail_PeerAnalysis!D28 -> 8669.9 | J33: =IF(ISNUMBER(Detail_PeerAnalysis!E28),Detail_PeerAnalysis!E28,"n/a") -> 8746.3529 | K33: =IF(AND(ISNUMBER(Inputs_Sources!$D$251),ISNUMBER(Inputs_Sources!$D$413)),Detail_PeerAnalysis!D63*Inputs_Sources!$D$251+Detail_PeerAnalysis!E63*Inputs_Sources!$D$413,"n/a") -> 8925.6652 | L33: =IF(ISNUMBER(Inputs_Sources!$D$430),Inputs_Sources!$D$430,"n/a") -> 2678.3 | M33: =IF(ISNUMBER(Inputs_Sources!$D$431),Inputs_Sources!$D$431,"n/a") -> 2865.9 | N33: =IF(AND(ISNUMBER(Inputs_Sources!$D$411),ISNUMBER(Inputs_Sources!$D$432)),Inputs_Sources!$D$411*Inputs_Sources!$D$432/100,"n/a") -> 2835.6728 | O33: =IF(ISNUMBER(Detail_PeerAnalysis!M28),Detail_PeerAnalysis!M28,"n/a") -> 2834.9 | P33: =IF(AND(ISNUMBER(Inputs_Sources!$D$249),ISNUMBER(Inputs_Sources!$D$251),ISNUMBER(Inputs_Sources!$D$432),ISNUMBER(Inputs_Sources!$D$433)),(Detail_PeerAnalysis!D63*Inputs_Sources!$D$249*Inputs_Sources!$D$432+Detail_PeerAnalysis!E63*Inputs_Sources!$D$251*Inputs_Sources!$D$433)/100,"n/a") -> 2898.6933 | Q33: =IF(AND(ISNUMBER(Inputs_Sources!$D$251),ISNUMBER(Inputs_Sources!$D$413),ISNUMBER(Inputs_Sources!$D$433),ISNUMBER(Inputs_Sources!$D$434)),(Detail_PeerAnalysis!D63*Inputs_Sources!$D$251*Inputs_Sources!$D$433+Detail_PeerAnalysis!E63*Inputs_Sources!$D$413*Inputs_Sources!$D$434)/100,"n/a") -> 2967.3424 | R33: =IF(ISNUMBER(Inputs_Sources!$D$410),IFERROR(Detail_PeerAnalysis!F28/Inputs_Sources!$D$410-1,"n/a"),"n/a") -> 0.058971774 | S33: =IFERROR(Detail_PeerAnalysis!G28/Detail_PeerAnalysis!F28-1,"n/a") -> 0.12962082 | T33: =IF(ISNUMBER(Inputs_Sources!$D$412),IFERROR(Inputs_Sources!$D$412/Detail_PeerAnalysis!G28-1,"n/a"),"n/a") -> -0.016713483 | V33: =IFERROR(Detail_PeerAnalysis!K28/Detail_PeerAnalysis!H28-1,"n/a") -> 0.036884536 | W33: =IF(AND(ISNUMBER(Inputs_Sources!$D$250),ISNUMBER(Inputs_Sources!$D$414)),IFERROR((Detail_PeerAnalysis!D63*Inputs_Sources!$D$250+Detail_PeerAnalysis!E63*Inputs_Sources!$D$414)/Detail_PeerAnalysis!K28-1,"n/a"),"n/a") -> 0.03819267
B34: =Detail_PeerAnalysis!A15 -> ARYZTA AG | D34: Core | E34: =Detail_PeerAnalysis!B15 -> SWX:ARYN | F34: =Detail_PeerAnalysis!B29 -> 2374.1 | G34: =Detail_PeerAnalysis!C29 -> 2513.7 | H34: =IF(ISNUMBER(Inputs_Sources!$D$448),Inputs_Sources!$D$448,"n/a") -> 2594.7 | I34: =Detail_PeerAnalysis!D29 -> 2567.4 | J34: =IF(ISNUMBER(Detail_PeerAnalysis!E29),Detail_PeerAnalysis!E29,"n/a") -> 2569.3718 | K34: =IF(AND(ISNUMBER(Inputs_Sources!$D$256),ISNUMBER(Inputs_Sources!$D$450)),Detail_PeerAnalysis!D64*Inputs_Sources!$D$256+Detail_PeerAnalysis!E64*Inputs_Sources!$D$450,"n/a") -> 2599.2904 | L34: =IF(ISNUMBER(Inputs_Sources!$D$467),Inputs_Sources!$D$467,"n/a") -> 507.6 | M34: =IF(ISNUMBER(Inputs_Sources!$D$468),Inputs_Sources!$D$468,"n/a") -> 506.5 | N34: =IF(AND(ISNUMBER(Inputs_Sources!$D$448),ISNUMBER(Inputs_Sources!$D$469)),Inputs_Sources!$D$448*Inputs_Sources!$D$469/100,"n/a") -> 679.03299 | O34: =IF(ISNUMBER(Detail_PeerAnalysis!M29),Detail_PeerAnalysis!M29,"n/a") -> 514.8 | P34: =IF(AND(ISNUMBER(Inputs_Sources!$D$254),ISNUMBER(Inputs_Sources!$D$256),ISNUMBER(Inputs_Sources!$D$469),ISNUMBER(Inputs_Sources!$D$470)),(Detail_PeerAnalysis!D64*Inputs_Sources!$D$254*Inputs_Sources!$D$469+Detail_PeerAnalysis!E64*Inputs_Sources!$D$256*Inputs_Sources!$D$470)/100,"n/a") -> 676.04419 | Q34: =IF(AND(ISNUMBER(Inputs_Sources!$D$256),ISNUMBER(Inputs_Sources!$D$450),ISNUMBER(Inputs_Sources!$D$470),ISNUMBER(Inputs_Sources!$D$471)),(Detail_PeerAnalysis!D64*Inputs_Sources!$D$256*Inputs_Sources!$D$470+Detail_PeerAnalysis!E64*Inputs_Sources!$D$450*Inputs_Sources!$D$471)/100,"n/a") -> 690.88322 | R34: =IF(ISNUMBER(Inputs_Sources!$D$447),IFERROR(Detail_PeerAnalysis!F29/Inputs_Sources!$D$447-1,"n/a"),"n/a") -> 0.24441635 | S34: =IFERROR(Detail_PeerAnalysis!G29/Detail_PeerAnalysis!F29-1,"n/a") -> -0.026752455 | T34: =IF(ISNUMBER(Inputs_Sources!$D$449),IFERROR(Inputs_Sources!$D$449/Detail_PeerAnalysis!G29-1,"n/a"),"n/a") -> 0.23416841 | V34: =IFERROR(Detail_PeerAnalysis!K29/Detail_PeerAnalysis!H29-1,"n/a") -> 0.4331318 | W34: =IF(AND(ISNUMBER(Inputs_Sources!$D$255),ISNUMBER(Inputs_Sources!$D$451)),IFERROR((Detail_PeerAnalysis!D64*Inputs_Sources!$D$255+Detail_PeerAnalysis!E64*Inputs_Sources!$D$451)/Detail_PeerAnalysis!K29-1,"n/a"),"n/a") -> 0.043364056
B35: =Detail_PeerAnalysis!A16 -> The J. M. Smucker Company | D35: Secondary | E35: =Detail_PeerAnalysis!B16 -> NYSE:SJM | F35: =Detail_PeerAnalysis!B30 -> 8178.7 | G35: =Detail_PeerAnalysis!C30 -> 8726.1 | H35: =IF(ISNUMBER(Inputs_Sources!$D$485),Inputs_Sources!$D$485,"n/a") -> 9050.9 | I35: =Detail_PeerAnalysis!D30 -> 9156.9 | J35: =IF(ISNUMBER(Detail_PeerAnalysis!E30),Detail_PeerAnalysis!E30,"n/a") -> 8979.6414 | K35: =IF(AND(ISNUMBER(Inputs_Sources!$D$261),ISNUMBER(Inputs_Sources!$D$487)),Detail_PeerAnalysis!D65*Inputs_Sources!$D$261+Detail_PeerAnalysis!E65*Inputs_Sources!$D$487,"n/a") -> 9108.083 | L35: =IF(ISNUMBER(Inputs_Sources!$D$504),Inputs_Sources!$D$504,"n/a") -> 3118.3 | M35: =IF(ISNUMBER(Inputs_Sources!$D$505),Inputs_Sources!$D$505,"n/a") -> 3393.8 | O35: =IF(ISNUMBER(Detail_PeerAnalysis!M30),Detail_PeerAnalysis!M30,"n/a") -> 3475.1 | P35: =IF(AND(ISNUMBER(Inputs_Sources!$D$259),ISNUMBER(Inputs_Sources!$D$261),ISNUMBER(Inputs_Sources!$D$506),ISNUMBER(Inputs_Sources!$D$507)),(Detail_PeerAnalysis!D65*Inputs_Sources!$D$259*Inputs_Sources!$D$506+Detail_PeerAnalysis!E65*Inputs_Sources!$D$261*Inputs_Sources!$D$507)/100,"n/a") -> 3457.1684 | Q35: =IF(AND(ISNUMBER(Inputs_Sources!$D$261),ISNUMBER(Inputs_Sources!$D$487),ISNUMBER(Inputs_Sources!$D$507),ISNUMBER(Inputs_Sources!$D$508)),(Detail_PeerAnalysis!D65*Inputs_Sources!$D$261*Inputs_Sources!$D$507+Detail_PeerAnalysis!E65*Inputs_Sources!$D$487*Inputs_Sources!$D$508)/100,"n/a") -> 3508.5718 | R35: =IF(ISNUMBER(Inputs_Sources!$D$484),IFERROR(Detail_PeerAnalysis!F30/Inputs_Sources!$D$484-1,"n/a"),"n/a") -> 0.16875585 | S35: =IFERROR(Detail_PeerAnalysis!G30/Detail_PeerAnalysis!F30-1,"n/a") -> 0.15052559 | T35: =IF(ISNUMBER(Inputs_Sources!$D$486),IFERROR(Inputs_Sources!$D$486/Detail_PeerAnalysis!G30-1,"n/a"),"n/a") -> -0.060986921 | V35: =IFERROR(Detail_PeerAnalysis!K30/Detail_PeerAnalysis!H30-1,"n/a") -> -0.037685241 | W35: =IF(AND(ISNUMBER(Inputs_Sources!$D$260),ISNUMBER(Inputs_Sources!$D$488)),IFERROR((Detail_PeerAnalysis!D65*Inputs_Sources!$D$260+Detail_PeerAnalysis!E65*Inputs_Sources!$D$488)/Detail_PeerAnalysis!K30-1,"n/a"),"n/a") -> n/a
B36: =Detail_PeerAnalysis!A17 -> The Campbell's Company | D36: Secondary | E36: =Detail_PeerAnalysis!B17 -> NasdaqGS:CPB | F36: =Detail_PeerAnalysis!B31 -> 9636 | G36: =Detail_PeerAnalysis!C31 -> 10253 | H36: =IF(ISNUMBER(Inputs_Sources!$D$522),Inputs_Sources!$D$522,"n/a") -> 9744 | I36: =Detail_PeerAnalysis!D31 -> 9744 | J36: =IF(ISNUMBER(Detail_PeerAnalysis!E31),Detail_PeerAnalysis!E31,"n/a") -> 9491.011 | K36: =IF(AND(ISNUMBER(Inputs_Sources!$D$266),ISNUMBER(Inputs_Sources!$D$524)),Detail_PeerAnalysis!D66*Inputs_Sources!$D$266+Detail_PeerAnalysis!E66*Inputs_Sources!$D$524,"n/a") -> 9487.1781 | L36: =IF(ISNUMBER(Inputs_Sources!$D$541),Inputs_Sources!$D$541,"n/a") -> 3017 | M36: =IF(ISNUMBER(Inputs_Sources!$D$542),Inputs_Sources!$D$542,"n/a") -> 3151 | O36: =IF(ISNUMBER(Detail_PeerAnalysis!M31),Detail_PeerAnalysis!M31,"n/a") -> 2781 | P36: =IF(AND(ISNUMBER(Inputs_Sources!$D$264),ISNUMBER(Inputs_Sources!$D$266),ISNUMBER(Inputs_Sources!$D$543),ISNUMBER(Inputs_Sources!$D$544)),(Detail_PeerAnalysis!D66*Inputs_Sources!$D$264*Inputs_Sources!$D$543+Detail_PeerAnalysis!E66*Inputs_Sources!$D$266*Inputs_Sources!$D$544)/100,"n/a") -> 2646.0614 | Q36: =IF(AND(ISNUMBER(Inputs_Sources!$D$266),ISNUMBER(Inputs_Sources!$D$524),ISNUMBER(Inputs_Sources!$D$544),ISNUMBER(Inputs_Sources!$D$545)),(Detail_PeerAnalysis!D66*Inputs_Sources!$D$266*Inputs_Sources!$D$544+Detail_PeerAnalysis!E66*Inputs_Sources!$D$524*Inputs_Sources!$D$545)/100,"n/a") -> 2704.567 | R36: =IF(ISNUMBER(Inputs_Sources!$D$521),IFERROR(Detail_PeerAnalysis!F31/Inputs_Sources!$D$521-1,"n/a"),"n/a") -> -0.0023500448 | S36: =IFERROR(Detail_PeerAnalysis!G31/Detail_PeerAnalysis!F31-1,"n/a") -> 0.058889512 | T36: =IF(ISNUMBER(Inputs_Sources!$D$523),IFERROR(Inputs_Sources!$D$523/Detail_PeerAnalysis!G31-1,"n/a"),"n/a") -> -0.15572034 | V36: =IFERROR(Detail_PeerAnalysis!K31/Detail_PeerAnalysis!H31-1,"n/a") -> -0.088924404 | W36: =IF(AND(ISNUMBER(Inputs_Sources!$D$265),ISNUMBER(Inputs_Sources!$D$525)),IFERROR((Detail_PeerAnalysis!D66*Inputs_Sources!$D$265+Detail_PeerAnalysis!E66*Inputs_Sources!$D$525)/Detail_PeerAnalysis!K31-1,"n/a"),"n/a") -> n/a
B37: =Detail_PeerAnalysis!A18 -> Mondelez International, Inc. | D37: Secondary | E37: =Detail_PeerAnalysis!B18 -> NasdaqGS:MDLZ | F37: =Detail_PeerAnalysis!B32 -> 36441 | G37: =Detail_PeerAnalysis!C32 -> 38537 | H37: =IF(ISNUMBER(Inputs_Sources!$D$559),Inputs_Sources!$D$559,"n/a") -> 40101.2 | I37: =Detail_PeerAnalysis!D32 -> 39675 | J37: =IF(ISNUMBER(Detail_PeerAnalysis!E32),Detail_PeerAnalysis!E32,"n/a") -> 40994.158 | K37: =IF(AND(ISNUMBER(Inputs_Sources!$D$271),ISNUMBER(Inputs_Sources!$D$561)),Detail_PeerAnalysis!D67*Inputs_Sources!$D$271+Detail_PeerAnalysis!E67*Inputs_Sources!$D$561,"n/a") -> 42355.863 | L37: =IF(ISNUMBER(Inputs_Sources!$D$578),Inputs_Sources!$D$578,"n/a") -> 14257 | M37: =IF(ISNUMBER(Inputs_Sources!$D$579),Inputs_Sources!$D$579,"n/a") -> 10935 | N37: =IF(AND(ISNUMBER(Inputs_Sources!$D$559),ISNUMBER(Inputs_Sources!$D$580)),Inputs_Sources!$D$559*Inputs_Sources!$D$580/100,"n/a") -> 13269.487 | O37: =IF(ISNUMBER(Detail_PeerAnalysis!M32),Detail_PeerAnalysis!M32,"n/a") -> 12357 | P37: =IF(AND(ISNUMBER(Inputs_Sources!$D$269),ISNUMBER(Inputs_Sources!$D$271),ISNUMBER(Inputs_Sources!$D$580),ISNUMBER(Inputs_Sources!$D$581)),(Detail_PeerAnalysis!D67*Inputs_Sources!$D$269*Inputs_Sources!$D$580+Detail_PeerAnalysis!E67*Inputs_Sources!$D$271*Inputs_Sources!$D$581)/100,"n/a") -> 14137.573 | Q37: =IF(AND(ISNUMBER(Inputs_Sources!$D$271),ISNUMBER(Inputs_Sources!$D$561),ISNUMBER(Inputs_Sources!$D$581),ISNUMBER(Inputs_Sources!$D$582)),(Detail_PeerAnalysis!D67*Inputs_Sources!$D$271*Inputs_Sources!$D$581+Detail_PeerAnalysis!E67*Inputs_Sources!$D$561*Inputs_Sources!$D$582)/100,"n/a") -> 14882.185 | R37: =IF(ISNUMBER(Inputs_Sources!$D$558),IFERROR(Detail_PeerAnalysis!F32/Inputs_Sources!$D$558-1,"n/a"),"n/a") -> 0.11928967 | S37: =IFERROR(Detail_PeerAnalysis!G32/Detail_PeerAnalysis!F32-1,"n/a") -> -0.35529716 | T37: =IF(ISNUMBER(Inputs_Sources!$D$560),IFERROR(Inputs_Sources!$D$560/Detail_PeerAnalysis!G32-1,"n/a"),"n/a") -> 0.34973948 | V37: =IFERROR(Detail_PeerAnalysis!K32/Detail_PeerAnalysis!H32-1,"n/a") -> 0.17651875 | W37: =IF(AND(ISNUMBER(Inputs_Sources!$D$270),ISNUMBER(Inputs_Sources!$D$562)),IFERROR((Detail_PeerAnalysis!D67*Inputs_Sources!$D$270+Detail_PeerAnalysis!E67*Inputs_Sources!$D$562)/Detail_PeerAnalysis!K32-1,"n/a"),"n/a") -> 0.063640532
B38: =Detail_PeerAnalysis!A19 -> Arca Continental, S.A.B. de C.V. | D38: Secondary | E38: =Detail_PeerAnalysis!B19 -> BMV:AC | F38: =Detail_PeerAnalysis!B33 -> 13149.5 | G38: =Detail_PeerAnalysis!C33 -> 13058.3 | H38: =IF(ISNUMBER(Inputs_Sources!$D$596),Inputs_Sources!$D$596,"n/a") -> 14453.8 | I38: =Detail_PeerAnalysis!D33 -> 13945.2 | J38: =IF(ISNUMBER(Detail_PeerAnalysis!E33),Detail_PeerAnalysis!E33,"n/a") -> 14591.724 | K38: =IF(AND(ISNUMBER(Inputs_Sources!$D$276),ISNUMBER(Inputs_Sources!$D$598)),Detail_PeerAnalysis!D68*Inputs_Sources!$D$276+Detail_PeerAnalysis!E68*Inputs_Sources!$D$598,"n/a") -> 15424.9 | L38: =IF(ISNUMBER(Inputs_Sources!$D$615),Inputs_Sources!$D$615,"n/a") -> 6131.3 | M38: =IF(ISNUMBER(Inputs_Sources!$D$616),Inputs_Sources!$D$616,"n/a") -> 6074.7 | N38: =IF(AND(ISNUMBER(Inputs_Sources!$D$596),ISNUMBER(Inputs_Sources!$D$617)),Inputs_Sources!$D$596*Inputs_Sources!$D$617/100,"n/a") -> 6855.4373 | O38: =IF(ISNUMBER(Detail_PeerAnalysis!M33),Detail_PeerAnalysis!M33,"n/a") -> 6537.9 | P38: =IF(AND(ISNUMBER(Inputs_Sources!$D$274),ISNUMBER(Inputs_Sources!$D$276),ISNUMBER(Inputs_Sources!$D$617),ISNUMBER(Inputs_Sources!$D$618)),(Detail_PeerAnalysis!D68*Inputs_Sources!$D$274*Inputs_Sources!$D$617+Detail_PeerAnalysis!E68*Inputs_Sources!$D$276*Inputs_Sources!$D$618)/100,"n/a") -> 6933.5517 | Q38: =IF(AND(ISNUMBER(Inputs_Sources!$D$276),ISNUMBER(Inputs_Sources!$D$598),ISNUMBER(Inputs_Sources!$D$618),ISNUMBER(Inputs_Sources!$D$619)),(Detail_PeerAnalysis!D68*Inputs_Sources!$D$276*Inputs_Sources!$D$618+Detail_PeerAnalysis!E68*Inputs_Sources!$D$598*Inputs_Sources!$D$619)/100,"n/a") -> 7337.9331 | R38: =IF(ISNUMBER(Inputs_Sources!$D$595),IFERROR(Detail_PeerAnalysis!F33/Inputs_Sources!$D$595-1,"n/a"),"n/a") -> 0.10567515 | S38: =IFERROR(Detail_PeerAnalysis!G33/Detail_PeerAnalysis!F33-1,"n/a") -> -0.022470181 | T38: =IF(ISNUMBER(Inputs_Sources!$D$597),IFERROR(Inputs_Sources!$D$597/Detail_PeerAnalysis!G33-1,"n/a"),"n/a") -> 0.1533496 | V38: =IFERROR(Detail_PeerAnalysis!K33/Detail_PeerAnalysis!H33-1,"n/a") -> 0.10463466 | W38: =IF(AND(ISNUMBER(Inputs_Sources!$D$275),ISNUMBER(Inputs_Sources!$D$599)),IFERROR((Detail_PeerAnalysis!D68*Inputs_Sources!$D$275+Detail_PeerAnalysis!E68*Inputs_Sources!$D$599)/Detail_PeerAnalysis!K33-1,"n/a"),"n/a") -> 0.065505125
B39: =Detail_PeerAnalysis!A20 -> PepsiCo, Inc. | D39: Secondary | E39: =Detail_PeerAnalysis!B20 -> NasdaqGS:PEP | F39: =Detail_PeerAnalysis!B34 -> 91854 | G39: =Detail_PeerAnalysis!C34 -> 93925 | H39: =IF(ISNUMBER(Inputs_Sources!$D$633),Inputs_Sources!$D$633,"n/a") -> 99300.5 | I39: =Detail_PeerAnalysis!D34 -> 98241 | J39: =IF(ISNUMBER(Detail_PeerAnalysis!E34),Detail_PeerAnalysis!E34,"n/a") -> 101251.48 | K39: =IF(AND(ISNUMBER(Inputs_Sources!$D$281),ISNUMBER(Inputs_Sources!$D$635)),Detail_PeerAnalysis!D69*Inputs_Sources!$D$281+Detail_PeerAnalysis!E69*Inputs_Sources!$D$635,"n/a") -> 104438.72 | L39: =IF(ISNUMBER(Inputs_Sources!$D$652),Inputs_Sources!$D$652,"n/a") -> 50419 | M39: =IF(ISNUMBER(Inputs_Sources!$D$653),Inputs_Sources!$D$653,"n/a") -> 51152 | N39: =IF(AND(ISNUMBER(Inputs_Sources!$D$633),ISNUMBER(Inputs_Sources!$D$654)),Inputs_Sources!$D$633*Inputs_Sources!$D$654/100,"n/a") -> 53711.64 | O39: =IF(ISNUMBER(Detail_PeerAnalysis!M34),Detail_PeerAnalysis!M34,"n/a") -> 53371 | P39: =IF(AND(ISNUMBER(Inputs_Sources!$D$279),ISNUMBER(Inputs_Sources!$D$281),ISNUMBER(Inputs_Sources!$D$654),ISNUMBER(Inputs_Sources!$D$655)),(Detail_PeerAnalysis!D69*Inputs_Sources!$D$279*Inputs_Sources!$D$654+Detail_PeerAnalysis!E69*Inputs_Sources!$D$281*Inputs_Sources!$D$655)/100,"n/a") -> 54694.654 | Q39: =IF(AND(ISNUMBER(Inputs_Sources!$D$281),ISNUMBER(Inputs_Sources!$D$635),ISNUMBER(Inputs_Sources!$D$655),ISNUMBER(Inputs_Sources!$D$656)),(Detail_PeerAnalysis!D69*Inputs_Sources!$D$281*Inputs_Sources!$D$655+Detail_PeerAnalysis!E69*Inputs_Sources!$D$635*Inputs_Sources!$D$656)/100,"n/a") -> 56454.986 | R39: =IF(ISNUMBER(Inputs_Sources!$D$632),IFERROR(Detail_PeerAnalysis!F34/Inputs_Sources!$D$632-1,"n/a"),"n/a") -> 0.060086627 | S39: =IFERROR(Detail_PeerAnalysis!G34/Detail_PeerAnalysis!F34-1,"n/a") -> 0.018607779 | T39: =IF(ISNUMBER(Inputs_Sources!$D$634),IFERROR(Inputs_Sources!$D$634/Detail_PeerAnalysis!G34-1,"n/a"),"n/a") -> 0.048228238 | V39: =IFERROR(Detail_PeerAnalysis!K34/Detail_PeerAnalysis!H34-1,"n/a") -> 0.015799878 | W39: =IF(AND(ISNUMBER(Inputs_Sources!$D$280),ISNUMBER(Inputs_Sources!$D$636)),IFERROR((Detail_PeerAnalysis!D69*Inputs_Sources!$D$280+Detail_PeerAnalysis!E69*Inputs_Sources!$D$636)/Detail_PeerAnalysis!K34-1,"n/a"),"n/a") -> 0.04643211
B40: =Detail_PeerAnalysis!A11 -> Grupo Bimbo, S.A.B. de C.V. (subject) | D40: Subject Company >> | E40: =Detail_PeerAnalysis!B11 -> BMV:BIMBO A | F40: =Detail_PeerAnalysis!B25 -> 22097.246 | G40: =Detail_PeerAnalysis!C25 -> 23105.309 | H40: =Inputs_Sources!$D$669/Inputs_Sources!$D$10 -> 23068.063 | I40: =Detail_PeerAnalysis!D25 -> 22805.509 | J40: =Detail_PeerAnalysis!E25 -> 23879.916 | K40: =(Detail_PeerAnalysis!D60*Inputs_Sources!$D$681+Detail_PeerAnalysis!E60*Inputs_Sources!$D$693)/Inputs_Sources!$D$10 -> 25085.161 | L40: =Detail_TearSheet!F9/Inputs_Sources!$D$10 -> 11630.932 | M40: =Detail_TearSheet!G9/Inputs_Sources!$D$10 -> 12134.948 | N40: =Inputs_Sources!$D$669*Inputs_Sources!$D$679/100/Inputs_Sources!$D$10 -> 12064.597 | O40: =Detail_PeerAnalysis!M25 -> 11986.052 | P40: =(Detail_PeerAnalysis!D60*Inputs_Sources!$D$669*Inputs_Sources!$D$679+Detail_PeerAnalysis!E60*Inputs_Sources!$D$681*Inputs_Sources!$D$691)/100/Inputs_Sources!$D$10 -> 12432.155 | Q40: =(Detail_PeerAnalysis!D60*Inputs_Sources!$D$681*Inputs_Sources!$D$691+Detail_PeerAnalysis!E60*Inputs_Sources!$D$693*Inputs_Sources!$D$703)/100/Inputs_Sources!$D$10 -> 13054.285 | R40: =IFERROR(Detail_TearSheet!F19/Detail_TearSheet!E19-1,"n/a") -> 0.0096647374 | S40: =IFERROR(Detail_TearSheet!G19/Detail_TearSheet!F19-1,"n/a") -> 0.071800696 | T40: =IFERROR(Inputs_Sources!$D$670/Detail_TearSheet!G19-1,"n/a") -> 0.044753864 | V40: =IFERROR(Detail_PeerAnalysis!K25/Detail_PeerAnalysis!H25-1,"n/a") -> 0.055595135 | W40: =IFERROR((Detail_PeerAnalysis!D60*Inputs_Sources!$D$682+Detail_PeerAnalysis!E60*Inputs_Sources!$D$694)/(Detail_PeerAnalysis!H60)-1,"n/a") -> 0.059500621
F45: Free Cash Flow Yield (%) | L45: Price / Sales (x) | R45: Price / Free Cash Flow (x)
F47: Performance Valuations
F48: FY2024 | G48: FY2025 | H48: FY2026 | I48: LTM | J48: NTM | K48: STM | L48: FY2024 | M48: FY2025 | N48: FY2026 | O48: LTM | P48: NTM | Q48: STM | R48: FY2024 | S48: FY2025 | T48: FY2026 | U48: LTM | V48: NTM | W48: STM
B49: Company Name | D49: Group | E49: Exchange:Ticker
B50: =Detail_PeerAnalysis!A12 -> Flowers Foods, Inc. | D50: Core | E50: =Detail_PeerAnalysis!B12 -> NYSE:FLO | F50: =IFERROR(IF(ISNUMBER(Inputs_Sources!$D$341),(Inputs_Sources!$D$341)/Detail_PeerAnalysis!I12,"n/a"),"n/a") -> 0.12117002 | G50: =IFERROR(IF(ISNUMBER(Inputs_Sources!$D$342),(Inputs_Sources!$D$342)/Detail_PeerAnalysis!I12,"n/a"),"n/a") -> 0.17064135 | H50: =IFERROR(IF(ISNUMBER(Inputs_Sources!$D$361),(Inputs_Sources!$D$361)/Detail_PeerAnalysis!I12,"n/a"),"n/a") -> 0.17038666 | I50: =IFERROR(IF(ISNUMBER(Detail_PeerAnalysis!N26),(Detail_PeerAnalysis!N26)/Detail_PeerAnalysis!I12,"n/a"),"n/a") -> 0.2303774 | J50: =IFERROR(IF(ISNUMBER((Detail_PeerAnalysis!D61*Inputs_Sources!$D$361+Detail_PeerAnalysis!E61*Inputs_Sources!$D$362)),((Detail_PeerAnalysis!D61*Inputs_Sources!$D$361+Detail_PeerAnalysis!E61*Inputs_Sources!$D$362))/Detail_PeerAnalysis!I12,"n/a"),"n/a") -> 0.14567094 | K50: =IFERROR(IF(ISNUMBER((Detail_PeerAnalysis!D61*Inputs_Sources!$D$362+Detail_PeerAnalysis!E61*Inputs_Sources!$D$363)),((Detail_PeerAnalysis!D61*Inputs_Sources!$D$362+Detail_PeerAnalysis!E61*Inputs_Sources!$D$363))/Detail_PeerAnalysis!I12,"n/a"),"n/a") -> 0.13709012 | L50: =IFERROR(Detail_PeerAnalysis!I12/F31,"n/a") -> 0.25388459 | M50: =IFERROR(Detail_PeerAnalysis!I12/G31,"n/a") -> 0.24649482 | N50: =IFERROR(Detail_PeerAnalysis!I12/H31,"n/a") -> 0.25527011 | O50: =IFERROR(Detail_PeerAnalysis!I12/I31,"n/a") -> 0.24803308 | P50: =IFERROR(Detail_PeerAnalysis!I12/J31,"n/a") -> 0.25596159 | Q50: =IFERROR(Detail_PeerAnalysis!I12/K31,"n/a") -> 0.2571771 | R50: =IFERROR(IF(ISNUMBER(Inputs_Sources!$D$341),IF((Inputs_Sources!$D$341)>0,Detail_PeerAnalysis!I12/(Inputs_Sources!$D$341),"n.m."),"n/a"),"n/a") -> 8.2528662 | S50: =IFERROR(IF(ISNUMBER(Inputs_Sources!$D$342),IF((Inputs_Sources!$D$342)>0,Detail_PeerAnalysis!I12/(Inputs_Sources!$D$342),"n.m."),"n/a"),"n/a") -> 5.8602442 | T50: =IFERROR(IF(ISNUMBER(Inputs_Sources!$D$361),IF((Inputs_Sources!$D$361)>0,Detail_PeerAnalysis!I12/(Inputs_Sources!$D$361),"n.m."),"n/a"),"n/a") -> 5.8690039 | U50: =IFERROR(IF(ISNUMBER(Detail_PeerAnalysis!N26),IF((Detail_PeerAnalysis!N26)>0,Detail_PeerAnalysis!I12/(Detail_PeerAnalysis!N26),"n.m."),"n/a"),"n/a") -> 4.3407035 | V50: =IFERROR(IF(ISNUMBER((Detail_PeerAnalysis!D61*Inputs_Sources!$D$361+Detail_PeerAnalysis!E61*Inputs_Sources!$D$362)),IF(((Detail_PeerAnalysis!D61*Inputs_Sources!$D$361+Detail_PeerAnalysis!E61*Inputs_Sources!$D$362))>0,Detail_PeerAnalysis!I12/((Detail_PeerAnalysis!D61*Inputs_Sources!$D$361+Detail_PeerAnalysis!E61*Inputs_Sources!$D$362)),"n.m."),"n/a"),"n/a") -> 6.8647872 | W50: =IFERROR(IF(ISNUMBER((Detail_PeerAnalysis!D61*Inputs_Sources!$D$362+Detail_PeerAnalysis!E61*Inputs_Sources!$D$363)),IF(((Detail_PeerAnalysis!D61*Inputs_Sources!$D$362+Detail_PeerAnalysis!E61*Inputs_Sources!$D$363))>0,Detail_PeerAnalysis!I12/((Detail_PeerAnalysis!D61*Inputs_Sources!$D$362+Detail_PeerAnalysis!E61*Inputs_Sources!$D$363)),"n.m."),"n/a"),"n/a") -> 7.2944716
B51: =Detail_PeerAnalysis!A13 -> Gruma, S.A.B. de C.V. | D51: Core | E51: =Detail_PeerAnalysis!B13 -> BMV:GRUMA B | F51: =IFERROR(IF(ISNUMBER(Inputs_Sources!$D$378),(Inputs_Sources!$D$378)/Detail_PeerAnalysis!I13,"n/a"),"n/a") -> n/a | G51: =IFERROR(IF(ISNUMBER(Inputs_Sources!$D$379),(Inputs_Sources!$D$379)/Detail_PeerAnalysis!I13,"n/a"),"n/a") -> n/a | H51: =IFERROR(IF(ISNUMBER(Inputs_Sources!$D$398),(Inputs_Sources!$D$398)/Detail_PeerAnalysis!I13,"n/a"),"n/a") -> 0.039749501 | I51: =IFERROR(IF(ISNUMBER(Detail_PeerAnalysis!N27),(Detail_PeerAnalysis!N27)/Detail_PeerAnalysis!I13,"n/a"),"n/a") -> n/a | J51: =IFERROR(IF(ISNUMBER((Detail_PeerAnalysis!D62*Inputs_Sources!$D$398+Detail_PeerAnalysis!E62*Inputs_Sources!$D$399)),((Detail_PeerAnalysis!D62*Inputs_Sources!$D$398+Detail_PeerAnalysis!E62*Inputs_Sources!$D$399))/Detail_PeerAnalysis!I13,"n/a"),"n/a") -> 0.10393969 | K51: =IFERROR(IF(ISNUMBER((Detail_PeerAnalysis!D62*Inputs_Sources!$D$399+Detail_PeerAnalysis!E62*Inputs_Sources!$D$400)),((Detail_PeerAnalysis!D62*Inputs_Sources!$D$399+Detail_PeerAnalysis!E62*Inputs_Sources!$D$400))/Detail_PeerAnalysis!I13,"n/a"),"n/a") -> 0.12068771 | L51: =IFERROR(Detail_PeerAnalysis!I13/F32,"n/a") -> 0.67880278 | M51: =IFERROR(Detail_PeerAnalysis!I13/G32,"n/a") -> 0.69076111 | N51: =IFERROR(Detail_PeerAnalysis!I13/H32,"n/a") -> 0.66231858 | O51: =IFERROR(Detail_PeerAnalysis!I13/I32,"n/a") -> 0.67742431 | P51: =IFERROR(Detail_PeerAnalysis!I13/J32,"n/a") -> 0.67874536 | Q51: =IFERROR(Detail_PeerAnalysis!I13/K32,"n/a") -> 0.66924548 | R51: =IFERROR(IF(ISNUMBER(Inputs_Sources!$D$378),IF((Inputs_Sources!$D$378)>0,Detail_PeerAnalysis!I13/(Inputs_Sources!$D$378),"n.m."),"n/a"),"n/a") -> n/a | S51: =IFERROR(IF(ISNUMBER(Inputs_Sources!$D$379),IF((Inputs_Sources!$D$379)>0,Detail_PeerAnalysis!I13/(Inputs_Sources!$D$379),"n.m."),"n/a"),"n/a") -> n/a | T51: =IFERROR(IF(ISNUMBER(Inputs_Sources!$D$398),IF((Inputs_Sources!$D$398)>0,Detail_PeerAnalysis!I13/(Inputs_Sources!$D$398),"n.m."),"n/a"),"n/a") -> 25.157549 | U51: =IFERROR(IF(ISNUMBER(Detail_PeerAnalysis!N27),IF((Detail_PeerAnalysis!N27)>0,Detail_PeerAnalysis!I13/(Detail_PeerAnalysis!N27),"n.m."),"n/a"),"n/a") -> n/a | V51: =IFERROR(IF(ISNUMBER((Detail_PeerAnalysis!D62*Inputs_Sources!$D$398+Detail_PeerAnalysis!E62*Inputs_Sources!$D$399)),IF(((Detail_PeerAnalysis!D62*Inputs_Sources!$D$398+Detail_PeerAnalysis!E62*Inputs_Sources!$D$399))>0,Detail_PeerAnalysis!I13/((Detail_PeerAnalysis!D62*Inputs_Sources!$D$398+Detail_PeerAnalysis!E62*Inputs_Sources!$D$399)),"n.m."),"n/a"),"n/a") -> 9.6209641 | W51: =IFERROR(IF(ISNUMBER((Detail_PeerAnalysis!D62*Inputs_Sources!$D$399+Detail_PeerAnalysis!E62*Inputs_Sources!$D$400)),IF(((Detail_PeerAnalysis!D62*Inputs_Sources!$D$399+Detail_PeerAnalysis!E62*Inputs_Sources!$D$400))>0,Detail_PeerAnalysis!I13/((Detail_PeerAnalysis!D62*Inputs_Sources!$D$399+Detail_PeerAnalysis!E62*Inputs_Sources!$D$400)),"n.m."),"n/a"),"n/a") -> 8.2858476
...

Sheet Detail_TearSheet
A1: TearSheet: Grupo Bimbo, S.A.B. de C.V. (BMV:BIMBO A), MXN millions unless stated
A2: Actuals: CIQ quarterly CSVs (sum of quarters; FY2021 restated) with company annual values where the CSV lacks Q4 2024 (flagged). FY2026E-FY2028E: CIQ consensus mean (20-Sep-2026). Adjusted EBITDA is the company IFRS 16 figure; CIQ EBITDA is standardised and sits after lease depreciation.
A3: Tags: sourced = CIQ CSV or company filing; calc = computed here; consensus = CIQ mean estimate; memo rows are not used in valuation except where stated.
A5: Line item | B5: Unit | C5: FY2021A | D5: FY2022A | E5: FY2023A | F5: FY2024A | G5: FY2025A | H5: FY2026E | I5: FY2027E | J5: FY2028E | K5: Tag | L5: Source / note
A6: Income statement
A7: Total revenue | B7: MXN m | C7: 338792 | D7: 398706 | E7: 399879 | F7: 408335 | G7: 426963 | H7: 426274.7 | I7: 445288 | J7: 468430.9 | K7: sourced / consensus | L7: CSV income_statement 'Total Revenue' (FY2021 restated = 338,792); FY2024 company annual (4Q24 missing in CSV; wiki/Financials/bimbo-income-statement-fy21-fy25.md s.1); FY26E-28E consensus.csv Revenue mean
A8: Revenue growth YoY | B8: % | D8: =IFERROR(D7/C7-1,"n/a") -> 0.17684597 | E8: =IFERROR(E7/D7-1,"n/a") -> 0.0029420174 | F8: =IFERROR(F7/E7-1,"n/a") -> 0.021146397 | G8: =IFERROR(G7/F7-1,"n/a") -> 0.045619406 | H8: =IFERROR(H7/G7-1,"n/a") -> -0.0016120835 | I8: =IFERROR(I7/H7-1,"n/a") -> 0.044603398 | J8: =IFERROR(J7/I7-1,"n/a") -> 0.05197288 | K8: calc | L8: calc
A9: Gross profit | B9: MXN m | C9: 181789.4 | D9: 205974.4 | E9: 206159.5 | F9: 214928 | G9: 224241.7 | K9: sourced | L9: CSV 'Gross Profit' (CIQ basis; company FY24 214,928; company FY25 223,487 differs by 0.3%)
A10: Gross margin | B10: % | C10: =IFERROR(C9/C7,"n/a") -> 0.53658115 | D10: =IFERROR(D9/D7,"n/a") -> 0.51660722 | E10: =IFERROR(E9/E7,"n/a") -> 0.51555471 | F10: =IFERROR(F9/F7,"n/a") -> 0.52635214 | G10: =IFERROR(G9/G7,"n/a") -> 0.52520172 | K10: calc | L10: calc
A11: Gross margin, consensus mean | B11: % | H11: 52.3 | I11: 52 | J11: 52.05 | K11: consensus | L11: consensus.csv Gross Margin (%) mean
A12: SG&A (selling, general and administrative) | B12: MXN m | C12: 147963 | D12: 167254 | E12: 165748 | F12: 175164 | G12: 184186 | H12: 177262 | I12: 189938 | J12: 197030 | K12: sourced / consensus | L12: CSV 'Selling General & Admin Exp.' (CIQ basis); FY2024 company general expenses 175,164; FY26E-28E consensus mean
A13: SG&A / sales | B13: % | C13: =IFERROR(C12/C7,"n/a") -> 0.43673699 | D13: =IFERROR(D12/D7,"n/a") -> 0.41949206 | E13: =IFERROR(E12/E7,"n/a") -> 0.41449538 | F13: =IFERROR(F12/F7,"n/a") -> 0.42897131 | G13: =IFERROR(G12/G7,"n/a") -> 0.43138633 | H13: =IFERROR(H12/H7,"n/a") -> 0.41583983 | I13: =IFERROR(I12/I7,"n/a") -> 0.42655091 | J13: =IFERROR(J12/J7,"n/a") -> 0.420617 | K13: calc | L13: calc
A14: Total operating expenses, CIQ basis | B14: MXN m | C14: 148200.4 | D14: 169510.4 | E14: 168704.7 | F14: 181779 | G14: 187970.1 | K14: sourced | L14: CSV 'Other Operating Exp., Total'; FY2024 company total operating expenses (wiki s.1)
A15: EBIT, CIQ standardised | B15: MXN m | C15: 33588.9 | D15: 36464.1 | E15: 37454.8 | G15: 36271.6 | K15: sourced | L15: CSV 'Operating Income' (sum of quarters); not like-for-like with company operating income (see next row); FY2024 CSV Q4 missing
A16: Operating income, company basis (FY26E-28E: consensus EBIT) | B16: MXN m | C16: 32580 | D16: 53696 | E16: 35455 | F16: 33149 | G16: 34146 | H16: 37446 | I16: 38779 | J16: 41926 | K16: sourced / consensus | L16: Company FY21 restated 32,580 and FY22 53,696 incl. MEPP/Ricolino one-offs (wiki s.1); consensus.csv EBIT is company basis (FY25A 34,146)
A17: Operating margin, company basis | B17: % | C17: =IFERROR(C16/C7,"n/a") -> 0.096165199 | D17: =IFERROR(D16/D7,"n/a") -> 0.13467568 | E17: =IFERROR(E16/E7,"n/a") -> 0.088664321 | F17: =IFERROR(F16/F7,"n/a") -> 0.081180893 | G17: =IFERROR(G16/G7,"n/a") -> 0.079974143 | H17: =IFERROR(H16/H7,"n/a") -> 0.087844763 | I17: =IFERROR(I16/I7,"n/a") -> 0.087087458 | J17: =IFERROR(J16/J7,"n/a") -> 0.089503062 | K17: calc | L17: calc
A18: EBITDA, CIQ standardised (after lease depreciation) | B18: MXN m | C18: 45540.9 | D18: 50087.1 | E18: 51987.8 | G18: 54815.1 | K18: sourced | L18: CSV 'EBITDA' (sum of quarters); about 6 bn below company Adj. EBITDA (ROU depreciation); not the valuation basis
A19: Adjusted EBITDA, company, IFRS 16 (valuation basis) | B19: MXN m | C19: 47372 | D19: 53446 | E19: 54942 | F19: 55473 | G19: 59456 | H19: 62117 | I19: 64891 | J19: 68999 | K19: sourced / consensus | L19: Company Adj. EBITDA FY21 restated, FY22-25 (wiki s.1; FY24 55,473 vs 55,474 in releases); FY26E-28E consensus EBITDA mean (same definition, FY25A 59,456)
