Workbook
Name Data: TearSheet!$AC$3:$AI$3
Name IQ_CH: 110000
Name IQ_CQ: 5000
Name IQ_CY: 10000
Name IQ_DAILY: 500000
Name IQ_FH: 100000
Name IQ_FQ: 500
Name IQ_FY: 1000
Name IQ_LTM: 2000
Name IQ_MONTH: 15000
Name IQ_NTM: 6000
Name IQ_WEEK: 50000
Name IQ_YTD: 3000

Sheet __snloffice
A1: 允䅁䡁䉑䅁允䅁䅁杒婂䍁䄰杍睁䑁䅉杍䅁䅁䅉䅁䍁䅁䅁䅁啁䅁䅁䅈䅁䙁䅍䅕時䙁䅁杕䩂䕁䅍兒時䕁䅧兓䡂䕁䅧䅁㝃䅁䅁杣䅁䍁䅣睗呂䙁䅁睒時䙁䅙兙獂䡁䅕兙あ䝁䅫睢畂䕁䄰兤獂䡁䅑兡睂䝁䅷党穂䙁䄸杖䉂䕁䅍睢瑂䝁䅉睢時䡁䅙免杁䍁䅧免灁䍁䄴䅥獂䡁䅍䅥摂䕁䅑兙あ䝁䅅睊桁䍁䅑睑歁䑁䅉䅏䅁䑁䅣䅁千䅁䅁睔睂䡁䅑兡療䝁䄴督㙁䕁䅑兙あ䝁䅅䅖㕂䡁䅁党㥁䙁䅍䅒獁䙁䅍睢ㅂ䡁䅉睙求䑁䄰睙療䝁䄴督求䝁䄴督ㅂ䡁䅍杌㉂䝁䅅兙橂䡁䅑兤桂䝁䅷督獁䕁䄰兙湂䝁䅫䅤ㅂ䝁䅑党㥁䕁䅅杙穂䍁䅷睑ㅂ䡁䅉杣求䝁䄴睙㕂䑁䄰兖呂䕁䅑䅁卂䅁䅁杇䅁䝁䅍兤祂䡁䅉党畂䝁䅍入㥁䙁䅕睕䕂䅁䅁児䅁䡁䅁䅁偂䡁䅁䅤灂䝁䄸杢穂䑁䅯䅒桂䡁䅑兙啂䡁䅫䅣求䑁䄰睕䕂䍁䅷睕祂䝁䅍児橂䝁䄸杢穂䝁䅕杢穂䡁䅕督畁䡁䅙兙桂䝁䅍䅤ㅂ䝁䅅䅢穂䍁䅷兔桂䝁䅣児䉂䝁䅉督獁䕁䄴兑㥁䅁䅁朶䅁䝁䅯䅁偂䡁䅁䅤灂䝁䄸杢穂䑁䅯䅒桂䡁䅑兙啂䡁䅫䅣求䑁䄰睕䕂䍁䅷睕祂䝁䅍児䑂䝁䄸杢穂䝁䅕杢穂䡁䅕督畁䕁䄰党歂䝁䅫兙畂䍁䅷兔桂䝁䅣児䉂䝁䅉督獁䕁䄴兑㥁䅁䅁兊䅅䉁䅉䅁佂䙁䅫睕䙂䑁䅯䅒奂䕁䅍䅁佁允䅁杄䅁䍁䅉杒婂䍁䄰杉流䅁䅁兎䅁䙁䄴䅁䙂䙁䅁睕杁䕁䅑兡獂䡁䅕䅤求䝁䅑䅌杁䕁䅅䅣睂䝁䅷兡橂䝁䅅杙獂䝁䅕䅉あ䝁䄸䅉橂䝁䄸兢瑂䝁䄸杢杁䡁䅍䅤療䝁䅍睡潂䝁䄸䅢歂䝁䅕杣穂䅁䅁杶䅁䝁䅯䅁湁䙁䅳睕兂䕁䅣睘䝂䝁䅫杢桂䝁䄴睙灂䝁䅅䅢䥂䝁䅫睚潂䝁䅷兡湂䝁䅧䅤穂䙁䄸杖䉂䙁䄸杤硁䍁䅁䅋硁䍁䅫杌㑂䝁䅷督㑂䙁䄰兔桂䝁䅫杢湁䍁䅅䅊䕂䍁䅑李ㅁ䅁䅁兴䅁䅁䄴䅁橁䕁䅕杕卂䕁䄸杕䅁䕁䅫䅁楁䅁䅁睔睂䝁䅕杣桂䡁䅑兡畂䝁䅣䅉瑂䝁䅅杣湂䝁䅫杢䅁䑁䅉䅁楁䅁䅁睉䩂䕁䄴杖䉂䕁䅷兓䕂䙁䅉兒坂䕁䅫睕䩂䕁䄸杔䅁䅁䅧䅁慁䅁䅁䅖療䡁䅑兙獂䍁䅁兙穂䡁䅍党あ䡁䅍䅁呄䅁䅁杋䅁䍁䅍兓佂䙁䅙兑䵂䕁䅫䅒杁䕁䄰兒啂䙁䅉兓䑂䍁䅁杔䉂䕁䄰兒䅁䅁䅕䅁捁䅁䅁兒䍂䕁䅫䅖䕂䕁䅅䅉瑂䝁䅅杣湂䝁䅫杢䅁䑁䅁䅁獁䅁䅁睔睂䡁䅑兡療䝁䄴督㙁䕁䅍兤祂䡁䅉児噂䙁䅍䅒獁䕁䄴兑㥁䑁䅁䅁㉃䅁䅁䅫䅁䙁䅳杓求䝁䅙杚求䡁䅉兡求䡁䅍䅔䵂䕁䅍睘祁䑁䅁李睁䑁䅙李硁䑁䅉睘䑂䡁䅕督あ䝁䄸兢䩂䝁䄴䅚求䡁䅧睘䑂䕁䅫兕兂䡁䅉睢畁䡁䅧䅢穂䝁䄰兘䩂䝁䄴督あ䡁䅉兤橂䡁䅑兡療䝁䄴督桁䍁䅑䅕歁䑁䅅睍㙁䍁䅑䅕歁䑁䅉䅍䅁䡁䄴䅁楁䅁䅁睉䩂䕁䄴杖䉂䕁䅷兓䕂䕁䅍兖卂䙁䅉兒佂䕁䅍兗䅁䥁䅕䅁⭂䅁䅁睊扂䙁䅍䅕䡂䙁䄸杖桂䝁䅷兤桂䡁䅑兡療䝁䄴兔ㅂ䝁䅷䅤灂䡁䅁䅢求䡁䅍睘坂䕁䅅睑療䝁䄰杙療䙁䄸杤硁䍁䅁䅋硁䍁䅫杌㑂䝁䅷督㑂䙁䄰䅒桂䡁䅑兙湁䍁䅅䅊䑂䍁䅑睍祁䑁䅯䅊䑂䍁䅑䅎穁䅁䅁䅏䅁䉁䅁䅁䝂䙁䅅䅎祁䑁䅁杍ぁ䅁䅁党䅅䉁䅁䅁䑂䙁䅅睍祁䑁䅁杍㉁䅁䅁䅎䅅䝁䅑䅁扂䙁䅍䅕䡂䙁䄸杒灂䝁䄴兙畂䝁䅍兡桂䝁䅷䅓灂䝁䅣䅡獂䝁䅫睚潂䡁䅑督時䙁䅙兑時䙁䅣兓兂䍁䄴䅥獂䡁䅍䅥摂䙁䅉党睂䝁䄸杣あ䍁䅅䅊䕂䍁䅑李ㅁ䅁䅁眴䅁䡁䅯䅁偂䡁䅁䅤灂䝁䄸杢穂䑁䅯䅒桂䡁䅑兙啂䡁䅫䅣求䑁䄰睕䕂䍁䅷睕橂䡁䅉児橂䝁䄸杢穂䝁䅕杢穂䡁䅕督畁䡁䅙兙桂䝁䅍䅤ㅂ䝁䅅䅢穂䍁䅷兔桂䝁䅣児䉂䝁䅉督獁䕁䅍兤祂䡁䅉児噂䙁䅍䅒䅁䕁䅑䅁敁䅁䅁睉䩂䕁䄴杖䉂䕁䅷兓䕂䙁䅁兒卂䕁䅫睔䕂䅁䅁李䅁䅁䄴䅁䑂䙁䅫杍睁䑁䅉兎䅁䵁䄰䅁杁䅁䅁䅒桂䡁䅫䅉䑂䝁䅷睢穂䝁䅕䅉兂䡁䅉兡橂䝁䅕䅁祂䅁䅁杈䅁䕁䅙杣求䝁䅕䅉橂䝁䅅督潂䍁䅁杚獂䝁䄸睤䅁乁䄸䅁䅃䅁䅁睊扂䙁䅍䅕䡂䙁䄸杖桂䝁䅷兤桂䡁䅑兡療䝁䄴兔ㅂ䝁䅷䅤灂䡁䅁䅢求䡁䅍睘坂䕁䅅睑療䝁䄰杙療䙁䄸杤硁䍁䅁䅋硁䍁䅫杌㑂䝁䅷督㑂䙁䄰䅒桂䡁䅑兙湁䍁䅅䅊䙂䍁䅑杍㕁䑁䅯䅊䩂䕁䅧䅊祁䑁䅫䅁㕁䅁䅁杍䅁䙁䅁兙獂䝁䄸䅉䉂䝁䅷䅤療䍁䅁杔求䡁䅑睤療䡁䅉睡穂䍁䅷䅉䩂䝁䄴睙畁䅁䅁杅䅅䍁䄴䅁啂䝁䄸䅤桂䝁䅷䅉祂䝁䅕杤求䝁䄴兤求䍁䅷䅉婂䝁䄸兗杁䍁䅧兊灁䅁䅁䅄䅅䥁䅁䅁湁䙁䅳睕兂䕁䅣睘坂䝁䅅䅢ㅂ䝁䅅䅤灂䝁䄸杢乂䡁䅕䅢あ䝁䅫䅣獂䝁䅕督時䙁䅙兑䑂䝁䄸兢楂䝁䄸睘㉂䑁䅅䅉潁䑁䅅克畁䡁䅧䅢穂䡁䅧兘䕂䝁䅅䅤桂䍁䅣光歁䕁䅕䅊穁䑁䅁杏歁䕁䅫䅓歁䑁䅍䅍䅁䑁䅯䅁捁䅁䅁睕兂䙁䄸兕噂䕁䅫睑䱂䙁䄸睑偂䕁䄰䅕䅁䩁䅑䅁佁䅁䅁杒婂䑁䅉䅍祁䑁䅧䅁浂䅁䅁杕䅁䍁䅧兓畂䝁䅍杣求䝁䅅督求䍁䅫䅉癁䍁䅁䅚求䝁䅍杣求䝁䅅督求䍁䅁兡畂䍁䅁睤療䡁䅉睡灂䝁䄴睚杁䝁䅍兙睂䝁䅫䅤桂䝁䅷䅁湁䅁䅁䅥䅁䕁䄸䅣あ䝁䅫睢畂䡁䅍杏䑂䡁䅕杣祂䑁䄰兖呂䕁䅑䅌乂䝁䅅睚㥁䕁䄰䅌䕂䝁䅅䅤桂䙁䅑入睂䝁䅕児呂䕁䅑䅌呂䡁䅉睙㥁䕁䅍睢畂䡁䅍党畂䡁䅍兤穂䍁䄴兔求䝁䅑兡桂䝁䄴䅌佂䕁䅅児䅁䍁䉍䅁煁䅁䅁睑桂䡁䅁兡あ䝁䅅䅢杁䝁䅕䅥睂䝁䅕杢歂䝁䅫䅤ㅂ䡁䅉党穂䅁䅁䅋䅁䉁䅁䅁䝂䙁䅫兌祁䑁䅁杍㉁䅁䅁充䅁䙁䅧䅁䩂䝁䄴䅤求䡁䅉杢桂䡁䅑兡療䝁䄴兙獂䍁䅁村ㅂ䡁䅍兡畂䝁䅕督穂䍁䅁兔桂䝁䅍䅡灂䝁䄴党穂䍁䅁睑療䡁䅉䅣療䡁䅉兙あ䝁䅫睢畂䅁䅁兕䅁䝁䄴䅁䑂䝁䅅督潂䍁䅷䅉穂䝁䅧睢祂䡁䅑兌あ䝁䅕杣瑂䍁䅁兡畂䡁䅙党穂䡁䅑兢求䝁䄴䅤穂䍁䅁兙畂䝁䅑䅉瑂䝁䅅杣牂䝁䅕䅤桂䝁䅉䅢求䍁䅁督求䝁䅍兤祂䝁䅫䅤灂䝁䅕督䅁䍁䅁䅁あ䅁䅁杔求䡁䅑䅉橂䝁䅅督潂䍁䅁杚獂䝁䄸睤穂䍁䅁䅣祂䝁䄸杤灂䝁䅑党歂䍁䅁杙㕂䍁䄸䅋ㅂ䡁䅍党歂䍁䅁兡畂䍁䅫䅉浂䝁䅫杢桂䝁䄴睙灂䝁䄴睚杁䝁䅅睙あ䝁䅫杤灂䡁䅑兡求䡁䅍䅁歂允䅁䅓䅁䕁䄸䅣あ䝁䅫睢畂䡁䅍杏䑂䡁䅕杣祂䑁䄰兖呂䕁䅑䅌乂䝁䅅睚㥁䙁䅑杣灂䝁䅷䅢灂䝁䄸杢穂䍁䅷杔䉂䑁䄰䅍䅁䱁䅯䅁䍂䅁䅁睔睂䝁䅕杣桂䡁䅑兡畂䝁䅣䅉灂䝁䄴睙療䝁䄰党癁䍁䅧䅢療䡁䅍督灁䍁䅷䅉兂䡁䅉兡瑂䝁䅅杣㕂䅁䅁䅇䅁䙁䅯䅁偂䡁䅁䅤灂䝁䄸杢穂䑁䅯䅒桂䡁䅑兙啂䡁䅫䅣求䑁䄰睕䕂䍁䅷睕療䡁䅕杣橂䝁䅕児獁䕁䄰兙湂䑁䄰兑楂䡁䅍䅌䑂䡁䅕杣祂䑁䄰兖呂䕁䅑䅁乂䅁䅁䅖䅁䕁䄸䅣あ䝁䅫睢畂䡁䅍杏䉂䝁䅣睚祂䝁䅕睚桂䡁䅑党㥁䡁䅣兑坂䕁䅣䅌佂䕁䅅児橁䕁䄴睌䉂䍁䅷杒灂䝁䅷䅢㥁䕁䅑兙灂䝁䅷入䅁䡁䅷䅁允䅁䅁睑剂䑁䅉杍睁䑁䅉李䅁䑁䉕䅁啃䅁䅁睔睂䡁䅑兡療䝁䄴督㙁䕁䅑兙あ䝁䅅䅖㕂䡁䅁党㥁䙁䅍䅒獁䙁䅍睢ㅂ䡁䅉睙求䑁䄰睙療䝁䄴督求䝁䄴督ㅂ䡁䅍杌㉂䝁䅅兙橂䡁䅑兤桂䝁䅷督獁䕁䄰兙湂䝁䄴兡あ䡁䅕䅚求䑁䄰兑楂䡁䅍䅌䑂䡁䅕杣祂䝁䅕杢橂䡁䅫児噂䙁䅍䅒䅁䙁䅕䅁㡁䅁䅁䅒灂䡁䅙兡歂䝁䅕杢歂䍁䅁兑歂䝁䅯兤穂䡁䅑党歂䍁䅁睑獂䝁䄸督求䍁䅁䅕祂䝁䅫睙求䅁䅁睤䅁䥁䅁䅁偂䡁䅁䅤灂䝁䄸杢穂䑁䅯睑ㅂ䡁䅉杣㥁䙁䅕睕䕂䍁䅷兔桂䝁䅣児乂䍁䅷䅒桂䡁䅑兙啂䡁䅫䅣求䑁䄰睕䕂䍁䅷睕祂䝁䅍児橂䝁䄸杢穂䝁䅕杢穂䡁䅕督畁䡁䅙兙桂䝁䅍䅤ㅂ䝁䅅䅢穂䍁䅷杔䉂䑁䄰䅍䅁乁䅉䅁捁䅁䅁杔䉂䙁䅍䅒䉂䙁䅅睒呂䑁䅯兑䕂䕁䅉兒䅁䥁䅯䅁敁䅁䅁䅒灂䡁䅙兡歂䝁䅕杢歂䍁䅁兗灂䝁䅕䅢歂䅁䅁睋䅁䅁䄴䅁䝂䙁䅫杍睁䑁䅉睍䅁䝁䅯䅁畂䅁䅁睔睂䡁䅑兡療䝁䄴督㙁䕁䅅睚湂䡁䅉党湂䝁䅅䅤求䑁䄰睤䉂䙁䅙睒獁䕁䅑兙あ䝁䅕督㥁䕁䅉党浂䝁䄸杣求䍁䅷杔䉂䑁䄰睉佂䍁䄸兑獁䕁䅙兡獂䝁䅷児䕂䝁䅅兡獂䡁䅫䅁䑃䅁䅁李䅁䙁䅍睢ㅂ䡁䅉睙求䑁䄰睙療䝁䄴督求䝁䄴督ㅂ䡁䅍杌㉂䝁䅅兙橂䡁䅑兤桂䝁䅷督䅁䅁䅷䅁流䅁䅁䅒灂䡁䅙兡歂䝁䅕杢歂䍁䅁䅣求䡁䅉䅉穂䝁䅧兙祂䝁䅕䅁敁䅁䅁䅅䅁䑁䅑䅍睁䑁䅑杍硁䑁䅑䅁牃䅁䅁䅉䅁䕁䅕村䩂䙁䅑䅒䉂䍁䅷䅉兂䡁䅉兡瑂䝁䅅杣㕂䅁䅁杆䅁䝁䄴䅁䙂䙁䅁睕瑁䕁䅑兡獂䡁䅕䅤求䝁䅑兌䉂䡁䅁䅣獂䝁䅫睙桂䝁䅉䅢求䍁䅁䅤療䍁䅁睑療䝁䄰兢療䝁䄴䅉呂䡁䅑睢橂䝁䅳䅡療䝁䅷䅚求䡁䅉督獁䍁䅁䅕祂䝁䅫兢桂䡁䅉入䅁䉁䄰䅁杂䅁䅁睔睂䡁䅑兡療䝁䄴督㙁䕁䅑兙あ䝁䅅䅖㕂䡁䅁党㥁䙁䅍䅒獁䙁䅍杣橂䑁䄰睑療䝁䄴督求䝁䄴督ㅂ䡁䅍杌坂䕁䅅兑橂䡁䅑兤桂䝁䅷督獁䕁䄴兑㥁䅁䅁先䅅䉁䄴䅁䙂䝁䅅杣畂䝁䅫杢湂䡁䅍䅉婂䝁䅫党獂䝁䅑䅁灁䅁䅁䅬䅁䕁䄸䅣あ䝁䅫睢畂䡁䅍杏䕂䝁䅅䅤桂䙁䅑入睂䝁䅕児䑂䕁䅑䅌呂䝁䄸兤祂䝁䅍党㥁䝁䅍睢畂䡁䅍党畂䡁䅍兤穂䍁䄴杤桂䝁䅅睙あ䡁䅕兙獂䡁䅍䅌乂䝁䅅睚畂䝁䅫䅤ㅂ䝁䅑党㥁䕁䅅杙穂䍁䅷睑ㅂ䡁䅉杣求䝁䄴睙㕂䑁䄰兖呂䕁䅑䅁扂䅁䅁䅎䅁䕁䅕杢あ䝁䅕杣睂䡁䅉兡穂䝁䅕䅉坂䝁䅅䅢ㅂ䝁䅕䅉癁䍁䅁兒䍂䕁䅫䅖䕂䕁䅅䅁獁䅁䅁䅃䅁䕁䅫村乂䅁䅁䅕䅁䑁䅯䅁佂䝁䅕䅤杁䝁䅫杢橂䝁䄸兢求䍁䅁睌杁䍁䅧䅢療䡁䅍督灁䍁䅷䅉兂䡁䅉兡瑂䝁䅅杣㕂䅁䅁睆䅁䉁䅧䅁䩂䝁䄴䅤ㅂ䝁䅫䅤杁䕁䅫杢橂䍁䄴䅁㥄䅁䅁䅢䅁䙁䅳睕兂䕁䅣睘䝂䝁䅫杢桂䝁䄴睙灂䝁䅅䅢穂䕁䅅杢歂䙁䅁党求䡁䅉兑畂䝁䅅䅢㕂䡁䅍兡穂䙁䄸杖䉂䍁䄴䅥獂䡁䅍䅥摂䙁䅑党桂䡁䅉睕潂䝁䅕党あ䍁䅅䅊䙂䍁䅑兎䅁䝁䉉䅁允䅁䅁杒婂䍁䄰杍睁䑁䅉睍䅁䉁䅁䅁允䅁䅁杒婂䍁䄰杍睁䑁䅉䅎䅁䅁䄴䅁あ䅁䅁睔睂䡁䅑兡療䝁䄴督㙁䕁䅑兙あ䝁䅅䅖㕂䡁䅁党㥁䙁䅍䅒獁䙁䅍杣橂䑁䄰睙療䝁䄴督求䝁䄴督ㅂ䡁䅍杌㉂䝁䅅兙橂䡁䅑兤桂䝁䅷督獁䕁䄰兙湂䑁䄰䅌䑂䡁䅕杣祂䑁䄰兖呂䕁䅑䅁橂䅁䅁䅄䅁䕁䄰兙湂䑁䄰克䅁䑁䅑䅁䕂䅁䅁睔睂䡁䅑兡療䝁䄴督㙁䕁䅍兤祂䡁䅉児噂䙁䅍䅒獁䕁䄰兙湂䑁䄰村灂䝁䅷䅢灂䝁䄸杢穂䍁䅷杔䉂䑁䄰䅁䵂允䅁䅅䅁䕁䅙兗瑁䑁䅉䅍祁䑁䅕䅁呁䅁䅁䅅䅁䕁䅙兗瑁䑁䅉䅍祁䑁䅣䅁十䅁䅁䅡䅁䕁䄸䅣あ䝁䅫睢畂䡁䅍杏䉂䝁䅣睚祂䝁䅕睚桂䡁䅑党㥁䕁䄰睡あ䕁䅍兙睂䙁䅣党灂䝁䅣䅡あ䝁䅕䅚獁䕁䄴兑㥁䍁䅍杔癁䕁䅅䅌䝂䝁䅫䅢獂䑁䄰䅒桂䝁䅫䅢㕂䅁䅁杤䅁䉁䅷䅁兂䡁䅉兡橂䝁䅕䅉癁䍁䅁睕桂䝁䅷党穂䅁䅁䄴䅁䑁䅑䅁啂䝁䄸䅤桂䝁䅷䅉橂䡁䅕杣祂䝁䅕杢あ䍁䅁䅢灂䝁䅅杙灂䝁䅷兡あ䝁䅫党穂䅁䅁杉䅁䉁䅁䅁䝂䙁䅫兌祁䑁䅁杍㑁䅁䅁睄䅁䅁䄴䅁䝂䙁䅫杍睁䑁䅉杍䅁䝁䅣䅁佁䅁䅁杒婂䑁䅉䅍祁䑁䅑䅁牂䅁䅁杄䅁䕁䅙兗祁䑁䅁杍ㅁ䅁䅁党䅁䝁䅧䅁佂䝁䅕䅤杁䝁䅫杢橂䝁䄸兢求䍁䅁睌杁䍁䅧䅢療䡁䅍督灁䍁䅁杚祂䝁䄸兢杁䝁䅍睢畂䡁䅑兡畂䡁䅕兡畂䝁䅣䅉療䡁䅁党祂䝁䅅䅤灂䝁䄸杢穂䍁䅁䅋䑂䕁䅙克䅁䍁䅙䅁佁䅁䅁杒婂䑁䅉䅍祁䑁䅙䅁灂䅁䅁䅌䅁䕁䅣杣療䡁䅍督杁䙁䅁杣療䝁䅙兡あ䍁䅁睌杁䍁䅧䅢療䡁䅍督灁䅁䅁䅈䅁䥁䅉䅁偂䡁䅁䅤灂䝁䄸杢穂䑁䅯䅒桂䡁䅑兙啂䡁䅫䅣求䑁䄰睕䕂䍁䅷睕祂䝁䅍児䑂䝁䄸杢穂䝁䅕杢穂䡁䅕督畁䙁䅙兑䉂䝁䅍䅤ㅂ䝁䅅䅢穂䍁䅷兔桂䝁䅣児桂䝁䅉督獁䕁䅍兤祂䡁䅉児噂䙁䅍䅒獁䕁䄴兑㥁䅁䅁睈䅅䅁䄴䅁䝂䙁䅫杍睁䑁䅉睎䅁䝁䅧䅁慁䅁䅁睒祂䝁䄸督穂䍁䅁兢桂䡁䅉睚灂䝁䄴䅁畁䅁䅁䅉䅁䕁䅫兕時䕁䅍睔乂䙁䅁兑佂䙁䅫睘佂䕁䅅兔䙂䅁䅁兒䅁䡁䄴䅁䩂䝁䄴睙療䝁䄰党杁䍁䄸䅉潁䝁䅷睢穂䡁䅍克杁䝁䅙杣療䝁䄰䅉橂䝁䄸杢あ䝁䅫杢ㅂ䝁䅫杢湂䍁䅁睢睂䝁䅕杣桂䡁䅑兡療䝁䄴督杁䝁䅉党浂䝁䄸杣求䍁䅁兡畂䝁䅍睢瑂䝁䅕䅉あ䝁䅅䅥求䡁䅍䅁慁䅁䅁权䅁䕁䄰睕䝂䙁䅑䅁䅁䅁䅁䅅䅁䕁䄰兙湂䑁䄰兑楂䡁䅍䅁⽁䅁䅁杅䅁䕁䄴兗呂䕁䅕杏䥂䙁䅁兒䅁䩁䅙䅁佁䅁䅁兔桂䝁䅣児瑂䍁䅫䅁穁䅁䅁杍䅁䙁䅑睢あ䝁䅅䅢杁䝁䄴睢畂䍁䄰睑ㅂ䡁䅉杣求䝁䄴䅤杁䕁䅅督穂䝁䅕䅤穂䅁䅁睉䅁䉁䅷䅁乂䝁䅅睚畂䝁䅫䅤ㅂ䝁䅑党㥁䕁䅅杙穂䅁䅁材䅁䍁䅷䅁乂䝁䅫睙祂䝁䄸督療䝁䅙䅤杁䕁䅍睢祂䡁䅁睢祂䝁䅅䅤灂䝁䄸杢䅁䕁䅣䅁䝁䅁䅁杔䉂䅁䅁兆䅁䡁䅙䅁扂䙁䅍䅕䡂䙁䄸杒灂䝁䄴兙畂䝁䅍兡桂䝁䅷督䉂䝁䄴䅚兂䝁䅕党祂䕁䅅杢桂䝁䅷入穂䝁䅫督時䙁䅙兑畁䡁䅧䅢穂䡁䅧兘兂䝁䅕党祂䕁䅅杢桂䝁䅷入穂䝁䅫督桁䍁䅑兑䉂䍁䅑免祁䅁䅁兢䅅䉁䅉䅁佂䝁䅕䅤杁䕁䅑党楂䡁䅑䅁晁䅁䅁䅫䅁䕁䄸䅣あ䝁䅫睢畂䡁䅍杏䕂䝁䅅䅤桂䙁䅑入睂䝁䅕児䑂䕁䅑䅌呂䝁䄸兤祂䝁䅍党㥁䝁䅍睢畂䡁䅍党畂䡁䅍兤穂䍁䄴杤桂䝁䅅睙あ䡁䅕兙獂䡁䅍䅌乂䝁䅅睚畂䝁䅫䅤ㅂ䝁䅑党㥁䕁䄰䅌䑂䡁䅕杣祂䝁䅕杢橂䡁䅫児噂䙁䅍䅒䅁䙁䅯䅁㑂䅁䅁杔求䡁䅑䅉橂䝁䅅督潂䍁䅁杚獂䝁䄸睤穂䍁䅁䅣祂䝁䄸杤灂䝁䅑党歂䍁䅁杙㕂䍁䅁睌杁䍁䅧兤穂䝁䅕䅚杁䝁䅫杢灁䍁䅁睢睂䝁䅕杣桂䡁䅑兡畂䝁䅣䅉桂䝁䅍䅤灂䡁䅙兡あ䝁䅫党穂䅁䅁兊䅁䉁䅁䅁䝂䙁䅅杍祁䑁䅁杍㉁䅁䅁睌䅅䉁䅙䅁佂䝁䅕䅤杁䝁䄰兙祂䝁䅣兡畂䅁䅁睌䅁䥁䅉䅁偂䡁䅁䅤灂䝁䄸杢穂䑁䅯兑湂䝁䅣杣求䝁䅣兙あ䝁䅕児乂䝁䅳䅤䑂䝁䅅䅣塂䝁䅕兡湂䝁䅧䅤求䝁䅑䅌䕂䝁䅅䅤求䡁䅍児䍂䝁䅕杚療䡁䅉党獁䕁䄴兑㥁䍁䅍杔癁䕁䅅䅌䝂䝁䅫䅢獂䑁䄰䅒桂䝁䅫䅢㕂䅁䅁兣䅁䍁䅧䅁偂䡁䅁䅤灂䝁䄸杢穂䑁䅯䅒桂䡁䅑兙啂䡁䅫䅣求䑁䄰睕䕂䅁䅁睂䅁䝁䄴䅁偂䡁䅁䅤灂䝁䄸杢穂䑁䅯䅒桂䡁䅑兙啂䡁䅫䅣求䑁䄰睕䕂䍁䅷睕橂䡁䅉児獁䕁䅅䅚煂䑁䄰䅌䡂䡁䅉睢㍂䡁䅑䅡㥁䍁䅷兔桂䝁䅣児䉂䝁䅉督獁䕁䅍兤祂䡁䅉児噂䙁䅍䅒䅁䕁䅁䅁煂䅁䅁睔睂䡁䅑兡療䝁䄴督㙁䕁䅑兙あ䝁䅅䅖㕂䡁䅁党㥁䙁䅍䅒獁䙁䅍睙祂䑁䄰䅌䉂䝁䅑条㥁䍁䅷睒祂䝁䄸睤あ䝁䅧児獁䕁䄰兙湂䑁䄰兔獁䕁䅍兤祂䡁䅉児噂䙁䅍䅒䅁䕁䅅䅁允䅁䅁䅎硁䑁䅑䅎硁䑁䅕李䅁䅁䉧䅁啂䅁䅁睔睂䡁䅑兡療䝁䄴督㙁䕁䅑兙あ䝁䅅䅖㕂䡁䅁党㥁䙁䅍䅒獁䙁䅍睙祂䑁䄰䅌乂䝁䅅睚㥁䕁䅅杙穂䍁䅷睑ㅂ䡁䅉杣㥁䙁䅕睕䕂䅁䅁杓䅁䝁䅙䅁扂䙁䅍䅕䡂䙁䄸杒灂䝁䄴兙畂䝁䅍兡桂䝁䅷䅓灂䝁䅣䅡獂䝁䅫睚潂䡁䅑督時䙁䅙兑時䙁䅣兓兂䍁䄴䅥獂䡁䅍䅥摂䙁䅉党睂䝁䄸杣あ䍁䅅䅊䉂䕁䅕䅊㉁䑁䅙䅁䙁允䅁䅕䅁䕁䄸䅣あ䝁䅫睢畂䡁䅍杏䕂䝁䅅䅤桂䙁䅑入睂䝁䅕児呂䕁䅑䅌呂䝁䅍杣㥁䍁䅷兔桂䝁䅣児乂䍁䅷睑ㅂ䡁䅉杣㥁䙁䅕睕䕂䅁䅁睓䅁䩁䅁䅁偂䡁䅁䅤灂䝁䄸杢穂䑁䅯䅒桂䡁䅑兙啂䡁䅫䅣求䑁䄰睕䕂䍁䅷睕橂䡁䅉児橂䝁䄸杢穂䝁䅕杢穂䡁䅕督畁䡁䅙兙桂䝁䅍䅤ㅂ䝁䅅䅢穂䍁䅷兑歂䝁䅯児獁䕁䅣杣療䡁䅣䅤潂䑁䄰䅌乂䝁䅅睚㥁䕁䄰䅌䑂䡁䅕杣祂䑁䄰兖呂䕁䅑䅁䍂䅁䅁条䅁䕁䄸䅣あ䝁䅫睢畂䡁䅍杏䕂䝁䅅䅤桂䙁䅑入睂䝁䅕児呂䕁䅑䅌呂䝁䅍杣㥁䝁䅍睢畂䡁䅍党畂䡁䅍兤穂䍁䄴杤桂䝁䅅睙あ䡁䅕兙獂䡁䅍䅌䑂䡁䅕杣祂䑁䄰兖呂䕁䅑䅁䥂䅁䅁杤䅁䕁䄸䅣あ䝁䅫睢畂䡁䅍杏䕂䝁䅅䅤桂䙁䅑入睂䝁䅕児呂䕁䅑䅌呂䝁䅍杣㥁䝁䅍睢畂䡁䅍党畂䡁䅍兤穂䍁䄴杤桂䝁䅅睙あ䡁䅕兙獂䡁䅍䅌乂䝁䅅睚㥁䕁䄰䅌䑂䡁䅕杣祂䑁䄰兖呂䕁䅑䅁䑂䅁䅁杖䅁䕁䄸䅣あ䝁䅫睢畂䡁䅍杏䕂䝁䅅䅤桂䙁䅑入睂䝁䅕児呂䕁䅑䅌呂䝁䄸兤祂䝁䅍党㥁䍁䅷兔桂䝁䅣児乂䍁䅷睑ㅂ䡁䅉杣㥁䙁䅕睕䕂䅁䅁䅔䅁䅁䄴䅁䝂䙁䅫杍睁䑁䅍䅍䅁䥁䅫䅁䅃䅁䅁睔睂䡁䅑兡療䝁䄴督㙁䕁䅑兙あ䝁䅅䅖㕂䡁䅁党㥁䙁䅍䅒獁䙁䅍睢ㅂ䡁䅉睙求䑁䄰睙療䝁䄴督求䝁䄴督ㅂ䡁䅍杌㉂䝁䅅兙橂䡁䅑兤桂䝁䅷督獁䕁䄰兙湂䑁䄰兑楂䡁䅍䅌䑂䡁䅕杣祂䑁䄰兖呂䕁䅑䅁佂䅁䅁䅨䅁䙁䅳杓求䝁䅙杚求䡁䅉兡求䡁䅍䅔䵂䕁䅍睘祁䑁䅁李睁䑁䅙李硁䑁䅉睘䑂䡁䅕督あ䝁䄸兢䩂䝁䄴䅚求䡁䅧睘䑂䕁䅫兕兂䡁䅉睢畁䡁䅧䅢穂䝁䄰兘䩂䝁䄴督あ䡁䅉兤橂䡁䅑兡療䝁䄴督桁䍁䅑睒歁䑁䅅兏䅁䝁䄸䅁䥃䅁䅁睔睂䡁䅑兡療䝁䄴督㙁䕁䅑兙あ䝁䅅䅖㕂䡁䅁党㥁䙁䅍䅒獁䙁䅍睢ㅂ䡁䅉睙求䑁䄰睙療䝁䄴督求䝁䄴督ㅂ䡁䅍杌㉂䝁䅅兙橂䡁䅑兤桂䝁䅷督獁䕁䄰兙湂䑁䄰兑楂䡁䅍䅌䑂䡁䅕杣祂䝁䅕杢橂䡁䅫児噂䙁䅍䅒䅁䙁䅍䅁㡂䅁䅁睔睂䡁䅑兡療䝁䄴督㙁䕁䅑兙あ䝁䅅䅖㕂䡁䅁党㥁䙁䅍䅒獁䙁䅍睢ㅂ䡁䅉睙求䑁䄰睙療䝁䄴督求䝁䄴督ㅂ䡁䅍杌㉂䝁䅅兙橂䡁䅑兤桂䝁䅷督獁䕁䄰兙湂䑁䄰兔獁䕁䅍兤祂䡁䅉児噂䙁䅍䅒䅁䕁䄸䅁啃䅁䅁睔睂䡁䅑兡療䝁䄴督㙁䕁䅑兙あ䝁䅅䅖㕂䡁䅁党㥁䙁䅍䅒獁䙁䅍睢ㅂ䡁䅉睙求䑁䄰睙療䝁䄴督求䝁䄴督ㅂ䡁䅍杌㉂䝁䅅兙橂䡁䅑兤桂䝁䅷督獁䕁䄰兙湂䝁䄴兡あ䡁䅕䅚求䝁䄴兡あ䡁䅕䅚求䑁䄰兔獁䕁䅍兤祂䡁䅉児噂䙁䅍䅒䅁䙁䅣䅁㙂䅁䅁睔睂䡁䅑兡療䝁䄴督㙁䕁䅑兙あ䝁䅅䅖㕂䡁䅁党㥁䙁䅍䅒獁䙁䅍睢ㅂ䡁䅉睙求䑁䄰睙療䝁䄴督求䝁䄴督ㅂ䡁䅍杌㉂䝁䅅兙橂䡁䅑兤桂䝁䅷督獁䕁䄰兙湂䝁䄴兡あ䡁䅕䅚求䑁䄰兑楂䡁䅍䅁捂䅁䅁䅪䅁䕁䄸䅣あ䝁䅫睢畂䡁䅍杏䕂䝁䅅䅤桂䙁䅑入睂䝁䅕児呂䕁䅑䅌呂䝁䄸兤祂䝁䅍党㥁䝁䅍睢畂䡁䅍党畂䡁䅍兤穂䍁䄴杤桂䝁䅅睙あ䡁䅕兙獂䡁䅍䅌乂䝁䅅睚畂䝁䅫䅤ㅂ䝁䅑党㥁䕁䅅杙穂䍁䅷睑ㅂ䡁䅉杣㥁䙁䅕睕䕂䅁䅁杖䅁䥁䅧䅁偂䡁䅁䅤灂䝁䄸杢穂䑁䅯䅒桂䡁䅑兙啂䡁䅫䅣求䑁䄰睕䕂䍁䅷睕療䡁䅕杣橂䝁䅕児橂䝁䄸杢穂䝁䅕杢穂䡁䅕督畁䡁䅙兙桂䝁䅍䅤ㅂ䝁䅅䅢穂䍁䅷兔桂䝁䅣杢灂䡁䅑兤歂䝁䅕児乂䍁䅷睑ㅂ䡁䅉杣㥁䙁䅕睕䕂䅁䅁䅖䅁䙁䅁䅁偂䡁䅁䅤灂䝁䄸杢穂䑁䅯䅒桂䡁䅑兙啂䡁䅫䅣求䑁䄰睕䕂䍁䅷睕祂䝁䅍児噂䕁䅉睕獁䕁䄰兙湂䑁䄰兑楂䡁䅍䅌佂䕁䅅児䅁䕁䉕䅁元䅁䅁睔睂䡁䅑兡療䝁䄴督㙁䕁䅑兙あ䝁䅅䅖㕂䡁䅁党㥁䙁䅍䅒獁䙁䅍睢ㅂ䡁䅉睙求䑁䄰睙療䝁䄴督求䝁䄴督ㅂ䡁䅍杌㉂䝁䅅兙橂䡁䅑兤桂䝁䅷督獁䕁䄰兙湂䝁䄴兡あ䡁䅕䅚求䑁䄰兔獁䕁䅍兤祂䡁䅉党畂䝁䅍入㥁䙁䅕睕䕂䅁䅁䅗䅁䉁䅷䅁佂䕁䅅睕䕂䕁䅅兕䡂䙁䅍杏乂䕁䅕䅖䉂䅁䅁杂䅅䝁䅯䅁偂䡁䅁䅤灂䝁䄸杢穂䑁䅯䅒桂䡁䅑兙啂䡁䅫䅣求䑁䄰睕䕂䍁䅷睕祂䝁䅍児橂䝁䄸杢穂䝁䅕杢穂䡁䅕督畁䡁䅙兙桂䝁䅍䅤ㅂ䝁䅅䅢穂䍁䅷睑ㅂ䡁䅉杣㥁䙁䅕睕䕂䅁䅁兙䅁䝁䅧䅁偂䡁䅁䅤灂䝁䄸杢穂䑁䅯䅒桂䡁䅑兙啂䡁䅫䅣求䑁䄰睕䕂䍁䅷睕祂䝁䅍児橂䝁䄸杢穂䝁䅕杢穂䡁䅕督畁䡁䅙兙桂䝁䅍䅤ㅂ䝁䅅䅢穂䍁䅷兔桂䝁䅣児䉂䝁䅉督䅁䝁䅑䅁㉂䅁䅁睔睂䡁䅑兡療䝁䄴督㙁䕁䅑兙あ䝁䅅䅖㕂䡁䅁党㥁䙁䅍䅒獁䙁䅍杣橂䑁䄰睙療䝁䄴督求䝁䄴督ㅂ䡁䅍杌㉂䝁䅅兙橂䡁䅑兤桂䝁䅷督獁䕁䄰兙湂䑁䄰兔獁䕁䅍兤祂䡁䅉児䉂䕁䅕䅒䅁䥁䅣䅁䍃䅁䅁睔睂䡁䅑兡療䝁䄴督㙁䕁䅑兙あ䝁䅅䅖㕂䡁䅁党㥁䙁䅍䅒獁䙁䅍杣橂䑁䄰睙療䝁䄴督求䝁䄴督ㅂ䡁䅍杌㉂䝁䅅兙橂䡁䅑兤桂䝁䅷督獁䕁䄰兙湂䑁䄰兔獁䕁䅍兤祂䡁䅉児噂䙁䅍䅉䕂䝁䄸䅢獂䝁䅅杣䅁䥁䅑䅁㉂䅁䅁睔睂䡁䅑兡療䝁䄴督㙁䕁䅑兙あ䝁䅅䅖㕂䡁䅁党㥁䙁䅍䅒獁䙁䅍杣橂䑁䄰睙療䝁䄴督求䝁䄴督ㅂ䡁䅍杌㉂䝁䅅兙橂䡁䅑兤桂䝁䅷督獁䕁䄰兙湂䑁䄰兔獁䕁䅍兤祂䡁䅉児噂䙁䅍䅒䅁䝁䅁䅁㙂䅁䅁睔睂䡁䅑兡療䝁䄴督㙁䕁䅑兙あ䝁䅅䅖㕂䡁䅁党㥁䙁䅍䅒獁䙁䅍杣橂䑁䄰睙療䝁䄴督求䝁䄴督ㅂ䡁䅍杌㉂䝁䅅兙橂䡁䅑兤桂䝁䅷督獁䕁䄰兙湂䑁䄰兙楂䡁䅍䅌䑂䡁䅕杣祂䑁䄰兑䙂䕁䅑䅁䥃䅁䅁杨䅁䕁䄸䅣あ䝁䅫睢畂䡁䅍杏䕂䝁䅅䅤桂䙁䅑入睂䝁䅕児呂䕁䅑䅌呂䡁䅉睙㥁䝁䅍睢畂䡁䅍党畂䡁䅍兤穂䍁䄴杤桂䝁䅅睙あ䡁䅕兙獂䡁䅍䅌乂䝁䅅睚㥁䝁䅅杙穂䍁䅷睑ㅂ䡁䅉杣㥁䙁䅕睕杁䕁䅑睢獂䝁䅷兙祂䅁䅁杨䅁䡁䅯䅁偂䡁䅁䅤灂䝁䄸杢穂䑁䅯䅒桂䡁䅑兙啂䡁䅫䅣求䑁䄰睕䕂䍁䅷睕祂䝁䅍児橂䝁䄸杢穂䝁䅕杢穂䡁䅕督畁䡁䅙兙桂䝁䅍䅤ㅂ䝁䅅䅢穂䍁䅷兔桂䝁䅣児桂䝁䅉督獁䕁䅍兤祂䡁䅉児噂䙁䅍䅒䅁䝁䅉䅁䝁䅁䅁免䕂䅁䅁睃䅅䉁䅙䅁偂䡁䅁䅤灂䝁䄸杢穂䑁䅯睕䕂䅁䅁䅂䅁䉁䅁䅁ぁ䑁䅙杍ㅁ䑁䅁兏㕁䅁䅁杰䅁䍁䅉䅁兂䡁䅉兡橂䝁䅕䅉癁䍁䅁兒桂䡁䅉杢灂䝁䄴睚穂䅁䅁兌䅁䙁䄴䅁偂䡁䅁䅤灂䝁䄸杢穂䑁䅯䅒桂䡁䅑兙啂䡁䅫䅣求䑁䄰睕䕂䍁䅷睕祂䝁䅍児噂䕁䅉睕獁䕁䄰兙湂䑁䄰睓獁䕁䅍兤祂䡁䅉児噂䙁䅍䅒獁䕁䄴兑㥁䅁䅁兔䅅䍁䄴䅁兂䡁䅉兡橂䝁䅕䅉癁䍁䅁杒祂䝁䅕党杁䕁䅍兙穂䝁䅧䅉䝂䝁䅷睢㍂䅁䅁杋䅁䅁䅧䅁䵂䙁䅑兔䅁䵁䅕䅁慁䅁䅁睕䡂䍁䅙兑杁䍁䄸䅉呂䝁䅅䅢求䡁䅍䅁硁䅁䅁䅧䅁䙁䅍䅕䡂䕁䄸䅣あ䝁䅫睢畂䡁䅍杏䕂䝁䅅䅤桂䙁䅑入睂䝁䅕児呂䕁䅑䅌呂䝁䄸兤祂䝁䅍党㥁䝁䅍睢畂䡁䅍党畂䡁䅍兤穂䍁䄴杤桂䝁䅅睙あ䡁䅕兙獂䡁䅍䅌乂䝁䅅睚畂䝁䅫䅤ㅂ䝁䅑党㥁䕁䅅杙穂䅁䅁杘䅁䩁䅯䅁呂䙁䅁睒偂䡁䅁䅤灂䝁䄸杢穂䑁䅯䅒桂䡁䅑兙啂䡁䅫䅣求䑁䄰睕䕂䍁䅷睕療䡁䅕杣橂䝁䅕児橂䝁䄸杢穂䝁䅕杢穂䡁䅕督畁䡁䅙兙桂䝁䅍䅤ㅂ䝁䅅䅢穂䍁䅷兔桂䝁䅣杢灂䡁䅑兤歂䝁䅕児䉂䝁䅉督獁䕁䅍兤祂䡁䅉党畂䝁䅍入㥁䙁䅕睕䕂䅁䅁睘䅁䑁䅉䅁䡂䡁䅉睢穂䡁䅍䅉睂䡁䅉睢浂䝁䅫䅤癁䍁䅧䅢療䡁䅍督灁䍁䅷䅉婂䝁䄸兗䅁䅁䈰䅁坃䅁䅁睕兂䕁䅣睔睂䡁䅑兡療䝁䄴督㙁䕁䅑兙あ䝁䅅䅖㕂䡁䅁党㥁䙁䅍䅒獁䙁䅍睢ㅂ䡁䅉睙求䑁䄰睙療䝁䄴督求䝁䄴督ㅂ䡁䅍杌㉂䝁䅅兙橂䡁䅑兤桂䝁䅷督獁䕁䄰兙湂䝁䄴兡あ䡁䅕䅚求䑁䄰兔獁䕁䅍兤祂䡁䅉党畂䝁䅍入㥁䙁䅕睕䕂䅁䅁兘䅁䉁䅉䅁呂䙁䅁睒啂䝁䅅杙獂䝁䅕䅁㝁䅁䅁䅣䅁䙁䅳睕兂䕁䅣睘坂䝁䅅䅢ㅂ䝁䅅䅤灂䝁䄸杢䉂䝁䄴䅚兂䝁䅕党祂䕁䅅杢桂䝁䅷入穂䝁䅫督時䙁䅙兑時䡁䅙杍畁䡁䅧䅢穂䡁䅧兘啂䝁䅕兙祂䙁䅍䅡求䝁䅕䅤桁䍁䅑兒歁䑁䅕䅁捂允䅁䅉䅁䙁䅍䅕時䕁䅍睔乂䙁䅁兑佂䙁䅫睘佂䕁䅅兔䙂䅁䅁杒䅁䡁䅉䅁偂䡁䅁䅤灂䝁䄸杢穂䑁䅯睑ㅂ䡁䅉杣㥁䙁䅕睕䕂䍁䅷䅒桂䡁䅑兙啂䡁䅫䅣求䑁䄰睕䕂䍁䅷睕祂䝁䅍児䑂䝁䄸杢穂䝁䅕杢穂䡁䅕督畁䙁䅙兑䉂䝁䅍䅤ㅂ䝁䅅䅢穂䍁䅷杔䉂䑁䄰䅁杁允䅁杈䅁䙁䅍䅕時䙁䅁杕䩂䕁䅍兒時䕁䅍䅔偂䙁䅍兒䅁䝁䄴䅁流䅁䅁睕兂䙁䄸䅕卂䕁䅫睑䙂䙁䄸睑䵂䕁䄸睕䙂䙁䄸兑䕂䕁䅯䅁ㅂ䅁䅁䅂䅁䑁䅁䅁䵄䅁䅁杄䅁䙁䅍睘ㅁ䑁䅙兎祁䅁䅁杂䅁䉁䅁䅁䝂䙁䅅免祁䑁䅁杍㉁䅁䅁杌䅅䉁䅁䅁䑂䙁䅅䅎祁䑁䅁杍㉁䅁䅁睎䅅䙁䅯䅁呂䝁䅕䅢獂䝁䅫杢湂䍁䅷䅉湂䝁䅕杢求䡁䅉兙獂䍁䅁兙畂䝁䅑䅉桂䝁䅑兢灂䝁䄴兡穂䡁䅑杣桂䡁䅑兡㉂䝁䅕䅉求䡁䅧䅣求䝁䄴督求䡁䅍䅁婁䅁䅁李䅁䙁䅍睢ㅂ䡁䅉睙求䑁䅯睙療䝁䄴督求䝁䄴督ㅂ䡁䅍杌㉂䝁䅅兙橂䡁䅑兤桂䝁䅷督䅁䅁䅳䅁䝃䅁䅁睗䭂䝁䅕杚浂䝁䅕杣灂䝁䅕督䵂䕁䅷睑時䑁䅉䅍㉁䑁䅁李㉁䑁䅅杍時䕁䅍兤穂䡁䅑睢瑂䕁䅫杢歂䝁䅕䅥時䕁䅍兓剂䙁䅁杣療䍁䄴䅥獂䡁䅍兢摂䕁䅑兙あ䝁䅅睘乂䡁䅕䅢あ䝁䅫䅣獂䝁䅕督桁䍁䅑睑歁䑁䅣䅁䍃䅁䅁䅊䅁䙁䅍睢ㅂ䡁䅉睙求䑁䄰杖䉂䍁䅁兑橂䡁䅑兤桂䝁䅷督䅁䅁䄰䅁允䅁䅁䅎祁䑁䅉杍祁䑁䅧李䅁䭁䅷䅁煁䅁䅁杒祂䝁䅕党杁䕁䅍兙穂䝁䅧䅉䝂䝁䅷睢㍂䍁䅁兗灂䝁䅕䅢歂䅁䅁杗䅅䉁䅷䅁䉂䝁䅷䅣潂䝁䅅杙求䡁䅑䅉䩂䝁䄴睙畁䅁䅁朹䅁䉁䄴䅁呂䡁䅉睙㥁䙁䅙兑杁䕁䅅睙あ䡁䅕兙獂䡁䅍䅁䭁䅁䅁杒䅁䕁䄸䅣あ䝁䅫睢畂䡁䅍杏䑂䡁䅕杣祂䑁䄰兖呂䕁䅑䅌乂䝁䅅睚㥁䕁䄰兡獂䝁䅷兡療䝁䄴督獁䕁䄴兑㥁䍁䄰䅁奄䅁䅁䅍䅁䙁䅍杣橂䑁䄰睙療䝁䄴督求䝁䄴督ㅂ䡁䅍杌㉂䝁䅅兙橂䡁䅑兤桂䝁䅷督䅁䅁䅫䅁煁䅁䅁䅖療䡁䅑兙獂䍁䅁睑ㅂ䡁䅉杣求䝁䄴䅤杁䕁䅅督穂䝁䅕䅤穂䅁䅁䅊䅁䉁䅯䅁佂䝁䅕䅤䉂䡁䅁䅣獁䍁䅁兓畂䝁䅍杌䅁䩁䅅䅁䥁䅁䅁兎祁䙁䅣䅁㡃䅁䅁䅐䅁䙁䅑睢あ䝁䅅䅢杁䝁䄴睢畂䍁䄰睙ㅂ䡁䅉杣求䝁䄴䅤杁䝁䅷兡桂䝁䅉兡獂䝁䅫䅤灂䝁䅕督䅁䍁䅅䅁祁䅁䅁䅖療䡁䅑兙獂䍁䅁睢睂䝁䅕杣桂䡁䅑兡畂䝁䅣䅉求䡁䅧䅣求䝁䄴督求䡁䅍䅁扁䅁䅁䅈䅁䙁䅑睢あ䝁䅅䅢杁䡁䅉党㉂䝁䅕杢ㅂ䝁䅕䅁婂䅁䅁杌䅁䙁䅑睢あ䝁䅅䅢杁䡁䅉党㉂䝁䅕杢ㅂ䝁䅕䅌杁䙁䅁杣灂䝁䄰兙祂䡁䅫䅁䉁䅁䅁杨䅁䙁䅳杓求䝁䅙杚求䡁䅉兡求䡁䅍䅔䵂䕁䅍睘祁䑁䅁李睁䑁䅙李硁䑁䅉睘䑂䡁䅕督あ䝁䄸兢䩂䝁䄴䅚求䡁䅧睘䑂䕁䅫兕兂䡁䅉睢畁䡁䅧䅢穂䝁䄰兘䕂䝁䅅䅤桂䙁䄸兔ㅂ䝁䅷䅤灂䡁䅁䅢求䡁䅍光歁䕁䅑䅊㍁䅁䅁入䅁䥁䅙䅁扂䕁䅯党浂䝁䅙党祂䝁䅫党穂䕁䅷䅔䑂䙁䄸杍睁䑁䅙䅍㉁䑁䅙免祁䙁䄸睑ㅂ䡁䅍䅤療䝁䄰兓畂䝁䅑党㑂䙁䄸睑䩂䙁䅅䅕祂䝁䄸杌㑂䝁䅷督瑂䙁䄰䅒桂䡁䅑兙時䕁䄰兤獂䡁䅑兡睂䝁䅷党穂䍁䅅䅊䙂䍁䅑睎䅁䥁䅁䅁䍃䅁䅁睗䭂䝁䅕杚浂䝁䅕杣灂䝁䅕督䵂䕁䅷睑時䑁䅉䅍㉁䑁䅁李㉁䑁䅅杍時䕁䅍兤穂䡁䅑睢瑂䕁䅫杢歂䝁䅕䅥時䕁䅍兓剂䙁䅁杣療䍁䄴䅥獂䡁䅍兢摂䕁䅑兙あ䝁䅅睘卂䝁䅕䅤ㅂ䡁䅉杢穂䍁䅅䅊䑂䍁䅑睎䅁䝁䅷䅁捁䅁䅁杔䉂䙁䅍䅒䉂䙁䅅睒呂䑁䅯兓佂䙁䅑睑䅁䥁䄴䅁䍃䅁䅁睗䭂䝁䅕杚浂䝁䅕杣灂䝁䅕督䵂䕁䅷睑時䑁䅉䅍㉁䑁䅁李㉁䑁䅅杍時䕁䅍兤穂䡁䅑睢瑂䕁䅫杢歂䝁䅕䅥時䕁䅍兓剂䙁䅁杣療䍁䄴䅥獂䡁䅍兢摂䕁䅑兙あ䝁䅅睘卂䝁䅕䅤ㅂ䡁䅉杢穂䍁䅅䅊䕂䍁䅑睎䅁䡁䅧䅁䍃䅁䅁睗䭂䝁䅕杚浂䝁䅕杣灂䝁䅕督䵂䕁䅷睑時䑁䅉䅍㉁䑁䅁李㉁䑁䅅杍時䕁䅍兤穂䡁䅑睢瑂䕁䅫杢歂䝁䅕䅥時䕁䅍兓剂䙁䅁杣療䍁䄴䅥獂䡁䅍兢摂䕁䅑兙あ䝁䅅睘卂䝁䅕䅤ㅂ䡁䅉杢穂䍁䅅䅊䙂䍁䅑睎䅁䡁䄸䅁䍃䅁䅁睗䭂䝁䅕杚浂䝁䅕杣灂䝁䅕督䵂䕁䅷睑時䑁䅉䅍㉁䑁䅁李㉁䑁䅅杍時䕁䅍兤穂䡁䅑睢瑂䕁䅫杢歂䝁䅕䅥時䕁䅍兓剂䙁䅁杣療䍁䄴䅥獂䡁䅍兢摂䕁䅑兙あ䝁䅅睘卂䝁䅕䅤ㅂ䡁䅉杢穂䍁䅅䅊䭂䍁䅑睎䅁䥁䅅䅁䍃䅁䅁睗䭂䝁䅕杚浂䝁䅕杣灂䝁䅕督䵂䕁䅷睑時䑁䅉䅍㉁䑁䅁李㉁䑁䅅杍時䕁䅍兤穂䡁䅑睢瑂䕁䅫杢歂䝁䅕䅥時䕁䅍兓剂䙁䅁杣療䍁䄴䅥獂䡁䅍兢摂䕁䅑兙あ䝁䅅睘卂䝁䅕䅤ㅂ䡁䅉杢穂䍁䅅䅊䱂䍁䅑睎䅁䡁䅍䅁䍃䅁䅁睗䭂䝁䅕杚浂䝁䅕杣灂䝁䅕督䵂䕁䅷睑時䑁䅉䅍㉁䑁䅁李㉁䑁䅅杍時䕁䅍兤穂䡁䅑睢瑂䕁䅫杢歂䝁䅕䅥時䕁䅍兓剂䙁䅁杣療䍁䄴䅥獂䡁䅍兢摂䕁䅑兙あ䝁䅅睘卂䝁䅕䅤ㅂ䡁䅉杢穂䍁䅅䅊䵂䍁䅑睎䅁䡁䄰䅁䕃䅁䅁睗䭂䝁䅕杚浂䝁䅕杣灂䝁䅕督䵂䕁䅷睑時䑁䅉䅍㉁䑁䅁李㉁䑁䅅杍時䕁䅍兤穂䡁䅑睢瑂䕁䅫杢歂䝁䅕䅥時䕁䅍兓剂䙁䅁杣療䍁䄴䅥獂䡁䅍兢摂䕁䅫杢穂䡁䅑杣ㅂ䝁䅍䅤灂䝁䄸杢穂䍁䅅䅊䡂䍁䅑杍睁䅁䅁䅣䅁䡁䄴䅁偂䡁䅁䅤灂䝁䄸杢穂䑁䅯䅒桂䡁䅑兙啂䡁䅫䅣求䑁䄰睕䕂䍁䅷睕祂䝁䅍児䑂䝁䄸杢穂䝁䅕杢穂䡁䅕督畁䙁䅙兑䉂䝁䅍䅤ㅂ䝁䅅䅢穂䍁䅷兔桂䝁䅣児䍂䍁䅷睑ㅂ䡁䅉杣㥁䙁䅕睕䕂䍁䅷杔䉂䑁䄰䅁䭂允䅁䅫䅁䙁䅳杓求䝁䅙杚求䡁䅉兡求䡁䅍䅔䵂䕁䅍睘祁䑁䅁李睁䑁䅙李硁䑁䅉睘䑂䡁䅕督あ䝁䄸兢䩂䝁䄴䅚求䡁䅧睘䑂䕁䅫兕兂䡁䅉睢畁䡁䅧䅢穂䝁䄰兘䩂䝁䄴督あ䡁䅉兤橂䡁䅑兡療䝁䄴督桁䍁䅑䅔歁䑁䅅睍㙁䍁䅑䅔歁䑁䅅兎䅁䝁䄰䅁元䅁䅁睗䭂䝁䅕杚浂䝁䅕杣灂䝁䅕督䵂䕁䅷睑時䑁䅉䅍㉁䑁䅁李㉁䑁䅅杍時䕁䅍兤穂䡁䅑睢瑂䕁䅫杢歂䝁䅕䅥時䕁䅍兓剂䙁䅁杣療䍁䄴䅥獂䡁䅍兢摂䕁䅫杢穂䡁䅑杣ㅂ䝁䅍䅤灂䝁䄸杢穂䍁䅅䅊佂䍁䅑免穁䑁䅯䅊佂䍁䅑杍祁䅁䅁䅤䅁䉁䅧䅁剂䡁䅕兡橂䝁䅳䅉䑂䝁䄸兢睂䡁䅍䅁歃䅁䅁䅨䅁䙁䅳杓求䝁䅙杚求䡁䅉兡求䡁䅍䅔䵂䕁䅍睘祁䑁䅁李睁䑁䅙李硁䑁䅉睘䑂䡁䅕督あ䝁䄸兢䩂䝁䄴䅚求䡁䅧睘䑂䕁䅫兕兂䡁䅉睢畁䡁䅧䅢穂䝁䄰兘䩂䝁䄴䅤求䡁䅉兢求䝁䅑兡桂䡁䅑党桁䍁䅑䅔歁䑁䅑䅎䅁䡁䅯䅁䕃䅁䅁睗䭂䝁䅕杚浂䝁䅕杣灂䝁䅕督䵂䕁䅷睑時䑁䅉䅍㉁䑁䅁李㉁䑁䅅杍時䕁䅍兤穂䡁䅑睢瑂䕁䅫杢歂䝁䅕䅥時䕁䅍兓剂䙁䅁杣療䍁䄴䅥獂䡁䅍兢摂䕁䅫杢あ䝁䅕杣瑂䝁䅕䅚灂䝁䅅䅤求䍁䅅䅊乂䍁䅑䅎ぁ䅁䅁睥䅁䍁䅧䅁橂䝁䄸杢穂䝁䅕杢穂䡁䅕督畁䡁䅙兙桂䝁䅍䅤ㅂ䝁䅅䅢穂䅁䅁睁䅁䉁䅉䅁橂䡁䅕杣祂䑁䄰兖呂䕁䅑䅁㡁䅁䅁䅅䅁䕁䅙兕穁䑁䅉䅍祁䑁䅕䅁㙁允䅁杆䅁䕁䅅䅚療䝁䅉党杁䕁䅫杢橂䍁䄴䅁䱃䅁䅁杄䅁䕁䅙兗祁䑁䅁杍㕁䅁䅁䅪䅁䉁䅷䅁佂䕁䅅睕䕂䕁䅅兕䡂䙁䅍杏乂䙁䅍杒啂䅁䅁兪䅁䉁䅁䅁ぁ䑁䅍免㑁䑁䅙兎硁䅁䅁睅䅅䍁䅑䅁䩂䝁䄴䅤求䝁䅷䅉䑂䝁䄸杣睂䝁䄸杣桂䡁䅑兡療䝁䄴䅁偃䅁䅁䅈䅁䕁䄴兑呂䕁䅑兑剂䕁䅣睕㙁䕁䄴䅖䉂䙁䅁䅁元䅁䅁䅢䅁䍁䅣睗呂䙁䅁睒時䕁䅙兡畂䝁䅅杢橂䝁䅫兙獂䕁䅧兡湂䝁䅧䅢灂䝁䅣䅡あ䡁䅍睘坂䕁䅅睘㉂䑁䅅䅉潁䑁䅅克畁䡁䅧䅢穂䡁䅧兘乂䝁䅅兡畂䍁䅣光歁䕁䅅兓歁䑁䅑䅏䅁䩁䅉䅁潂䅁䅁睊扂䙁䅍䅕䡂䙁䄸杒灂䝁䄴兙畂䝁䅍兡桂䝁䅷䅓灂䝁䅣䅡獂䝁䅫睚潂䡁䅑督時䙁䅙兑時䡁䅙免杁䍁䅧免灁䍁䄴䅥獂䡁䅍䅥摂䕁䄰兙灂䝁䄴睊桁䍁䅑杒歁䑁䅫䅁呃䅁䅁杄䅁䕁䅍兗祁䑁䅁睍睁䅁䅁杕䅅䍁䅧䅁橁䕁䅫杔坂䕁䅅䅔䩂䕁䅑䅉䑂䕁䄸兔兂䕁䅅杔婂䍁䅁兓䕂䅁䅁公䅁䕁䅙䅁䥂䝁䅕睤獂䝁䅕䅤あ䍁䅁䅕桂䝁䅍睡桂䡁䅉䅚杁䕁䅕杢あ䝁䅕杣睂䡁䅉兡穂䝁䅕䅉䑂䝁䄸兢睂䝁䅅杢㕂䅁䅁睬䅁䉁䅑䅁佂䙁䅫睕䙂䑁䅯睔卂䕁䅍䅔䅁䩁䅧䅁流䅁䅁睔祂䝁䅅睙獂䝁䅕䅉䑂䝁䄸杣睂䝁䄸杣桂䡁䅑兡療䝁䄴䅁婃䅁䅁条䅁䍁䅣睗呂䙁䅁睒時䕁䅙兡畂䝁䅅杢橂䝁䅫兙獂䕁䅧兡湂䝁䅧䅢灂䝁䅣䅡あ䡁䅍睘坂䕁䅅睘㉂䑁䅅䅉潁䑁䅅克畁䡁䅧䅢穂䡁䅧兘乂䝁䅅兡畂䍁䅣光歁䕁䅑䅊㉁䑁䅙䅁楃䅁䅁杅䅁䕁䄴兗呂䕁䅕杏䉂䕁䅍杔䅁䩁䅯䅁捁䅁䅁兑橂䝁䅍党畂䡁䅑兤祂䝁䅕䅉睂䝁䅷睙䅁䩁䅳䅁獂䅁䅁睔睂䡁䅑兡療䝁䄴督㙁䕁䅍兤祂䡁䅉児噂䙁䅍䅒獁䕁䅑兙あ䝁䅅䅖㕂䡁䅁党㥁䙁䅍䅒獁䙁䅍杣橂䑁䄰睑療䝁䄴督求䝁䄴督ㅂ䡁䅍杌乂䝁䅕䅚灂䝁䅅杢獁䕁䄴兑㥁䅁䅁杊䅅䉁䅷䅁佂䕁䅅睕䕂䕁䅅兕䡂䙁䅍杏䑂䙁䅍睑偂䅁䅁䅮䅁䍁䅧䅁䑂䝁䅫督橂䝁䄸䅉呂䡁䅫督あ䝁䅕兢穂䍁䅷䅉䩂䝁䄴睙畁䅁䅁兮䅁䉁䅷䅁佂䕁䅅睕䕂䕁䅅兕䡂䙁䅍杏䑂䙁䅑睕䥂䅁䅁杮䅁䙁䅙䅁䑂䝁䄸睚畂䝁䅫来桂䝁䄴䅤杁䙁䅑党橂䝁䅧杢療䝁䅷睢湂䡁䅫䅉呂䝁䄸䅢ㅂ䡁䅑兡療䝁䄴督杁䕁䅍睢祂䡁䅁睢祂䝁䅅䅤灂䝁䄸杢䅁䩁䄸䅁允䅁䅁䅎㕁䑁䅣䅍ぁ䑁䅣睍䅁偁䅯䅁啁䅁䅁杔婂䙁䅍兒㙁䕁䅑兒䵂䕁䅷䅁权䅁䅁杌䅁䕁䅑党獂䝁䅷䅉啂䝁䅕睙潂䝁䄴睢獂䝁䄸睚灂䝁䅕督杁䕁䅫杢橂䍁䄴䅁桃䅁䅁䅚䅁䙁䅳睕兂䕁䅣睘䝂䝁䅫杢桂䝁䄴睙灂䝁䅅䅢䥂䝁䅫睚潂䝁䅷兡湂䝁䅧䅤穂䙁䄸杖䉂䙁䄸睖䩂䙁䅁杌㑂䝁䅷督㑂䙁䄰杕求䡁䅁睢祂䡁䅑光歁䕁䅑䅊㉁䑁䅣䅁䕁允䅁杅䅁䕁䄴兗呂䕁䅕杏䩂䕁䅉兔䅁偁䅣䅁潂䅁䅁睊扂䙁䅍䅕䡂䙁䄸杒灂䝁䄴兙畂䝁䅍兡桂䝁䅷䅓灂䝁䅣䅡獂䝁䅫睚潂䡁䅑督時䙁䅙兑時䡁䅙免杁䍁䅧免灁䍁䄴䅥獂䡁䅍䅥摂䕁䄰兙灂䝁䄴睊桁䍁䅑䅒歁䑁䅕䅁橃䅁䅁䅅䅁䕁䅙兕ぁ䑁䅉䅍祁䑁䅙䅁睁允䅁䅅䅁䕁䅍兕硁䑁䅉䅍祁䑁䅙䅁穁允䅁杇䅁䙁䅍䅕時䕁䅕杔啂䕁䅫䅖婂䙁䄸兓䕂䅁䅁兰䅁䉁䅁䅁ぁ䑁䅅䅎祁䑁䅣李睁䅁䅁睰䅁䉁䅯䅁呂䙁䅁睘兂䙁䅉兓䑂䕁䅕睘䵂䕁䄸睖䅁䱁䄰䅁允䅁䅁䅎㉁䑁䅑免穁䑁䅧睍䅁䭁䅧䅁允䅁䅁䅎睁䑁䅑睎㑁䑁䅕睎䅁䭁䅫䅁允䅁䅁䅎睁䑁䅑免穁䑁䅙睍䅁䭁䅯䅁允䅁䅁䅎穁䑁䅁兎ㅁ䑁䅙杍䅁䭁䄰䅁允䅁䅁䅎睁䑁䅑睎㑁䑁䅑睎䅁䭁䄴䅁捁䅁䅁杔䉂䙁䅍䅒䉂䙁䅅睒呂䑁䅯兕䑂䕁䄸兔䅁䭁䄸䅁允䅁䅁䅎睁䑁䅙杍ぁ䑁䅫李䅁䱁䅁䅁煂䅁䅁睊扂䙁䅍䅕䡂䙁䄸杒灂䝁䄴兙畂䝁䅍兡桂䝁䅷䅓灂䝁䅣䅡獂䝁䅫睚潂䡁䅑督時䙁䅙兑時䡁䅙免杁䍁䅧免灁䍁䄴䅥獂䡁䅍䅥摂䕁䄰兙灂䝁䄴睊桁䍁䅑䅒歁䑁䅙䅏䅁䱁䅅䅁歁䅁䅁睉䩂䕁䄴杖䉂䕁䅷兓䕂䕁䄰兑䡂䕁䄴兓啂䙁䅕䅒䙂䅁䅁睺䅁䕁䅁䅁偂䡁䅁䅤灂䝁䄸杢穂䑁䅯睑䉂䙁䅁䅖䩂䕁䄸杔㥁䕁䅕䅥橂䝁䅧兙畂䝁䅣党㙁䙁䅑兡橂䝁䅳党祂䅁䅁杳䅁䍁䅁䅁䙂䡁䅧睙潂䝁䅅杢湂䝁䅕杏啂䝁䅫睙牂䝁䅕杣䅁䱁䅍䅁獁䅁䅁兕噂䕁䅅䅔䑂䕁䄸兔乂䍁䅁兓畂䝁䅍睢祂䡁䅁睢祂䝁䅅䅤求䝁䅑䅁ぃ䅁䅁杇䅁䙁䅍䅕時䕁䄰兑卂䕁䅳兒啂䕁䅍兑兂䅁䅁睴䅁䉁䅁䅁䝂䙁䅅睍祁䑁䅁杍㉁䅁䅁兌䅅䅁䄴䅁䩂䙁䅅睘啂䕁䅕杖䅁䱁䅧䅁䝂䅁䅁睔睂䡁䅑兡療䝁䄴督㙁䕁䅍兤祂䡁䅉児噂䙁䅍䅒獁䕁䄰兙湂䑁䄰兔灂䝁䅷䅢灂䝁䄸杢穂䍁䅷杔䉂䑁䄰䅍䅁䱁䅫䅁佁䅁䅁睑婂䑁䅉䅍祁䑁䅑䅁⽃䅁䅁杣䅁䕁䄸䅣あ䝁䅫睢畂䡁䅍杏䑂䡁䅕杣祂䑁䄰兖呂䕁䅑䅌䕂䝁䅅䅤桂䙁䅑入睂䝁䅕児呂䕁䅑䅌呂䡁䅉睙㥁䝁䅍睢畂䡁䅍党畂䡁䅍兤穂䍁䄴杤桂䝁䅅睙あ䡁䅕兙獂䡁䅍䅌佂䕁䅅児䅁佁䅷䅁あ䅁䅁睔睂䡁䅑兡療䝁䄴督㙁䕁䅍兤祂䡁䅉児噂䙁䅍䅒獁䕁䅑兙あ䝁䅅䅖㕂䡁䅁党㥁䙁䅍䅒獁䙁䅍杣橂䑁䄰睙療䝁䄴督求䝁䄴督ㅂ䡁䅍杌㉂䝁䅅兙橂䡁䅑兤桂䝁䅷督獁䕁䄴兑㥁䑁䅁䅁䅄䅁䅁䅋䅁䕁䅑兡㉂䝁䅫䅚求䝁䄴䅚穂䍁䅁䅣求䡁䅉䅉穂䝁䅧兙祂䝁䅕䅁䉄䅁䅁杄䅁䕁䅍兗祁䑁䅁杍㉁䅁䅁杷䅁䅁䄴䅁䑂䙁䅫杍睁䑁䅉睎䅁䵁䅍䅁䥁䅁䅁杔啂䕁䄰䅁䕄䅁䅁䅉䅁䙁䅍䅕時䙁䅁杕䩂䕁䅍兒時䕁䅍䅓䉂䕁䄴睒䙂䅁䅁杸䅁䅁䅧䅁婂䙁䅑䅒䅁䵁䅣䅁䥁䅁䅁兔啂䕁䅑䅁䥄䅁䅁杂䅁䑁䅅兗䅁䵁䅫䅁䝁䅁䅁睍婂䅁䅁杹䅁䅁䅙䅁ㅁ䙁䅫䅁䱄䅁䅁杪䅁䕁䄸䅣あ䝁䅫睢畂䡁䅍杏䑂䡁䅕杣祂䑁䄰兖呂䕁䅑䅌乂䝁䅅睚㥁䕁䄰兡獂䝁䅷兡療䝁䄴督獁䕁䅑兙あ䝁䅅䅖㕂䡁䅁党㥁䙁䅍䅒獁䙁䅍杣橂䑁䄰睙療䝁䄴督求䝁䄴督ㅂ䡁䅍杌㉂䝁䅅兙橂䡁䅑兤桂䝁䅷督獁䕁䄴兑㥁䑁䅁䅁佄䅁䅁䅏䅁䕁䄸䅣あ䝁䅫睢畂䡁䅍杏䑂䡁䅕杣祂䑁䄰兖呂䕁䅑䅌乂䝁䅅睚㥁䕁䄰䅌佂䕁䅅児睁䅁䅁䄰䅁䉁䅷䅁佂䕁䅅睕䕂䕁䅅兕䡂䙁䅍杏兂䕁䅅杔塂䅁䅁充䅅䍁䅙䅁橁䕁䅫杔坂䕁䅅䅔䩂䕁䅑䅉乂䕁䅅睒佂䕁䅫䅖噂䕁䅑兒䅁乁䅅䅁㉁䅁䅁䅖療䡁䅑兙獂䍁䅁督あ䝁䄸睙牂䝁䅧睢獂䝁䅑党祂䡁䅍睊杁䝁䅕兣ㅂ䝁䅫䅤㕂䅁䅁䄱䅁䥁䅁䅁偂䡁䅁䅤灂䝁䄸杢穂䑁䅯睑ㅂ䡁䅉杣㥁䙁䅕睕䕂䍁䅷兔桂䝁䅣児乂䍁䅷䅒桂䡁䅑兙啂䡁䅫䅣求䑁䄰睕䕂䍁䅷睕祂䝁䅍児橂䝁䄸杢穂䝁䅕杢穂䡁䅕督畁䡁䅙兙桂䝁䅍䅤ㅂ䝁䅅䅢穂䍁䅷杔䉂䑁䄰兌䅁乁䅕䅁䕁䅁䅁兌䅁乁䅙䅁十䅁䅁睑剂䍁䄰免祁䑁䅁杍㉁䅁䅁睔䅅䍁䅷䅁偂䡁䅁䅤灂䝁䄸杢穂䑁䅯睑ㅂ䡁䅉杣㥁䙁䅕睕䕂䍁䅷杔䉂䑁䄰兌䅁乁䅣䅁あ䅁䅁睔睂䡁䅑兡療䝁䄴督㙁䕁䅍兤祂䡁䅉児噂䙁䅍䅒獁䕁䅑兙あ䝁䅅䅖㕂䡁䅁党㥁䙁䅍䅒獁䙁䅍杣橂䑁䄰睙療䝁䄴督求䝁䄴督ㅂ䡁䅍杌㉂䝁䅅兙橂䡁䅑兤桂䝁䅷督獁䕁䄴兑㥁䍁䄰䅁婄䅁䅁䅧䅁䕁䄸䅣あ䝁䅫睢畂䡁䅍杏䕂䝁䅅䅤桂䙁䅑入睂䝁䅕児呂䕁䅑䅌呂䡁䅉睙㥁䝁䅍睢畂䡁䅍党畂䡁䅍兤穂䍁䄴杤桂䝁䅅睙あ䡁䅕兙獂䡁䅍䅌乂䝁䅅睚㥁䕁䄰䅌䑂䡁䅕杣祂䑁䄰兖呂䕁䅑䅌佂䕁䅅児瑁䅁䅁朲䅁䥁䅑䅁偂䡁䅁䅤灂䝁䄸杢穂䑁䅯䅒桂䡁䅑兙啂䡁䅫䅣求䑁䄰睕䕂䍁䅷睕祂䝁䅍児橂䝁䄸杢穂䝁䅕杢穂䡁䅕督畁䡁䅙兙桂䝁䅍䅤ㅂ䝁䅅䅢穂䍁䅷兔桂䝁䅣児桂䝁䅉督獁䕁䅍兤祂䡁䅉児噂䙁䅍䅒獁䕁䄴兑㥁䍁䄰䅁扄䅁䅁杣䅁䕁䄸䅣あ䝁䅫睢畂䡁䅍杏䕂䝁䅅䅤桂䙁䅑入睂䝁䅕児呂䕁䅑䅌呂䡁䅉睙㥁䝁䅍睢畂䡁䅍党畂䡁䅍兤穂䍁䄴杤桂䝁䅅睙あ䡁䅕兙獂䡁䅍䅌乂䝁䅅睚㥁䕁䅅杙穂䍁䅷杔䉂䑁䄰兌䅁乁䅷䅁楂䅁䅁睔睂䡁䅑兡療䝁䄴督㙁䕁䅑兙あ䝁䅅䅖㕂䡁䅁党㥁䙁䅍䅒獁䙁䅍杣橂䑁䄰睙療䝁䄴督求䝁䄴督ㅂ䡁䅍杌㉂䝁䅅兙橂䡁䅑兤桂䝁䅷督獁䕁䄴兑㥁䑁䅁䅁摄䅁䅁杌䅁䕁䄸䅣あ䝁䅫睢畂䡁䅍杏䕂䝁䅅䅤桂䙁䅑入睂䝁䅕児歁䕁䅕䅊祁䑁䅍䅁祂允䅁杙䅁䕁䄸䅣あ䝁䅫睢畂䡁䅍杏䕂䝁䅅䅤桂䙁䅑入睂䝁䅕児呂䕁䅑䅌呂䡁䅉睙㥁䝁䅍睢畂䡁䅍党畂䡁䅍兤穂䍁䄴杤桂䝁䅅睙あ䡁䅕兙獂䡁䅍䅌佂䕁䅅児瑁䅁䅁朳䅁䍁䅙䅁兂䡁䅉兡橂䝁䅕䅉癁䍁䅁村療䝁䄸睡杁䙁䅙兙獂䡁䅕党䅁佁䅅䅁敂䅁䅁睔睂䡁䅑兡療䝁䄴督㙁䕁䅑兙あ䝁䅅䅖㕂䡁䅁党㥁䙁䅍䅒獁䙁䅍杣橂䑁䄰兖䍂䙁䅍䅌乂䝁䅅睚㥁䕁䄰䅌䑂䡁䅕杣祂䑁䄰兖呂䕁䅑䅌佂䕁䅅児䅁䕁䉅䅁允䅁䅁䅎睁䑁䅑䅏硁䑁䅕睎䅁偁䅷䅁流䅁䅁䅖療䡁䅑兙獂䍁䅁杣求䡁䅙党畂䡁䅕党獁䍁䅁兗療䙁䅫䅁楄䅁䅁杙䅁䙁䅳睕兂䕁䅣睘䝂䝁䅫杢桂䝁䄴睙灂䝁䅅䅢䥂䝁䅫睚潂䝁䅷兡湂䝁䅧䅤穂䙁䄸杖䉂䙁䄸睖䩂䙁䅁杌㑂䝁䅷督㑂䙁䄰杕求䡁䅁睢祂䡁䅑光歁䕁䅑䅊ㅁ䅁䅁䄵䅁䉁䅧䅁䙂䕁䅉兓啂䕁䅑兑獁䍁䅁兗療䙁䅫䅁汄䅁䅁杒䅁䕁䄸䅣あ䝁䅫睢畂䡁䅍杏䕂䝁䅅䅤桂䙁䅑入睂䝁䅕児呂䕁䅑䅌杁䙁䅍杣橂䑁䄰睑療䝁䄴督求䝁䄴督ㅂ䡁䅍䅁浄䅁䅁杦䅁䕁䄸䅣あ䝁䅫睢畂䡁䅍杏䕂䝁䅅䅤桂䙁䅑入睂䝁䅕児呂䕁䅑䅌呂䡁䅉睙㥁䝁䅍睢畂䡁䅍党畂䡁䅍兤穂䍁䄴杤桂䝁䅅睙あ䡁䅕兙獂䡁䅍䅌乂䝁䅅睚㥁䕁䄰䅌䑂䡁䅕杣祂䑁䄰兖呂䕁䅑䅌佂䕁䅅児䅁佁䅣䅁㑂䅁䅁睔睂䡁䅑兡療䝁䄴督㙁䕁䅑兙あ䝁䅅䅖㕂䡁䅁党㥁䙁䅍䅒獁䙁䅍杣橂䑁䄰睑療䝁䄴督求䝁䄴督ㅂ䡁䅍杌乂䝁䅕䅚灂䝁䅅杢獁䕁䄰兙湂䑁䄰兔獁䕁䅍兤祂䡁䅉児噂䙁䅍䅒獁䕁䄴兑㥁䅁䅁光䅅䝁䅁䅁偂䡁䅁䅤灂䝁䄸杢穂䑁䅯䅒桂䡁䅑兙啂䡁䅫䅣求䑁䄰睕䕂䍁䅷睕祂䝁䅍児橂䝁䄸杢穂䝁䅕杢穂䡁䅕督畁䡁䅙兙桂䝁䅍䅤ㅂ䝁䅅䅢穂䍁䅷杔䉂䑁䄰䅁潄䅁䅁杗䅁䕁䄸䅣あ䝁䅫睢畂䡁䅍杏䕂䝁䅅䅤桂䙁䅑入睂䝁䅕児呂䕁䅑䅌呂䡁䅉睙㥁䕁䅍睢畂䡁䅍党畂䡁䅍兤穂䍁䄴兔求䝁䅑兡桂䝁䄴䅌佂䕁䅅児䅁䍁䉉䅁⭂䅁䅁睔睂䡁䅑兡療䝁䄴督㙁䕁䅍兤祂䡁䅉児噂䙁䅍䅒獁䕁䄰兙湂䑁䄰兔獁䕁䅑兙あ䝁䅅䅖㕂䡁䅁党㥁䙁䅍䅒獁䙁䅍杣橂䑁䄰睙療䝁䄴督求䝁䄴督ㅂ䡁䅍杌㉂䝁䅅兙橂䡁䅑兤桂䝁䅷督獁䕁䄴兑㥁䅁䅁儶䅁䡁䄴䅁偂䡁䅁䅤灂䝁䄸杢穂䑁䅯睑ㅂ䡁䅉杣㥁䙁䅕睕䕂䍁䅷兔桂䝁䅣児乂䍁䅷䅒桂䡁䅑兙啂䡁䅫䅣求䑁䄰睕䕂䍁䅷睕祂䝁䅍児䑂䝁䄸杢穂䝁䅕杢穂䡁䅕督畁䙁䅙兙桂䝁䅍䅤ㅂ䝁䅅䅢穂䍁䅷杔䉂䑁䄰䅁㥁允䅁杧䅁䕁䄸䅣あ䝁䅫睢畂䡁䅍杏䕂䝁䅅䅤桂䙁䅑入睂䝁䅕児呂䕁䅑䅌呂䡁䅉睙㥁䝁䅍睢畂䡁䅍党畂䡁䅍兤穂䍁䄴杤桂䝁䅅睙あ䡁䅕兙獂䡁䅍䅌乂䝁䅅睚㥁䝁䅅杙穂䍁䅷睑ㅂ䡁䅉杣㥁䙁䅕睕䕂䍁䅷杔䉂䑁䄰䅁牄䅁䅁䅦䅁䕁䄸䅣あ䝁䅫睢畂䡁䅍杏䕂䝁䅅䅤桂䙁䅑入睂䝁䅕児呂䕁䅑䅌呂䡁䅉睙㥁䕁䅍睢畂䡁䅍党畂䡁䅍兤穂䍁䄴兔求䝁䅑兡桂䝁䄴䅌乂䝁䅅睚㥁䝁䅅杙穂䍁䅷睑ㅂ䡁䅉杣㥁䙁䅕睕䕂䍁䅷杔䉂䑁䄰䅁歁允䅁杋䅁䕁䄸䅣あ䝁䅫睢畂䡁䅍杏䑂䡁䅕杣祂䑁䄰兖呂䕁䅑䅌佂䕁䅅児䅁佁䄰䅁䕂䅁䅁睔睂䡁䅑兡療䝁䄴督㙁䕁䅍兤祂䡁䅉児噂䙁䅍䅒獁䕁䄰兙湂䑁䄰兔灂䝁䅷䅢灂䝁䄸杢穂䍁䅷杔䉂䑁䄰䅁畄䅁䅁杆䅁䕁䅅䅣睂䝁䅷党杁䕁䅫杢橂䍁䄴䅁㑄䅁䅁䅈䅁䕁䄴兑呂䕁䅑兑剂䕁䅣睕㙁䕁䅅兑兂䕁䅷䅁癄䅁䅁䅅䅁䑁䅑䅍祁䑁䅑䅎睁䑁䅅䅁偁允䅁䅅䅁䑁䅑䅍睁䑁䅑杍睁䑁䅕䅁睄䅁䅁䅈䅁䕁䄴兑呂䕁䅑兑剂䕁䅣睕㙁䕁䅅杖䡂䕁䄸䅁硄䅁䅁杈䅁䕁䄴兑呂䕁䅑兑剂䕁䅣睕㙁䕁䅣睔偂䕁䅣䅔䅁偁䅉䅁䝂䅁䅁睔睂䡁䅑兡療䝁䄴督㙁䕁䅍兤祂䡁䅉児噂䙁䅍䅒獁䕁䄰兙湂䑁䄰䅖潂䝁䄸兤穂䝁䅅杢歂䡁䅍䅌佂䕁䅅児䅁䍁䉫䅁十䅁䅁杔婂䙁䅍兒㙁䕁䅍杕乂䅁䅁眸䅁䉁䅁䅁ぁ䑁䅙睍穁䑁䅙免㑁䅁䅁䄹䅁䉁䅷䅁佂䕁䅅睕䕂䕁䅅兕䡂䙁䅍杏䩂䕁䄴䅖噂䅁䅁儹䅁䉁䅷䅁佂䕁䅅睕䕂䕁䅅兕䡂䙁䅍杏佂䙁䅙䅒䉂䅁䅁儫䅁䉁䅁䅁ぁ䑁䅁䅍睁䑁䅅兏穁䅁䅁眫䅁䍁䅯䅁乂䝁䅕䅤桂䍁䅁䅕獂䝁䅅䅤浂䝁䄸杣瑂䡁䅍䅌杁䕁䅫杢橂䍁䄴䅁䡁允䅁䅅䅁䑁䅑杍睁䑁䅕䅏ぁ䑁䅧䅁⭄䅁䅁杉䅁䙁䅍兙獂䝁䅕督浂䝁䄸杣橂䝁䅕䅌杁䕁䅫杢橂䍁䄴䅁⽄䅁䅁䅈䅁䕁䅉杣療䝁䅅䅚橂䝁䄸兢杁䕁䅫杢橂䍁䄴䅁䅁允䅁杘䅁䕁䄸䅣あ䝁䅫睢畂䡁䅍杏䑂䡁䅕杣祂䑁䄰兖呂䕁䅑䅌乂䝁䅅睚㥁䕁䅳䅌䕂䝁䅅䅤桂䙁䅑入睂䝁䅕児呂䕁䅑䅌呂䡁䅉睙㥁䙁䅕村呂䍁䅷杔䉂䑁䄰䅁佂允䅁䅅䅁䑁䅑䅍㕁䑁䅑杍㑁䑁䅙䅁䉁允䅁杊䅁䕁䄴杖䩂䕁䅑兓䉂䍁䅁睑療䡁䅉䅣療䡁䅉兙あ䝁䅫睢畂䅁䅁杁䅅䝁䅙䅁扂䙁䅍䅕䡂䙁䄸杒灂䝁䄴兙畂䝁䅍兡桂䝁䅷䅓灂䝁䅣䅡獂䝁䅫睚潂䡁䅑督時䙁䅙兑時䙁䅣兓兂䍁䄴䅥獂䡁䅍䅥摂䙁䅉党睂䝁䄸杣あ䍁䅅䅊䉂䕁䅕䅊㉁䑁䅣䅁䑁允䅁䅅䅁䑁䅑䅍祁䑁䅕睎ぁ䑁䅙䅁䩁允䅁杚䅁䙁䅳睕兂䕁䅣睘䝂䝁䅫杢桂䝁䄴睙灂䝁䅅䅢䥂䝁䅫睚潂䝁䅷兡湂䝁䅧䅤穂䙁䄸杖䉂䙁䄸睖䩂䙁䅁杌㑂䝁䅷督㑂䙁䄰杕求䡁䅁睢祂䡁䅑光歁䕁䅅䅓歁䑁䅙李䅁䅁䉯䅁畁䅁䅁䅒奂䕁䅍䅉啂䝁䅕睙潂䝁䄴睢獂䝁䄸睚㕂䍁䅁睑療䝁䄰䅣桂䝁䄴入䅁䉁䉁䅁畂䅁䅁睊扂䙁䅍䅕䡂䙁䄸杒灂䝁䄴兙畂䝁䅍兡桂䝁䅷督流䙁䅁党求䡁䅉睑療䝁䄰䅣桂䡁䅉兡穂䝁䅫睢畂䙁䄸杖䉂䍁䄴䅥獂䡁䅍䅥摂䙁䅉党睂䝁䄸杣あ䍁䅣光歁䕁䅑䅊㉁䑁䅣䅁啁允䅁䅢䅁䍁䅣睗呂䙁䅁睒時䕁䅙兡畂䝁䅅杢橂䝁䅫兙獂䡁䅍杊兂䝁䅕党祂䕁䅍睢瑂䡁䅁兙祂䝁䅫督灂䝁䄸杢時䙁䅙兑畁䡁䅧䅢穂䡁䅧兘卂䝁䅕䅣療䡁䅉䅤湁䍁䅅䅊䕂䍁䅑兎䅁䉁䉕䅁潂䅁䅁睊扂䙁䅍䅕䡂䙁䄸杒灂䝁䄴兙畂䝁䅍兡桂䝁䅷督流䙁䅁党求䡁䅉兑畂䝁䅅䅢㕂䡁䅍兡穂䙁䄸杖䉂䍁䄴䅥獂䡁䅍䅥摂䙁䅉党睂䝁䄸杣あ䍁䅣光歁䕁䅑䅊㉁䑁䅣䅁坁允䅁杚䅁䍁䅣睗呂䙁䅁睒時䕁䅙兡畂䝁䅅杢橂䝁䅫兙獂䡁䅍杊兂䝁䅕党祂䕁䅅杢桂䝁䅷入穂䝁䅫督時䙁䅙兑畁䡁䅧䅢穂䡁䅧兘卂䝁䅕䅣療䡁䅉䅤湁䍁䅅䅊䕂䍁䅑兎䅁䉁䉣䅁捁䅁䅁杔䉂䙁䅍䅒䉂䙁䅅睒呂䑁䅯兑乂䙁䅯杔䅁䉁䉧䅁允䅁䅁睍睁䑁䅁免㍁䑁䅫杍䅁䉁䉫䅁楁䅁䅁兑瑂䝁䅅来療䝁䄴杌橂䝁䄸兢獁䍁䅁兓畂䝁䅍杌䅁䉁䉯䅁⭂䅁䅁睔睂䡁䅑兡療䝁䄴督㙁䕁䅑兙あ䝁䅅䅖㕂䡁䅁党㥁䙁䅍䅒獁䙁䅍杣橂䑁䄰睑療䝁䄴督求䝁䄴督ㅂ䡁䅍杌坂䕁䅅兑橂䡁䅑兤桂䝁䅷督獁䕁䄰兙湂䑁䄰兔獁䕁䅍兤祂䡁䅉児噂䙁䅍䅒獁䕁䄴兑㥁䅁䅁睇䅅䡁䅁䅁偂䡁䅁䅤灂䝁䄸杢穂䑁䅯䅒桂䡁䅑兙啂䡁䅫䅣求䑁䄰睕䕂䍁䅷睕祂䝁䅍児䑂䝁䄸杢穂䝁䅕杢穂䡁䅕督畁䙁䅙兑䉂䝁䅍䅤ㅂ䝁䅅䅢穂䍁䅷兔桂䝁䅣児䉂䝁䅉督獁䕁䄴兑㥁䅁䅁䅈䅅䡁䄴䅁偂䡁䅁䅤灂䝁䄸杢穂䑁䅯睑ㅂ䡁䅉杣㥁䙁䅕睕䕂䍁䅷兔桂䝁䅣児乂䍁䅷䅒桂䡁䅑兙啂䡁䅫䅣求䑁䄰睕䕂䍁䅷睕祂䝁䅍児䑂䝁䄸杢穂䝁䅕杢穂䡁䅕督畁䙁䅙兑䉂䝁䅍䅤ㅂ䝁䅅䅢穂䍁䅷杔䉂䑁䄰䅁敁允䅁杦䅁䕁䄸䅣あ䝁䅫睢畂䡁䅍杏䕂䝁䅅䅤桂䙁䅑入睂䝁䅕児呂䕁䅑䅌呂䡁䅉睙㥁䕁䅍睢畂䡁䅍党畂䡁䅍兤穂䍁䄴杖䉂䕁䅅睙あ䡁䅕兙獂䡁䅍䅌乂䝁䅅睚㥁䕁䅳䅌䑂䡁䅕杣祂䑁䄰兖呂䕁䅑䅌佂䕁䅅児䅁䍁䉣䅁⭂䅁䅁睔睂䡁䅑兡療䝁䄴督㙁䕁䅍兤祂䡁䅉児噂䙁䅍䅒獁䕁䄰兙湂䑁䄰睓獁䕁䅑兙あ䝁䅅䅖㕂䡁䅁党㥁䙁䅍䅒獁䙁䅍杣橂䑁䄰睑療䝁䄴督求䝁䄴督ㅂ䡁䅍杌坂䕁䅅兑橂䡁䅑兤桂䝁䅷督獁䕁䄴兑㥁䅁䅁䅋䅅䉁䅁䅁䝂䙁䅅免祁䑁䅁杍㍁䅁䅁杋䅅䉁䅉䅁啂䝁䄸䅤桂䝁䅷䅉桂䡁䅍䅁牁允䅁䅅䅁䕁䅙兕祁䑁䅉䅍祁䑁䅑䅁灂允䅁䅅䅁䕁䅙兕睁䑁䅉䅍祁䑁䅙䅁獁允䅁䅅䅁䕁䅙兕硁䑁䅉䅍祁䑁䅕䅁浂允䅁䅅䅁䕁䅍兕ぁ䑁䅉䅍祁䑁䅕䅁硁允䅁䅅䅁䕁䅍兕硁䑁䅉䅍祁䑁䅣䅁祁允䅁䅅䅁䕁䅍兕穁䑁䅉䅍祁䑁䅕䅁剂允䅁䅅䅁䕁䅍兕祁䑁䅉䅍祁䑁䅣䅁㉁允䅁杕䅁䕁䄸䅣あ䝁䅫睢畂䡁䅍杏䑂䡁䅕杣祂䑁䄰兖呂䕁䅑䅌䕂䝁䅅䅤桂䙁䅑入睂䝁䅕児呂䕁䅑䅌呂䡁䅉睙㥁䙁䅕村呂䍁䅷杔䉂䑁䄰䅁䝂允䅁杦䅁䕁䄸䅣あ䝁䅫睢畂䡁䅍杏䕂䝁䅅䅤桂䙁䅑入睂䝁䅕児呂䕁䅑䅌呂䡁䅉睙㥁䕁䅍睢畂䡁䅍党畂䡁䅍兤穂䍁䄴杖桂䝁䅅睙あ䡁䅕兙獂䡁䅍䅌乂䝁䅅睚㥁䕁䄰䅌䑂䡁䅕杣祂䑁䄰兖呂䕁䅑䅌佂䕁䅅児䅁䑁䉧䅁允䅁䅁杒剂䑁䅑杍睁䑁䅉兎䅁䑁䉫䅁杂䅁䅁睔睂䡁䅑兡療䝁䄴督㙁䕁䅑兙あ䝁䅅䅖㕂䡁䅁党㥁䙁䅍䅒獁䙁䅍杣橂䑁䄰睑療䝁䄴督求䝁䄴督ㅂ䡁䅍杌坂䝁䅅兙橂䡁䅑兤桂䝁䅷督獁䕁䄴兑㥁䅁䅁睏䅅䥁䅉䅁偂䡁䅁䅤灂䝁䄸杢穂䑁䅯䅒桂䡁䅑兙啂䡁䅫䅣求䑁䄰睕䕂䍁䅷睕祂䝁䅍児䑂䝁䄸杢穂䝁䅕杢穂䡁䅕督畁䙁䅙兙桂䝁䅍䅤ㅂ䝁䅅䅢穂䍁䅷兔桂䝁䅣児桂䝁䅉督獁䕁䅍兤祂䡁䅉児噂䙁䅍䅒獁䕁䄴兑㥁䅁䅁䅐䅅䑁䅯䅁䉂䝁䅑杤桂䝁䄴睙求䝁䅑䅉乂䝁䅫睙祂䝁䄸䅉䕂䝁䅕杤灂䝁䅍党穂䍁䅷䅉䩂䝁䄴睙畁䅁䅁䅙䅅䡁䅁䅁偂䡁䅁䅤灂䝁䄸杢穂䑁䅯䅒桂䡁䅑兙啂䡁䅫䅣求䑁䄰睕䕂䍁䅷睕祂䝁䅍児䑂䝁䄸杢穂䝁䅕杢穂䡁䅕督畁䙁䅙兙桂䝁䅍䅤ㅂ䝁䅅䅢穂䍁䅷兔桂䝁䅣児䉂䝁䅉督獁䕁䄴兑㥁䅁䅁材䅅䝁䅙䅁湁䙁䅳睕兂䕁䅣睘䝂䝁䅫杢桂䝁䄴睙灂䝁䅅䅢穂䍁䅙䅕求䝁䅕杣䉂䝁䄴兙獂䡁䅫督灂䡁䅍睘坂䕁䅅杌㑂䝁䅷督㑂䙁䄰杕求䡁䅁睢祂䡁䅑睊桁䍁䅑兒歁䑁䅕䅁⽁允䅁杣䅁䕁䄸䅣あ䝁䅫睢畂䡁䅍杏䑂䡁䅕杣祂䑁䄰兖呂䕁䅑䅌䕂䝁䅅䅤桂䙁䅑入睂䝁䅕児呂䕁䅑䅌呂䡁䅉睙㥁䕁䅍睢畂䡁䅍党畂䡁䅍兤穂䍁䄴杖桂䝁䅅睙あ䡁䅕兙獂䡁䅍䅌佂䕁䅅児䅁䕁䉁䅁歂䅁䅁睗呂䙁䅁睒時䙁䅙兙獂䡁䅕兙あ䝁䅫睢畂䕁䅅杢歂䙁䅁党求䡁䅉兑畂䝁䅅䅢㕂䡁䅍兡穂䙁䄸杖䉂䍁䄴䅥獂䡁䅍䅥摂䙁䅉党睂䝁䄸杣あ䍁䅅䅊䙂䍁䅑兎䅁䙁䉧䅁䅂䅁䅁睔睂䡁䅑兡療䝁䄴督㙁䕁䅑兙あ䝁䅅䅖㕂䡁䅁党㥁䙁䅍䅒獁䙁䅍杣橂䑁䄰兖䍂䙁䅍䅌佂䕁䅅児䅁䕁䉉䅁敂䅁䅁睔睂䡁䅑兡療䝁䄴督㙁䕁䅍兤祂䡁䅉児噂䙁䅍䅒獁䕁䄰兙湂䑁䄰兔獁䕁䅑兙あ䝁䅅䅖㕂䡁䅁党㥁䙁䅍䅒獁䙁䅍杣橂䑁䄰兖䍂䙁䅍䅌佂䕁䅅児䅁䕁䉍䅁楂䅁䅁睔睂䡁䅑兡療䝁䄴督㙁䕁䅑兙あ䝁䅅䅖㕂䡁䅁党㥁䙁䅍䅒獁䙁䅍杣橂䑁䄰兖䍂䙁䅍䅌乂䝁䅅睚㥁䝁䅅杙穂䍁䅷睑ㅂ䡁䅉杣㥁䙁䅕睕䕂䍁䅷杔䉂䑁䄰䅁䕂允䅁䅤䅁䙁䅳睕兂䕁䅣睘䝂䝁䅫杢桂䝁䄴睙灂䝁䅅䅢穂䕁䅅杢歂䙁䅁党求䡁䅉兑畂䝁䅅䅢㕂䡁䅍兡穂䙁䄸杖䉂䍁䄴䅥獂䡁䅍䅥摂䙁䅁党求䡁䅉兑畂䝁䅅䅢㕂䡁䅍兡穂䍁䅅䅊䉂䕁䅑䅊㍁䅁䅁睡䅅䉁䅁䅁䝂䙁䅅免祁䑁䅁杍ぁ䅁䅁䅡䅅䅁䅧䅁呂䙁䅑兔䅁䕁䉣䅁⭂䅁䅁睔睂䡁䅑兡療䝁䄴督㙁䕁䅍兤祂䡁䅉児噂䙁䅍䅒獁䕁䄰兙湂䑁䄰村獁䕁䅑兙あ䝁䅅䅖㕂䡁䅁党㥁䙁䅍䅒獁䙁䅍杣橂䑁䄰睑療䝁䄴督求䝁䄴督ㅂ䡁䅍杌坂䕁䅅兑橂䡁䅑兤桂䝁䅷督獁䕁䄴兑㥁䅁䅁睓䅅䅁䅙䅁祁䙁䅫䅁䥂允䅁䅃䅁䙁䅅䅖䕂䅁䅁兓䅅䉁䅁䅁䑂䙁䅅䅍祁䑁䅁杍㉁䅁䅁䅕䅅䅁䄴䅁䑂䙁䅫杍睁䑁䅉䅏䅁䙁䉍䅁佁䅁䅁睑婂䑁䅉䅍祁䑁䅫䅁啂允䅁䅙䅁䙁䅳睕兂䕁䅣睘坂䝁䅅䅢ㅂ䝁䅅䅤灂䝁䄸杢兂䝁䅕党祂䕁䅅杢桂䝁䅷入穂䝁䅫督時䙁䅙兑畁䡁䅧䅢穂䡁䅧兘卂䝁䅕䅣療䡁䅉䅤桁䍁䅑䅒歁䑁䅙睎䅁䙁䉕䅁敂䅁䅁睗呂䙁䅁睒時䙁䅙兙獂䡁䅕兙あ䝁䅫睢畂䙁䅁党求䡁䅉兑畂䝁䅅䅢㕂䡁䅍兡穂䙁䄸杖䉂䍁䄴䅥獂䡁䅍䅥摂䙁䅉党睂䝁䄸杣あ䍁䅅䅊䙂䍁䅑兎䅁䙁䉙䅁獂䅁䅁睗呂䙁䅁睒時䙁䅙兙獂䡁䅕兙あ䝁䅫睢畂䕁䅅杢歂䙁䅁党求䡁䅉兑畂䝁䅅䅢㕂䡁䅍兡穂䙁䄸杖䉂䍁䄴䅥獂䡁䅍䅥摂䙁䅙兙獂䡁䅕兙あ䝁䅫睢畂䍁䅅䅊䕂䍁䅑睍硁䅁䅁睖䅅䝁䅯䅁扂䙁䅍䅕䡂䙁䄸杖桂䝁䅷兤桂䡁䅑兡療䝁䄴兑畂䝁䅑䅕求䝁䅕杣䉂䝁䄴兙獂䡁䅫督灂䡁䅍睘坂䕁䅅杌㑂䝁䅷督㑂䙁䄰杖桂䝁䅷兤桂䡁䅑兡療䝁䄴光歁䕁䅑䅊㕁䅁䅁兗䅅䡁䅁䅁扂䙁䅍䅕䡂䙁䄸杖桂䝁䅷兤桂䡁䅑兡療䝁䄴兑畂䝁䅑䅕求䝁䅕杣䉂䝁䄴兙獂䡁䅫督灂䡁䅍睘坂䕁䅅睘㉂䑁䅉杌㑂䝁䅷督㑂䙁䄰杖桂䝁䅷兤桂䡁䅑兡療䝁䄴光歁䕁䅑䅊㕁䅁䅁睗䅅䝁䅯䅁扂䙁䅍䅕䡂䙁䄸杖桂䝁䅷兤桂䡁䅑兡療䝁䄴兑畂䝁䅑䅕求䝁䅕杣䉂䝁䄴兙獂䡁䅫督灂䡁䅍睘坂䕁䅅杌㑂䝁䅷督㑂䙁䄰䅖求䝁䅅杣呂䝁䅧党求䡁䅑光歁䕁䅕䅊ㅁ䅁䅁兘䅅䉁䅯䅁佂䕁䅅睕䕂䕁䅅兕䡂䙁䅍杏䉂䕁䄰䅒䅁䙁䈴䅁允䅁䅁䅎睁䑁䅙李㍁䑁䅑睍䅁䙁䈸䅁祂䅁䅁睗呂䙁䅁睒時䕁䅙兡畂䝁䅅杢橂䝁䅫兙獂䡁䅍兑畂䝁䅑䅕求䝁䅕杣䉂䝁䄴兙獂䡁䅫督灂䡁䅍睘坂䕁䅅杌㑂䝁䅷督㑂䙁䄰䅕求䝁䅕杣䉂䝁䄴兙獂䡁䅫督灂䡁䅍光歁䕁䅑䅊㕁䅁䅁兙䅅䡁䅑䅁佂䝁䅕䅤杁䝁䅍兙穂䝁䅧䅉浂䝁䅷睢㍂䡁䅍䅉睂䡁䅉睢㉂䝁䅫䅚求䝁䅑䅉楂䡁䅫睌潁䡁䅕督求䝁䅑䅉灂䝁䄴克杁䝁䅫杢㉂䝁䅕督あ䝁䅫杢湂䍁䅁兙橂䡁䅑兡㉂䝁䅫䅤灂䝁䅕督䅁䝁䉍䅁允䅁䅁杒剂䑁䅉杍睁䑁䅉兎䅁䝁䉣䅁允䅁䅁杒剂䑁䅍杍睁䑁䅉䅎䅁䝁䉯䅁あ䅁䅁睗呂䙁䅁睒時䕁䅙兡畂䝁䅅杢橂䝁䅫兙獂䡁䅍兑畂䝁䅑䅕求䝁䅕杣䉂䝁䄴兙獂䡁䅫督灂䡁䅍睘坂䕁䅅杌㑂䝁䅷督㑂䙁䄰䅕求䝁䅕杣䉂䝁䄴兙獂䡁䅫督灂䡁䅍光歁䕁䅅兑歁䑁䅫䅁獂允䅁杉䅁䕁䅅睙あ䡁䅕兙獂䝁䄸杣䙂䡁䅍䅤灂䝁䄰兙あ䝁䅕䅁畂允䅁䅋䅁䕁䅍睢畂䡁䅍党畂䡁䅍兤穂䍁䄴杖䉂䕁䅅睙あ䡁䅕兙獂䡁䅍䅁療允䅁䅂䅁䕁䅅䅁睂允䅁䅂䅁䕁䅕䅁硂允䅁䅗䅁䕁䄸䅣あ䝁䅫睢畂䡁䅍杏䕂䝁䅅䅤桂䙁䅑入睂䝁䅕児呂䕁䅑䅌呂䡁䅉睙㥁䕁䅍睢畂䡁䅍党畂䡁䅍兤穂䍁䄴杖䉂䕁䅅睙あ䡁䅕兙獂䡁䅍䅁穂允䅁䅁䅁䅁㴽

Sheet TearSheet
AB1: 1 | AC1: =AB1+1 -> 2 | AD1: =AC1+1 -> 3 | AE1: =AD1+1 -> 4 | AF1: =AE1+1 -> 5 | AG1: =AF1+1 -> 6 | AH1: =AG1+1 -> 7 | AI1: =AH1+1 -> 8 | AK1: =$E$14 -> U.S. Dollar | AL1: =VLOOKUP($AK$1,$AK$3:$AN$82,2,FALSE) -> USD | AM1: =VLOOKUP($AK$1,$AK$3:$AN$82,3,FALSE) -> $ | AN1: =VLOOKUP($AK$1,$AK$3:$AN$82,4,FALSE) -> 000
B2: Financials & Peer Analysis | AA2: ="(in "&$AL$1&", "&$AG$33&")" -> (in USD, M) | AB2: Selected Metric | AC2: =E27&" ("&E26&")" -> FY2023 (A) | AD2: =F27&" ("&F26&")" -> FY2024 (A) | AE2: =G27&" ("&G26&")" -> FY2025 (A) | AF2: =H27&" ("&H26&")" -> FY2026 (A) | AG2: =I27&" ("&I26&")" -> FY2027 (E) | AH2: =J27&" ("&J26&")" -> FY2028 (E) | AI2: =K27&" ("&K26&")" -> FY2029 (E) | AK2: Currency Name | AL2: ISO Code | AM2: Symbol | AN2: Mag.
AA3: ="(in "&$AL$1&")" -> (in USD) | AB3: =$O$26 -> Total revenue | AC3: =IF(OR(VLOOKUP($AB3,$C$28:$K$61,AC$5,0)="-",VLOOKUP($AB3,$C$28:$K$61,AC$5,0)=0),NA(),VLOOKUP($AB3,$C$28:$K$61,AC$5,0)) -> 211915 | AD3: =IF(OR(VLOOKUP($AB3,$C$28:$K$61,AD$5,0)="-",VLOOKUP($AB3,$C$28:$K$61,AD$5,0)=0),NA(),VLOOKUP($AB3,$C$28:$K$61,AD$5,0)) -> 245122 | AE3: =IF(OR(VLOOKUP($AB3,$C$28:$K$61,AE$5,0)="-",VLOOKUP($AB3,$C$28:$K$61,AE$5,0)=0),NA(),VLOOKUP($AB3,$C$28:$K$61,AE$5,0)) -> 281724 | AF3: =IF(OR(VLOOKUP($AB3,$C$28:$K$61,AF$5,0)="-",VLOOKUP($AB3,$C$28:$K$61,AF$5,0)=0),NA(),VLOOKUP($AB3,$C$28:$K$61,AF$5,0)) -> 331839 | AG3: =IF(OR(VLOOKUP($AB3,$C$28:$K$61,AG$5,0)="-",VLOOKUP($AB3,$C$28:$K$61,AG$5,0)=0),NA(),VLOOKUP($AB3,$C$28:$K$61,AG$5,0)) -> 391146.94 | AH3: =IF(OR(VLOOKUP($AB3,$C$28:$K$61,AH$5,0)="-",VLOOKUP($AB3,$C$28:$K$61,AH$5,0)=0),NA(),VLOOKUP($AB3,$C$28:$K$61,AH$5,0)) -> 467637.47 | AI3: =IF(OR(VLOOKUP($AB3,$C$28:$K$61,AI$5,0)="-",VLOOKUP($AB3,$C$28:$K$61,AI$5,0)=0),NA(),VLOOKUP($AB3,$C$28:$K$61,AI$5,0)) -> 568944.85 | AK3: Reported Currency | AL3: Reported Currency | AM3: Reported | AN3: 000
B4: Instructions: | AA4: =IF(OR($O$26=$AB$14,$O$26=$AB$15),$AA$3,$AA$2) -> (in USD, M) | AK4: Euro | AL4: EUR | AM4: € | AN4: 000
B5: Step 1: Enter Company Identifier. | E5: MSFT | H5: Contact: | AB5: Data | AC5: =AC1+1 -> 3 | AD5: =AD1+1 -> 4 | AE5: =AE1+1 -> 5 | AF5: =AF1+1 -> 6 | AG5: =AG1+1 -> 7 | AH5: =AH1+1 -> 8 | AI5: =AI1+1 -> 9 | AK5: British Pound Sterling | AL5: GBP | AM5: £ | AN5: 000
B6: (Ticker, Entity ID or Exchange:Ticker) | H6: Please contact S&P Capital IQ Pro Support with any questions or comments: | AB6: Total revenue | AC6: =IF(OR(VLOOKUP($AB6,$C$28:$K$61,AC$5,0)="-",VLOOKUP($AB6,$C$28:$K$61,AC$5,0)=0),NA(),VLOOKUP($AB6,$C$28:$K$61,AC$5,0)) -> 211915 | AD6: =IF(OR(VLOOKUP($AB6,$C$28:$K$61,AD$5,0)="-",VLOOKUP($AB6,$C$28:$K$61,AD$5,0)=0),NA(),VLOOKUP($AB6,$C$28:$K$61,AD$5,0)) -> 245122 | AE6: =IF(OR(VLOOKUP($AB6,$C$28:$K$61,AE$5,0)="-",VLOOKUP($AB6,$C$28:$K$61,AE$5,0)=0),NA(),VLOOKUP($AB6,$C$28:$K$61,AE$5,0)) -> 281724 | AF6: =IF(OR(VLOOKUP($AB6,$C$28:$K$61,AF$5,0)="-",VLOOKUP($AB6,$C$28:$K$61,AF$5,0)=0),NA(),VLOOKUP($AB6,$C$28:$K$61,AF$5,0)) -> 331839 | AG6: =IF(OR(VLOOKUP($AB6,$C$28:$K$61,AG$5,0)="-",VLOOKUP($AB6,$C$28:$K$61,AG$5,0)=0),NA(),VLOOKUP($AB6,$C$28:$K$61,AG$5,0)) -> 391146.94 | AH6: =IF(OR(VLOOKUP($AB6,$C$28:$K$61,AH$5,0)="-",VLOOKUP($AB6,$C$28:$K$61,AH$5,0)=0),NA(),VLOOKUP($AB6,$C$28:$K$61,AH$5,0)) -> 467637.47 | AI6: =IF(OR(VLOOKUP($AB6,$C$28:$K$61,AI$5,0)="-",VLOOKUP($AB6,$C$28:$K$61,AI$5,0)=0),NA(),VLOOKUP($AB6,$C$28:$K$61,AI$5,0)) -> 568944.85 | AK6: Japanese Yen | AL6: JPY | AM6: ¥ | AN6: M
H7: Email: | I7: support.CapIQPro@spglobal.com | AB7: Gross Profit / (loss) | AC7: =IF(OR(VLOOKUP($AB7,$C$28:$K$61,AC$5,0)="-",VLOOKUP($AB7,$C$28:$K$61,AC$5,0)=0),NA(),VLOOKUP($AB7,$C$28:$K$61,AC$5,0)) -> 146052 | AD7: =IF(OR(VLOOKUP($AB7,$C$28:$K$61,AD$5,0)="-",VLOOKUP($AB7,$C$28:$K$61,AD$5,0)=0),NA(),VLOOKUP($AB7,$C$28:$K$61,AD$5,0)) -> 171008 | AE7: =IF(OR(VLOOKUP($AB7,$C$28:$K$61,AE$5,0)="-",VLOOKUP($AB7,$C$28:$K$61,AE$5,0)=0),NA(),VLOOKUP($AB7,$C$28:$K$61,AE$5,0)) -> 193893 | AF7: =IF(OR(VLOOKUP($AB7,$C$28:$K$61,AF$5,0)="-",VLOOKUP($AB7,$C$28:$K$61,AF$5,0)=0),NA(),VLOOKUP($AB7,$C$28:$K$61,AF$5,0)) -> 225465 | AG7: =IF(OR(VLOOKUP($AB7,$C$28:$K$61,AG$5,0)="-",VLOOKUP($AB7,$C$28:$K$61,AG$5,0)=0),NA(),VLOOKUP($AB7,$C$28:$K$61,AG$5,0)) -> 258531.28 | AH7: =IF(OR(VLOOKUP($AB7,$C$28:$K$61,AH$5,0)="-",VLOOKUP($AB7,$C$28:$K$61,AH$5,0)=0),NA(),VLOOKUP($AB7,$C$28:$K$61,AH$5,0)) -> 303584.18 | AI7: =IF(OR(VLOOKUP($AB7,$C$28:$K$61,AI$5,0)="-",VLOOKUP($AB7,$C$28:$K$61,AI$5,0)=0),NA(),VLOOKUP($AB7,$C$28:$K$61,AI$5,0)) -> 363586.46 | AK7: U.S. Dollar | AL7: USD | AM7: $ | AN7: 000
B8: Step 2: Enter Latest Completed Year. | E8: FY2025 | AB8: Selling, general and administrative expenses | AC8: =IF(OR(VLOOKUP($AB8,$C$28:$K$61,AC$5,0)="-",VLOOKUP($AB8,$C$28:$K$61,AC$5,0)=0),NA(),VLOOKUP($AB8,$C$28:$K$61,AC$5,0)) -> 30334 | AD8: =IF(OR(VLOOKUP($AB8,$C$28:$K$61,AD$5,0)="-",VLOOKUP($AB8,$C$28:$K$61,AD$5,0)=0),NA(),VLOOKUP($AB8,$C$28:$K$61,AD$5,0)) -> 32065 | AE8: =IF(OR(VLOOKUP($AB8,$C$28:$K$61,AE$5,0)="-",VLOOKUP($AB8,$C$28:$K$61,AE$5,0)=0),NA(),VLOOKUP($AB8,$C$28:$K$61,AE$5,0)) -> 32877 | AF8: =IF(OR(VLOOKUP($AB8,$C$28:$K$61,AF$5,0)="-",VLOOKUP($AB8,$C$28:$K$61,AF$5,0)=0),NA(),VLOOKUP($AB8,$C$28:$K$61,AF$5,0)) -> 26710 | AG8: =IF(OR(VLOOKUP($AB8,$C$28:$K$61,AG$5,0)="-",VLOOKUP($AB8,$C$28:$K$61,AG$5,0)=0),NA(),VLOOKUP($AB8,$C$28:$K$61,AG$5,0)) -> 37250.704 | AH8: =IF(OR(VLOOKUP($AB8,$C$28:$K$61,AH$5,0)="-",VLOOKUP($AB8,$C$28:$K$61,AH$5,0)=0),NA(),VLOOKUP($AB8,$C$28:$K$61,AH$5,0)) -> 41663.245 | AI8: =IF(OR(VLOOKUP($AB8,$C$28:$K$61,AI$5,0)="-",VLOOKUP($AB8,$C$28:$K$61,AI$5,0)=0),NA(),VLOOKUP($AB8,$C$28:$K$61,AI$5,0)) -> 47095.314 | AK8: Afghan Afghani | AL8: AFN | AM8: AFN | AN8: 000
B9: (Format: FY2026, CY2026, FQ12026, CQ12026) | H9: Notes: | AB9: Total operating expenses | AC9: =IF(OR(VLOOKUP($AB9,$C$28:$K$61,AC$5,0)="-",VLOOKUP($AB9,$C$28:$K$61,AC$5,0)=0),NA(),VLOOKUP($AB9,$C$28:$K$61,AC$5,0)) -> 57529 | AD9: =IF(OR(VLOOKUP($AB9,$C$28:$K$61,AD$5,0)="-",VLOOKUP($AB9,$C$28:$K$61,AD$5,0)=0),NA(),VLOOKUP($AB9,$C$28:$K$61,AD$5,0)) -> 61575 | AE9: =IF(OR(VLOOKUP($AB9,$C$28:$K$61,AE$5,0)="-",VLOOKUP($AB9,$C$28:$K$61,AE$5,0)=0),NA(),VLOOKUP($AB9,$C$28:$K$61,AE$5,0)) -> 65365 | AF9: =IF(OR(VLOOKUP($AB9,$C$28:$K$61,AF$5,0)="-",VLOOKUP($AB9,$C$28:$K$61,AF$5,0)=0),NA(),VLOOKUP($AB9,$C$28:$K$61,AF$5,0)) -> 70228 | AG9: =IF(OR(VLOOKUP($AB9,$C$28:$K$61,AG$5,0)="-",VLOOKUP($AB9,$C$28:$K$61,AG$5,0)=0),NA(),VLOOKUP($AB9,$C$28:$K$61,AG$5,0)) -> 76784.76 | AH9: =IF(OR(VLOOKUP($AB9,$C$28:$K$61,AH$5,0)="-",VLOOKUP($AB9,$C$28:$K$61,AH$5,0)=0),NA(),VLOOKUP($AB9,$C$28:$K$61,AH$5,0)) -> 87159.935 | AI9: =IF(OR(VLOOKUP($AB9,$C$28:$K$61,AI$5,0)="-",VLOOKUP($AB9,$C$28:$K$61,AI$5,0)=0),NA(),VLOOKUP($AB9,$C$28:$K$61,AI$5,0)) -> 99208.302 | AK9: Albanian Lek | AL9: ALL | AM9: ALL | AN9: 000
H10: This template provides an overview of a company and its peers, combining historical financials, consensus estimates, and key performance metrics. It supports peer company analysis across market data, valuation, profitability, earnings, ratios, and growth metrics. The model utilizes Visible Alpha data from the S&P Capital IQ Pro Plug-In. | AB10: Operating income/(loss), Primary | AC10: =IF(OR(VLOOKUP($AB10,$C$28:$K$61,AC$5,0)="-",VLOOKUP($AB10,$C$28:$K$61,AC$5,0)=0),NA(),VLOOKUP($AB10,$C$28:$K$61,AC$5,0)) -> 88523 | AD10: =IF(OR(VLOOKUP($AB10,$C$28:$K$61,AD$5,0)="-",VLOOKUP($AB10,$C$28:$K$61,AD$5,0)=0),NA(),VLOOKUP($AB10,$C$28:$K$61,AD$5,0)) -> 109433 | AE10: =IF(OR(VLOOKUP($AB10,$C$28:$K$61,AE$5,0)="-",VLOOKUP($AB10,$C$28:$K$61,AE$5,0)=0),NA(),VLOOKUP($AB10,$C$28:$K$61,AE$5,0)) -> 128528 | AF10: =IF(OR(VLOOKUP($AB10,$C$28:$K$61,AF$5,0)="-",VLOOKUP($AB10,$C$28:$K$61,AF$5,0)=0),NA(),VLOOKUP($AB10,$C$28:$K$61,AF$5,0)) -> 155237 | AG10: =IF(OR(VLOOKUP($AB10,$C$28:$K$61,AG$5,0)="-",VLOOKUP($AB10,$C$28:$K$61,AG$5,0)=0),NA(),VLOOKUP($AB10,$C$28:$K$61,AG$5,0)) -> 181653.65 | AH10: =IF(OR(VLOOKUP($AB10,$C$28:$K$61,AH$5,0)="-",VLOOKUP($AB10,$C$28:$K$61,AH$5,0)=0),NA(),VLOOKUP($AB10,$C$28:$K$61,AH$5,0)) -> 216163.44 | AI10: =IF(OR(VLOOKUP($AB10,$C$28:$K$61,AI$5,0)="-",VLOOKUP($AB10,$C$28:$K$61,AI$5,0)=0),NA(),VLOOKUP($AB10,$C$28:$K$61,AI$5,0)) -> 263481.44 | AK10: Argentine Peso | AL10: ARS | AM10: AR$ | AN10: 000
B11: Step 3: Enter As of Date. | E11: {=_xll.SNL.Clients.Office.Excel.Functions.SPGDATE()} -> 46309 | AB11: EBITDA, Primary | AC11: =IF(OR(VLOOKUP($AB11,$C$28:$K$61,AC$5,0)="-",VLOOKUP($AB11,$C$28:$K$61,AC$5,0)=0),NA(),VLOOKUP($AB11,$C$28:$K$61,AC$5,0)) -> 102384 | AD11: =IF(OR(VLOOKUP($AB11,$C$28:$K$61,AD$5,0)="-",VLOOKUP($AB11,$C$28:$K$61,AD$5,0)=0),NA(),VLOOKUP($AB11,$C$28:$K$61,AD$5,0)) -> 131720 | AE11: =IF(OR(VLOOKUP($AB11,$C$28:$K$61,AE$5,0)="-",VLOOKUP($AB11,$C$28:$K$61,AE$5,0)=0),NA(),VLOOKUP($AB11,$C$28:$K$61,AE$5,0)) -> 157961 | AF11: =IF(OR(VLOOKUP($AB11,$C$28:$K$61,AF$5,0)="-",VLOOKUP($AB11,$C$28:$K$61,AF$5,0)=0),NA(),VLOOKUP($AB11,$C$28:$K$61,AF$5,0)) -> 198685 | AG11: =IF(OR(VLOOKUP($AB11,$C$28:$K$61,AG$5,0)="-",VLOOKUP($AB11,$C$28:$K$61,AG$5,0)=0),NA(),VLOOKUP($AB11,$C$28:$K$61,AG$5,0)) -> 238124.89 | AH11: =IF(OR(VLOOKUP($AB11,$C$28:$K$61,AH$5,0)="-",VLOOKUP($AB11,$C$28:$K$61,AH$5,0)=0),NA(),VLOOKUP($AB11,$C$28:$K$61,AH$5,0)) -> 288816.91 | AI11: =IF(OR(VLOOKUP($AB11,$C$28:$K$61,AI$5,0)="-",VLOOKUP($AB11,$C$28:$K$61,AI$5,0)=0),NA(),VLOOKUP($AB11,$C$28:$K$61,AI$5,0)) -> 361803.99 | AK11: Armenian Dram | AL11: AMD | AM11: dr | AN11: 000
AB12: Income / (loss) from continuing operations before income taxes | AC12: =IF(OR(VLOOKUP($AB12,$C$28:$K$61,AC$5,0)="-",VLOOKUP($AB12,$C$28:$K$61,AC$5,0)=0),NA(),VLOOKUP($AB12,$C$28:$K$61,AC$5,0)) -> 90482 | AD12: =IF(OR(VLOOKUP($AB12,$C$28:$K$61,AD$5,0)="-",VLOOKUP($AB12,$C$28:$K$61,AD$5,0)=0),NA(),VLOOKUP($AB12,$C$28:$K$61,AD$5,0)) -> 107787 | AE12: =IF(OR(VLOOKUP($AB12,$C$28:$K$61,AE$5,0)="-",VLOOKUP($AB12,$C$28:$K$61,AE$5,0)=0),NA(),VLOOKUP($AB12,$C$28:$K$61,AE$5,0)) -> 128390 | AF12: =IF(OR(VLOOKUP($AB12,$C$28:$K$61,AF$5,0)="-",VLOOKUP($AB12,$C$28:$K$61,AF$5,0)=0),NA(),VLOOKUP($AB12,$C$28:$K$61,AF$5,0)) -> 160709.72 | AG12: =IF(OR(VLOOKUP($AB12,$C$28:$K$61,AG$5,0)="-",VLOOKUP($AB12,$C$28:$K$61,AG$5,0)=0),NA(),VLOOKUP($AB12,$C$28:$K$61,AG$5,0)) -> 182893.39 | AH12: =IF(OR(VLOOKUP($AB12,$C$28:$K$61,AH$5,0)="-",VLOOKUP($AB12,$C$28:$K$61,AH$5,0)=0),NA(),VLOOKUP($AB12,$C$28:$K$61,AH$5,0)) -> 217228.83 | AI12: =IF(OR(VLOOKUP($AB12,$C$28:$K$61,AI$5,0)="-",VLOOKUP($AB12,$C$28:$K$61,AI$5,0)=0),NA(),VLOOKUP($AB12,$C$28:$K$61,AI$5,0)) -> 264678.58 | AK12: Australian Dollar | AL12: AUD | AM12: AU$ | AN12: 000
AB13: Net income / (loss), Primary | AC13: =IF(OR(VLOOKUP($AB13,$C$28:$K$61,AC$5,0)="-",VLOOKUP($AB13,$C$28:$K$61,AC$5,0)=0),NA(),VLOOKUP($AB13,$C$28:$K$61,AC$5,0)) -> 72361 | AD13: =IF(OR(VLOOKUP($AB13,$C$28:$K$61,AD$5,0)="-",VLOOKUP($AB13,$C$28:$K$61,AD$5,0)=0),NA(),VLOOKUP($AB13,$C$28:$K$61,AD$5,0)) -> 88136 | AE13: =IF(OR(VLOOKUP($AB13,$C$28:$K$61,AE$5,0)="-",VLOOKUP($AB13,$C$28:$K$61,AE$5,0)=0),NA(),VLOOKUP($AB13,$C$28:$K$61,AE$5,0)) -> 101832 | AF13: =IF(OR(VLOOKUP($AB13,$C$28:$K$61,AF$5,0)="-",VLOOKUP($AB13,$C$28:$K$61,AF$5,0)=0),NA(),VLOOKUP($AB13,$C$28:$K$61,AF$5,0)) -> 133749 | AG13: =IF(OR(VLOOKUP($AB13,$C$28:$K$61,AG$5,0)="-",VLOOKUP($AB13,$C$28:$K$61,AG$5,0)=0),NA(),VLOOKUP($AB13,$C$28:$K$61,AG$5,0)) -> 146336.07 | AH13: =IF(OR(VLOOKUP($AB13,$C$28:$K$61,AH$5,0)="-",VLOOKUP($AB13,$C$28:$K$61,AH$5,0)=0),NA(),VLOOKUP($AB13,$C$28:$K$61,AH$5,0)) -> 174134.28 | AI13: =IF(OR(VLOOKUP($AB13,$C$28:$K$61,AI$5,0)="-",VLOOKUP($AB13,$C$28:$K$61,AI$5,0)=0),NA(),VLOOKUP($AB13,$C$28:$K$61,AI$5,0)) -> 212216.41 | AK13: Azerbaijani Manat | AL13: AZN | AM13: m | AN13: 000
B14: Step 4: Select the Currency. | E14: U.S. Dollar | H14: Changing the Input for Period or Metrics dropdown requires refreshing the entire sheet. Refer to Step 7. | AB14: EPS-Diluted-Applicable to Common Stockholders, Primary | AC14: =IF(OR(VLOOKUP($AB14,$C$28:$K$61,AC$5,0)="-",VLOOKUP($AB14,$C$28:$K$61,AC$5,0)=0),NA(),VLOOKUP($AB14,$C$28:$K$61,AC$5,0)) -> 9.683964 | AD14: =IF(OR(VLOOKUP($AB14,$C$28:$K$61,AD$5,0)="-",VLOOKUP($AB14,$C$28:$K$61,AD$5,0)=0),NA(),VLOOKUP($AB14,$C$28:$K$61,AD$5,0)) -> 11.801031 | AE14: =IF(OR(VLOOKUP($AB14,$C$28:$K$61,AE$5,0)="-",VLOOKUP($AB14,$C$28:$K$61,AE$5,0)=0),NA(),VLOOKUP($AB14,$C$28:$K$61,AE$5,0)) -> 13.641259 | AF14: =IF(OR(VLOOKUP($AB14,$C$28:$K$61,AF$5,0)="-",VLOOKUP($AB14,$C$28:$K$61,AF$5,0)=0),NA(),VLOOKUP($AB14,$C$28:$K$61,AF$5,0)) -> 17.944268 | AG14: =IF(OR(VLOOKUP($AB14,$C$28:$K$61,AG$5,0)="-",VLOOKUP($AB14,$C$28:$K$61,AG$5,0)=0),NA(),VLOOKUP($AB14,$C$28:$K$61,AG$5,0)) -> 19.681468 | AH14: =IF(OR(VLOOKUP($AB14,$C$28:$K$61,AH$5,0)="-",VLOOKUP($AB14,$C$28:$K$61,AH$5,0)=0),NA(),VLOOKUP($AB14,$C$28:$K$61,AH$5,0)) -> 23.43518 | AI14: =IF(OR(VLOOKUP($AB14,$C$28:$K$61,AI$5,0)="-",VLOOKUP($AB14,$C$28:$K$61,AI$5,0)=0),NA(),VLOOKUP($AB14,$C$28:$K$61,AI$5,0)) -> 28.54601 | AK14: Bahamian Dollar | AL14: BSD | AM14: B$ | AN14: 000
AB15: Dividend per share | AC15: =IF(OR(VLOOKUP($AB15,$C$28:$K$61,AC$5,0)="-",VLOOKUP($AB15,$C$28:$K$61,AC$5,0)=0),NA(),VLOOKUP($AB15,$C$28:$K$61,AC$5,0)) -> 2.7168448 | AD15: =IF(OR(VLOOKUP($AB15,$C$28:$K$61,AD$5,0)="-",VLOOKUP($AB15,$C$28:$K$61,AD$5,0)=0),NA(),VLOOKUP($AB15,$C$28:$K$61,AD$5,0)) -> 3.0001682 | AE15: =IF(OR(VLOOKUP($AB15,$C$28:$K$61,AE$5,0)="-",VLOOKUP($AB15,$C$28:$K$61,AE$5,0)=0),NA(),VLOOKUP($AB15,$C$28:$K$61,AE$5,0)) -> 3.32 | AF15: =IF(OR(VLOOKUP($AB15,$C$28:$K$61,AF$5,0)="-",VLOOKUP($AB15,$C$28:$K$61,AF$5,0)=0),NA(),VLOOKUP($AB15,$C$28:$K$61,AF$5,0)) -> 3.64 | AG15: =IF(OR(VLOOKUP($AB15,$C$28:$K$61,AG$5,0)="-",VLOOKUP($AB15,$C$28:$K$61,AG$5,0)=0),NA(),VLOOKUP($AB15,$C$28:$K$61,AG$5,0)) -> 3.7723479 | AH15: =IF(OR(VLOOKUP($AB15,$C$28:$K$61,AH$5,0)="-",VLOOKUP($AB15,$C$28:$K$61,AH$5,0)=0),NA(),VLOOKUP($AB15,$C$28:$K$61,AH$5,0)) -> 4.0732413 | AI15: =IF(OR(VLOOKUP($AB15,$C$28:$K$61,AI$5,0)="-",VLOOKUP($AB15,$C$28:$K$61,AI$5,0)=0),NA(),VLOOKUP($AB15,$C$28:$K$61,AI$5,0)) -> 4.6334552 | AK15: Bahraini Dinar | AL15: BHD | AM15: BD | AN15: 000
B16: Step 5: Select the Magnitude. | E16: Millions | H16: This template includes Visible Alpha data, which requires a separate subscription. Contact S&P Capital IQ Pro Support or your Account Manager for access. | AB16: Cash, short-term investments and marketable securities | AC16: =IF(OR(VLOOKUP($AB16,$C$28:$K$61,AC$5,0)="-",VLOOKUP($AB16,$C$28:$K$61,AC$5,0)=0),NA(),VLOOKUP($AB16,$C$28:$K$61,AC$5,0)) -> 111262 | AD16: =IF(OR(VLOOKUP($AB16,$C$28:$K$61,AD$5,0)="-",VLOOKUP($AB16,$C$28:$K$61,AD$5,0)=0),NA(),VLOOKUP($AB16,$C$28:$K$61,AD$5,0)) -> 75543 | AE16: =IF(OR(VLOOKUP($AB16,$C$28:$K$61,AE$5,0)="-",VLOOKUP($AB16,$C$28:$K$61,AE$5,0)=0),NA(),VLOOKUP($AB16,$C$28:$K$61,AE$5,0)) -> 94565 | AF16: =IF(OR(VLOOKUP($AB16,$C$28:$K$61,AF$5,0)="-",VLOOKUP($AB16,$C$28:$K$61,AF$5,0)=0),NA(),VLOOKUP($AB16,$C$28:$K$61,AF$5,0)) -> 76843 | AG16: =IF(OR(VLOOKUP($AB16,$C$28:$K$61,AG$5,0)="-",VLOOKUP($AB16,$C$28:$K$61,AG$5,0)=0),NA(),VLOOKUP($AB16,$C$28:$K$61,AG$5,0)) -> 76432.361 | AH16: =IF(OR(VLOOKUP($AB16,$C$28:$K$61,AH$5,0)="-",VLOOKUP($AB16,$C$28:$K$61,AH$5,0)=0),NA(),VLOOKUP($AB16,$C$28:$K$61,AH$5,0)) -> 91971.939 | AI16: =IF(OR(VLOOKUP($AB16,$C$28:$K$61,AI$5,0)="-",VLOOKUP($AB16,$C$28:$K$61,AI$5,0)=0),NA(),VLOOKUP($AB16,$C$28:$K$61,AI$5,0)) -> 137678.95 | AK16: Bangladeshi Taka | AL16: BDT | AM16: Bt. | AN16: 000
AB17: Total Current Assets | AC17: =IF(OR(VLOOKUP($AB17,$C$28:$K$61,AC$5,0)="-",VLOOKUP($AB17,$C$28:$K$61,AC$5,0)=0),NA(),VLOOKUP($AB17,$C$28:$K$61,AC$5,0)) -> 184257 | AD17: =IF(OR(VLOOKUP($AB17,$C$28:$K$61,AD$5,0)="-",VLOOKUP($AB17,$C$28:$K$61,AD$5,0)=0),NA(),VLOOKUP($AB17,$C$28:$K$61,AD$5,0)) -> 159734 | AE17: =IF(OR(VLOOKUP($AB17,$C$28:$K$61,AE$5,0)="-",VLOOKUP($AB17,$C$28:$K$61,AE$5,0)=0),NA(),VLOOKUP($AB17,$C$28:$K$61,AE$5,0)) -> 191131 | AF17: =IF(OR(VLOOKUP($AB17,$C$28:$K$61,AF$5,0)="-",VLOOKUP($AB17,$C$28:$K$61,AF$5,0)=0),NA(),VLOOKUP($AB17,$C$28:$K$61,AF$5,0)) -> 207710 | AG17: =IF(OR(VLOOKUP($AB17,$C$28:$K$61,AG$5,0)="-",VLOOKUP($AB17,$C$28:$K$61,AG$5,0)=0),NA(),VLOOKUP($AB17,$C$28:$K$61,AG$5,0)) -> 217427.2 | AH17: =IF(OR(VLOOKUP($AB17,$C$28:$K$61,AH$5,0)="-",VLOOKUP($AB17,$C$28:$K$61,AH$5,0)=0),NA(),VLOOKUP($AB17,$C$28:$K$61,AH$5,0)) -> 251290.45 | AI17: =IF(OR(VLOOKUP($AB17,$C$28:$K$61,AI$5,0)="-",VLOOKUP($AB17,$C$28:$K$61,AI$5,0)=0),NA(),VLOOKUP($AB17,$C$28:$K$61,AI$5,0)) -> 326323.59 | AK17: Belarusian Ruble | AL17: BYN | AM17: Br | AN17: 000
B18: Step 6: Select the Source. | E18: Consensus.VAActuals | AB18: Total non-Current Assets | AC18: =IF(OR(VLOOKUP($AB18,$C$28:$K$61,AC$5,0)="-",VLOOKUP($AB18,$C$28:$K$61,AC$5,0)=0),NA(),VLOOKUP($AB18,$C$28:$K$61,AC$5,0)) -> 227719 | AD18: =IF(OR(VLOOKUP($AB18,$C$28:$K$61,AD$5,0)="-",VLOOKUP($AB18,$C$28:$K$61,AD$5,0)=0),NA(),VLOOKUP($AB18,$C$28:$K$61,AD$5,0)) -> 352429 | AE18: =IF(OR(VLOOKUP($AB18,$C$28:$K$61,AE$5,0)="-",VLOOKUP($AB18,$C$28:$K$61,AE$5,0)=0),NA(),VLOOKUP($AB18,$C$28:$K$61,AE$5,0)) -> 427872 | AF18: =IF(OR(VLOOKUP($AB18,$C$28:$K$61,AF$5,0)="-",VLOOKUP($AB18,$C$28:$K$61,AF$5,0)=0),NA(),VLOOKUP($AB18,$C$28:$K$61,AF$5,0)) -> 550666 | AG18: =IF(OR(VLOOKUP($AB18,$C$28:$K$61,AG$5,0)="-",VLOOKUP($AB18,$C$28:$K$61,AG$5,0)=0),NA(),VLOOKUP($AB18,$C$28:$K$61,AG$5,0)) -> 666956.24 | AH18: =IF(OR(VLOOKUP($AB18,$C$28:$K$61,AH$5,0)="-",VLOOKUP($AB18,$C$28:$K$61,AH$5,0)=0),NA(),VLOOKUP($AB18,$C$28:$K$61,AH$5,0)) -> 804918.68 | AI18: =IF(OR(VLOOKUP($AB18,$C$28:$K$61,AI$5,0)="-",VLOOKUP($AB18,$C$28:$K$61,AI$5,0)=0),NA(),VLOOKUP($AB18,$C$28:$K$61,AI$5,0)) -> 990820.78 | AK18: Bosnian Convertible Marks | AL18: BAM | AM18: KM | AN18: 000
H19: Disclaimer: | AB19: Total current liabilities | AC19: =IF(OR(VLOOKUP($AB19,$C$28:$K$61,AC$5,0)="-",VLOOKUP($AB19,$C$28:$K$61,AC$5,0)=0),NA(),VLOOKUP($AB19,$C$28:$K$61,AC$5,0)) -> 104149 | AD19: =IF(OR(VLOOKUP($AB19,$C$28:$K$61,AD$5,0)="-",VLOOKUP($AB19,$C$28:$K$61,AD$5,0)=0),NA(),VLOOKUP($AB19,$C$28:$K$61,AD$5,0)) -> 125286 | AE19: =IF(OR(VLOOKUP($AB19,$C$28:$K$61,AE$5,0)="-",VLOOKUP($AB19,$C$28:$K$61,AE$5,0)=0),NA(),VLOOKUP($AB19,$C$28:$K$61,AE$5,0)) -> 141218 | AF19: =IF(OR(VLOOKUP($AB19,$C$28:$K$61,AF$5,0)="-",VLOOKUP($AB19,$C$28:$K$61,AF$5,0)=0),NA(),VLOOKUP($AB19,$C$28:$K$61,AF$5,0)) -> 168825 | AG19: =IF(OR(VLOOKUP($AB19,$C$28:$K$61,AG$5,0)="-",VLOOKUP($AB19,$C$28:$K$61,AG$5,0)=0),NA(),VLOOKUP($AB19,$C$28:$K$61,AG$5,0)) -> 188107.27 | AH19: =IF(OR(VLOOKUP($AB19,$C$28:$K$61,AH$5,0)="-",VLOOKUP($AB19,$C$28:$K$61,AH$5,0)=0),NA(),VLOOKUP($AB19,$C$28:$K$61,AH$5,0)) -> 215558.26 | AI19: =IF(OR(VLOOKUP($AB19,$C$28:$K$61,AI$5,0)="-",VLOOKUP($AB19,$C$28:$K$61,AI$5,0)=0),NA(),VLOOKUP($AB19,$C$28:$K$61,AI$5,0)) -> 254477.68 | AK19: Brazilian Real | AL19: BRL | AM19: R$ | AN19: 000
D20: Enter Broker Code>> | H20: {="Copyright © "&YEAR(_xll.SNL.Clients.Office.Excel.Functions.SPGDATE())&" S&P Global Market Intelligence LLC (and its affiliates as applicable) – All rights reserved. "&"This model and/or any data in it are provided subject to the written agreement of S&P Global Market Intelligence LLC governing the subscription service to which this model is applied."} -> Copyright © 2026 S&P Global Market Intelligence LLC (and its affiliates as applicable) – All rights reserved. This model and/or any data in it are provided subject to the written agreement of S&P Global Market Intelligence LLC governing the subscription service to which this model is applied. | AB20: Total non-current liabilities | AC20: =IF(OR(VLOOKUP($AB20,$C$28:$K$61,AC$5,0)="-",VLOOKUP($AB20,$C$28:$K$61,AC$5,0)=0),NA(),VLOOKUP($AB20,$C$28:$K$61,AC$5,0)) -> 101604 | AD20: =IF(OR(VLOOKUP($AB20,$C$28:$K$61,AD$5,0)="-",VLOOKUP($AB20,$C$28:$K$61,AD$5,0)=0),NA(),VLOOKUP($AB20,$C$28:$K$61,AD$5,0)) -> 118400 | AE20: =IF(OR(VLOOKUP($AB20,$C$28:$K$61,AE$5,0)="-",VLOOKUP($AB20,$C$28:$K$61,AE$5,0)=0),NA(),VLOOKUP($AB20,$C$28:$K$61,AE$5,0)) -> 134306 | AF20: =IF(OR(VLOOKUP($AB20,$C$28:$K$61,AF$5,0)="-",VLOOKUP($AB20,$C$28:$K$61,AF$5,0)=0),NA(),VLOOKUP($AB20,$C$28:$K$61,AF$5,0)) -> 147164 | AG20: =IF(OR(VLOOKUP($AB20,$C$28:$K$61,AG$5,0)="-",VLOOKUP($AB20,$C$28:$K$61,AG$5,0)=0),NA(),VLOOKUP($AB20,$C$28:$K$61,AG$5,0)) -> 157224.88 | AH20: =IF(OR(VLOOKUP($AB20,$C$28:$K$61,AH$5,0)="-",VLOOKUP($AB20,$C$28:$K$61,AH$5,0)=0),NA(),VLOOKUP($AB20,$C$28:$K$61,AH$5,0)) -> 170249.63 | AI20: =IF(OR(VLOOKUP($AB20,$C$28:$K$61,AI$5,0)="-",VLOOKUP($AB20,$C$28:$K$61,AI$5,0)=0),NA(),VLOOKUP($AB20,$C$28:$K$61,AI$5,0)) -> 198277.78 | AK20: Bulgarian Lev | AL20: BGN | AM20: BGN | AN20: 000
B21: Step 7: To REFRESH, Go to S&P Cap IQ Pro in the Ribbon > Refresh Data > All Sheets. | AB21: Net Debt | AC21: =IF(OR(VLOOKUP($AB21,$C$28:$K$61,AC$5,0)="-",VLOOKUP($AB21,$C$28:$K$61,AC$5,0)=0),NA(),VLOOKUP($AB21,$C$28:$K$61,AC$5,0)) -> -51297 | AD21: =IF(OR(VLOOKUP($AB21,$C$28:$K$61,AD$5,0)="-",VLOOKUP($AB21,$C$28:$K$61,AD$5,0)=0),NA(),VLOOKUP($AB21,$C$28:$K$61,AD$5,0)) -> -8416 | AE21: =IF(OR(VLOOKUP($AB21,$C$28:$K$61,AE$5,0)="-",VLOOKUP($AB21,$C$28:$K$61,AE$5,0)=0),NA(),VLOOKUP($AB21,$C$28:$K$61,AE$5,0)) -> -33977 | AF21: =IF(OR(VLOOKUP($AB21,$C$28:$K$61,AF$5,0)="-",VLOOKUP($AB21,$C$28:$K$61,AF$5,0)=0),NA(),VLOOKUP($AB21,$C$28:$K$61,AF$5,0)) -> -20017 | AG21: =IF(OR(VLOOKUP($AB21,$C$28:$K$61,AG$5,0)="-",VLOOKUP($AB21,$C$28:$K$61,AG$5,0)=0),NA(),VLOOKUP($AB21,$C$28:$K$61,AG$5,0)) -> -13032.555 | AH21: =IF(OR(VLOOKUP($AB21,$C$28:$K$61,AH$5,0)="-",VLOOKUP($AB21,$C$28:$K$61,AH$5,0)=0),NA(),VLOOKUP($AB21,$C$28:$K$61,AH$5,0)) -> -16775.179 | AI21: =IF(OR(VLOOKUP($AB21,$C$28:$K$61,AI$5,0)="-",VLOOKUP($AB21,$C$28:$K$61,AI$5,0)=0),NA(),VLOOKUP($AB21,$C$28:$K$61,AI$5,0)) -> -47697.724 | AK21: Cambodian Riel | AL21: KHR | AM21: ៛ | AN21: M
AB22: Capital expenditures | AC22: =IF(OR(VLOOKUP($AB22,$C$28:$K$61,AC$5,0)="-",VLOOKUP($AB22,$C$28:$K$61,AC$5,0)=0),NA(),VLOOKUP($AB22,$C$28:$K$61,AC$5,0)) -> 28107 | AD22: =IF(OR(VLOOKUP($AB22,$C$28:$K$61,AD$5,0)="-",VLOOKUP($AB22,$C$28:$K$61,AD$5,0)=0),NA(),VLOOKUP($AB22,$C$28:$K$61,AD$5,0)) -> 44477 | AE22: =IF(OR(VLOOKUP($AB22,$C$28:$K$61,AE$5,0)="-",VLOOKUP($AB22,$C$28:$K$61,AE$5,0)=0),NA(),VLOOKUP($AB22,$C$28:$K$61,AE$5,0)) -> 64551 | AF22: =IF(OR(VLOOKUP($AB22,$C$28:$K$61,AF$5,0)="-",VLOOKUP($AB22,$C$28:$K$61,AF$5,0)=0),NA(),VLOOKUP($AB22,$C$28:$K$61,AF$5,0)) -> 115948 | AG22: =IF(OR(VLOOKUP($AB22,$C$28:$K$61,AG$5,0)="-",VLOOKUP($AB22,$C$28:$K$61,AG$5,0)=0),NA(),VLOOKUP($AB22,$C$28:$K$61,AG$5,0)) -> 195481.71 | AH22: =IF(OR(VLOOKUP($AB22,$C$28:$K$61,AH$5,0)="-",VLOOKUP($AB22,$C$28:$K$61,AH$5,0)=0),NA(),VLOOKUP($AB22,$C$28:$K$61,AH$5,0)) -> 223523.11 | AI22: =IF(OR(VLOOKUP($AB22,$C$28:$K$61,AI$5,0)="-",VLOOKUP($AB22,$C$28:$K$61,AI$5,0)=0),NA(),VLOOKUP($AB22,$C$28:$K$61,AI$5,0)) -> 257861.81 | AK22: Canadian Dollar | AL22: CAD | AM22: C$ | AN22: 000
D23: Data Type >> | E23: SD | AB23: (Increase) / decrease in working capital | AC23: =IF(OR(VLOOKUP($AB23,$C$28:$K$61,AC$5,0)="-",VLOOKUP($AB23,$C$28:$K$61,AC$5,0)=0),NA(),VLOOKUP($AB23,$C$28:$K$61,AC$5,0)) -> -7923 | AD23: =IF(OR(VLOOKUP($AB23,$C$28:$K$61,AD$5,0)="-",VLOOKUP($AB23,$C$28:$K$61,AD$5,0)=0),NA(),VLOOKUP($AB23,$C$28:$K$61,AD$5,0)) -> -3524 | AE23: =IF(OR(VLOOKUP($AB23,$C$28:$K$61,AE$5,0)="-",VLOOKUP($AB23,$C$28:$K$61,AE$5,0)=0),NA(),VLOOKUP($AB23,$C$28:$K$61,AE$5,0)) -> -10788 | AF23: =IF(OR(VLOOKUP($AB23,$C$28:$K$61,AF$5,0)="-",VLOOKUP($AB23,$C$28:$K$61,AF$5,0)=0),NA(),VLOOKUP($AB23,$C$28:$K$61,AF$5,0)) -> -14256 | AG23: =IF(OR(VLOOKUP($AB23,$C$28:$K$61,AG$5,0)="-",VLOOKUP($AB23,$C$28:$K$61,AG$5,0)=0),NA(),VLOOKUP($AB23,$C$28:$K$61,AG$5,0)) -> -2648.058 | AH23: =IF(OR(VLOOKUP($AB23,$C$28:$K$61,AH$5,0)="-",VLOOKUP($AB23,$C$28:$K$61,AH$5,0)=0),NA(),VLOOKUP($AB23,$C$28:$K$61,AH$5,0)) -> -5915.8246 | AI23: =IF(OR(VLOOKUP($AB23,$C$28:$K$61,AI$5,0)="-",VLOOKUP($AB23,$C$28:$K$61,AI$5,0)=0),NA(),VLOOKUP($AB23,$C$28:$K$61,AI$5,0)) -> -13816.39 | AK23: Chilean Peso | AL23: CLP | AM23: CL$ | AN23: M
AB24: Net cash flows provided by / (used in) operating activities | AC24: =IF(OR(VLOOKUP($AB24,$C$28:$K$61,AC$5,0)="-",VLOOKUP($AB24,$C$28:$K$61,AC$5,0)=0),NA(),VLOOKUP($AB24,$C$28:$K$61,AC$5,0)) -> 87582 | AD24: =IF(OR(VLOOKUP($AB24,$C$28:$K$61,AD$5,0)="-",VLOOKUP($AB24,$C$28:$K$61,AD$5,0)=0),NA(),VLOOKUP($AB24,$C$28:$K$61,AD$5,0)) -> 118548 | AE24: =IF(OR(VLOOKUP($AB24,$C$28:$K$61,AE$5,0)="-",VLOOKUP($AB24,$C$28:$K$61,AE$5,0)=0),NA(),VLOOKUP($AB24,$C$28:$K$61,AE$5,0)) -> 136162 | AF24: =IF(OR(VLOOKUP($AB24,$C$28:$K$61,AF$5,0)="-",VLOOKUP($AB24,$C$28:$K$61,AF$5,0)=0),NA(),VLOOKUP($AB24,$C$28:$K$61,AF$5,0)) -> 182935 | AG24: =IF(OR(VLOOKUP($AB24,$C$28:$K$61,AG$5,0)="-",VLOOKUP($AB24,$C$28:$K$61,AG$5,0)=0),NA(),VLOOKUP($AB24,$C$28:$K$61,AG$5,0)) -> 215211.58 | AH24: =IF(OR(VLOOKUP($AB24,$C$28:$K$61,AH$5,0)="-",VLOOKUP($AB24,$C$28:$K$61,AH$5,0)=0),NA(),VLOOKUP($AB24,$C$28:$K$61,AH$5,0)) -> 256160.57 | AI24: =IF(OR(VLOOKUP($AB24,$C$28:$K$61,AI$5,0)="-",VLOOKUP($AB24,$C$28:$K$61,AI$5,0)=0),NA(),VLOOKUP($AB24,$C$28:$K$61,AI$5,0)) -> 308937.29 | AK24: Chinese Yuan Renminbi | AL24: CNY | AM24: CN¥ | AN24: 000
B25: {=_xll.SNL.Clients.Office.Excel.Functions.SPG($E$5,"SP_COMPANY_NAME")} -> Microsoft Corporation | K25: ="Data in ("&AM1&""&AG33&"), except per share" -> Data in ($M), except per share | AB25: Net cash flows provided by/(used in) investing activities | AC25: =IF(OR(VLOOKUP($AB25,$C$28:$K$61,AC$5,0)="-",VLOOKUP($AB25,$C$28:$K$61,AC$5,0)=0),NA(),VLOOKUP($AB25,$C$28:$K$61,AC$5,0)) -> -22680 | AD25: =IF(OR(VLOOKUP($AB25,$C$28:$K$61,AD$5,0)="-",VLOOKUP($AB25,$C$28:$K$61,AD$5,0)=0),NA(),VLOOKUP($AB25,$C$28:$K$61,AD$5,0)) -> -96970 | AE25: =IF(OR(VLOOKUP($AB25,$C$28:$K$61,AE$5,0)="-",VLOOKUP($AB25,$C$28:$K$61,AE$5,0)=0),NA(),VLOOKUP($AB25,$C$28:$K$61,AE$5,0)) -> -72599 | AF25: =IF(OR(VLOOKUP($AB25,$C$28:$K$61,AF$5,0)="-",VLOOKUP($AB25,$C$28:$K$61,AF$5,0)=0),NA(),VLOOKUP($AB25,$C$28:$K$61,AF$5,0)) -> -139500 | AG25: =IF(OR(VLOOKUP($AB25,$C$28:$K$61,AG$5,0)="-",VLOOKUP($AB25,$C$28:$K$61,AG$5,0)=0),NA(),VLOOKUP($AB25,$C$28:$K$61,AG$5,0)) -> -189843.82 | AH25: =IF(OR(VLOOKUP($AB25,$C$28:$K$61,AH$5,0)="-",VLOOKUP($AB25,$C$28:$K$61,AH$5,0)=0),NA(),VLOOKUP($AB25,$C$28:$K$61,AH$5,0)) -> -218604.85 | AI25: =IF(OR(VLOOKUP($AB25,$C$28:$K$61,AI$5,0)="-",VLOOKUP($AB25,$C$28:$K$61,AI$5,0)=0),NA(),VLOOKUP($AB25,$C$28:$K$61,AI$5,0)) -> -252478.37 | AK25: Colombian Peso | AL25: COP | AM25: Col$ | AN25: M
E26: {=_xll.SNL.Clients.Office.Excel.Functions.SPG($E$5,"ActualorEstimate",E$27,$E$11,_xll.SNL.Clients.Office.Excel.Functions.SPGOPTIONS("DataType",$E$23,"Src",$AI$40))} -> A | F26: {=_xll.SNL.Clients.Office.Excel.Functions.SPG($E$5,"ActualorEstimate",F$27,$E$11,_xll.SNL.Clients.Office.Excel.Functions.SPGOPTIONS("DataType",$E$23,"Src",$AI$40))} -> A | G26: {=_xll.SNL.Clients.Office.Excel.Functions.SPG($E$5,"ActualorEstimate",G$27,$E$11,_xll.SNL.Clients.Office.Excel.Functions.SPGOPTIONS("DataType",$E$23,"Src",$AI$40))} -> A | H26: {=_xll.SNL.Clients.Office.Excel.Functions.SPG($E$5,"ActualorEstimate",H$27,$E$11,_xll.SNL.Clients.Office.Excel.Functions.SPGOPTIONS("DataType",$E$23,"Src",$AI$40))} -> A | I26: {=_xll.SNL.Clients.Office.Excel.Functions.SPG($E$5,"ActualorEstimate",I$27,$E$11,_xll.SNL.Clients.Office.Excel.Functions.SPGOPTIONS("DataType",$E$23,"Src",$AI$40))} -> E | J26: {=_xll.SNL.Clients.Office.Excel.Functions.SPG($E$5,"ActualorEstimate",J$27,$E$11,_xll.SNL.Clients.Office.Excel.Functions.SPGOPTIONS("DataType",$E$23,"Src",$AI$40))} -> E | K26: {=_xll.SNL.Clients.Office.Excel.Functions.SPG($E$5,"ActualorEstimate",K$27,$E$11,_xll.SNL.Clients.Office.Excel.Functions.SPGOPTIONS("DataType",$E$23,"Src",$AI$40))} -> E | L26: Chart 1 : | M26: Select Metric ---> | O26: Total revenue | AB26: Net cash flows provided by/(used in) financing activities | AC26: =IF(OR(VLOOKUP($AB26,$C$28:$K$61,AC$5,0)="-",VLOOKUP($AB26,$C$28:$K$61,AC$5,0)=0),NA(),VLOOKUP($AB26,$C$28:$K$61,AC$5,0)) -> -43935 | AD26: =IF(OR(VLOOKUP($AB26,$C$28:$K$61,AD$5,0)="-",VLOOKUP($AB26,$C$28:$K$61,AD$5,0)=0),NA(),VLOOKUP($AB26,$C$28:$K$61,AD$5,0)) -> -37757 | AE26: =IF(OR(VLOOKUP($AB26,$C$28:$K$61,AE$5,0)="-",VLOOKUP($AB26,$C$28:$K$61,AE$5,0)=0),NA(),VLOOKUP($AB26,$C$28:$K$61,AE$5,0)) -> -51699 | AF26: =IF(OR(VLOOKUP($AB26,$C$28:$K$61,AF$5,0)="-",VLOOKUP($AB26,$C$28:$K$61,AF$5,0)=0),NA(),VLOOKUP($AB26,$C$28:$K$61,AF$5,0)) -> -52546 | AG26: =IF(OR(VLOOKUP($AB26,$C$28:$K$61,AG$5,0)="-",VLOOKUP($AB26,$C$28:$K$61,AG$5,0)=0),NA(),VLOOKUP($AB26,$C$28:$K$61,AG$5,0)) -> -34812.238 | AH26: =IF(OR(VLOOKUP($AB26,$C$28:$K$61,AH$5,0)="-",VLOOKUP($AB26,$C$28:$K$61,AH$5,0)=0),NA(),VLOOKUP($AB26,$C$28:$K$61,AH$5,0)) -> -36917.601 | AI26: =IF(OR(VLOOKUP($AB26,$C$28:$K$61,AI$5,0)="-",VLOOKUP($AB26,$C$28:$K$61,AI$5,0)=0),NA(),VLOOKUP($AB26,$C$28:$K$61,AI$5,0)) -> -41375.214 | AK26: Costa Rican Colon | AL26: CRC | AM26: ¢ | AN26: 000
B27: Income Statement | E27: =IF(OR(LEFT(F27,2)="FY",LEFT(F27,2)="CY"),LEFT(F27,2)&VALUE(RIGHT(F27,4))-1,LEFT(F27,2)&IF(MID(F27,3,1)="1","4",MID(F27,3,1)-1)&IF(MID(F27,3,1)="1",VALUE(RIGHT(F27,4))-1,RIGHT(F27,4))) -> FY2023 | F27: =IF(OR(LEFT(G27,2)="FY",LEFT(G27,2)="CY"),LEFT(G27,2)&VALUE(RIGHT(G27,4))-1,LEFT(G27,2)&IF(MID(G27,3,1)="1","4",MID(G27,3,1)-1)&IF(MID(G27,3,1)="1",VALUE(RIGHT(G27,4))-1,RIGHT(G27,4))) -> FY2024 | G27: =E8 -> FY2025 | H27: =IF(MID(G27,2,1)="Q",IF(MID(G27,2,2)="Q4",LEFT(G27,2)&"1"&RIGHT(G27,4)+1,LEFT(G27,2)&MID(G27,3,1)+1&RIGHT(G27,4)),LEFT(G27,2)&RIGHT(G27,4)+1) -> FY2026 | I27: =IF(MID(H27,2,1)="Q",IF(MID(H27,2,2)="Q4",LEFT(H27,2)&"1"&RIGHT(H27,4)+1,LEFT(H27,2)&MID(H27,3,1)+1&RIGHT(H27,4)),LEFT(H27,2)&RIGHT(H27,4)+1) -> FY2027 | J27: =IF(MID(I27,2,1)="Q",IF(MID(I27,2,2)="Q4",LEFT(I27,2)&"1"&RIGHT(I27,4)+1,LEFT(I27,2)&MID(I27,3,1)+1&RIGHT(I27,4)),LEFT(I27,2)&RIGHT(I27,4)+1) -> FY2028 | K27: =IF(MID(J27,2,1)="Q",IF(MID(J27,2,2)="Q4",LEFT(J27,2)&"1"&RIGHT(J27,4)+1,LEFT(J27,2)&MID(J27,3,1)+1&RIGHT(J27,4)),LEFT(J27,2)&RIGHT(J27,4)+1) -> FY2029 | AB27: Gross margin | AC27: =IF(OR(VLOOKUP($AB27,$C$28:$K$61,AC$5,0)="-",VLOOKUP($AB27,$C$28:$K$61,AC$5,0)=0),NA(),VLOOKUP($AB27,$C$28:$K$61,AC$5,0)) -> 0.68920086 | AD27: =IF(OR(VLOOKUP($AB27,$C$28:$K$61,AD$5,0)="-",VLOOKUP($AB27,$C$28:$K$61,AD$5,0)=0),NA(),VLOOKUP($AB27,$C$28:$K$61,AD$5,0)) -> 0.69764444 | AE27: =IF(OR(VLOOKUP($AB27,$C$28:$K$61,AE$5,0)="-",VLOOKUP($AB27,$C$28:$K$61,AE$5,0)=0),NA(),VLOOKUP($AB27,$C$28:$K$61,AE$5,0)) -> 0.68823742 | AF27: =IF(OR(VLOOKUP($AB27,$C$28:$K$61,AF$5,0)="-",VLOOKUP($AB27,$C$28:$K$61,AF$5,0)=0),NA(),VLOOKUP($AB27,$C$28:$K$61,AF$5,0)) -> 0.67944093 | AG27: =IF(OR(VLOOKUP($AB27,$C$28:$K$61,AG$5,0)="-",VLOOKUP($AB27,$C$28:$K$61,AG$5,0)=0),NA(),VLOOKUP($AB27,$C$28:$K$61,AG$5,0)) -> 0.66096726 | AH27: =IF(OR(VLOOKUP($AB27,$C$28:$K$61,AH$5,0)="-",VLOOKUP($AB27,$C$28:$K$61,AH$5,0)=0),NA(),VLOOKUP($AB27,$C$28:$K$61,AH$5,0)) -> 0.64938314 | AI27: =IF(OR(VLOOKUP($AB27,$C$28:$K$61,AI$5,0)="-",VLOOKUP($AB27,$C$28:$K$61,AI$5,0)=0),NA(),VLOOKUP($AB27,$C$28:$K$61,AI$5,0)) -> 0.63949896 | AK27: Croatian Kuna | AL27: HRK | AM27: kn | AN27: 000
B28: Sales | C28: Total revenue | E28: {=_xll.SNL.Clients.Office.Excel.Functions.SPG($E$5,$C28,E$27,$E$11,_xll.SNL.Clients.Office.Excel.Functions.SPGOPTIONS("DataType",$E$23,"Src",$AI$40,"Mag",$AG$33,"Curr",$AL$1,"NA",""))} -> 211915 | F28: {=_xll.SNL.Clients.Office.Excel.Functions.SPG($E$5,$C28,F$27,$E$11,_xll.SNL.Clients.Office.Excel.Functions.SPGOPTIONS("DataType",$E$23,"Src",$AI$40,"Mag",$AG$33,"Curr",$AL$1,"NA",""))} -> 245122 | G28: {=_xll.SNL.Clients.Office.Excel.Functions.SPG($E$5,$C28,G$27,$E$11,_xll.SNL.Clients.Office.Excel.Functions.SPGOPTIONS("DataType",$E$23,"Src",$AI$40,"Mag",$AG$33,"Curr",$AL$1,"NA",""))} -> 281724 | H28: {=_xll.SNL.Clients.Office.Excel.Functions.SPG($E$5,$C28,H$27,$E$11,_xll.SNL.Clients.Office.Excel.Functions.SPGOPTIONS("DataType",$E$23,"Src",$AI$40,"Mag",$AG$33,"Curr",$AL$1,"NA",""))} -> 331839 | I28: {=_xll.SNL.Clients.Office.Excel.Functions.SPG($E$5,$C28,I$27,$E$11,_xll.SNL.Clients.Office.Excel.Functions.SPGOPTIONS("DataType",$E$23,"Src",$AI$40,"Mag",$AG$33,"Curr",$AL$1,"NA",""))} -> 391146.94 | J28: {=_xll.SNL.Clients.Office.Excel.Functions.SPG($E$5,$C28,J$27,$E$11,_xll.SNL.Clients.Office.Excel.Functions.SPGOPTIONS("DataType",$E$23,"Src",$AI$40,"Mag",$AG$33,"Curr",$AL$1,"NA",""))} -> 467637.47 | K28: {=_xll.SNL.Clients.Office.Excel.Functions.SPG($E$5,$C28,K$27,$E$11,_xll.SNL.Clients.Office.Excel.Functions.SPGOPTIONS("DataType",$E$23,"Src",$AI$40,"Mag",$AG$33,"Curr",$AL$1,"NA",""))} -> 568944.85 | AB28: SG&A / Sales | AC28: =IF(OR(VLOOKUP($AB28,$C$28:$K$61,AC$5,0)="-",VLOOKUP($AB28,$C$28:$K$61,AC$5,0)=0),NA(),VLOOKUP($AB28,$C$28:$K$61,AC$5,0)) -> 0.10739683 | AD28: =IF(OR(VLOOKUP($AB28,$C$28:$K$61,AD$5,0)="-",VLOOKUP($AB28,$C$28:$K$61,AD$5,0)=0),NA(),VLOOKUP($AB28,$C$28:$K$61,AD$5,0)) -> 0.13081241 | AE28: =IF(OR(VLOOKUP($AB28,$C$28:$K$61,AE$5,0)="-",VLOOKUP($AB28,$C$28:$K$61,AE$5,0)=0),NA(),VLOOKUP($AB28,$C$28:$K$61,AE$5,0)) -> 0.11669932 | AF28: =IF(OR(VLOOKUP($AB28,$C$28:$K$61,AF$5,0)="-",VLOOKUP($AB28,$C$28:$K$61,AF$5,0)=0),NA(),VLOOKUP($AB28,$C$28:$K$61,AF$5,0)) -> 0.08049084 | AG28: =IF(OR(VLOOKUP($AB28,$C$28:$K$61,AG$5,0)="-",VLOOKUP($AB28,$C$28:$K$61,AG$5,0)=0),NA(),VLOOKUP($AB28,$C$28:$K$61,AG$5,0)) -> 0.095265139 | AH28: =IF(OR(VLOOKUP($AB28,$C$28:$K$61,AH$5,0)="-",VLOOKUP($AB28,$C$28:$K$61,AH$5,0)=0),NA(),VLOOKUP($AB28,$C$28:$K$61,AH$5,0)) -> 0.089306329 | AI28: =IF(OR(VLOOKUP($AB28,$C$28:$K$61,AI$5,0)="-",VLOOKUP($AB28,$C$28:$K$61,AI$5,0)=0),NA(),VLOOKUP($AB28,$C$28:$K$61,AI$5,0)) -> 0.083192461 | AK28: Czech Koruna | AL28: CZK | AM28: Kc | AN28: 000
B29: - growth YoY | F29: {=IF(OR(LEFT($E$8,2)="FY",LEFT($E$8,2)="CY"),IFERROR(F28/E28-1,"-"),IF(OR(LEFT($E$8,2)="FQ",LEFT($E$8,2)="CQ"),IFERROR(F28/_xll.SNL.Clients.Office.Excel.Functions.SPG($E$5,$C28,LEFT(F$27,3)&(RIGHT(F$27,4)-1),$E$11,_xll.SNL.Clients.Office.Excel.Functions.SPGOPTIONS("DataType",$E$23,"Src",$AI$40,"Mag",$AG$33,"Curr",$AL$1,"NA",""))-1,"-"),"-"))} -> 0.15669962 | G29: {=IF(OR(LEFT($E$8,2)="FY",LEFT($E$8,2)="CY"),IFERROR(G28/F28-1,"-"),IF(OR(LEFT($E$8,2)="FQ",LEFT($E$8,2)="CQ"),IFERROR(G28/_xll.SNL.Clients.Office.Excel.Functions.SPG($E$5,$C28,LEFT(G$27,3)&(RIGHT(G$27,4)-1),$E$11,_xll.SNL.Clients.Office.Excel.Functions.SPGOPTIONS("DataType",$E$23,"Src",$AI$40,"Mag",$AG$33,"Curr",$AL$1,"NA",""))-1,"-"),"-"))} -> 0.14932156 | H29: {=IF(OR(LEFT($E$8,2)="FY",LEFT($E$8,2)="CY"),IFERROR(H28/G28-1,"-"),IF(OR(LEFT($E$8,2)="FQ",LEFT($E$8,2)="CQ"),IFERROR(H28/_xll.SNL.Clients.Office.Excel.Functions.SPG($E$5,$C28,LEFT(H$27,3)&(RIGHT(H$27,4)-1),$E$11,_xll.SNL.Clients.Office.Excel.Functions.SPGOPTIONS("DataType",$E$23,"Src",$AI$40,"Mag",$AG$33,"Curr",$AL$1,"NA",""))-1,"-"),"-"))} -> 0.17788687 | I29: {=IF(OR(LEFT($E$8,2)="FY",LEFT($E$8,2)="CY"),IFERROR(I28/H28-1,"-"),IF(OR(LEFT($E$8,2)="FQ",LEFT($E$8,2)="CQ"),IFERROR(I28/_xll.SNL.Clients.Office.Excel.Functions.SPG($E$5,$C28,LEFT(I$27,3)&(RIGHT(I$27,4)-1),$E$11,_xll.SNL.Clients.Office.Excel.Functions.SPGOPTIONS("DataType",$E$23,"Src",$AI$40,"Mag",$AG$33,"Curr",$AL$1,"NA",""))-1,"-"),"-"))} -> 0.17872504 | J29: {=IF(OR(LEFT($E$8,2)="FY",LEFT($E$8,2)="CY"),IFERROR(J28/I28-1,"-"),IF(OR(LEFT($E$8,2)="FQ",LEFT($E$8,2)="CQ"),IFERROR(J28/_xll.SNL.Clients.Office.Excel.Functions.SPG($E$5,$C28,LEFT(J$27,3)&(RIGHT(J$27,4)-1),$E$11,_xll.SNL.Clients.Office.Excel.Functions.SPGOPTIONS("DataType",$E$23,"Src",$AI$40,"Mag",$AG$33,"Curr",$AL$1,"NA",""))-1,"-"),"-"))} -> 0.19555446 | K29: {=IF(OR(LEFT($E$8,2)="FY",LEFT($E$8,2)="CY"),IFERROR(K28/J28-1,"-"),IF(OR(LEFT($E$8,2)="FQ",LEFT($E$8,2)="CQ"),IFERROR(K28/_xll.SNL.Clients.Office.Excel.Functions.SPG($E$5,$C28,LEFT(K$27,3)&(RIGHT(K$27,4)-1),$E$11,_xll.SNL.Clients.Office.Excel.Functions.SPGOPTIONS("DataType",$E$23,"Src",$AI$40,"Mag",$AG$33,"Curr",$AL$1,"NA",""))-1,"-"),"-"))} -> 0.21663657 | AB29: Operating margin | AC29: =IF(OR(VLOOKUP($AB29,$C$28:$K$61,AC$5,0)="-",VLOOKUP($AB29,$C$28:$K$61,AC$5,0)=0),NA(),VLOOKUP($AB29,$C$28:$K$61,AC$5,0)) -> 0.42325461 | AD29: =IF(OR(VLOOKUP($AB29,$C$28:$K$61,AD$5,0)="-",VLOOKUP($AB29,$C$28:$K$61,AD$5,0)=0),NA(),VLOOKUP($AB29,$C$28:$K$61,AD$5,0)) -> 0.446443 | AE29: =IF(OR(VLOOKUP($AB29,$C$28:$K$61,AE$5,0)="-",VLOOKUP($AB29,$C$28:$K$61,AE$5,0)=0),NA(),VLOOKUP($AB29,$C$28:$K$61,AE$5,0)) -> 0.45621956 | AF29: =IF(OR(VLOOKUP($AB29,$C$28:$K$61,AF$5,0)="-",VLOOKUP($AB29,$C$28:$K$61,AF$5,0)=0),NA(),VLOOKUP($AB29,$C$28:$K$61,AF$5,0)) -> 0.46780594 | AG29: =IF(OR(VLOOKUP($AB29,$C$28:$K$61,AG$5,0)="-",VLOOKUP($AB29,$C$28:$K$61,AG$5,0)=0),NA(),VLOOKUP($AB29,$C$28:$K$61,AG$5,0)) -> 0.46439393 | AH29: =IF(OR(VLOOKUP($AB29,$C$28:$K$61,AH$5,0)="-",VLOOKUP($AB29,$C$28:$K$61,AH$5,0)=0),NA(),VLOOKUP($AB29,$C$28:$K$61,AH$5,0)) -> 0.46258442 | AI29: =IF(OR(VLOOKUP($AB29,$C$28:$K$61,AI$5,0)="-",VLOOKUP($AB29,$C$28:$K$61,AI$5,0)=0),NA(),VLOOKUP($AB29,$C$28:$K$61,AI$5,0)) -> 0.46421321 | AK29: Danish Krone | AL29: DKK | AM29: Dkr | AN29: 000
B30: Gross Profit | C30: Gross Profit / (loss) | E30: {=_xll.SNL.Clients.Office.Excel.Functions.SPG($E$5,$C30,E$27,$E$11,_xll.SNL.Clients.Office.Excel.Functions.SPGOPTIONS("DataType",$E$23,"Src",$AI$40,"Mag",$AG$33,"Curr",$AL$1,"NA",""))} -> 146052 | F30: {=_xll.SNL.Clients.Office.Excel.Functions.SPG($E$5,$C30,F$27,$E$11,_xll.SNL.Clients.Office.Excel.Functions.SPGOPTIONS("DataType",$E$23,"Src",$AI$40,"Mag",$AG$33,"Curr",$AL$1,"NA",""))} -> 171008 | G30: {=_xll.SNL.Clients.Office.Excel.Functions.SPG($E$5,$C30,G$27,$E$11,_xll.SNL.Clients.Office.Excel.Functions.SPGOPTIONS("DataType",$E$23,"Src",$AI$40,"Mag",$AG$33,"Curr",$AL$1,"NA",""))} -> 193893 | H30: {=_xll.SNL.Clients.Office.Excel.Functions.SPG($E$5,$C30,H$27,$E$11,_xll.SNL.Clients.Office.Excel.Functions.SPGOPTIONS("DataType",$E$23,"Src",$AI$40,"Mag",$AG$33,"Curr",$AL$1,"NA",""))} -> 225465 | I30: {=_xll.SNL.Clients.Office.Excel.Functions.SPG($E$5,$C30,I$27,$E$11,_xll.SNL.Clients.Office.Excel.Functions.SPGOPTIONS("DataType",$E$23,"Src",$AI$40,"Mag",$AG$33,"Curr",$AL$1,"NA",""))} -> 258531.28 | J30: {=_xll.SNL.Clients.Office.Excel.Functions.SPG($E$5,$C30,J$27,$E$11,_xll.SNL.Clients.Office.Excel.Functions.SPGOPTIONS("DataType",$E$23,"Src",$AI$40,"Mag",$AG$33,"Curr",$AL$1,"NA",""))} -> 303584.18 | K30: {=_xll.SNL.Clients.Office.Excel.Functions.SPG($E$5,$C30,K$27,$E$11,_xll.SNL.Clients.Office.Excel.Functions.SPGOPTIONS("DataType",$E$23,"Src",$AI$40,"Mag",$AG$33,"Curr",$AL$1,"NA",""))} -> 363586.46 | AB30: EBITDA margin | AC30: =IF(OR(VLOOKUP($AB30,$C$28:$K$61,AC$5,0)="-",VLOOKUP($AB30,$C$28:$K$61,AC$5,0)=0),NA(),VLOOKUP($AB30,$C$28:$K$61,AC$5,0)) -> 0.48866291 | AD30: =IF(OR(VLOOKUP($AB30,$C$28:$K$61,AD$5,0)="-",VLOOKUP($AB30,$C$28:$K$61,AD$5,0)=0),NA(),VLOOKUP($AB30,$C$28:$K$61,AD$5,0)) -> 0.53736507 | AE30: =IF(OR(VLOOKUP($AB30,$C$28:$K$61,AE$5,0)="-",VLOOKUP($AB30,$C$28:$K$61,AE$5,0)=0),NA(),VLOOKUP($AB30,$C$28:$K$61,AE$5,0)) -> 0.57744814 | AF30: =IF(OR(VLOOKUP($AB30,$C$28:$K$61,AF$5,0)="-",VLOOKUP($AB30,$C$28:$K$61,AF$5,0)=0),NA(),VLOOKUP($AB30,$C$28:$K$61,AF$5,0)) -> 0.59873745 | AG30: =IF(OR(VLOOKUP($AB30,$C$28:$K$61,AG$5,0)="-",VLOOKUP($AB30,$C$28:$K$61,AG$5,0)=0),NA(),VLOOKUP($AB30,$C$28:$K$61,AG$5,0)) -> 0.60872105 | AH30: =IF(OR(VLOOKUP($AB30,$C$28:$K$61,AH$5,0)="-",VLOOKUP($AB30,$C$28:$K$61,AH$5,0)=0),NA(),VLOOKUP($AB30,$C$28:$K$61,AH$5,0)) -> 0.61717467 | AI30: =IF(OR(VLOOKUP($AB30,$C$28:$K$61,AI$5,0)="-",VLOOKUP($AB30,$C$28:$K$61,AI$5,0)=0),NA(),VLOOKUP($AB30,$C$28:$K$61,AI$5,0)) -> 0.63279551 | AK30: Dominican Peso | AL30: DOP | AM30: RD$ | AN30: 000
B31: SG&A | C31: Selling, general and administrative expenses | E31: {=_xll.SNL.Clients.Office.Excel.Functions.SPG($E$5,$C31,E$27,$E$11,_xll.SNL.Clients.Office.Excel.Functions.SPGOPTIONS("DataType",$E$23,"Src",$AI$40,"Mag",$AG$33,"Curr",$AL$1,"NA",""))} -> 30334 | F31: {=_xll.SNL.Clients.Office.Excel.Functions.SPG($E$5,$C31,F$27,$E$11,_xll.SNL.Clients.Office.Excel.Functions.SPGOPTIONS("DataType",$E$23,"Src",$AI$40,"Mag",$AG$33,"Curr",$AL$1,"NA",""))} -> 32065 | G31: {=_xll.SNL.Clients.Office.Excel.Functions.SPG($E$5,$C31,G$27,$E$11,_xll.SNL.Clients.Office.Excel.Functions.SPGOPTIONS("DataType",$E$23,"Src",$AI$40,"Mag",$AG$33,"Curr",$AL$1,"NA",""))} -> 32877 | H31: {=_xll.SNL.Clients.Office.Excel.Functions.SPG($E$5,$C31,H$27,$E$11,_xll.SNL.Clients.Office.Excel.Functions.SPGOPTIONS("DataType",$E$23,"Src",$AI$40,"Mag",$AG$33,"Curr",$AL$1,"NA",""))} -> 26710 | I31: {=_xll.SNL.Clients.Office.Excel.Functions.SPG($E$5,$C31,I$27,$E$11,_xll.SNL.Clients.Office.Excel.Functions.SPGOPTIONS("DataType",$E$23,"Src",$AI$40,"Mag",$AG$33,"Curr",$AL$1,"NA",""))} -> 37250.704 | J31: {=_xll.SNL.Clients.Office.Excel.Functions.SPG($E$5,$C31,J$27,$E$11,_xll.SNL.Clients.Office.Excel.Functions.SPGOPTIONS("DataType",$E$23,"Src",$AI$40,"Mag",$AG$33,"Curr",$AL$1,"NA",""))} -> 41663.245 | K31: {=_xll.SNL.Clients.Office.Excel.Functions.SPG($E$5,$C31,K$27,$E$11,_xll.SNL.Clients.Office.Excel.Functions.SPGOPTIONS("DataType",$E$23,"Src",$AI$40,"Mag",$AG$33,"Curr",$AL$1,"NA",""))} -> 47095.314 | AB31: Net margin | AC31: =IF(OR(VLOOKUP($AB31,$C$28:$K$61,AC$5,0)="-",VLOOKUP($AB31,$C$28:$K$61,AC$5,0)=0),NA(),VLOOKUP($AB31,$C$28:$K$61,AC$5,0)) -> 0.3459248 | AD31: =IF(OR(VLOOKUP($AB31,$C$28:$K$61,AD$5,0)="-",VLOOKUP($AB31,$C$28:$K$61,AD$5,0)=0),NA(),VLOOKUP($AB31,$C$28:$K$61,AD$5,0)) -> 0.35955973 | AE31: =IF(OR(VLOOKUP($AB31,$C$28:$K$61,AE$5,0)="-",VLOOKUP($AB31,$C$28:$K$61,AE$5,0)=0),NA(),VLOOKUP($AB31,$C$28:$K$61,AE$5,0)) -> 0.37430961 | AF31: =IF(OR(VLOOKUP($AB31,$C$28:$K$61,AF$5,0)="-",VLOOKUP($AB31,$C$28:$K$61,AF$5,0)=0),NA(),VLOOKUP($AB31,$C$28:$K$61,AF$5,0)) -> 0.38809784 | AG31: =IF(OR(VLOOKUP($AB31,$C$28:$K$61,AG$5,0)="-",VLOOKUP($AB31,$C$28:$K$61,AG$5,0)=0),NA(),VLOOKUP($AB31,$C$28:$K$61,AG$5,0)) -> 0.37527446 | AH31: =IF(OR(VLOOKUP($AB31,$C$28:$K$61,AH$5,0)="-",VLOOKUP($AB31,$C$28:$K$61,AH$5,0)=0),NA(),VLOOKUP($AB31,$C$28:$K$61,AH$5,0)) -> 0.37338368 | AI31: =IF(OR(VLOOKUP($AB31,$C$28:$K$61,AI$5,0)="-",VLOOKUP($AB31,$C$28:$K$61,AI$5,0)=0),NA(),VLOOKUP($AB31,$C$28:$K$61,AI$5,0)) -> 0.37335807 | AK31: Egyptian Pound | AL31: EGP | AM31: £E. | AN31: 000
