Workbook

Sheet Cover
B2: Grupo Bimbo, S.A.B. de C.V. (BIMBOA)
B4: Accounting framework | C4: IFRS
B5: Currency and units | C5: MXN millions
B6: Historical years | C6: 2021-2025
B7: Forecast years | C7: 2026-2035
B8: Model file | C8: BIMBOA_model_v7.xlsx
B9: Version | C9: 7
B10: Built on | C10: 2026-10-17
B12: Model status (live) | C12: =IF(COUNTIF(Checks!$C$6:$Q$32,"ERROR")>0,"CHECKS FAILING",IF(COUNTIF(Checks!$C$6:$Q$32,"WARN")>0,"OK WITH WARNINGS","ALL CHECKS OK"))
B13: Status computed by Python at build | C13: ALL CHECKS OK
B15: How to read this model | C15: Blue = input or reported figure (hover a reported figure for its source); black = formula; green = link to another sheet.
C16: Interest is charged on opening balances, so the model has no circular references.
C17: A revolving credit line keeps cash at or above the minimum cash balance.
C18: Value per share is at the last fiscal year-end rolled forward to today at the cost of equity; the 12-month target rolls it one more year and subtracts next year's dividend.

Sheet Drivers
B1: Grupo Bimbo, S.A.B. de C.V. (BIMBOA) - Drivers and assumptions
B2: MXN millions | A = actual, E = estimate | blue = input, black = formula, green = link to another sheet
C4: 2021 | D4: 2022 | E4: 2023 | F4: 2024 | G4: 2025 | H4: 2026 | I4: 2027 | J4: 2028 | K4: 2029 | L4: 2030 | M4: 2031 | N4: 2032 | O4: 2033 | P4: 2034 | Q4: 2035
B6: Operating drivers | R6: Tag | S6: Rationale | T6: Thesis pillar
B7: Revenue growth | D7: =IS!D7/IS!C7-1 | E7: =IS!E7/IS!D7-1 | F7: =IS!F7/IS!E7-1 | G7: =IS!G7/IS!F7-1 | H7: =G7 | I7: =G7 | J7: =G7 | K7: =G7 | L7: =G7 | M7: =G7 | N7: =G7 | O7: =G7 | P7: =G7 | Q7: =G7 | R7: assumption | S7: engine default: held at last actual
B8: Gross margin | C8: =IS!C9/IS!C7 | D8: =IS!D9/IS!D7 | E8: =IS!E9/IS!E7 | F8: =IS!F9/IS!F7 | G8: =IS!G9/IS!G7 | H8: 0.524 | I8: 0.52 | J8: 0.523 | K8: 0.525 | L8: 0.525 | M8: 0.525 | N8: 0.525 | O8: 0.525 | P8: 0.525 | Q8: 0.525 | R8: assumption | S8: STORY DRIVER (proposal; climate pillar). History 53.4/51.5/51.4/52.6/52.3% (FY21-25, model mapping). 1H26 ~52.6% on the model basis (CIQ 52.9% less the 0.33pp mapping gap) [calc]. CBOT wheat 2026 YTD average +17% vs 2025 and gross margin follows wheat with ~1-year lag (r = -0.74, n = 9; wiki bimbo-climate-metrics-capiq-2026-10) -> FY27 dip of 40bp, recovery to 52.5% [assumption]. | T8: Pillar 1
B9: Operating expenses / revenue | C9: =IS!C10/IS!C7 | D9: =IS!D10/IS!D7 | E9: =IS!E10/IS!E7 | F9: =IS!F10/IS!F7 | G9: =IS!G10/IS!G7 | H9: 0.436 | I9: 0.434 | J9: 0.433 | K9: 0.4325 | L9: 0.4305 | M9: 0.4305 | N9: 0.4305 | O9: 0.4305 | P9: 0.4305 | Q9: 0.4305 | R9: assumption | S9: STORY DRIVER (proposal; new-CEO pillar). Set so model EBITDA margin = 14.7% FY26 (FY25 13.8% + ~90bp, mid of the +70-120bp guidance raised on 2026-07-23 [guidance] 2Q26 call), 14.5% FY27 (wheat lag), then +20bp/yr productivity to 15.3% by FY30. Includes restructuring at a run-rate (FY24 6,293; FY25 3,908). History 43.8/38.0/42.5/44.5/44.4%. | T9: Pillar 2
B10: D&A / revenue | C10: =IS!C24/IS!C7 | D10: =IS!D24/IS!D7 | E10: =IS!E24/IS!E7 | F10: =IS!F24/IS!F7 | G10: =IS!G24/IS!G7 | H10: 0.059 | I10: 0.059 | J10: 0.059 | K10: 0.0585 | L10: 0.0585 | M10: 0.0585 | N10: 0.0585 | O10: 0.0585 | P10: 0.0585 | Q10: 0.0585 | R10: assumption | S10: Mechanical: FY24-FY25 5.65-5.82% incl. right-of-use depreciation (6,142 in FY25); held near 5.85-5.9% as capex normalises [calc] data/financials.csv.
B11: Amortization of intangibles / revenue (part of D&A) | H11: 0 | I11: 0 | J11: 0 | K11: 0 | L11: 0 | M11: 0 | N11: 0 | O11: 0 | P11: 0 | Q11: 0 | R11: assumption | S11: Intangible amortisation not split out in data/financials.csv; 0 keeps all D&A in the PP&E roll-forward. No effect on FCFF or EBITDA.
B12: Capex / revenue | C12: =CF!C13/IS!C7 | D12: =CF!D13/IS!D7 | E12: =CF!E13/IS!E7 | F12: =CF!F13/IS!F7 | G12: =CF!G13/IS!G7 | H12: 0.046 | I12: 0.05 | J12: 0.052 | K12: 0.054 | L12: 0.055 | M12: 0.056 | N12: 0.057 | O12: 0.058 | P12: 0.059 | Q12: 0.06 | R12: assumption | S12: STORY DRIVER (proposal; debt/FCF pillar). FY26 = guidance US$1.0-1.2bn (cut on 2026-07-23 [guidance]) at ~Ps 17.6/US$ = ~Ps 19.4bn = 4.6% of revenue; FY27-28 ~5.0-5.2% (consensus capex US$1.21-1.24bn [sourced] CIQ 2026-10-17). Rises to 6.0% by FY35 [assumption] (history 6.3/7.4/8.9/7.4/5.4%, FY21-25 average 7.0%). On the published basis (lease book grows with revenue) total terminal net reinvestment is 29% of NOPAT and the return on new capital implied by the terminal value is 14.6% (engine basis 17.9%); each 50 bp of capex = Ps 9.44 per share (valuation/BIMBOA_DCF_v3.xlsx, Levers). Benchmarks [calc] valuation/BIMBOA_PeerAnalysis_v3.xlsx: peers' consensus capex / revenue 3.66/3.82/3.79% (FY1-FY3), Bimbo consensus 5.16/5.02/4.90% (FY2026-28); the company's impairment tests assume 3.3-4.3% (RA25 p.265, continuity capex). The terminal level is the team's decision (valuation/valuation.md section 11). | T12: Pillar 3
B13: Lease principal paid / revenue | C13: =IF(IS!C7<>0,CF!C19/IS!C7,0) | D13: =IF(IS!D7<>0,CF!D19/IS!D7,0) | E13: =IF(IS!E7<>0,CF!E19/IS!E7,0) | F13: =IF(IS!F7<>0,CF!F19/IS!F7,0) | G13: =IF(IS!G7<>0,CF!G19/IS!G7,0) | H13: 0.0139 | I13: 0.0139 | J13: 0.0139 | K13: 0.0139 | L13: 0.0139 | M13: 0.0139 | N13: 0.0139 | O13: 0.0139 | P13: 0.0139 | Q13: 0.0139 | R13: assumption | S13: Mechanical: FY25 lease principal 5,923 / revenue 426,952 = 1.39% (FY23-25: 1.20/1.30/1.39%) [calc]. Principal is derived (payments 8,060 less lease interest 2,137) and tagged calc in data/financials.csv: the filings do not split the cash interest inside lease payments (data/adjustments.md #6). The engine also uses it as new leases, which keeps the lease liability flat; the published basis in valuation/BIMBOA_DCF_v3.xlsx adds the growth in the lease liability (held at the FY2025 8.15% of revenue).
B14: Receivable days (DSO) | C14: =BS!C8/IS!C7*365 | D14: =BS!D8/IS!D7*365 | E14: =BS!E8/IS!E7*365 | F14: =BS!F8/IS!F7*365 | G14: =BS!G8/IS!G7*365 | H14: 20.3 | I14: 20.3 | J14: 20.3 | K14: 20.3 | L14: 20.3 | M14: 20.3 | N14: 20.3 | O14: 20.3 | P14: 20.3 | Q14: 20.3 | R14: assumption | S14: Mechanical: FY25 20.3 days (FY21-25 range 19.4-21.1) on trade receivables only [calc].
B15: Inventory days (DIO) | C15: =IF(IS!C8<>0,BS!C9*365/IS!C8,0) | D15: =IF(IS!D8<>0,BS!D9*365/IS!D8,0) | E15: =IF(IS!E8<>0,BS!E9*365/IS!E8,0) | F15: =IF(IS!F8<>0,BS!F9*365/IS!F8,0) | G15: =IF(IS!G8<>0,BS!G9*365/IS!G8,0) | H15: 30.8 | I15: 30.8 | J15: 30.8 | K15: 30.8 | L15: 30.8 | M15: 30.8 | N15: 30.8 | O15: 30.8 | P15: 30.8 | Q15: 30.8 | R15: assumption | S15: Mechanical: FY25 30.8 days on cost of sales (FY21-25 range 30.3-35.5) [calc].
B16: Payable days (DPO) | C16: =IF(IS!C8<>0,BS!C18*365/IS!C8,0) | D16: =IF(IS!D8<>0,BS!D18*365/IS!D8,0) | E16: =IF(IS!E8<>0,BS!E18*365/IS!E8,0) | F16: =IF(IS!F8<>0,BS!F18*365/IS!F8,0) | G16: =IF(IS!G8<>0,BS!G18*365/IS!G8,0) | H16: 70.1 | I16: 70.1 | J16: 70.1 | K16: 70.1 | L16: 70.1 | M16: 70.1 | N16: 70.1 | O16: 70.1 | P16: 70.1 | Q16: 70.1 | R16: assumption | S16: Mechanical: FY25 70.1 days on cost of sales; held flat, not rebuilt to the 75-83 days of FY21-24 (rising payables would flatter cash flow) [calc].
B17: Other current assets / revenue | C17: =BS!C10/IS!C7 | D17: =BS!D10/IS!D7 | E17: =BS!E10/IS!E7 | F17: =BS!F10/IS!F7 | G17: =BS!G10/IS!G7 | H17: 0.03563 | I17: 0.035486 | J17: 0.035352 | K17: 0.035224 | L17: 0.0351 | M17: 0.034983 | N17: 0.034872 | O17: 0.034766 | P17: 0.034666 | Q17: 0.03457 | R17: assumption | S17: Mechanical, operating part only grows: FY25 other current assets 15,201 = operating 13,796 (other receivables 11,998 + prepayments 1,798; 3.23% of revenue) + non-operating 1,405 (derivatives 60, collateral 459, held-for-sale 886) held flat in pesos so they create no FCFF [calc] data/adjustments.md working-capital table (Codex audit 2026-10-17, finding 1).
B18: Other current liabilities / revenue | C18: =BS!C19/IS!C7 | D18: =BS!D19/IS!D7 | E18: =BS!E19/IS!E7 | F18: =BS!F19/IS!F7 | G18: =BS!G19/IS!G7 | H18: 0.074643 | I18: 0.073628 | J18: 0.072684 | K18: 0.071777 | L18: 0.070906 | M18: 0.070082 | N18: 0.069299 | O18: 0.068555 | P18: 0.067848 | Q18: 0.067173 | R18: assumption | S18: Mechanical, operating part only grows: FY25 other current liabilities 31,788 = operating 21,889 (related-party payables 1,154 + PTU 1,592 + operating accruals 19,143; 5.13% of revenue) + non-operating 9,899 (income and other taxes, tax contributions, accrued interest, derivatives) held flat in pesos [calc] data/adjustments.md #9 and working-capital table (Codex audit finding 1).
B19: Effective tax rate | C19: =IF(IS!C15>0,IS!C16/IS!C15,0) | D19: =IF(IS!D15>0,IS!D16/IS!D15,0) | E19: =IF(IS!E15>0,IS!E16/IS!E15,0) | F19: =IF(IS!F15>0,IS!F16/IS!F15,0) | G19: =IF(IS!G15>0,IS!G16/IS!G15,0) | H19: 0.34 | I19: 0.34 | J19: 0.34 | K19: 0.34 | L19: 0.34 | M19: 0.34 | N19: 0.34 | O19: 0.34 | P19: 0.34 | Q19: 0.34 | R19: assumption | S19: Effective (not marginal) rate: FY23-25 33.1/32.6/35.7%, 1H26 ~37% [calc]; statutory 30% plus non-deductibles and loss-making units. The WACC uses the 30% marginal rate separately.
B20: Interest rate on opening debt | D20: =IF(BS!C33<>0,IS!D12/BS!C33,0) | E20: =IF(BS!D33<>0,IS!E12/BS!D33,0) | F20: =IF(BS!E33<>0,IS!F12/BS!E33,0) | G20: =IF(BS!F33<>0,IS!G12/BS!F33,0) | H20: 0.077 | I20: 0.077 | J20: 0.077 | K20: 0.077 | L20: 0.077 | M20: 0.077 | N20: 0.077 | O20: 0.077 | P20: 0.077 | Q20: 0.077 | R20: assumption | S20: Mechanical: FY25 interest expense 14,464 / opening debt incl. leases 186,706 = 7.75% [calc]; consistent with the 6.5% average cost of financial debt plus lease interest.
B21: Interest rate on opening cash | D21: =IF(BS!C7<>0,IS!D13/BS!C7,0) | E21: =IF(BS!D7<>0,IS!E13/BS!D7,0) | F21: =IF(BS!E7<>0,IS!F13/BS!E7,0) | G21: =IF(BS!F7<>0,IS!G13/BS!F7,0) | H21: 0.1 | I21: 0.1 | J21: 0.1 | K21: 0.1 | L21: 0.1 | M21: 0.1 | N21: 0.1 | O21: 0.1 | P21: 0.1 | Q21: 0.1 | R21: assumption | S21: Mechanical: FY23-25 interest income / opening cash 6.6/14.5/11.1% (average 10.7%) [calc].
B22: Dividend payout ratio | C22: =IF(IS!C19>0,CF!C18/IS!C19,0) | D22: =IF(IS!D19>0,CF!D18/IS!D19,0) | E22: =IF(IS!E19>0,CF!E18/IS!E19,0) | F22: =IF(IS!F19>0,CF!F18/IS!F19,0) | G22: =IF(IS!G19>0,CF!G18/IS!G19,0) | H22: 0.38 | I22: 0.38 | J22: 0.38 | K22: 0.38 | L22: 0.38 | M22: 0.38 | N22: 0.38 | O22: 0.38 | P22: 0.38 | Q22: 0.38 | R22: assumption | S22: Proposal (debt pillar, hold): FY25 38.8%, FY24 32.9%; CFO said dividends and buybacks stay 'to the same extent' (2026-07-23 call) [guidance]. | T22: Pillar 3
B23: Non-controlling share of net income | C23: =IF(IS!C17<>0,IS!C18/IS!C17,0) | D23: =IF(IS!D17<>0,IS!D18/IS!D17,0) | E23: =IF(IS!E17<>0,IS!E18/IS!E17,0) | F23: =IF(IS!F17<>0,IS!F18/IS!F17,0) | G23: =IF(IS!G17<>0,IS!G18/IS!G17,0) | H23: 0.14 | I23: 0.14 | J23: 0.14 | K23: 0.14 | L23: 0.14 | M23: 0.14 | N23: 0.14 | O23: 0.14 | P23: 0.14 | Q23: 0.14 | R23: assumption | S23: Mechanical: FY25 14.0%, 1H26 14.6% (mostly consolidated BBU independent-operator structured entities) [calc]. Their market value is treated in valuation.yaml debt-like items.
B24: Net new long-term debt | D24: =BS!D23-BS!C23 | E24: =BS!E23-BS!D23 | F24: =BS!F23-BS!E23 | G24: =BS!G23-BS!F23 | H24: 0 | I24: 0 | J24: 0 | K24: 0 | L24: 0 | M24: 0 | N24: 0 | O24: 0 | P24: 0 | Q24: 0 | R24: assumption | S24: Proposal (debt pillar, hold): gross debt held flat; leverage falls with EBITDA growth. Management comfort range 2.0-2.5x net debt / EBITDA ex-IFRS 16 (reached 2.5x at Jun-26). | T24: Pillar 3
B25: Diluted share count growth | D25: =IS!D22/IS!C22-1 | E25: =IS!E22/IS!D22-1 | F25: =IS!F22/IS!E22-1 | G25: =IS!G22/IS!F22-1 | H25: 0 | I25: 0 | J25: 0 | K25: 0 | L25: 0 | M25: 0 | N25: 0 | O25: 0 | P25: 0 | Q25: 0 | R25: assumption | S25: Mechanical: no buyback programme size announced; 1H26 weighted shares flat vs FY25 [calc].
B26: Minimum cash balance | H26: 8500 | I26: 8500 | J26: 8500 | K26: 8500 | L26: 8500 | M26: 8500 | N26: 8500 | O26: 8500 | P26: 8500 | Q26: 8500 | R26: assumption | S26: Mechanical: FY25 closing cash 8,535 [sourced] data/financials.csv.
B28: Revenue segments
B29: North America growth | D29: =Schedules!D7/Schedules!C7-1 | E29: =Schedules!E7/Schedules!D7-1 | F29: =Schedules!F7/Schedules!E7-1 | G29: =Schedules!G7/Schedules!F7-1 | H29: -0.074 | I29: 0.03 | J29: 0.03 | K29: 0.03 | L29: 0.03 | M29: 0.03 | N29: 0.03 | O29: 0.03 | P29: 0.03 | Q29: 0.03 | R29: assumption | S29: STORY DRIVER (proposal). FY26 = 1H26 actual (84,901, -11.3% in MXN; ex-FX +0.7%/+1.3% in 1Q/2Q26) plus 2H26 at -3.5% (ex-FX +1.5%, peso about -5% vs 2H25) [calc] wiki quarterly trend. FY27+: USD growth ~+1.5% (category volume -2% to -4%, price/mix +1-2%, share gains claimed by management) plus ~1.5%/yr MXN depreciation (inflation differential) [assumption]. Alternatives in valuation/BIMBOA_DCF_v3.xlsx 'Scenarios': PPP at the 3%/2% inflation targets (0.98%/yr; Gordon -2.18 per share) or at Banxico survey inflation (1.67%/yr; +0.75); Sep-2026 CPI was 3.45% in Mexico vs 3.74% in the US [sourced] macro/macro-view.yaml. | T29: Pillar 2
B30: Mexico growth | D30: =Schedules!D8/Schedules!C8-1 | E30: =Schedules!E8/Schedules!D8-1 | F30: =Schedules!F8/Schedules!E8-1 | G30: =Schedules!G8/Schedules!F8-1 | H30: 0.046 | I30: 0.055 | J30: 0.0525 | K30: 0.0525 | L30: 0.0525 | M30: 0.0515 | N30: 0.051 | O30: 0.0505 | P30: 0.05 | Q30: 0.05 | R30: assumption | S30: STORY DRIVER (proposal). FY26 = 1H26 +4.6% and 2H26 +4.7% (1Q26 +4.5%, 2Q26 +4.7%) [calc]. FY27+: packaged bakery market ~3.5% value CAGR 2024-29E (RA25 p.111) plus price/mix with ~3.5-3.8% inflation; fades to 5.0% (long-run nominal) [assumption]. | T30: Pillar 2
B31: Europe, Asia & Africa growth | D31: =Schedules!D9/Schedules!C9-1 | E31: =Schedules!E9/Schedules!D9-1 | F31: =Schedules!F9/Schedules!E9-1 | G31: =Schedules!G9/Schedules!F9-1 | H31: 0.006 | I31: 0.045 | J31: 0.045 | K31: 0.045 | L31: 0.045 | M31: 0.0445 | N31: 0.044 | O31: 0.0435 | P31: 0.043 | Q31: 0.0425 | R31: assumption | S31: Proposal. FY26 = 1H26 +1.3% in MXN (ex-FX +12.6%/+8.4% incl. 2025 bolt-ons) with flat 2H26 after FX [calc]. FY27+: organic ~4.5% (European market 3.4%, Eastern Europe 6.6% CAGR per RA25 p.108), no new M&A [assumption].
B32: Latin America growth | D32: =Schedules!D10/Schedules!C10-1 | E32: =Schedules!E10/Schedules!D10-1 | F32: =Schedules!F10/Schedules!E10-1 | G32: =Schedules!G10/Schedules!F10-1 | H32: 0.085 | I32: 0.07 | J32: 0.065 | K32: 0.065 | L32: 0.065 | M32: 0.063 | N32: 0.061 | O32: 0.059 | P32: 0.057 | Q32: 0.055 | R32: assumption | S32: Proposal. FY26 = 1H26 +7.1% plus 2H26 ~+10% (Wickbold consolidated from Oct-2025) [calc]. FY27+: LatAm bakery 5.5% CAGR (RA25 p.108) plus Wickbold synergies, fading to 5.5% [assumption].
B33: Inter-regional eliminations growth | D33: =Schedules!D11/Schedules!C11-1 | E33: =Schedules!E11/Schedules!D11-1 | F33: =Schedules!F11/Schedules!E11-1 | G33: =Schedules!G11/Schedules!F11-1 | H33: 0.036 | I33: 0.045 | J33: 0.045 | K33: 0.045 | L33: 0.045 | M33: 0.045 | N33: 0.045 | O33: 0.045 | P33: 0.045 | Q33: 0.045 | R33: assumption | S33: Mechanical: inter-regional eliminations grow with regional sales (1H26 eliminations -8,545 vs -8,202 in 1H25, +4.2%) [calc].

Sheet IS
B1: Grupo Bimbo, S.A.B. de C.V. (BIMBOA) - Income statement
B2: MXN millions | A = actual, E = estimate | blue = input, black = formula, green = link to another sheet
C4: 2021 | D4: 2022 | E4: 2023 | F4: 2024 | G4: 2025 | H4: 2026 | I4: 2027 | J4: 2028 | K4: 2029 | L4: 2030 | M4: 2031 | N4: 2032 | O4: 2033 | P4: 2034 | Q4: 2035
B6: Income statement
B7: Revenue | C7: 338792 | D7: 398706 | E7: 399879 | F7: 408335 | G7: 426952 | H7: =SUM(Schedules!H7,Schedules!H8,Schedules!H9,Schedules!H10,Schedules!H11) | I7: =SUM(Schedules!I7,Schedules!I8,Schedules!I9,Schedules!I10,Schedules!I11) | J7: =SUM(Schedules!J7,Schedules!J8,Schedules!J9,Schedules!J10,Schedules!J11) | K7: =SUM(Schedules!K7,Schedules!K8,Schedules!K9,Schedules!K10,Schedules!K11) | L7: =SUM(Schedules!L7,Schedules!L8,Schedules!L9,Schedules!L10,Schedules!L11) | M7: =SUM(Schedules!M7,Schedules!M8,Schedules!M9,Schedules!M10,Schedules!M11) | N7: =SUM(Schedules!N7,Schedules!N8,Schedules!N9,Schedules!N10,Schedules!N11) | O7: =SUM(Schedules!O7,Schedules!O8,Schedules!O9,Schedules!O10,Schedules!O11) | ... Q7: =SUM(Schedules!Q7,Schedules!Q8,Schedules!Q9,Schedules!Q10,Schedules!Q11)
B8: Cost of sales | C8: 157703 | D8: 193325 | E8: 194369 | F8: 193407 | G8: 203465 | H8: =H7*(1-Drivers!H8) | I8: =I7*(1-Drivers!I8) | J8: =J7*(1-Drivers!J8) | K8: =K7*(1-Drivers!K8) | L8: =L7*(1-Drivers!L8) | M8: =M7*(1-Drivers!M8) | N8: =N7*(1-Drivers!N8) | O8: =O7*(1-Drivers!O8) | ... Q8: =Q7*(1-Drivers!Q8)
B9: Gross profit | C9: =C7-C8 | D9: =D7-D8 | E9: =E7-E8 | F9: =F7-F8 | G9: =G7-G8 | H9: =H7-H8 | I9: =I7-I8 | J9: =J7-J8 | ... Q9: =Q7-Q8
B10: Operating expenses (net) | C10: 148509 | D10: 151685 | E10: 170055 | F10: 181779 | G10: 189341 | H10: =H7*Drivers!H9 | I10: =I7*Drivers!I9 | J10: =J7*Drivers!J9 | K10: =K7*Drivers!K9 | L10: =L7*Drivers!L9 | M10: =M7*Drivers!M9 | N10: =N7*Drivers!N9 | O10: =O7*Drivers!O9 | ... Q10: =Q7*Drivers!Q9
B11: EBIT | C11: =C9-C10 | D11: =D9-D10 | E11: =E9-E10 | F11: =F9-F10 | G11: =G9-G10 | H11: =H9-H10 | I11: =I9-I10 | J11: =J9-J10 | ... Q11: =Q9-Q10
B12: Interest expense | C12: 7823 | D12: 8049 | E12: 10006 | F12: 13100 | G12: 14464 | H12: =Schedules!H36 | I12: =Schedules!I36 | J12: =Schedules!J36 | K12: =Schedules!K36 | L12: =Schedules!L36 | M12: =Schedules!M36 | N12: =Schedules!N36 | O12: =Schedules!O36 | ... Q12: =Schedules!Q36
B13: Interest income | C13: 363 | D13: 740 | E13: 809 | F13: 924 | G13: 897 | H13: =Drivers!H21*BS!G7 | I13: =Drivers!I21*BS!H7 | J13: =Drivers!J21*BS!I7 | K13: =Drivers!K21*BS!J7 | L13: =Drivers!L21*BS!K7 | M13: =Drivers!M21*BS!L7 | N13: =Drivers!N21*BS!M7 | O13: =Drivers!O21*BS!N7 | ... Q13: =Drivers!Q21*BS!P7
B14: Other financial result, net | C14: 988 | D14: 16479 | E14: -950 | F14: -133 | G14: -436 | H14: 0 | I14: 0 | J14: 0 | K14: 0 | L14: 0 | M14: 0 | N14: 0 | O14: 0 | P14: 0 | Q14: 0 | R14: assumption: held at zero
B15: Pre-tax income | C15: =C11-C12+C13+C14 | D15: =D11-D12+D13+D14 | E15: =E11-E12+E13+E14 | F15: =F11-F12+F13+F14 | G15: =G11-G12+G13+G14 | H15: =H11-H12+H13+H14 | I15: =I11-I12+I13+I14 | J15: =J11-J12+J13+J14 | ... Q15: =Q11-Q12+Q13+Q14
B16: Income tax | C16: 8726 | D16: 14381 | E16: 8386 | F16: 6797 | G16: 7197 | H16: =H15*Drivers!H19 | I16: =I15*Drivers!I19 | J16: =J15*Drivers!J19 | K16: =K15*Drivers!K19 | L16: =L15*Drivers!L19 | M16: =M15*Drivers!M19 | N16: =N15*Drivers!N19 | O16: =O15*Drivers!O19 | ... Q16: =Q15*Drivers!Q19
B17: Net income | C17: =C15-C16 | D17: =D15-D16 | E17: =E15-E16 | F17: =F15-F16 | G17: =G15-G16 | H17: =H15-H16 | I17: =I15-I16 | J17: =J15-J16 | ... Q17: =Q15-Q16
B18: Attributable to non-controlling interests | C18: 1466 | D18: 1575 | E18: 1445 | F18: 1499 | G18: 1813 | H18: =H17*Drivers!H23 | I18: =I17*Drivers!I23 | J18: =J17*Drivers!J23 | K18: =K17*Drivers!K23 | L18: =L17*Drivers!L23 | M18: =M17*Drivers!M23 | N18: =N17*Drivers!N23 | O18: =O17*Drivers!O23 | ... Q18: =Q17*Drivers!Q23
B19: Net income to shareholders | C19: =C17-C18 | D19: =D17-D18 | E19: =E17-E18 | F19: =F17-F18 | G19: =G17-G18 | H19: =H17-H18 | I19: =I17-I18 | J19: =J17-J18 | ... Q19: =Q17-Q18
B21: Per share and memo
B22: Diluted shares | C22: 4487.268 | D22: 4448.693 | E22: 4418.137 | F22: 4357.25 | G22: 4310.531 | H22: =G22*(1+Drivers!H25) | I22: =H22*(1+Drivers!I25) | J22: =I22*(1+Drivers!J25) | K22: =J22*(1+Drivers!K25) | L22: =K22*(1+Drivers!L25) | M22: =L22*(1+Drivers!M25) | N22: =M22*(1+Drivers!N25) | O22: =N22*(1+Drivers!O25) | ... Q22: =P22*(1+Drivers!Q25)
B23: Diluted EPS | C23: =C19/C22 | D23: =D19/D22 | E23: =E19/E22 | F23: =F19/F22 | G23: =G19/G22 | H23: =H19/H22 | I23: =I19/I22 | J23: =J19/J22 | ... Q23: =Q19/Q22
B24: D&A (included in costs above) | C24: 16126 | D24: 18038 | E24: 18929 | F24: 23051 | G24: 24838 | H24: =H7*Drivers!H10 | I24: =I7*Drivers!I10 | J24: =J7*Drivers!J10 | K24: =K7*Drivers!K10 | L24: =L7*Drivers!L10 | M24: =M7*Drivers!M10 | N24: =N7*Drivers!N10 | O24: =O7*Drivers!O10 | ... Q24: =Q7*Drivers!Q10
B25: EBITDA (post-IFRS 16) | C25: =C11+C24 | D25: =D11+D24 | E25: =E11+E24 | F25: =F11+F24 | G25: =G11+G24 | H25: =H11+H24 | I25: =I11+I24 | J25: =J11+J24 | ... Q25: =Q11+Q24
B26: Net income as reported (check) | C26: 17382 | D26: 48485 | E26: 16922 | F26: 14043 | G26: 12946

Sheet BS
B1: Grupo Bimbo, S.A.B. de C.V. (BIMBOA) - Balance sheet
B2: MXN millions | A = actual, E = estimate | blue = input, black = formula, green = link to another sheet
C4: 2021 | D4: 2022 | E4: 2023 | F4: 2024 | G4: 2025 | H4: 2026 | I4: 2027 | J4: 2028 | K4: 2029 | L4: 2030 | M4: 2031 | N4: 2032 | O4: 2033 | P4: 2034 | Q4: 2035
B6: Assets
B7: Cash and equivalents | C7: 8748 | D7: 12313 | E7: 6353 | F7: 8057 | G7: 8535 | H7: =CF!H27 | I7: =CF!I27 | J7: =CF!J27 | K7: =CF!K27 | L7: =CF!L27 | M7: =CF!M27 | N7: =CF!N27 | O7: =CF!O27 | ... Q7: =CF!Q27
B8: Accounts receivable | C8: 19184 | D8: 21600 | E8: 21268 | F8: 23555 | G8: 23784 | H8: =Schedules!H25 | I8: =Schedules!I25 | J8: =Schedules!J25 | K8: =Schedules!K25 | L8: =Schedules!L25 | M8: =Schedules!M25 | N8: =Schedules!N25 | O8: =Schedules!O25 | ... Q8: =Schedules!Q25
B9: Inventories | C9: 13710 | D9: 16989 | E9: 16120 | F9: 18832 | G9: 17151 | H9: =Schedules!H26 | I9: =Schedules!I26 | J9: =Schedules!J26 | K9: =Schedules!K26 | L9: =Schedules!L26 | M9: =Schedules!M26 | N9: =Schedules!N26 | O9: =Schedules!O26 | ... Q9: =Schedules!Q26
B10: Other current assets | C10: 11769 | D10: 12568 | E10: 15173 | F10: 16736 | G10: 15201 | H10: =IS!H7*Drivers!H17 | I10: =IS!I7*Drivers!I17 | J10: =IS!J7*Drivers!J17 | K10: =IS!K7*Drivers!K17 | L10: =IS!L7*Drivers!L17 | M10: =IS!M7*Drivers!M17 | N10: =IS!N7*Drivers!N17 | O10: =IS!O7*Drivers!O17 | ... Q10: =IS!Q7*Drivers!Q17
B11: Total current assets | C11: =C7+C8+C9+C10 | D11: =D7+D8+D9+D10 | E11: =E7+E8+E9+E10 | F11: =F7+F8+F9+F10 | G11: =G7+G8+G9+G10 | H11: =H7+H8+H9+H10 | I11: =I7+I8+I9+I10 | J11: =J7+J8+J9+J10 | ... Q11: =Q7+Q8+Q9+Q10
B12: PP&E and right-of-use assets, net | C12: 134645 | D12: 141982 | E12: 155004 | F12: 189596 | G12: 190180 | H12: =Schedules!H22 | I12: =Schedules!I22 | J12: =Schedules!J22 | K12: =Schedules!K22 | L12: =Schedules!L22 | M12: =Schedules!M22 | N12: =Schedules!N22 | O12: =Schedules!O22 | ... Q12: =Schedules!Q22
B13: Intangibles and goodwill | C13: 131530 | D13: 127147 | E13: 117101 | F13: 140908 | G13: 135515 | H13: =G13-Schedules!H15 | I13: =H13-Schedules!I15 | J13: =I13-Schedules!J15 | K13: =J13-Schedules!K15 | L13: =K13-Schedules!L15 | M13: =L13-Schedules!M15 | N13: =M13-Schedules!N15 | O13: =N13-Schedules!O15 | ... Q13: =P13-Schedules!Q15
B14: Other non-current assets | C14: 18054 | D14: 15165 | E14: 17083 | F14: 19120 | G14: 19439 | H14: =G14 | I14: =H14 | J14: =I14 | K14: =J14 | L14: =K14 | M14: =L14 | N14: =M14 | O14: =N14 | ... Q14: =P14
B15: Total assets | C15: =C11+C12+C13+C14 | D15: =D11+D12+D13+D14 | E15: =E11+E12+E13+E14 | F15: =F11+F12+F13+F14 | G15: =G11+G12+G13+G14 | H15: =H11+H12+H13+H14 | I15: =I11+I12+I13+I14 | J15: =J11+J12+J13+J14 | ... Q15: =Q11+Q12+Q13+Q14
B17: Liabilities and equity
B18: Accounts payable | C18: 35752 | D18: 44058 | E18: 40409 | F18: 40815 | G18: 39074 | H18: =Schedules!H27 | I18: =Schedules!I27 | J18: =Schedules!J27 | K18: =Schedules!K27 | L18: =Schedules!L27 | M18: =Schedules!M27 | N18: =Schedules!N27 | O18: =Schedules!O27 | ... Q18: =Schedules!Q27
B19: Other current liabilities | C19: 28590 | D19: 33311 | E19: 28100 | F19: 32338 | G19: 31788 | H19: =IS!H7*Drivers!H18 | I19: =IS!I7*Drivers!I18 | J19: =IS!J7*Drivers!J18 | K19: =IS!K7*Drivers!K18 | L19: =IS!L7*Drivers!L18 | M19: =IS!M7*Drivers!M18 | N19: =IS!N7*Drivers!N18 | O19: =IS!O7*Drivers!O18 | ... Q19: =IS!Q7*Drivers!Q18
B20: Short-term debt | C20: 10625 | D20: 6435 | E20: 12932 | F20: 4862 | G20: 12635 | H20: =G20 | I20: =H20 | J20: =I20 | K20: =J20 | L20: =K20 | M20: =L20 | N20: =M20 | O20: =N20 | ... Q20: =P20
B21: Revolving credit facility | C21: =0 | D21: =0 | E21: =0 | F21: =0 | G21: =0 | H21: =Schedules!H35 | I21: =Schedules!I35 | J21: =Schedules!J35 | K21: =Schedules!K35 | L21: =Schedules!L35 | M21: =Schedules!M35 | N21: =Schedules!N35 | O21: =Schedules!O35 | ... Q21: =Schedules!Q35
B22: Total current liabilities | C22: =C18+C19+C20+C21 | D22: =D18+D19+D20+D21 | E22: =E18+E19+E20+E21 | F22: =F18+F19+F20+F21 | G22: =G18+G19+G20+G21 | H22: =H18+H19+H20+H21 | I22: =I18+I19+I20+I21 | J22: =J18+J19+J20+J21 | ... Q22: =Q18+Q19+Q20+Q21
B23: Long-term debt | C23: 82230 | D23: 77619 | E23: 97003 | F23: 146043 | G23: 141028 | H23: =Schedules!H32 | I23: =Schedules!I32 | J23: =Schedules!J32 | K23: =Schedules!K32 | L23: =Schedules!L32 | M23: =Schedules!M32 | N23: =Schedules!N32 | O23: =Schedules!O32 | ... Q23: =Schedules!Q32
B24: Lease liabilities | C24: 31149 | D24: 29185 | E24: 26815 | F24: 35801 | G24: 34790 | H24: =G24 | I24: =H24 | J24: =I24 | K24: =J24 | L24: =K24 | M24: =L24 | N24: =M24 | O24: =N24 | ... Q24: =P24
B25: Other non-current liabilities | C25: 47688 | D25: 29554 | E25: 31215 | F25: 29247 | G25: 30235 | H25: =G25 | I25: =H25 | J25: =I25 | K25: =J25 | L25: =K25 | M25: =L25 | N25: =M25 | O25: =N25 | ... Q25: =P25
B26: Total liabilities | C26: =C22+C23+C24+C25 | D26: =D22+D23+D24+D25 | E26: =E22+E23+E24+E25 | F26: =F22+F23+F24+F25 | G26: =G22+G23+G24+G25 | H26: =H22+H23+H24+H25 | I26: =I22+I23+I24+I25 | J26: =J22+J23+J24+J25 | ... Q26: =Q22+Q23+Q24+Q25
B27: Shareholders' equity | C27: 97100 | D27: 124111 | E27: 108322 | F27: 125944 | G27: 119512 | H27: =G27+IS!H19-CF!H18 | I27: =H27+IS!I19-CF!I18 | J27: =I27+IS!J19-CF!J18 | K27: =J27+IS!K19-CF!K18 | L27: =K27+IS!L19-CF!L18 | M27: =L27+IS!M19-CF!M18 | N27: =M27+IS!N19-CF!N18 | O27: =N27+IS!O19-CF!O18 | ... Q27: =P27+IS!Q19-CF!Q18
B28: Non-controlling interests | C28: 4506 | D28: 3491 | E28: 3306 | F28: 1754 | G28: 743 | H28: =G28+IS!H18-CF!H20 | I28: =H28+IS!I18-CF!I20 | J28: =I28+IS!J18-CF!J20 | K28: =J28+IS!K18-CF!K20 | L28: =K28+IS!L18-CF!L20 | M28: =L28+IS!M18-CF!M20 | N28: =M28+IS!N18-CF!N20 | O28: =N28+IS!O18-CF!O20 | ... Q28: =P28+IS!Q18-CF!Q20
B29: Total equity | C29: =C27+C28 | D29: =D27+D28 | E29: =E27+E28 | F29: =F27+F28 | G29: =G27+G28 | H29: =H27+H28 | I29: =I27+I28 | J29: =J27+J28 | ... Q29: =Q27+Q28
B30: Total liabilities and equity | C30: =C26+C29 | D30: =D26+D29 | E30: =E26+E29 | F30: =F26+F29 | G30: =G26+G29 | H30: =H26+H29 | I30: =I26+I29 | J30: =J26+J29 | ... Q30: =Q26+Q29
B32: Memo
B33: Total debt incl. leases and revolver | C33: =C20+C21+C23+C24 | D33: =D20+D21+D23+D24 | E33: =E20+E21+E23+E24 | F33: =F20+F21+F23+F24 | G33: =G20+G21+G23+G24 | H33: =H20+H21+H23+H24 | I33: =I20+I21+I23+I24 | J33: =J20+J21+J23+J24 | ... Q33: =Q20+Q21+Q23+Q24
B34: Net debt | C34: =C33-C7 | D34: =D33-D7 | E34: =E33-E7 | F34: =F33-F7 | G34: =G33-G7 | H34: =H33-H7 | I34: =I33-I7 | J34: =J33-J7 | ... Q34: =Q33-Q7
B35: Total assets as reported (check) | C35: 337640 | D35: 347764 | E35: 348102 | F35: 416804 | G35: 409805

Sheet CF
B1: Grupo Bimbo, S.A.B. de C.V. (BIMBOA) - Cash flow statement
B2: MXN millions | A = actual, E = estimate | blue = input, black = formula, green = link to another sheet
C4: 2021 | D4: 2022 | E4: 2023 | F4: 2024 | G4: 2025 | H4: 2026 | I4: 2027 | J4: 2028 | K4: 2029 | L4: 2030 | M4: 2031 | N4: 2032 | O4: 2033 | P4: 2034 | Q4: 2035
B6: Operating activities
B7: Net income | H7: =IS!H17 | I7: =IS!I17 | J7: =IS!J17 | K7: =IS!K17 | L7: =IS!L17 | M7: =IS!M17 | N7: =IS!N17 | O7: =IS!O17 | ... Q7: =IS!Q17
B8: D&A | H8: =IS!H24 | I8: =IS!I24 | J8: =IS!J24 | K8: =IS!K24 | L8: =IS!L24 | M8: =IS!M24 | N8: =IS!N24 | O8: =IS!O24 | ... Q8: =IS!Q24
B9: Change in working capital | D9: =-(BS!D8-BS!C8+BS!D9-BS!C9+BS!D10-BS!C10-(BS!D18-BS!C18)-(BS!D19-BS!C19)) | E9: =-(BS!E8-BS!D8+BS!E9-BS!D9+BS!E10-BS!D10-(BS!E18-BS!D18)-(BS!E19-BS!D19)) | F9: =-(BS!F8-BS!E8+BS!F9-BS!E9+BS!F10-BS!E10-(BS!F18-BS!E18)-(BS!F19-BS!E19)) | G9: =-(BS!G8-BS!F8+BS!G9-BS!F9+BS!G10-BS!F10-(BS!G18-BS!F18)-(BS!G19-BS!F19)) | H9: =-(BS!H8-BS!G8+BS!H9-BS!G9+BS!H10-BS!G10-(BS!H18-BS!G18)-(BS!H19-BS!G19)) | I9: =-(BS!I8-BS!H8+BS!I9-BS!H9+BS!I10-BS!H10-(BS!I18-BS!H18)-(BS!I19-BS!H19)) | J9: =-(BS!J8-BS!I8+BS!J9-BS!I9+BS!J10-BS!I10-(BS!J18-BS!I18)-(BS!J19-BS!I19)) | K9: =-(BS!K8-BS!J8+BS!K9-BS!J9+BS!K10-BS!J10-(BS!K18-BS!J18)-(BS!K19-BS!J19)) | ... Q9: =-(BS!Q8-BS!P8+BS!Q9-BS!P9+BS!Q10-BS!P10-(BS!Q18-BS!P18)-(BS!Q19-BS!P19))
B10: Cash flow from operations | C10: 45776 | D10: 38851 | E10: 31411 | F10: 39907 | G10: 47753 | H10: =H7+H8+H9 | I10: =I7+I8+I9 | J10: =J7+J8+J9 | K10: =K7+K8+K9 | L10: =L7+L8+L9 | M10: =M7+M8+M9 | N10: =N7+N8+N9 | O10: =O7+O8+O9 | ... Q10: =Q7+Q8+Q9
B12: Investing activities
B13: Capital expenditures | C13: 21293 | D13: 29467 | E13: 35672 | F13: 30174 | G13: 22841 | H13: =IS!H7*Drivers!H12 | I13: =IS!I7*Drivers!I12 | J13: =IS!J7*Drivers!J12 | K13: =IS!K7*Drivers!K12 | L13: =IS!L7*Drivers!L12 | M13: =IS!M7*Drivers!M12 | N13: =IS!N7*Drivers!N12 | O13: =IS!O7*Drivers!O12 | ... Q13: =IS!Q7*Drivers!Q12
B14: Cash flow from investing | H14: =-H13 | I14: =-I13 | J14: =-J13 | K14: =-K13 | L14: =-L13 | M14: =-M13 | N14: =-N13 | O14: =-O13 | ... Q14: =-Q13
B16: Financing activities
B17: Net debt issued / (repaid) | H17: =Schedules!H31 | I17: =Schedules!I31 | J17: =Schedules!J31 | K17: =Schedules!K31 | L17: =Schedules!L31 | M17: =Schedules!M31 | N17: =Schedules!N31 | O17: =Schedules!O31 | ... Q17: =Schedules!Q31
B18: Dividends paid | C18: 4502 | D18: 5791 | E18: 3458 | F18: 4125 | G18: 4316 | H18: =MAX(0,IS!H19*Drivers!H22) | I18: =MAX(0,IS!I19*Drivers!I22) | J18: =MAX(0,IS!J19*Drivers!J22) | K18: =MAX(0,IS!K19*Drivers!K22) | L18: =MAX(0,IS!L19*Drivers!L22) | M18: =MAX(0,IS!M19*Drivers!M22) | N18: =MAX(0,IS!N19*Drivers!N22) | O18: =MAX(0,IS!O19*Drivers!O22) | ... Q18: =MAX(0,IS!Q19*Drivers!Q22)
B19: Lease principal paid (IFRS 16) | C19: 4117 | D19: 5056 | E19: 4802 | F19: 5321 | G19: 5923 | H19: =IS!H7*Drivers!H13 | I19: =IS!I7*Drivers!I13 | J19: =IS!J7*Drivers!J13 | K19: =IS!K7*Drivers!K13 | L19: =IS!L7*Drivers!L13 | M19: =IS!M7*Drivers!M13 | N19: =IS!N7*Drivers!N13 | O19: =IS!O7*Drivers!O13 | ... Q19: =IS!Q7*Drivers!Q13
B20: Dividends to non-controlling interests | H20: =MAX(0,IS!H18*Drivers!H22) | I20: =MAX(0,IS!I18*Drivers!I22) | J20: =MAX(0,IS!J18*Drivers!J22) | K20: =MAX(0,IS!K18*Drivers!K22) | L20: =MAX(0,IS!L18*Drivers!L22) | M20: =MAX(0,IS!M18*Drivers!M22) | N20: =MAX(0,IS!N18*Drivers!N22) | O20: =MAX(0,IS!O18*Drivers!O22) | ... Q20: =MAX(0,IS!Q18*Drivers!Q22)
B21: Cash flow from financing before revolver | H21: =H17-H18-H19-H20 | I21: =I17-I18-I19-I20 | J21: =J17-J18-J19-J20 | K21: =K17-K18-K19-K20 | L21: =L17-L18-L19-L20 | M21: =M17-M18-M19-M20 | N21: =N17-N18-N19-N20 | O21: =O17-O18-O19-O20 | ... Q21: =Q17-Q18-Q19-Q20
B23: Cash and revolver
B24: Opening cash | H24: =BS!G7 | I24: =BS!H7 | J24: =BS!I7 | K24: =BS!J7 | L24: =BS!K7 | M24: =BS!L7 | N24: =BS!M7 | O24: =BS!N7 | ... Q24: =BS!P7
B25: Cash before revolver | H25: =H24+H10+H14+H21 | I25: =I24+I10+I14+I21 | J25: =J24+J10+J14+J21 | K25: =K24+K10+K14+K21 | L25: =L24+L10+L14+L21 | M25: =M24+M10+M14+M21 | N25: =N24+N10+N14+N21 | O25: =O24+O10+O14+O21 | ... Q25: =Q24+Q10+Q14+Q21
B26: Revolver draw / (repayment) | H26: =MAX(Drivers!H26-H25,-BS!G21) | I26: =MAX(Drivers!I26-I25,-BS!H21) | J26: =MAX(Drivers!J26-J25,-BS!I21) | K26: =MAX(Drivers!K26-K25,-BS!J21) | L26: =MAX(Drivers!L26-L25,-BS!K21) | M26: =MAX(Drivers!M26-M25,-BS!L21) | N26: =MAX(Drivers!N26-N25,-BS!M21) | O26: =MAX(Drivers!O26-O25,-BS!N21) | ... Q26: =MAX(Drivers!Q26-Q25,-BS!P21)
B27: Closing cash | H27: =H25+H26 | I27: =I25+I26 | J27: =J25+J26 | K27: =K25+K26 | L27: =L25+L26 | M27: =M25+M26 | N27: =N25+N26 | O27: =O25+O26 | ... Q27: =Q25+Q26
B29: Memo
B30: Free cash flow (CFO - capex - lease principal) | C30: =C10-C13-C19 | D30: =D10-D13-D19 | E30: =E10-E13-E19 | F30: =F10-F13-F19 | G30: =G10-G13-G19 | H30: =H10-H13-H19 | I30: =I10-I13-I19 | J30: =J10-J13-J19 | ... Q30: =Q10-Q13-Q19

Sheet Schedules
B1: Grupo Bimbo, S.A.B. de C.V. (BIMBOA) - Supporting schedules
B2: MXN millions | A = actual, E = estimate | blue = input, black = formula, green = link to another sheet
C4: 2021 | D4: 2022 | E4: 2023 | F4: 2024 | G4: 2025 | H4: 2026 | I4: 2027 | J4: 2028 | K4: 2029 | L4: 2030 | M4: 2031 | N4: 2032 | O4: 2033 | P4: 2034 | Q4: 2035
B6: Revenue build
B7: North America | C7: 175369 | D7: 205674 | E7: 192534 | F7: 189330 | G7: 190211 | H7: =G7*(1+Drivers!H29) | I7: =H7*(1+Drivers!I29) | J7: =I7*(1+Drivers!J29) | K7: =J7*(1+Drivers!K29) | L7: =K7*(1+Drivers!L29) | M7: =L7*(1+Drivers!M29) | N7: =M7*(1+Drivers!N29) | O7: =N7*(1+Drivers!O29) | ... Q7: =P7*(1+Drivers!Q29)
B8: Mexico | C8: 109089 | D8: 130401 | E8: 145387 | F8: 151164 | G8: 154809 | H8: =G8*(1+Drivers!H30) | I8: =H8*(1+Drivers!I30) | J8: =I8*(1+Drivers!J30) | K8: =J8*(1+Drivers!K30) | L8: =K8*(1+Drivers!L30) | M8: =L8*(1+Drivers!M30) | N8: =M8*(1+Drivers!N30) | O8: =N8*(1+Drivers!O30) | ... Q8: =P8*(1+Drivers!Q30)
B9: Europe, Asia & Africa | C9: 34195 | D9: 37536 | E9: 40545 | F9: 45044 | G9: 54214 | H9: =G9*(1+Drivers!H31) | I9: =H9*(1+Drivers!I31) | J9: =I9*(1+Drivers!J31) | K9: =J9*(1+Drivers!K31) | L9: =K9*(1+Drivers!L31) | M9: =L9*(1+Drivers!M31) | N9: =M9*(1+Drivers!N31) | O9: =N9*(1+Drivers!O31) | ... Q9: =P9*(1+Drivers!Q31)
B10: Latin America | C10: 31109 | D10: 38411 | E10: 36647 | F10: 39879 | G10: 44120 | H10: =G10*(1+Drivers!H32) | I10: =H10*(1+Drivers!I32) | J10: =I10*(1+Drivers!J32) | K10: =J10*(1+Drivers!K32) | L10: =K10*(1+Drivers!L32) | M10: =L10*(1+Drivers!M32) | N10: =M10*(1+Drivers!N32) | O10: =N10*(1+Drivers!O32) | ... Q10: =P10*(1+Drivers!Q32)
B11: Inter-regional eliminations | C11: -10970 | D11: -13316 | E11: -15234 | F11: -17082 | G11: -16402 | H11: =G11*(1+Drivers!H33) | I11: =H11*(1+Drivers!I33) | J11: =I11*(1+Drivers!J33) | K11: =J11*(1+Drivers!K33) | L11: =K11*(1+Drivers!L33) | M11: =L11*(1+Drivers!M33) | N11: =M11*(1+Drivers!N33) | O11: =N11*(1+Drivers!O33) | ... Q11: =P11*(1+Drivers!Q33)
B12: Total revenue (links to IS) | C12: =IS!C7 | D12: =IS!D7 | E12: =IS!E7 | F12: =IS!F7 | G12: =IS!G7 | H12: =IS!H7 | I12: =IS!I7 | J12: =IS!J7 | ... Q12: =IS!Q7
B14: Intangibles
B15: Amortization of intangibles | H15: =MIN(IS!H7*Drivers!H11,BS!G13) | I15: =MIN(IS!I7*Drivers!I11,BS!H13) | J15: =MIN(IS!J7*Drivers!J11,BS!I13) | K15: =MIN(IS!K7*Drivers!K11,BS!J13) | L15: =MIN(IS!L7*Drivers!L11,BS!K13) | M15: =MIN(IS!M7*Drivers!M11,BS!L13) | N15: =MIN(IS!N7*Drivers!N11,BS!M13) | O15: =MIN(IS!O7*Drivers!O11,BS!N13) | ... Q15: =MIN(IS!Q7*Drivers!Q11,BS!P13)
B17: PP&E and right-of-use roll-forward
B18: Opening PP&E | H18: =BS!G12 | I18: =BS!H12 | J18: =BS!I12 | K18: =BS!J12 | L18: =BS!K12 | M18: =BS!L12 | N18: =BS!M12 | O18: =BS!N12 | ... Q18: =BS!P12
B19: Plus: capex | H19: =CF!H13 | I19: =CF!I13 | J19: =CF!J13 | K19: =CF!K13 | L19: =CF!L13 | M19: =CF!M13 | N19: =CF!N13 | O19: =CF!O13 | ... Q19: =CF!Q13
B20: Plus: new leases (non-cash, = lease principal repaid) | H20: =CF!H19 | I20: =CF!I19 | J20: =CF!J19 | K20: =CF!K19 | L20: =CF!L19 | M20: =CF!M19 | N20: =CF!N19 | O20: =CF!O19 | ... Q20: =CF!Q19
B21: Less: depreciation of PP&E | H21: =IS!H24-H15 | I21: =IS!I24-I15 | J21: =IS!J24-J15 | K21: =IS!K24-K15 | L21: =IS!L24-L15 | M21: =IS!M24-M15 | N21: =IS!N24-N15 | O21: =IS!O24-O15 | ... Q21: =IS!Q24-Q15
B22: Closing PP&E | H22: =H18+H19+H20-H21 | I22: =I18+I19+I20-I21 | J22: =J18+J19+J20-J21 | K22: =K18+K19+K20-K21 | L22: =L18+L19+L20-L21 | M22: =M18+M19+M20-M21 | N22: =N18+N19+N20-N21 | O22: =O18+O19+O20-O21 | ... Q22: =Q18+Q19+Q20-Q21
B24: Working capital
B25: Receivables = revenue x DSO / 365 | H25: =IS!H7*Drivers!H14/365 | I25: =IS!I7*Drivers!I14/365 | J25: =IS!J7*Drivers!J14/365 | K25: =IS!K7*Drivers!K14/365 | L25: =IS!L7*Drivers!L14/365 | M25: =IS!M7*Drivers!M14/365 | N25: =IS!N7*Drivers!N14/365 | O25: =IS!O7*Drivers!O14/365 | ... Q25: =IS!Q7*Drivers!Q14/365
B26: Inventories = cost of sales x DIO / 365 | H26: =IS!H8*Drivers!H15/365 | I26: =IS!I8*Drivers!I15/365 | J26: =IS!J8*Drivers!J15/365 | K26: =IS!K8*Drivers!K15/365 | L26: =IS!L8*Drivers!L15/365 | M26: =IS!M8*Drivers!M15/365 | N26: =IS!N8*Drivers!N15/365 | O26: =IS!O8*Drivers!O15/365 | ... Q26: =IS!Q8*Drivers!Q15/365
B27: Payables = cost of sales x DPO / 365 | H27: =IS!H8*Drivers!H16/365 | I27: =IS!I8*Drivers!I16/365 | J27: =IS!J8*Drivers!J16/365 | K27: =IS!K8*Drivers!K16/365 | L27: =IS!L8*Drivers!L16/365 | M27: =IS!M8*Drivers!M16/365 | N27: =IS!N8*Drivers!N16/365 | O27: =IS!O8*Drivers!O16/365 | ... Q27: =IS!Q8*Drivers!Q16/365
B29: Debt and interest
B30: Opening long-term debt | H30: =BS!G23 | I30: =BS!H23 | J30: =BS!I23 | K30: =BS!J23 | L30: =BS!K23 | M30: =BS!L23 | N30: =BS!M23 | O30: =BS!N23 | ... Q30: =BS!P23
B31: Plus: net new debt (repayment capped at opening balance) | H31: =MAX(Drivers!H24,-BS!G23) | I31: =MAX(Drivers!I24,-BS!H23) | J31: =MAX(Drivers!J24,-BS!I23) | K31: =MAX(Drivers!K24,-BS!J23) | L31: =MAX(Drivers!L24,-BS!K23) | M31: =MAX(Drivers!M24,-BS!L23) | N31: =MAX(Drivers!N24,-BS!M23) | O31: =MAX(Drivers!O24,-BS!N23) | ... Q31: =MAX(Drivers!Q24,-BS!P23)
B32: Closing long-term debt | H32: =H30+H31 | I32: =I30+I31 | J32: =J30+J31 | K32: =K30+K31 | L32: =L30+L31 | M32: =M30+M31 | N32: =N30+N31 | O32: =O30+O31 | ... Q32: =Q30+Q31
B33: Opening revolver | H33: =BS!G21 | I33: =BS!H21 | J33: =BS!I21 | K33: =BS!J21 | L33: =BS!K21 | M33: =BS!L21 | N33: =BS!M21 | O33: =BS!N21 | ... Q33: =BS!P21
B34: Plus: draw / (repayment) | H34: =CF!H26 | I34: =CF!I26 | J34: =CF!J26 | K34: =CF!K26 | L34: =CF!L26 | M34: =CF!M26 | N34: =CF!N26 | O34: =CF!O26 | ... Q34: =CF!Q26
B35: Closing revolver | H35: =H33+H34 | I35: =I33+I34 | J35: =J33+J34 | K35: =K33+K34 | L35: =L33+L34 | M35: =M33+M34 | N35: =N33+N34 | O35: =O33+O34 | ... Q35: =Q33+Q34
B36: Interest expense = rate x opening total debt | H36: =Drivers!H20*BS!G33 | I36: =Drivers!I20*BS!H33 | J36: =Drivers!J20*BS!I33 | K36: =Drivers!K20*BS!J33 | L36: =Drivers!L20*BS!K33 | M36: =Drivers!M20*BS!L33 | N36: =Drivers!N20*BS!M33 | O36: =Drivers!O20*BS!N33 | ... Q36: =Drivers!Q20*BS!P33

Sheet Ratios
B1: Grupo Bimbo, S.A.B. de C.V. (BIMBOA) - Ratios
B2: MXN millions | A = actual, E = estimate | blue = input, black = formula, green = link to another sheet
C4: 2021 | D4: 2022 | E4: 2023 | F4: 2024 | G4: 2025 | H4: 2026 | I4: 2027 | J4: 2028 | K4: 2029 | L4: 2030 | M4: 2031 | N4: 2032 | O4: 2033 | P4: 2034 | Q4: 2035
B6: Growth and margins
B7: Revenue growth | D7: =IS!D7/IS!C7-1 | E7: =IS!E7/IS!D7-1 | F7: =IS!F7/IS!E7-1 | G7: =IS!G7/IS!F7-1 | H7: =IS!H7/IS!G7-1 | I7: =IS!I7/IS!H7-1 | J7: =IS!J7/IS!I7-1 | K7: =IS!K7/IS!J7-1 | ... Q7: =IS!Q7/IS!P7-1
B8: Gross margin | C8: =IS!C9/IS!C7 | D8: =IS!D9/IS!D7 | E8: =IS!E9/IS!E7 | F8: =IS!F9/IS!F7 | G8: =IS!G9/IS!G7 | H8: =IS!H9/IS!H7 | I8: =IS!I9/IS!I7 | J8: =IS!J9/IS!J7 | ... Q8: =IS!Q9/IS!Q7
B9: EBITDA margin | C9: =IS!C25/IS!C7 | D9: =IS!D25/IS!D7 | E9: =IS!E25/IS!E7 | F9: =IS!F25/IS!F7 | G9: =IS!G25/IS!G7 | H9: =IS!H25/IS!H7 | I9: =IS!I25/IS!I7 | J9: =IS!J25/IS!J7 | ... Q9: =IS!Q25/IS!Q7
B10: EBIT margin | C10: =IS!C11/IS!C7 | D10: =IS!D11/IS!D7 | E10: =IS!E11/IS!E7 | F10: =IS!F11/IS!F7 | G10: =IS!G11/IS!G7 | H10: =IS!H11/IS!H7 | I10: =IS!I11/IS!I7 | J10: =IS!J11/IS!J7 | ... Q10: =IS!Q11/IS!Q7
B11: Net margin | C11: =IS!C19/IS!C7 | D11: =IS!D19/IS!D7 | E11: =IS!E19/IS!E7 | F11: =IS!F19/IS!F7 | G11: =IS!G19/IS!G7 | H11: =IS!H19/IS!H7 | I11: =IS!I19/IS!I7 | J11: =IS!J19/IS!J7 | ... Q11: =IS!Q19/IS!Q7
B12: Free cash flow margin | C12: =CF!C30/IS!C7 | D12: =CF!D30/IS!D7 | E12: =CF!E30/IS!E7 | F12: =CF!F30/IS!F7 | G12: =CF!G30/IS!G7 | H12: =CF!H30/IS!H7 | I12: =CF!I30/IS!I7 | J12: =CF!J30/IS!J7 | ... Q12: =CF!Q30/IS!Q7
B14: Returns
B15: Return on average equity | D15: =IS!D19/((BS!D27+BS!C27)/2) | E15: =IS!E19/((BS!E27+BS!D27)/2) | F15: =IS!F19/((BS!F27+BS!E27)/2) | G15: =IS!G19/((BS!G27+BS!F27)/2) | H15: =IS!H19/((BS!H27+BS!G27)/2) | I15: =IS!I19/((BS!I27+BS!H27)/2) | J15: =IS!J19/((BS!J27+BS!I27)/2) | K15: =IS!K19/((BS!K27+BS!J27)/2) | ... Q15: =IS!Q19/((BS!Q27+BS!P27)/2)
B16: ROIC = EBIT x (1 - tax rate) / opening (equity + net debt) | D16: =IS!D11*(1-Drivers!D19)/(BS!C29+BS!C34) | E16: =IS!E11*(1-Drivers!E19)/(BS!D29+BS!D34) | F16: =IS!F11*(1-Drivers!F19)/(BS!E29+BS!E34) | G16: =IS!G11*(1-Drivers!G19)/(BS!F29+BS!F34) | H16: =IS!H11*(1-Drivers!H19)/(BS!G29+BS!G34) | I16: =IS!I11*(1-Drivers!I19)/(BS!H29+BS!H34) | J16: =IS!J11*(1-Drivers!J19)/(BS!I29+BS!I34) | K16: =IS!K11*(1-Drivers!K19)/(BS!J29+BS!J34) | ... Q16: =IS!Q11*(1-Drivers!Q19)/(BS!P29+BS!P34)
B18: Leverage and working capital
B19: Net debt / EBITDA | C19: =BS!C34/IS!C25 | D19: =BS!D34/IS!D25 | E19: =BS!E34/IS!E25 | F19: =BS!F34/IS!F25 | G19: =BS!G34/IS!G25 | H19: =BS!H34/IS!H25 | I19: =BS!I34/IS!I25 | J19: =BS!J34/IS!J25 | ... Q19: =BS!Q34/IS!Q25
B20: EBIT / interest expense | C20: =IS!C11/IS!C12 | D20: =IS!D11/IS!D12 | E20: =IS!E11/IS!E12 | F20: =IS!F11/IS!F12 | G20: =IS!G11/IS!G12 | H20: =IS!H11/IS!H12 | I20: =IS!I11/IS!I12 | J20: =IS!J11/IS!J12 | ... Q20: =IS!Q11/IS!Q12
B21: Cash conversion cycle (days) = DSO + DIO - DPO | C21: =Drivers!C14+Drivers!C15-Drivers!C16 | D21: =Drivers!D14+Drivers!D15-Drivers!D16 | E21: =Drivers!E14+Drivers!E15-Drivers!E16 | F21: =Drivers!F14+Drivers!F15-Drivers!F16 | G21: =Drivers!G14+Drivers!G15-Drivers!G16 | H21: =Drivers!H14+Drivers!H15-Drivers!H16 | I21: =Drivers!I14+Drivers!I15-Drivers!I16 | J21: =Drivers!J14+Drivers!J15-Drivers!J16 | ... Q21: =Drivers!Q14+Drivers!Q15-Drivers!Q16

Sheet WACC
B1: Grupo Bimbo, S.A.B. de C.V. (BIMBOA) - Cost of capital
B2: MXN millions | A = actual, E = estimate | blue = input, black = formula, green = link to another sheet
B6: Cost of capital inputs
B7: Risk-free rate | C7: 0.075101188 | D7: input from valuation/valuation.yaml
B8: Equity risk premium | C8: 0.042 | D8: input from valuation/valuation.yaml
B9: Country risk premium | C9: 0.020496339 | D9: input from valuation/valuation.yaml
B10: Unlevered beta | C10: 0.53 | D10: input from valuation/valuation.yaml
B11: Target debt / equity (debt incl. leases, at market value) | C11: 0.7431 | D11: input from valuation/valuation.yaml
B12: Pre-tax cost of debt | C12: 0.0971 | D12: input from valuation/valuation.yaml
B13: Marginal tax rate | C13: 0.3 | D13: input from valuation/valuation.yaml
B15: Cost of capital
B16: Relevered beta = unlevered x (1 + (1 - tax) x D/E) | C16: =C10*(1+(1-C13)*C11)
B17: Cost of equity = rf + beta x ERP + CRP | C17: =C7+C16*C8+C9
B18: After-tax cost of debt | C18: =C12*(1-C13)
B19: Equity weight = 1 / (1 + D/E) | C19: =1/(1+C11)
B20: Debt weight = D/E / (1 + D/E) | C20: =C11/(1+C11)
B21: WACC | C21: =C19*C17+C20*C18
B22: Current debt / equity at market (total debt incl. leases / market cap) | C22: =BS!G33/(DCF!C45*DCF!C40)

Sheet DCF
B1: Grupo Bimbo, S.A.B. de C.V. (BIMBOA) - Discounted cash flow
B2: MXN millions | A = actual, E = estimate | blue = input, black = formula, green = link to another sheet
C4: 2021 | D4: 2022 | E4: 2023 | F4: 2024 | G4: 2025 | H4: 2026 | I4: 2027 | J4: 2028 | K4: 2029 | L4: 2030 | M4: 2031 | N4: 2032 | O4: 2033 | P4: 2034 | Q4: 2035
B6: Discounting convention | C6: Value
B7: Mid-year convention offset (0.5 = mid-year, 0 = end of year) | C7: 0.5 | D7: input from valuation/valuation.yaml (mid_year)
B9: Free cash flow to the firm
B10: EBIT | H10: =IS!H11 | I10: =IS!I11 | J10: =IS!J11 | K10: =IS!K11 | L10: =IS!L11 | M10: =IS!M11 | N10: =IS!N11 | O10: =IS!O11 | ... Q10: =IS!Q11
B11: Less: taxes on EBIT | H11: =H10*Drivers!H19 | I11: =I10*Drivers!I19 | J11: =J10*Drivers!J19 | K11: =K10*Drivers!K19 | L11: =L10*Drivers!L19 | M11: =M10*Drivers!M19 | N11: =N10*Drivers!N19 | O11: =O10*Drivers!O19 | ... Q11: =Q10*Drivers!Q19
B12: NOPAT | H12: =H10-H11 | I12: =I10-I11 | J12: =J10-J11 | K12: =K10-K11 | L12: =L10-L11 | M12: =M10-M11 | N12: =N10-N11 | O12: =O10-O11 | ... Q12: =Q10-Q11
B13: Plus: D&A | H13: =IS!H24 | I13: =IS!I24 | J13: =IS!J24 | K13: =IS!K24 | L13: =IS!L24 | M13: =IS!M24 | N13: =IS!N24 | O13: =IS!O24 | ... Q13: =IS!Q24
B14: Less: capex | H14: =CF!H13 | I14: =CF!I13 | J14: =CF!J13 | K14: =CF!K13 | L14: =CF!L13 | M14: =CF!M13 | N14: =CF!N13 | O14: =CF!O13 | ... Q14: =CF!Q13
B15: Less: new leases (IFRS 16, = lease principal repaid) | H15: =CF!H19 | I15: =CF!I19 | J15: =CF!J19 | K15: =CF!K19 | L15: =CF!L19 | M15: =CF!M19 | N15: =CF!N19 | O15: =CF!O19 | ... Q15: =CF!Q19
B16: Plus: change in working capital | H16: =CF!H9 | I16: =CF!I9 | J16: =CF!J9 | K16: =CF!K9 | L16: =CF!L9 | M16: =CF!M9 | N16: =CF!N9 | O16: =CF!O9 | ... Q16: =CF!Q9
B17: Free cash flow to the firm | H17: =H12+H13-H14-H15+H16 | I17: =I12+I13-I14-I15+I16 | J17: =J12+J13-J14-J15+J16 | K17: =K12+K13-K14-K15+K16 | L17: =L12+L13-L14-L15+L16 | M17: =M12+M13-M14-M15+M16 | N17: =N12+N13-N14-N15+N16 | O17: =O12+O13-O14-O15+O16 | ... Q17: =Q12+Q13-Q14-Q15+Q16
B18: Forecast year number | H18: 1 | I18: 2 | J18: 3 | K18: 4 | L18: 5 | M18: 6 | N18: 7 | O18: 8 | P18: 9 | Q18: 10 | R18: mechanical
B19: Discount period (years) = year number - mid-year offset | H19: =H18-C7 | I19: =I18-C7 | J19: =J18-C7 | K19: =K18-C7 | L19: =L18-C7 | M19: =M18-C7 | N19: =N18-C7 | O19: =O18-C7 | P19: =P18-C7 | Q19: =Q18-C7
B20: Discount factor | H20: =1/(1+WACC!C21)^H19 | I20: =1/(1+WACC!C21)^I19 | J20: =1/(1+WACC!C21)^J19 | K20: =1/(1+WACC!C21)^K19 | L20: =1/(1+WACC!C21)^L19 | M20: =1/(1+WACC!C21)^M19 | N20: =1/(1+WACC!C21)^N19 | O20: =1/(1+WACC!C21)^O19 | P20: =1/(1+WACC!C21)^P19 | Q20: =1/(1+WACC!C21)^Q19
B21: Present value of FCFF | H21: =H17*H20 | I21: =I17*I20 | J21: =J17*J20 | K21: =K17*K20 | L21: =L17*L20 | M21: =M17*M20 | N21: =N17*N20 | O21: =O17*O20 | ... Q21: =Q17*Q20
B23: Terminal value and enterprise value | C23: Value
B24: Terminal growth (g) | C24: 0.0425 | D24: input from valuation/valuation.yaml
B25: Exit EV / EBITDA multiple (applied to final-year EBITDA) | C25: 6 | D25: input from valuation/valuation.yaml
B26: Long-term nominal GDP growth (cap for g) | C26: 0.05 | D26: input from valuation/valuation.yaml
B27: Sum of PV of FCFF | C27: =SUM(H21:Q21)
B28: Terminal value - Gordon growth | C28: =Q17*(1+C24)/(WACC!C21-C24)
B29: PV of terminal value - Gordon | C29: =C28/(1+WACC!C21)^(Q18-C7)
B30: Enterprise value - Gordon | C30: =C27+C29
B31: Terminal value - exit multiple | C31: =IS!Q25*C25
B32: PV of terminal value - exit multiple | C32: =C31/(1+WACC!C21)^Q18
B33: Enterprise value - exit multiple | C33: =C27+C32
B35: Equity value per share | C35: Value
B36: Net debt incl. leases (last actual) | C36: =BS!G34
B37: Non-controlling interests (last actual) | C37: =BS!G28
B38: Plus: non-operating assets (associates, investments, excess land) | C38: 7018 | D38: input from valuation/valuation.yaml
B39: Less: debt-like items (pensions, provisions treated as debt) | C39: 37053.896 | D39: input from valuation/valuation.yaml
B40: Diluted shares (last actual) | C40: =IS!G22
B41: Years since last fiscal year-end | C41: 0.7918 | D41: input from valuation/valuation.yaml
B42: Roll-forward to today = (1 + cost of equity) ^ years since fiscal year-end | C42: =(1+WACC!C17)^C41
B43: Value per share today - Gordon | C43: =(C30+C38-C36-C37-C39)/C40*C42
B44: Value per share today - exit multiple | C44: =(C33+C38-C36-C37-C39)/C40*C42
B45: Current share price | C45: 58.6 | D45: input from valuation/valuation.yaml
...

Sheet Comps
B1: Grupo Bimbo, S.A.B. de C.V. (BIMBOA) - Comparable companies
B2: MXN millions | A = actual, E = estimate | blue = input, black = formula, green = link to another sheet
B6: Peer multiples | C6: Price | D6: Shares | E6: Net debt incl. leases + NCI | F6: EBITDA next yr | G6: EPS next yr | H6: EV | I6: EV / EBITDA | J6: P / E
B7: Flowers Foods, Inc. (NYSE:FLO) | C7: 6.108911 | D7: 212.1 | E7: 1950.536 | F7: 528.07749 | G7: 0.684089 | H7: =C7*D7+E7 | I7: =H7/F7 | J7: =C7/G7
B8: Gruma, S.A.B. de C.V. (BMV:GRUMA B) | C8: 13.097029 | D8: 336.20799 | E8: 1631 | F8: 1070.1899 | G8: 1.344767 | H8: =C8*D8+E8 | I8: =H8/F8 | J8: =C8/G8
B9: The Campbell's Company (NasdaqGS:CPB) | C9: 19.872233 | D9: 298.2 | E9: 7362 | F9: 1589.9425 | G9: 1.695583 | H9: =C9*D9+E9 | I9: =H9/F9 | J9: =C9/G9
B10: Mondelez International, Inc. (NasdaqGS:MDLZ) | C10: 63.910366 | D10: 1276.3 | E10: 20560 | F10: 7399.234 | G10: 3.222913 | H10: =C10*D10+E10 | I10: =H10/F10 | J10: =C10/G10
B11: PepsiCo, Inc. (NasdaqGS:PEP) | C11: 131.504 | D11: 1362.7 | E11: 45247 | F11: 20353.899 | G11: 8.46774 | H11: =C11*D11+E11 | I11: =H11/F11 | J11: =C11/G11
B13: Implied value per share
B14: Median EV / EBITDA | C14: =MEDIAN(I7,I8,I9,I10,I11)
B15: Lowest EV / EBITDA | C15: =MIN(I7,I8,I9,I10,I11)
B16: Highest EV / EBITDA | C16: =MAX(I7,I8,I9,I10,I11)
B17: Median P / E | C17: =MEDIAN(J7,J8,J9,J10,J11)
B18: Lowest P / E | C18: =MIN(J7,J8,J9,J10,J11)
B19: Highest P / E | C19: =MAX(J7,J8,J9,J10,J11)
B20: Company EBITDA next year | C20: =IS!H25
B21: Company EPS next year | C21: =IS!H23
B22: Value per share at median EV / EBITDA | C22: =(C14*C20+DCF!C38-DCF!C36-DCF!C37-DCF!C39)/DCF!C40
B23: Value per share at median P / E | C23: =C17*C21

Sheet Sensitivity
B1: Grupo Bimbo, S.A.B. de C.V. (BIMBOA) - Sensitivity (value per share)
B2: MXN millions | A = actual, E = estimate | blue = input, black = formula, green = link to another sheet
B6: Value per share today (Gordon): WACC down the side, terminal growth across; n.m. where WACC - g < 1%
B7: Terminal growth -> | D7: =DCF!C24+(-0.01) | E7: =DCF!C24+(-0.005) | F7: =DCF!C24+0 | G7: =DCF!C24+0.005 | H7: =DCF!C24+0.01
B8: WACC | C8: =WACC!C21+(-0.02) | D8: =IF(C8-D7>=0.01,(NPV(C8,DCF!H17:Q17)*(1+C8)^DCF!C7+DCF!Q17*(1+D7)/(C8-D7)/(1+C8)^(DCF!Q18-DCF!C7)+DCF!C38-DCF!C36-DCF!C37-DCF!C39)/DCF!C40*DCF!C42,0) | E8: =IF(C8-E7>=0.01,(NPV(C8,DCF!H17:Q17)*(1+C8)^DCF!C7+DCF!Q17*(1+E7)/(C8-E7)/(1+C8)^(DCF!Q18-DCF!C7)+DCF!C38-DCF!C36-DCF!C37-DCF!C39)/DCF!C40*DCF!C42,0) | F8: =IF(C8-F7>=0.01,(NPV(C8,DCF!H17:Q17)*(1+C8)^DCF!C7+DCF!Q17*(1+F7)/(C8-F7)/(1+C8)^(DCF!Q18-DCF!C7)+DCF!C38-DCF!C36-DCF!C37-DCF!C39)/DCF!C40*DCF!C42,0) | G8: =IF(C8-G7>=0.01,(NPV(C8,DCF!H17:Q17)*(1+C8)^DCF!C7+DCF!Q17*(1+G7)/(C8-G7)/(1+C8)^(DCF!Q18-DCF!C7)+DCF!C38-DCF!C36-DCF!C37-DCF!C39)/DCF!C40*DCF!C42,0) | H8: =IF(C8-H7>=0.01,(NPV(C8,DCF!H17:Q17)*(1+C8)^DCF!C7+DCF!Q17*(1+H7)/(C8-H7)/(1+C8)^(DCF!Q18-DCF!C7)+DCF!C38-DCF!C36-DCF!C37-DCF!C39)/DCF!C40*DCF!C42,0)
C9: =WACC!C21+(-0.01) | D9: =IF(C9-D7>=0.01,(NPV(C9,DCF!H17:Q17)*(1+C9)^DCF!C7+DCF!Q17*(1+D7)/(C9-D7)/(1+C9)^(DCF!Q18-DCF!C7)+DCF!C38-DCF!C36-DCF!C37-DCF!C39)/DCF!C40*DCF!C42,0) | E9: =IF(C9-E7>=0.01,(NPV(C9,DCF!H17:Q17)*(1+C9)^DCF!C7+DCF!Q17*(1+E7)/(C9-E7)/(1+C9)^(DCF!Q18-DCF!C7)+DCF!C38-DCF!C36-DCF!C37-DCF!C39)/DCF!C40*DCF!C42,0) | F9: =IF(C9-F7>=0.01,(NPV(C9,DCF!H17:Q17)*(1+C9)^DCF!C7+DCF!Q17*(1+F7)/(C9-F7)/(1+C9)^(DCF!Q18-DCF!C7)+DCF!C38-DCF!C36-DCF!C37-DCF!C39)/DCF!C40*DCF!C42,0) | G9: =IF(C9-G7>=0.01,(NPV(C9,DCF!H17:Q17)*(1+C9)^DCF!C7+DCF!Q17*(1+G7)/(C9-G7)/(1+C9)^(DCF!Q18-DCF!C7)+DCF!C38-DCF!C36-DCF!C37-DCF!C39)/DCF!C40*DCF!C42,0) | H9: =IF(C9-H7>=0.01,(NPV(C9,DCF!H17:Q17)*(1+C9)^DCF!C7+DCF!Q17*(1+H7)/(C9-H7)/(1+C9)^(DCF!Q18-DCF!C7)+DCF!C38-DCF!C36-DCF!C37-DCF!C39)/DCF!C40*DCF!C42,0)
C10: =WACC!C21+0 | D10: =IF(C10-D7>=0.01,(NPV(C10,DCF!H17:Q17)*(1+C10)^DCF!C7+DCF!Q17*(1+D7)/(C10-D7)/(1+C10)^(DCF!Q18-DCF!C7)+DCF!C38-DCF!C36-DCF!C37-DCF!C39)/DCF!C40*DCF!C42,0) | E10: =IF(C10-E7>=0.01,(NPV(C10,DCF!H17:Q17)*(1+C10)^DCF!C7+DCF!Q17*(1+E7)/(C10-E7)/(1+C10)^(DCF!Q18-DCF!C7)+DCF!C38-DCF!C36-DCF!C37-DCF!C39)/DCF!C40*DCF!C42,0) | F10: =IF(C10-F7>=0.01,(NPV(C10,DCF!H17:Q17)*(1+C10)^DCF!C7+DCF!Q17*(1+F7)/(C10-F7)/(1+C10)^(DCF!Q18-DCF!C7)+DCF!C38-DCF!C36-DCF!C37-DCF!C39)/DCF!C40*DCF!C42,0) | G10: =IF(C10-G7>=0.01,(NPV(C10,DCF!H17:Q17)*(1+C10)^DCF!C7+DCF!Q17*(1+G7)/(C10-G7)/(1+C10)^(DCF!Q18-DCF!C7)+DCF!C38-DCF!C36-DCF!C37-DCF!C39)/DCF!C40*DCF!C42,0) | H10: =IF(C10-H7>=0.01,(NPV(C10,DCF!H17:Q17)*(1+C10)^DCF!C7+DCF!Q17*(1+H7)/(C10-H7)/(1+C10)^(DCF!Q18-DCF!C7)+DCF!C38-DCF!C36-DCF!C37-DCF!C39)/DCF!C40*DCF!C42,0)
C11: =WACC!C21+0.01 | D11: =IF(C11-D7>=0.01,(NPV(C11,DCF!H17:Q17)*(1+C11)^DCF!C7+DCF!Q17*(1+D7)/(C11-D7)/(1+C11)^(DCF!Q18-DCF!C7)+DCF!C38-DCF!C36-DCF!C37-DCF!C39)/DCF!C40*DCF!C42,0) | E11: =IF(C11-E7>=0.01,(NPV(C11,DCF!H17:Q17)*(1+C11)^DCF!C7+DCF!Q17*(1+E7)/(C11-E7)/(1+C11)^(DCF!Q18-DCF!C7)+DCF!C38-DCF!C36-DCF!C37-DCF!C39)/DCF!C40*DCF!C42,0) | F11: =IF(C11-F7>=0.01,(NPV(C11,DCF!H17:Q17)*(1+C11)^DCF!C7+DCF!Q17*(1+F7)/(C11-F7)/(1+C11)^(DCF!Q18-DCF!C7)+DCF!C38-DCF!C36-DCF!C37-DCF!C39)/DCF!C40*DCF!C42,0) | G11: =IF(C11-G7>=0.01,(NPV(C11,DCF!H17:Q17)*(1+C11)^DCF!C7+DCF!Q17*(1+G7)/(C11-G7)/(1+C11)^(DCF!Q18-DCF!C7)+DCF!C38-DCF!C36-DCF!C37-DCF!C39)/DCF!C40*DCF!C42,0) | H11: =IF(C11-H7>=0.01,(NPV(C11,DCF!H17:Q17)*(1+C11)^DCF!C7+DCF!Q17*(1+H7)/(C11-H7)/(1+C11)^(DCF!Q18-DCF!C7)+DCF!C38-DCF!C36-DCF!C37-DCF!C39)/DCF!C40*DCF!C42,0)
C12: =WACC!C21+0.02 | D12: =IF(C12-D7>=0.01,(NPV(C12,DCF!H17:Q17)*(1+C12)^DCF!C7+DCF!Q17*(1+D7)/(C12-D7)/(1+C12)^(DCF!Q18-DCF!C7)+DCF!C38-DCF!C36-DCF!C37-DCF!C39)/DCF!C40*DCF!C42,0) | E12: =IF(C12-E7>=0.01,(NPV(C12,DCF!H17:Q17)*(1+C12)^DCF!C7+DCF!Q17*(1+E7)/(C12-E7)/(1+C12)^(DCF!Q18-DCF!C7)+DCF!C38-DCF!C36-DCF!C37-DCF!C39)/DCF!C40*DCF!C42,0) | F12: =IF(C12-F7>=0.01,(NPV(C12,DCF!H17:Q17)*(1+C12)^DCF!C7+DCF!Q17*(1+F7)/(C12-F7)/(1+C12)^(DCF!Q18-DCF!C7)+DCF!C38-DCF!C36-DCF!C37-DCF!C39)/DCF!C40*DCF!C42,0) | G12: =IF(C12-G7>=0.01,(NPV(C12,DCF!H17:Q17)*(1+C12)^DCF!C7+DCF!Q17*(1+G7)/(C12-G7)/(1+C12)^(DCF!Q18-DCF!C7)+DCF!C38-DCF!C36-DCF!C37-DCF!C39)/DCF!C40*DCF!C42,0) | H12: =IF(C12-H7>=0.01,(NPV(C12,DCF!H17:Q17)*(1+C12)^DCF!C7+DCF!Q17*(1+H7)/(C12-H7)/(1+C12)^(DCF!Q18-DCF!C7)+DCF!C38-DCF!C36-DCF!C37-DCF!C39)/DCF!C40*DCF!C42,0)

Sheet Football
B1: Grupo Bimbo, S.A.B. de C.V. (BIMBOA) - Football field
B2: MXN millions | A = actual, E = estimate | blue = input, black = formula, green = link to another sheet
B6: Valuation summary (football field) | C6: Low | D6: High | E6: Spread
B7: DCF - Gordon (sensitivity range) | C7: =MIN(IF(Sensitivity!C8-Sensitivity!D7>=0.01,Sensitivity!D8,DCF!C43),IF(Sensitivity!C8-Sensitivity!E7>=0.01,Sensitivity!E8,DCF!C43),IF(Sensitivity!C8-Sensitivity!F7>=0.01,Sensitivity!F8,DCF!C43),IF(Sensitivity!C8-Sensitivity!G7>=0.01,Sensitivity!G8,DCF!C43),IF(Sensitivity!C8-Sensitivity!H7>=0.01,Sensitivity!H8,DCF!C43),IF(Sensitivity!C9-Sensitivity!D7>=0.01,Sensitivity!D9,DCF!C43),IF(Sensitivity!C9-Sensitivity!E7>=0.01,Sensitivity!E9,DCF!C43),IF(Sensitivity!C9-Sensitivity!F7>=0.01,Sensitivity!F9,DCF!C43),IF(Sensitivity!C9-Sensitivity!G7>=0.01,Sensitivity!G9,DCF!C43),IF(Sensitivity!C9-Sensitivity!H7>=0.01,Sensitivity!H9,DCF!C43),IF(Sensitivity!C10-Sensitivity!D7>=0.01,Sensitivity!D10,DCF!C43),IF(Sensitivity!C10-Sensitivity!E7>=0.01,Sensitivity!E10,DCF!C43),IF(Sensitivity!C10-Sensitivity!F7>=0.01,Sensitivity!F10,DCF!C43),IF(Sensitivity!C10-Sensitivity!G7>=0.01,Sensitivity!G10,DCF!C43),IF(Sensitivity!C10-Sensitivity!H7>=0.01,Sensitivity!H10,DCF!C43),IF(Sensitivity!C11-Sensitivity!D7>=0.01,Sensitivity!D11,DCF!C43),IF(Sensitivity!C11-Sensitivity!E7>=0.01,Sensitivity!E11,DCF!C43),IF(Sensitivity!C11-Sensitivity!F7>=0.01,Sensitivity!F11,DCF!C43),IF(Sensitivity!C11-Sensitivity!G7>=0.01,Sensitivity!G11,DCF!C43),IF(Sensitivity!C11-Sensitivity!H7>=0.01,Sensitivity!H11,DCF!C43),IF(Sensitivity!C12-Sensitivity!D7>=0.01,Sensitivity!D12,DCF!C43),IF(Sensitivity!C12-Sensitivity!E7>=0.01,Sensitivity!E12,DCF!C43),IF(Sensitivity!C12-Sensitivity!F7>=0.01,Sensitivity!F12,DCF!C43),IF(Sensitivity!C12-Sensitivity!G7>=0.01,Sensitivity!G12,DCF!C43),IF(Sensitivity!C12-Sensitivity!H7>=0.01,Sensitivity!H12,DCF!C43)) | D7: =MAX(IF(Sensitivity!C8-Sensitivity!D7>=0.01,Sensitivity!D8,DCF!C43),IF(Sensitivity!C8-Sensitivity!E7>=0.01,Sensitivity!E8,DCF!C43),IF(Sensitivity!C8-Sensitivity!F7>=0.01,Sensitivity!F8,DCF!C43),IF(Sensitivity!C8-Sensitivity!G7>=0.01,Sensitivity!G8,DCF!C43),IF(Sensitivity!C8-Sensitivity!H7>=0.01,Sensitivity!H8,DCF!C43),IF(Sensitivity!C9-Sensitivity!D7>=0.01,Sensitivity!D9,DCF!C43),IF(Sensitivity!C9-Sensitivity!E7>=0.01,Sensitivity!E9,DCF!C43),IF(Sensitivity!C9-Sensitivity!F7>=0.01,Sensitivity!F9,DCF!C43),IF(Sensitivity!C9-Sensitivity!G7>=0.01,Sensitivity!G9,DCF!C43),IF(Sensitivity!C9-Sensitivity!H7>=0.01,Sensitivity!H9,DCF!C43),IF(Sensitivity!C10-Sensitivity!D7>=0.01,Sensitivity!D10,DCF!C43),IF(Sensitivity!C10-Sensitivity!E7>=0.01,Sensitivity!E10,DCF!C43),IF(Sensitivity!C10-Sensitivity!F7>=0.01,Sensitivity!F10,DCF!C43),IF(Sensitivity!C10-Sensitivity!G7>=0.01,Sensitivity!G10,DCF!C43),IF(Sensitivity!C10-Sensitivity!H7>=0.01,Sensitivity!H10,DCF!C43),IF(Sensitivity!C11-Sensitivity!D7>=0.01,Sensitivity!D11,DCF!C43),IF(Sensitivity!C11-Sensitivity!E7>=0.01,Sensitivity!E11,DCF!C43),IF(Sensitivity!C11-Sensitivity!F7>=0.01,Sensitivity!F11,DCF!C43),IF(Sensitivity!C11-Sensitivity!G7>=0.01,Sensitivity!G11,DCF!C43),IF(Sensitivity!C11-Sensitivity!H7>=0.01,Sensitivity!H11,DCF!C43),IF(Sensitivity!C12-Sensitivity!D7>=0.01,Sensitivity!D12,DCF!C43),IF(Sensitivity!C12-Sensitivity!E7>=0.01,Sensitivity!E12,DCF!C43),IF(Sensitivity!C12-Sensitivity!F7>=0.01,Sensitivity!F12,DCF!C43),IF(Sensitivity!C12-Sensitivity!G7>=0.01,Sensitivity!G12,DCF!C43),IF(Sensitivity!C12-Sensitivity!H7>=0.01,Sensitivity!H12,DCF!C43)) | E7: =D7-C7
B8: DCF - exit multiple +/- 1.0x | C8: =(DCF!C27+IS!Q25*(DCF!C25-1)/(1+WACC!C21)^DCF!Q18+DCF!C38-DCF!C36-DCF!C37-DCF!C39)/DCF!C40*DCF!C42 | D8: =(DCF!C27+IS!Q25*(DCF!C25+1)/(1+WACC!C21)^DCF!Q18+DCF!C38-DCF!C36-DCF!C37-DCF!C39)/DCF!C40*DCF!C42 | E8: =D8-C8
B9: Comps - EV / EBITDA (peer range) | C9: =(Comps!C15*Comps!C20+DCF!C38-DCF!C36-DCF!C37-DCF!C39)/DCF!C40 | D9: =(Comps!C16*Comps!C20+DCF!C38-DCF!C36-DCF!C37-DCF!C39)/DCF!C40 | E9: =D9-C9
B10: Comps - P / E (peer range) | C10: =Comps!C18*Comps!C21 | D10: =Comps!C19*Comps!C21 | E10: =D10-C10
B11: 52-week trading range | C11: 53.03 | D11: 68.67 | E11: =D11-C11
B12: Current share price | C12: =DCF!C45 | D12: =DCF!C45 | E12: =D12-C12

Sheet Checks
B1: Grupo Bimbo, S.A.B. de C.V. (BIMBOA) - Integrity checks
B2: MXN millions | A = actual, E = estimate | blue = input, black = formula, green = link to another sheet
C4: 2021 | D4: 2022 | E4: 2023 | F4: 2024 | G4: 2025 | H4: 2026 | I4: 2027 | J4: 2028 | K4: 2029 | L4: 2030 | M4: 2031 | N4: 2032 | O4: 2033 | P4: 2034 | Q4: 2035
B6: Checks by year
B7: Balance sheet balances (assets = liabilities + equity) | C7: =IF(ABS(BS!C15-BS!C30)<=0.5,"OK","ERROR") | D7: =IF(ABS(BS!D15-BS!D30)<=0.5,"OK","ERROR") | E7: =IF(ABS(BS!E15-BS!E30)<=0.5,"OK","ERROR") | F7: =IF(ABS(BS!F15-BS!F30)<=0.5,"OK","ERROR") | G7: =IF(ABS(BS!G15-BS!G30)<=0.5,"OK","ERROR") | H7: =IF(ABS(BS!H15-BS!H30)<=0.5,"OK","ERROR") | I7: =IF(ABS(BS!I15-BS!I30)<=0.5,"OK","ERROR") | J7: =IF(ABS(BS!J15-BS!J30)<=0.5,"OK","ERROR") | ... Q7: =IF(ABS(BS!Q15-BS!Q30)<=0.5,"OK","ERROR")
B8: Cash-flow closing cash = balance-sheet cash | H8: =IF(ABS(CF!H27-BS!H7)<=0.5,"OK","ERROR") | I8: =IF(ABS(CF!I27-BS!I7)<=0.5,"OK","ERROR") | J8: =IF(ABS(CF!J27-BS!J7)<=0.5,"OK","ERROR") | K8: =IF(ABS(CF!K27-BS!K7)<=0.5,"OK","ERROR") | L8: =IF(ABS(CF!L27-BS!L7)<=0.5,"OK","ERROR") | M8: =IF(ABS(CF!M27-BS!M7)<=0.5,"OK","ERROR") | N8: =IF(ABS(CF!N27-BS!N7)<=0.5,"OK","ERROR") | O8: =IF(ABS(CF!O27-BS!O7)<=0.5,"OK","ERROR") | ... Q8: =IF(ABS(CF!Q27-BS!Q7)<=0.5,"OK","ERROR")
B9: Equity roll-forward (opening + net income - dividends) | H9: =IF(ABS(BS!H27-(BS!G27+IS!H19-CF!H18))<=0.5,"OK","ERROR") | I9: =IF(ABS(BS!I27-(BS!H27+IS!I19-CF!I18))<=0.5,"OK","ERROR") | J9: =IF(ABS(BS!J27-(BS!I27+IS!J19-CF!J18))<=0.5,"OK","ERROR") | K9: =IF(ABS(BS!K27-(BS!J27+IS!K19-CF!K18))<=0.5,"OK","ERROR") | L9: =IF(ABS(BS!L27-(BS!K27+IS!L19-CF!L18))<=0.5,"OK","ERROR") | M9: =IF(ABS(BS!M27-(BS!L27+IS!M19-CF!M18))<=0.5,"OK","ERROR") | N9: =IF(ABS(BS!N27-(BS!M27+IS!N19-CF!N18))<=0.5,"OK","ERROR") | O9: =IF(ABS(BS!O27-(BS!N27+IS!O19-CF!O18))<=0.5,"OK","ERROR") | ... Q9: =IF(ABS(BS!Q27-(BS!P27+IS!Q19-CF!Q18))<=0.5,"OK","ERROR")
