Workbook

Sheet README
A1: Grupo Bimbo (BIMBOA) - Consolidated financial statements FY2021A-FY2030E
A2: MXN millions. Built 2026-10-19 by model/build/build_statements_workbook.py.
A4: What is here
A5: IS, OCI, BS, CF and Equity: every line of the face of the audited statements, FY2021A-FY2025A.
A6: Checks: links between the statements and tie-outs of every subtotal to the filing. History: all 0.
A8: Sources (PDF page numbers)
A9: FY2023-FY2025: filings/annual/IA25_GB_EEFF_V10.pdf - BS p.12, IS p.13, OCI p.14, equity p.15, CF p.16.
A10: FY2021-FY2022: filings/bmv/Reporte Anual 2023_XBRL_VF.PDF - BS p.256, IS p.257, OCI p.258, equity p.259, CF p.260.
A11: Rule: the latest report that presents a year wins (data/adjustments.md). FY2021 is restated for the Ricolino disposal.
A13: Colour code
A14: Blue number = typed from the filing [sourced]. Black = formula [calc].
A15: Yellow cell (FY2026E-FY2030E) = empty input for the team to project.
... A30: The condensed model inputs (data/financials.csv) group these lines; totals agree with this workbook.

Sheet IS
A1: Grupo Bimbo - Consolidated income statement
A2: Continuing operations; FY2021 restated for Ricolino (discontinued from 2022). Costs by function, as reported.
B3: Actual (audited) | G3: Forecast - team projects and balances
A4: MXN millions | B4: FY2021A | C4: FY2022A | D4: FY2023A | E4: FY2024A | F4: FY2025A | G4: FY2026E | H4: FY2027E | I4: FY2028E | J4: FY2029E | K4: FY2030E | L4: Tag | M4: Source / note
A5: Continuing operations
A6: Net sales | B6: 338792 | C6: 398706 | D6: 399879 | E6: 408335 | F6: 426952 | L6: [sourced] | M6: RA23 p.257 (FY21-22); IA25 p.13 (FY23-25)
A7: Cost of sales | B7: 157703 | C7: 193325 | D7: 194369 | E7: 193407 | F7: 203465 | L7: [sourced] | M7: RA23 p.257 (FY21-22); IA25 p.13 (FY23-25); Positive = expense
A8: Gross profit | B8: =B6-B7 -> 181089 | C8: =C6-C7 -> 205381 | D8: =D6-D7 -> 205510 | E8: =E6-E7 -> 214928 | F8: =F6-F7 -> 223487 | G8: =G6-G7 -> 0 | H8: =H6-H7 -> 0 | I8: =I6-I7 -> 0 | ... K8: =K6-K7 -> 0 | L8: [calc]
A9: Distribution and selling expenses | B9: 124422 | C9: 140455 | D9: 139477 | E9: 147628 | F9: 154866 | L9: [sourced] | M9: RA23 p.257 (FY21-22); IA25 p.13 (FY23-25)
A10: Administrative expenses | B10: 23147 | C10: 26172 | D10: 25860 | E10: 27536 | F10: 29023 | L10: [sourced] | M10: RA23 p.257 (FY21-22); IA25 p.13 (FY23-25)
A11: Integration expenses | B11: 724 | C11: 367 | D11: 288 | E11: 317 | F11: 541 | L11: [sourced] | M11: RA23 p.257 (FY21-22); IA25 p.13 (FY23-25)
A12: Other (income) expenses, net | B12: 216 | C12: -15309 | D12: 4430 | E12: 6298 | F12: 4911 | L12: [sourced] | M12: RA23 p.257 (FY21-22); IA25 p.13 (FY23-25); FY2022 includes the non-cash gain on multi-employer pension plans (MEPP)
A13: Total general expenses | B13: =SUM(B9:B12) -> 148509 | C13: =SUM(C9:C12) -> 151685 | D13: =SUM(D9:D12) -> 170055 | E13: =SUM(E9:E12) -> 181779 | F13: =SUM(F9:F12) -> 189341 | G13: =SUM(G9:G12) -> 0 | H13: =SUM(H9:H12) -> 0 | I13: =SUM(I9:I12) -> 0 | ... K13: =SUM(K9:K12) -> 0 | L13: [calc]
A14: Operating income (EBIT) | B14: =B8-B13 -> 32580 | C14: =C8-C13 -> 53696 | D14: =D8-D13 -> 35455 | E14: =E8-E13 -> 33149 | F14: =F8-F13 -> 34146 | G14: =G8-G13 -> 0 | H14: =H8-H13 -> 0 | I14: =I8-I13 -> 0 | ... K14: =K8-K13 -> 0 | L14: [calc]
A16: Comprehensive financing result
A17: Interest expense | B17: 7823 | C17: 8049 | D17: 10006 | E17: 13100 | F17: 14464 | L17: [sourced] | M17: RA23 p.257 (FY21-22); IA25 p.13 (FY23-25); Includes IFRS 16 lease interest
A18: Interest income | B18: -363 | C18: -740 | D18: -809 | E18: -924 | F18: -897 | L18: [sourced] | M18: RA23 p.257 (FY21-22); IA25 p.13 (FY23-25); Negative = income (as in the filing)
A19: Foreign exchange loss, net | B19: 538 | C19: 995 | D19: 1323 | E19: 506 | F19: 384 | L19: [sourced] | M19: RA23 p.257 (FY21-22); IA25 p.13 (FY23-25)
A20: Monetary position loss (gain) | B20: -25 | C20: -34 | D20: -73 | E20: -103 | F20: 50 | L20: [sourced] | M20: RA23 p.257 (FY21-22); IA25 p.13 (FY23-25)
A21: Total comprehensive financing result | B21: =SUM(B17:B20) -> 7973 | C21: =SUM(C17:C20) -> 8270 | D21: =SUM(D17:D20) -> 10447 | E21: =SUM(E17:E20) -> 12579 | F21: =SUM(F17:F20) -> 14001 | G21: =SUM(G17:G20) -> 0 | H21: =SUM(H17:H20) -> 0 | I21: =SUM(I17:I20) -> 0 | ... K21: =SUM(K17:K20) -> 0 | L21: [calc]
A22: Share of results of associates | B22: 247 | C22: 452 | D22: 316 | E22: 464 | F22: -2 | L22: [sourced] | M22: RA23 p.257 (FY21-22); IA25 p.13 (FY23-25)
A23: Income before taxes, continuing operations | B23: =B14-B21+B22 -> 24854 | C23: =C14-C21+C22 -> 45878 | D23: =D14-D21+D22 -> 25324 | E23: =E14-E21+E22 -> 21034 | F23: =F14-F21+F22 -> 20143 | G23: =G14-G21+G22 -> 0 | H23: =H14-H21+H22 -> 0 | I23: =I14-I21+I22 -> 0 | ... K23: =K14-K21+K22 -> 0 | L23: [calc]
A24: Income taxes | B24: 8726 | C24: 14381 | D24: 8386 | E24: 6797 | F24: 7197 | L24: [sourced] | M24: RA23 p.257 (FY21-22); IA25 p.13 (FY23-25)
A25: Net income from continuing operations | B25: =B23-B24 -> 16128 | C25: =C23-C24 -> 31497 | D25: =D23-D24 -> 16938 | E25: =E23-E24 -> 14237 | F25: =F23-F24 -> 12946 | G25: =G23-G24 -> 0 | H25: =H23-H24 -> 0 | I25: =I23-I24 -> 0 | ... K25: =K23-K24 -> 0 | L25: [calc]
A26: Net income from discontinued operations, after tax | B26: 1254 | C26: 16988 | D26: -16 | E26: -194 | F26: 0 | L26: [sourced] | M26: RA23 p.257 (FY21-22); IA25 p.13 (FY23-25); Ricolino (sold 1-Nov-2022)
A27: Consolidated net income | B27: =B25+B26 -> 17382 | C27: =C25+C26 -> 48485 | D27: =D25+D26 -> 16922 | E27: =E25+E26 -> 14043 | F27: =F25+F26 -> 12946 | G27: =G25+G26 -> 0 | H27: =H25+H26 -> 0 | I27: =I25+I26 -> 0 | ... K27: =K25+K26 -> 0 | L27: [calc]
A29: Attribution
A30: Non-controlling interest | B30: 1466 | C30: 1575 | D30: 1445 | E30: 1499 | F30: 1813 | L30: [sourced] | M30: RA23 p.257 (FY21-22); IA25 p.13 (FY23-25); FY21-22 include discontinued NCI (30; 402)
A31: Controlling interest | B31: =B27-B30 -> 15916 | C31: =C27-C30 -> 46910 | D31: =D27-D30 -> 15477 | E31: =E27-E30 -> 12544 | F31: =F27-F30 -> 11133 | G31: =G27-G30 -> 0 | H31: =H27-H30 -> 0 | I31: =I27-I30 -> 0 | ... K31: =K27-K30 -> 0 | L31: [calc]
A32: Weighted-average shares (millions) | B32: 4487.268 | C32: 4448.693 | D32: 4418.137 | E32: 4357.25 | F32: 4310.531 | L32: [sourced] | M32: RA23 p.257 (FY21-22); IA25 p.13 (FY23-25); Filing reports thousands; basic = diluted
A33: Basic EPS (MXN) | B33: =IFERROR(B31/B32,0) -> 3.5469243 | C33: =IFERROR(C31/C32,0) -> 10.54467 | D33: =IFERROR(D31/D32,0) -> 3.5030602 | E33: =IFERROR(E31/E32,0) -> 2.87888 | F33: =IFERROR(F31/F32,0) -> 2.5827444 | G33: =IFERROR(G31/G32,0) -> 0 | H33: =IFERROR(H31/H32,0) -> 0 | I33: =IFERROR(I31/I32,0) -> 0 | ... K33: =IFERROR(K31/K32,0) -> 0 | L33: [calc]
A35: Memo
A36: D&A, continuing (segment note) | B36: 16126 | C36: 18038 | D36: 18929 | E36: 23051 | F36: 24838 | L36: [sourced] | M36: RA23 p.358-359; IA25 p.85-86 (data/financials.csv)
A37: EBITDA (EBIT + D&A) | B37: =B14+B36 -> 48706 | C37: =C14+C36 -> 71734 | D37: =D14+D36 -> 54384 | E37: =E14+E36 -> 56200 | F37: =F14+F36 -> 58984 | G37: =G14+G36 -> 0 | H37: =H14+H36 -> 0 | I37: =I14+I36 -> 0 | ... K37: =K14+K36 -> 0 | L37: [calc]

Sheet OCI
A1: Grupo Bimbo - Consolidated statement of other comprehensive income
A2: As reported. Positive = gain.
B3: Actual (audited) | G3: Forecast - team projects and balances
A4: MXN millions | B4: FY2021A | C4: FY2022A | D4: FY2023A | E4: FY2024A | F4: FY2025A | G4: FY2026E | H4: FY2027E | I4: FY2028E | J4: FY2029E | K4: FY2030E | L4: Tag | M4: Source / note
A5: Consolidated net income | B5: 17382 | C5: 48485 | D5: 16922 | E5: 14043 | F5: 12946 | L5: [sourced] | M5: RA23 p.258 (FY21-22); IA25 p.14 (FY23-25); Must equal IS consolidated net income
A7: Items that will not be reclassified to profit or loss
A8: Valuation of equity financial instruments | B8: -112 | C8: -32 | D8: -236 | E8: -43 | F8: -118 | L8: [sourced] | M8: RA23 p.258 (FY21-22); IA25 p.14 (FY23-25)
A9: Actuarial gains (losses) on defined-benefit plans | B9: 1543 | C9: 800 | D9: -349 | E9: 802 | F9: -433 | L9: [sourced] | M9: RA23 p.258 (FY21-22); IA25 p.14 (FY23-25)
A10: Income tax | B10: -432 | C10: -207 | D10: 164 | E10: -540 | F10: 369 | L10: [sourced] | M10: RA23 p.258 (FY21-22); IA25 p.14 (FY23-25)
A11: Subtotal | B11: =SUM(B8:B10) -> 999 | C11: =SUM(C8:C10) -> 561 | D11: =SUM(D8:D10) -> -421 | E11: =SUM(E8:E10) -> 219 | F11: =SUM(F8:F10) -> -182 | G11: =SUM(G8:G10) -> 0 | H11: =SUM(H8:H10) -> 0 | I11: =SUM(I8:I10) -> 0 | ... K11: =SUM(K8:K10) -> 0 | L11: [calc]
A12: Items that may be reclassified to profit or loss
A13: Net investment hedge | B13: -723 | C13: 667 | D13: 1100 | E13: -3407 | F13: 2096 | L13: [sourced] | M13: RA23 p.258 (FY21-22); IA25 p.14 (FY23-25)
A14: Translation of foreign operations | B14: 2114 | C14: -9862 | D14: -15635 | E14: 15551 | F14: -10811 | L14: [sourced] | M14: RA23 p.258 (FY21-22); IA25 p.14 (FY23-25)
A15: Cash-flow hedges, net change | B15: 2988 | C15: -2213 | D15: 938 | E15: 287 | F15: -1800 | L15: [sourced] | M15: RA23 p.258 (FY21-22); IA25 p.14 (FY23-25)
A16: Income tax | B16: -937 | C16: 142 | D16: -772 | E16: 1164 | F16: -348 | L16: [sourced] | M16: RA23 p.258 (FY21-22); IA25 p.14 (FY23-25)
A17: Subtotal | B17: =SUM(B13:B16) -> 3442 | C17: =SUM(C13:C16) -> -11266 | D17: =SUM(D13:D16) -> -14369 | E17: =SUM(E13:E16) -> 13595 | F17: =SUM(F13:F16) -> -10863 | G17: =SUM(G13:G16) -> 0 | H17: =SUM(H13:H16) -> 0 | I17: =SUM(I13:I16) -> 0 | ... K17: =SUM(K13:K16) -> 0 | L17: [calc]
A18: Total other comprehensive income | B18: =B11+B17 -> 4441 | C18: =C11+C17 -> -10705 | D18: =D11+D17 -> -14790 | E18: =E11+E17 -> 13814 | F18: =F11+F17 -> -11045 | G18: =G11+G17 -> 0 | H18: =H11+H17 -> 0 | I18: =I11+I17 -> 0 | ... K18: =K11+K17 -> 0 | L18: [calc]
A19: Consolidated comprehensive income | B19: =B5+B18 -> 21823 | C19: =C5+C18 -> 37780 | D19: =D5+D18 -> 2132 | E19: =E5+E18 -> 27857 | F19: =F5+F18 -> 1901 | G19: =G5+G18 -> 0 | H19: =H5+H18 -> 0 | I19: =I5+I18 -> 0 | ... K19: =K5+K18 -> 0 | L19: [calc]
A20: Attributable to non-controlling interest | B20: 1470 | C20: 1155 | D20: 1540 | E20: 1677 | F20: 2012 | L20: [sourced] | M20: RA23 p.258 (FY21-22); IA25 p.14 (FY23-25)
A21: Attributable to controlling interest | B21: =B19-B20 -> 20353 | C21: =C19-C20 -> 36625 | D21: =D19-D20 -> 592 | E21: =E19-E20 -> 26180 | F21: =F19-F20 -> -111 | G21: =G19-G20 -> 0 | H21: =H19-H20 -> 0 | I21: =I19-I20 -> 0 | ... K21: =K19-K20 -> 0 | L21: [calc]

Sheet BS
A1: Grupo Bimbo - Consolidated balance sheet (31 December)
A2: As reported, every line of the face of the statement.
B3: Actual (audited) | G3: Forecast - team projects and balances
A4: MXN millions | B4: FY2021A | C4: FY2022A | D4: FY2023A | E4: FY2024A | F4: FY2025A | G4: FY2026E | H4: FY2027E | I4: FY2028E | J4: FY2029E | K4: FY2030E | L4: Tag | M4: Source / note
A5: Current assets
A6: Cash and cash equivalents | B6: 8748 | C6: 12313 | D6: 6353 | E6: 8057 | F6: 8535 | L6: [sourced] | M6: RA23 p.256 (FY21-22); IA25 p.12 (FY23-25); Must equal CF ending cash
A7: Trade and other receivables, net | B7: 27170 | C7: 32185 | D7: 33269 | E7: 36659 | F7: 35782 | L7: [sourced] | M7: RA23 p.256 (FY21-22); IA25 p.12 (FY23-25)
A8: Inventories | B8: 13710 | C8: 16989 | D8: 16120 | E8: 18832 | F8: 17151 | L8: [sourced] | M8: RA23 p.256 (FY21-22); IA25 p.12 (FY23-25)
A9: Prepaid expenses | B9: 2296 | C9: 928 | D9: 1378 | E9: 1371 | F9: 1798 | L9: [sourced] | M9: RA23 p.256 (FY21-22); IA25 p.12 (FY23-25)
A10: Derivative financial instruments | B10: 1293 | C10: 38 | D10: 119 | E10: 1417 | F10: 60 | L10: [sourced] | M10: RA23 p.256 (FY21-22); IA25 p.12 (FY23-25)
A11: Collateral deposits on derivatives | B11: 0 | C11: 879 | D11: 1519 | E11: 577 | F11: 459 | L11: [sourced] | M11: RA23 p.256 (FY21-22); IA25 p.12 (FY23-25)
A12: Assets held for sale | B12: 194 | C12: 138 | D12: 156 | E12: 267 | F12: 886 | L12: [sourced] | M12: RA23 p.256 (FY21-22); IA25 p.12 (FY23-25)
A13: Total current assets | B13: =SUM(B6:B12) -> 53411 | C13: =SUM(C6:C12) -> 63470 | D13: =SUM(D6:D12) -> 58914 | E13: =SUM(E6:E12) -> 67180 | F13: =SUM(F6:F12) -> 64671 | G13: =SUM(G6:G12) -> 0 | H13: =SUM(H6:H12) -> 0 | I13: =SUM(I6:I12) -> 0 | ... K13: =SUM(K6:K12) -> 0 | L13: [calc]
A14: Property, plant and equipment, net | B14: 103891 | C14: 113505 | D14: 129156 | E14: 155376 | F14: 157423 | L14: [sourced] | M14: RA23 p.256 (FY21-22); IA25 p.12 (FY23-25)
A15: Right-of-use assets, net | B15: 30754 | C15: 28477 | D15: 25848 | E15: 34220 | F15: 32757 | L15: [sourced] | M15: RA23 p.256 (FY21-22); IA25 p.12 (FY23-25)
A16: Investment in associates | B16: 3891 | C16: 4398 | D16: 5031 | E16: 7531 | F16: 7018 | L16: [sourced] | M16: RA23 p.256 (FY21-22); IA25 p.12 (FY23-25)
A17: Derivative financial instruments | B17: 1962 | C17: 2005 | D17: 468 | E17: 784 | F17: 657 | L17: [sourced] | M17: RA23 p.256 (FY21-22); IA25 p.12 (FY23-25)
A18: Deferred income taxes | B18: 7861 | C18: 3962 | D18: 7313 | E18: 6884 | F18: 6908 | L18: [sourced] | M18: RA23 p.256 (FY21-22); IA25 p.12 (FY23-25)
A19: Intangible assets, net | B19: 56965 | C19: 59062 | D19: 55101 | E19: 65808 | F19: 62947 | L19: [sourced] | M19: RA23 p.256 (FY21-22); IA25 p.12 (FY23-25)
A20: Goodwill | B20: 74565 | C20: 68085 | D20: 62000 | E20: 75100 | F20: 72568 | L20: [sourced] | M20: RA23 p.256 (FY21-22); IA25 p.12 (FY23-25)
A21: Other assets, net | B21: 4340 | C21: 4800 | D21: 4271 | E21: 3921 | F21: 4856 | L21: [sourced] | M21: RA23 p.256 (FY21-22); IA25 p.12 (FY23-25)
A22: TOTAL ASSETS | B22: =B13+SUM(B14:B21) -> 337640 | C22: =C13+SUM(C14:C21) -> 347764 | D22: =D13+SUM(D14:D21) -> 348102 | E22: =E13+SUM(E14:E21) -> 416804 | F22: =F13+SUM(F14:F21) -> 409805 | G22: =G13+SUM(G14:G21) -> 0 | H22: =H13+SUM(H14:H21) -> 0 | I22: =I13+SUM(I14:I21) -> 0 | ... K22: =K13+SUM(K14:K21) -> 0 | L22: [calc]
A24: Current liabilities
A25: Current portion of long-term debt | B25: 10625 | C25: 6435 | D25: 12932 | E25: 4862 | F25: 12635 | L25: [sourced] | M25: RA23 p.256 (FY21-22); IA25 p.12 (FY23-25)
A26: Trade payables | B26: 35752 | C26: 44058 | D26: 40409 | E26: 40815 | F26: 39074 | L26: [sourced] | M26: RA23 p.256 (FY21-22); IA25 p.12 (FY23-25)
A27: Other payables and accrued liabilities | B27: 24102 | C27: 24198 | D27: 22072 | E27: 27280 | F27: 26395 | L27: [sourced] | M27: RA23 p.256 (FY21-22); IA25 p.12 (FY23-25)
A28: Lease liabilities | B28: 5793 | C28: 5930 | D28: 5751 | E28: 7140 | F28: 7076 | L28: [sourced] | M28: RA23 p.256 (FY21-22); IA25 p.12 (FY23-25)
A29: Payables to related parties | B29: 1527 | C29: 1240 | D29: 1412 | E29: 1260 | F29: 1154 | L29: [sourced] | M29: RA23 p.256 (FY21-22); IA25 p.12 (FY23-25)
A30: Income taxes payable | B30: 708 | C30: 4604 | D30: 665 | E30: 1535 | F30: 1059 | L30: [sourced] | M30: RA23 p.256 (FY21-22); IA25 p.12 (FY23-25)
A31: Employee profit sharing (PTU) | B31: 1692 | C31: 1811 | D31: 1787 | E31: 1752 | F31: 1592 | L31: [sourced] | M31: RA23 p.256 (FY21-22); IA25 p.12 (FY23-25)
A32: Derivative financial instruments | B32: 169 | C32: 1458 | D32: 2164 | E32: 511 | F32: 1588 | L32: [sourced] | M32: RA23 p.256 (FY21-22); IA25 p.12 (FY23-25)
A33: Other short-term liabilities | B33: 392 | C33: 0 | D33: 0 | E33: 0 | F33: 0 | L33: [sourced] | M33: RA23 p.256 (FY21-22); IA25 p.12 (FY23-25)
A34: Total current liabilities | B34: =SUM(B25:B33) -> 80760 | C34: =SUM(C25:C33) -> 89734 | D34: =SUM(D25:D33) -> 87192 | E34: =SUM(E25:E33) -> 85155 | F34: =SUM(F25:F33) -> 90573 | G34: =SUM(G25:G33) -> 0 | H34: =SUM(H25:H33) -> 0 | I34: =SUM(I25:I33) -> 0 | ... K34: =SUM(K25:K33) -> 0 | L34: [calc]
A35: Long-term debt | B35: 82230 | C35: 77619 | D35: 97003 | E35: 146043 | F35: 141028 | L35: [sourced] | M35: RA23 p.256 (FY21-22); IA25 p.12 (FY23-25)
A36: Lease liabilities | B36: 25356 | C36: 23255 | D36: 21064 | E36: 28661 | F36: 27714 | L36: [sourced] | M36: RA23 p.256 (FY21-22); IA25 p.12 (FY23-25)
A37: Derivative financial instruments | B37: 67 | C37: 590 | D37: 1888 | E37: 689 | F37: 2314 | L37: [sourced] | M37: RA23 p.256 (FY21-22); IA25 p.12 (FY23-25)
A38: Employee benefits | B38: 30712 | C38: 9382 | D38: 7217 | E38: 6635 | F38: 6507 | L38: [sourced] | M38: RA23 p.256 (FY21-22); IA25 p.12 (FY23-25); FY2022 drop = MEPP settlement
A39: Deferred income taxes | B39: 7087 | C39: 7575 | D39: 9224 | E39: 8891 | F39: 8415 | L39: [sourced] | M39: RA23 p.256 (FY21-22); IA25 p.12 (FY23-25)
A40: Other long-term liabilities | B40: 9822 | C40: 12007 | D40: 12886 | E40: 13032 | F40: 12999 | L40: [sourced] | M40: RA23 p.256 (FY21-22); IA25 p.12 (FY23-25)
A41: TOTAL LIABILITIES | B41: =B34+SUM(B35:B40) -> 236034 | C41: =C34+SUM(C35:C40) -> 220162 | D41: =D34+SUM(D35:D40) -> 236474 | E41: =E34+SUM(E35:E40) -> 289106 | F41: =F34+SUM(F35:F40) -> 289550 | G41: =G34+SUM(G35:G40) -> 0 | H41: =H34+SUM(H35:H40) -> 0 | I41: =I34+SUM(I35:I40) -> 0 | ... K41: =K34+SUM(K35:K40) -> 0 | L41: [calc]
...

Sheet CF
A1: Grupo Bimbo - Consolidated cash flow statement
A2: Indirect method, as reported. Sign as in the filing: negative = cash outflow. FY2021-22 include Ricolino until its sale.
B3: Actual (audited) | G3: Forecast - team projects and balances
A4: MXN millions | B4: FY2021A | C4: FY2022A | D4: FY2023A | E4: FY2024A | F4: FY2025A | G4: FY2026E | H4: FY2027E | I4: FY2028E | J4: FY2029E | K4: FY2030E | L4: Tag | M4: Source / note
A5: Operating activities
A6: Income before taxes, continuing operations | B6: 24854 | C6: 45878 | D6: 25324 | E6: 21034 | F6: 20143 | L6: [sourced] | M6: RA23 p.260 (FY21-22); IA25 p.16 (FY23-25); Must equal IS
A7: Income (loss) before taxes, discontinued operations | B7: 1499 | C7: 23516 | D7: -23 | E7: -277 | F7: 0 | L7: [sourced] | M7: RA23 p.260 (FY21-22); IA25 p.16 (FY23-25)
A8: Income before taxes | B8: =B6+B7 -> 26353 | C8: =C6+C7 -> 69394 | D8: =D6+D7 -> 25301 | E8: =E6+E7 -> 20757 | F8: =F6+F7 -> 20143 | G8: =G6+G7 -> 0 | H8: =H6+H7 -> 0 | I8: =I6+I7 -> 0 | ... K8: =K6+K7 -> 0 | L8: [calc]
A9: Adjustments for:
A10: Depreciation and amortization | B10: 16375 | C10: 18282 | D10: 18929 | E10: 23051 | F10: 24838 | L10: [sourced] | M10: RA23 p.260 (FY21-22); IA25 p.16 (FY23-25); FY21-22 include discontinued D&A (249; 244)
A11: Loss (gain) on sale of property, plant and equipment | B11: -157 | C11: 650 | D11: 751 | E11: -192 | F11: 68 | L11: [sourced] | M11: RA23 p.260 (FY21-22); IA25 p.16 (FY23-25)
A12: Write-off of PP&E due to casualty | B12: 379 | C12: 0 | D12: 0 | E12: 0 | F12: 0 | L12: [sourced] | M12: RA23 p.260 (FY21-22); IA25 p.16 (FY23-25)
A13: Share of results of associates | B13: -247 | C13: -452 | D13: -316 | E13: -464 | F13: 2 | L13: [sourced] | M13: RA23 p.260 (FY21-22); IA25 p.16 (FY23-25)
A14: Impairment of long-lived assets | B14: 694 | C14: 1046 | D14: 383 | E14: 249 | F14: 445 | L14: [sourced] | M14: RA23 p.260 (FY21-22); IA25 p.16 (FY23-25)
A15: Gain on disposal of discontinued operation | B15: 0 | C15: -22038 | D15: 0 | E15: 277 | F15: 0 | L15: [sourced] | M15: RA23 p.260 (FY21-22); IA25 p.16 (FY23-25)
A16: Multi-employer pension plans and other long-term liabilities | B16: -2247 | C16: -19010 | D16: 0 | E16: -982 | F16: 27 | L16: [sourced] | M16: RA23 p.260 (FY21-22); IA25 p.16 (FY23-25)
A17: Current service cost | B17: 1128 | C17: 1013 | D17: 837 | E17: 942 | F17: 909 | L17: [sourced] | M17: RA23 p.260 (FY21-22); IA25 p.16 (FY23-25)
A18: Interest expense | B18: 7884 | C18: 8049 | D18: 10006 | E18: 13100 | F18: 14464 | L18: [sourced] | M18: RA23 p.260 (FY21-22); IA25 p.16 (FY23-25)
A19: Interest income | B19: -373 | C19: -740 | D19: -809 | E19: -924 | F19: -897 | L19: [sourced] | M19: RA23 p.260 (FY21-22); IA25 p.16 (FY23-25)
A20: Short-term and low-value lease expenses | B20: 2183 | C20: 2519 | D20: 3968 | E20: 4526 | F20: 4964 | L20: [sourced] | M20: RA23 p.260 (FY21-22); IA25 p.16 (FY23-25)
A21: Changes in assets and liabilities:
A22: Trade and other receivables | B22: 666 | C22: -6647 | D22: -4206 | E22: -319 | F22: 601 | L22: [sourced] | M22: RA23 p.260 (FY21-22); IA25 p.16 (FY23-25)
A23: Inventories | B23: -2320 | C23: -4163 | D23: -1078 | E23: -1104 | F23: 901 | L23: [sourced] | M23: RA23 p.260 (FY21-22); IA25 p.16 (FY23-25)
A24: Prepaid expenses | B24: -365 | C24: 1261 | D24: -625 | E24: 189 | F24: -594 | L24: [sourced] | M24: RA23 p.260 (FY21-22); IA25 p.16 (FY23-25)
A25: Trade payables | B25: 8286 | C25: 9920 | D25: -851 | E25: -2825 | F25: -1108 | L25: [sourced] | M25: RA23 p.260 (FY21-22); IA25 p.16 (FY23-25)
A26: Other payables and accrued liabilities | B26: -1025 | C26: -3395 | D26: 390 | E26: -3827 | F26: -560 | L26: [sourced] | M26: RA23 p.260 (FY21-22); IA25 p.16 (FY23-25)
A27: Payables to related parties | B27: 209 | C27: 287 | D27: -172 | E27: 153 | F27: 105 | L27: [sourced] | M27: RA23 p.260 (FY21-22); IA25 p.16 (FY23-25)
A28: Income taxes paid | B28: -7578 | C28: -11824 | D28: -13831 | E28: -6472 | F28: -8955 | L28: [sourced] | M28: RA23 p.260 (FY21-22); IA25 p.16 (FY23-25)
A29: Collateral deposits on derivatives | B29: 6 | C29: -1271 | D29: -640 | E29: 942 | F29: 118 | L29: [sourced] | M29: RA23 p.260 (FY21-22); IA25 p.16 (FY23-25)
A30: Employee profit sharing (PTU) | B30: 675 | C30: 122 | D30: -21 | E30: -36 | F30: -159 | L30: [sourced] | M30: RA23 p.260 (FY21-22); IA25 p.16 (FY23-25)
A31: Employee benefits and social security | B31: -2567 | C31: -754 | D31: -2637 | E31: -2608 | F31: -2595 | L31: [sourced] | M31: RA23 p.260 (FY21-22); IA25 p.16 (FY23-25)
A32: Dividends receivable from discontinued operation | B32: 0 | C32: -879 | D32: 0 | E32: 0 | F32: 0 | L32: [sourced] | M32: RA23 p.260 (FY21-22); IA25 p.16 (FY23-25)
A33: Short-term and low-value lease payments | B33: -2183 | C33: -2519 | D33: -3968 | E33: -4526 | F33: -4964 | L33: [sourced] | M33: RA23 p.260 (FY21-22); IA25 p.16 (FY23-25)
A34: Net cash from operating activities | B34: =SUM(B8:B33) -> 45776 | C34: =SUM(C8:C33) -> 38851 | D34: =SUM(D8:D33) -> 31411 | E34: =SUM(E8:E33) -> 39907 | F34: =SUM(F8:F33) -> 47753 | G34: =SUM(G8:G33) -> 0 | H34: =SUM(H8:H33) -> 0 | I34: =SUM(I8:I33) -> 0 | ... K34: =SUM(K8:K33) -> 0 | L34: [calc]
A36: Investing activities
A37: Purchases of property, plant and equipment | B37: -20671 | C37: -28669 | D37: -34754 | E37: -29402 | F37: -22530 | L37: [sourced] | M37: RA23 p.260 (FY21-22); IA25 p.16 (FY23-25)
A38: Business acquisitions and NCI, net of cash acquired | B38: -10637 | C38: -6520 | D38: -6548 | E38: -5988 | F38: -11294 | L38: [sourced] | M38: RA23 p.260 (FY21-22); IA25 p.16 (FY23-25)
A39: Proceeds from sale of discontinued operation | B39: 0 | C39: 25797 | D39: 0 | E39: 0 | F39: 0 | L39: [sourced] | M39: RA23 p.260 (FY21-22); IA25 p.16 (FY23-25); Ricolino
A40: Proceeds from sale of PP&E | B40: 882 | C40: 20 | D40: 152 | E40: 984 | F40: 824 | L40: [sourced] | M40: RA23 p.260 (FY21-22); IA25 p.16 (FY23-25)
A41: Insurance recoveries | B41: 201 | C41: 272 | D41: 0 | E41: 0 | F41: 0 | L41: [sourced] | M41: RA23 p.260 (FY21-22); IA25 p.16 (FY23-25)
...

Sheet Equity
A1: Grupo Bimbo - Equity roll-forward (statement of changes in equity)
A2: Columns of the statement of changes in equity condensed to controlling and non-controlling totals.
B3: Actual (audited) | G3: Forecast - team projects and balances
A4: MXN millions | B4: FY2021A | C4: FY2022A | D4: FY2023A | E4: FY2024A | F4: FY2025A | G4: FY2026E | H4: FY2027E | I4: FY2028E | J4: FY2029E | K4: FY2030E | L4: Tag | M4: Source / note
A5: Controlling interest
A6: Opening balance | B6: 83713 | C6: =B16 -> 97100 | D6: =C16 -> 124111 | E6: =D16 -> 108322 | F6: =E16 -> 125944 | G6: =F16 -> 119512 | H6: =G16 -> 119512 | I6: =H16 -> 119512 | J6: =I16 -> 119512 | K6: =J16 -> 119512 | L6: [sourced] FY21; [calc] after | M6: RA23 p.259 (FY21-22); IA25 p.15 (FY23-25); FY2021 typed (FY2020 close); later years = prior-year closing
A7: Yield on perpetual notes | B7: -621 | C7: -649 | D7: -395 | E7: 0 | F7: 0 | L7: [sourced] | M7: RA23 p.259 (FY21-22); IA25 p.15 (FY23-25)
A8: Tax effect on perpetual notes | B8: 58 | C8: -229 | D8: -20 | E8: 0 | F8: 0 | L8: [sourced] | M8: RA23 p.259 (FY21-22); IA25 p.15 (FY23-25)
A9: Repurchase of perpetual notes | B9: 0 | C9: -377 | D9: -78 | E9: 0 | F9: 0 | L9: [sourced] | M9: RA23 p.259 (FY21-22); IA25 p.15 (FY23-25)
A10: Reclassification of perpetual notes to debt | B10: 0 | C10: 0 | D10: -8844 | E10: 0 | F10: 0 | L10: [sourced] | M10: RA23 p.259 (FY21-22); IA25 p.15 (FY23-25)
A11: Dividends declared | B11: -4502 | C11: -5791 | D11: -3458 | E11: -4125 | F11: -4316 | L11: [sourced] | M11: RA23 p.259 (FY21-22); IA25 p.15 (FY23-25)
A12: Share repurchases | B12: -1901 | C12: -2568 | D12: -3586 | E12: -4433 | F12: -1253 | L12: [sourced] | M12: RA23 p.259 (FY21-22); IA25 p.15 (FY23-25)
A13: Changes in ownership interest | B13: 0 | C13: 0 | D13: 0 | E13: 0 | F13: -752 | L13: [sourced] | M13: RA23 p.259 (FY21-22); IA25 p.15 (FY23-25); Colombia NCI purchase
A14: Net income (controlling) | B14: 15916 | C14: 46910 | D14: 15477 | E14: 12544 | F14: 11133 | L14: [sourced] | M14: RA23 p.259 (FY21-22); IA25 p.15 (FY23-25); Must equal IS controlling NI
A15: Other comprehensive income (controlling) | B15: 4437 | C15: -10285 | D15: -14885 | E15: 13636 | F15: -11244 | L15: [sourced] | M15: RA23 p.259 (FY21-22); IA25 p.15 (FY23-25)
A16: Closing balance, controlling | B16: =SUM(B6:B15) -> 97100 | C16: =SUM(C6:C15) -> 124111 | D16: =SUM(D6:D15) -> 108322 | E16: =SUM(E6:E15) -> 125944 | F16: =SUM(F6:F15) -> 119512 | G16: =SUM(G6:G15) -> 119512 | H16: =SUM(H6:H15) -> 119512 | I16: =SUM(I6:I15) -> 119512 | ... K16: =SUM(K6:K15) -> 119512 | L16: [calc] | M16: Must equal BS controlling interest
A18: Non-controlling interest
A19: Opening balance | B19: 4298 | C19: =B25 -> 4506 | D19: =C25 -> 3491 | E19: =D25 -> 3306 | F19: =E25 -> 1754 | G19: =F25 -> 743 | H19: =G25 -> 743 | I19: =H25 -> 743 | J19: =I25 -> 743 | K19: =J25 -> 743 | L19: [sourced] FY21; [calc] after | M19: RA23 p.259 (FY21-22); IA25 p.15 (FY23-25); FY2021 typed (FY2020 close); later years = prior-year closing
A20: Consolidation of structured entities | B20: -1099 | C20: -2011 | D20: -1851 | E20: -3120 | F20: -2240 | L20: [sourced] | M20: RA23 p.259 (FY21-22); IA25 p.15 (FY23-25)
A21: Dividends declared | B21: -163 | C21: -94 | D21: -91 | E21: -109 | F21: -135 | L21: [sourced] | M21: RA23 p.259 (FY21-22); IA25 p.15 (FY23-25)
A22: Acquisitions, disposals and ownership changes | B22: 0 | C22: -65 | D22: 217 | E22: 0 | F22: -648 | L22: [sourced] | M22: RA23 p.259 (FY21-22); IA25 p.15 (FY23-25); FY22 discontinued (-65); FY23 acquisitions (+217); FY25 acquisitions 68 less decrease 716
A23: Net income (NCI) | B23: 1466 | C23: 1575 | D23: 1445 | E23: 1499 | F23: 1813 | L23: [sourced] | M23: RA23 p.259 (FY21-22); IA25 p.15 (FY23-25); Must equal IS NCI
A24: Other comprehensive income (NCI) | B24: 4 | C24: -420 | D24: 95 | E24: 178 | F24: 199 | L24: [sourced] | M24: RA23 p.259 (FY21-22); IA25 p.15 (FY23-25)
A25: Closing balance, NCI | B25: =SUM(B19:B24) -> 4506 | C25: =SUM(C19:C24) -> 3491 | D25: =SUM(D19:D24) -> 3306 | E25: =SUM(E19:E24) -> 1754 | F25: =SUM(F19:F24) -> 743 | G25: =SUM(G19:G24) -> 743 | H25: =SUM(H19:H24) -> 743 | I25: =SUM(I19:I24) -> 743 | ... K25: =SUM(K19:K24) -> 743 | L25: [calc] | M25: Must equal BS NCI
A27: Total equity, closing | B27: =B16+B25 -> 101606 | C27: =C16+C25 -> 127602 | D27: =D16+D25 -> 111628 | E27: =E16+E25 -> 127698 | F27: =F16+F25 -> 120255 | G27: =G16+G25 -> 120255 | H27: =H16+H25 -> 120255 | I27: =I16+I25 -> 120255 | ... K27: =K16+K25 -> 120255 | L27: [calc] | M27: Must equal BS total equity

Sheet Checks
A1: Integrity checks - every line must be 0 in every year
A2: Historical columns are 0 by construction. In the forecast, a non-zero value tells you which link is still missing.
A4: Check (difference, MXN m) | B4: FY2021A | C4: FY2022A | D4: FY2023A | E4: FY2024A | F4: FY2025A | G4: FY2026E | H4: FY2027E | I4: FY2028E | J4: FY2029E | K4: FY2030E
A5: Links between statements (all years)
A6: BS: total assets - (liabilities + equity) | B6: =BS!B22-BS!B54 -> 0 | C6: =BS!C22-BS!C54 -> 0 | D6: =BS!D22-BS!D54 -> 0 | E6: =BS!E22-BS!E54 -> 0 | F6: =BS!F22-BS!F54 -> 0 | G6: =BS!G22-BS!G54 -> 0 | H6: =BS!H22-BS!H54 -> 0 | I6: =BS!I22-BS!I54 -> 0 | ... K6: =BS!K22-BS!K54 -> 0
A7: CF ending cash - BS cash | B7: =CF!B67-BS!B6 -> 0 | C7: =CF!C67-BS!C6 -> 0 | D7: =CF!D67-BS!D6 -> 0 | E7: =CF!E67-BS!E6 -> 0 | F7: =CF!F67-BS!F6 -> 0 | G7: =CF!G67-BS!G6 -> 8535 | H7: =CF!H67-BS!H6 -> 8535 | I7: =CF!I67-BS!I6 -> 8535 | ... K7: =CF!K67-BS!K6 -> 8535
A8: CF income before taxes (continuing) - IS | B8: =CF!B6-IS!B23 -> 0 | C8: =CF!C6-IS!C23 -> 0 | D8: =CF!D6-IS!D23 -> 0 | E8: =CF!E6-IS!E23 -> 0 | F8: =CF!F6-IS!F23 -> 0 | G8: =CF!G6-IS!G23 -> 0 | H8: =CF!H6-IS!H23 -> 0 | I8: =CF!I6-IS!I23 -> 0 | ... K8: =CF!K6-IS!K23 -> 0
A9: OCI net income - IS consolidated net income | B9: =OCI!B5-IS!B27 -> 0 | C9: =OCI!C5-IS!C27 -> 0 | D9: =OCI!D5-IS!D27 -> 0 | E9: =OCI!E5-IS!E27 -> 0 | F9: =OCI!F5-IS!F27 -> 0 | G9: =OCI!G5-IS!G27 -> 0 | H9: =OCI!H5-IS!H27 -> 0 | I9: =OCI!I5-IS!I27 -> 0 | ... K9: =OCI!K5-IS!K27 -> 0
A10: Equity: controlling net income - IS | B10: =Equity!B14-IS!B31 -> 0 | C10: =Equity!C14-IS!C31 -> 0 | D10: =Equity!D14-IS!D31 -> 0 | E10: =Equity!E14-IS!E31 -> 0 | F10: =Equity!F14-IS!F31 -> 0 | G10: =Equity!G14-IS!G31 -> 0 | H10: =Equity!H14-IS!H31 -> 0 | I10: =Equity!I14-IS!I31 -> 0 | ... K10: =Equity!K14-IS!K31 -> 0
A11: Equity: NCI net income - IS | B11: =Equity!B23-IS!B30 -> 0 | C11: =Equity!C23-IS!C30 -> 0 | D11: =Equity!D23-IS!D30 -> 0 | E11: =Equity!E23-IS!E30 -> 0 | F11: =Equity!F23-IS!F30 -> 0 | G11: =Equity!G23-IS!G30 -> 0 | H11: =Equity!H23-IS!H30 -> 0 | I11: =Equity!I23-IS!I30 -> 0 | ... K11: =Equity!K23-IS!K30 -> 0
A12: Equity: OCI (controlling + NCI) - OCI statement | B12: =Equity!B15+Equity!B24-OCI!B18 -> 0 | C12: =Equity!C15+Equity!C24-OCI!C18 -> 0 | D12: =Equity!D15+Equity!D24-OCI!D18 -> 0 | E12: =Equity!E15+Equity!E24-OCI!E18 -> 0 | F12: =Equity!F15+Equity!F24-OCI!F18 -> 0 | G12: =Equity!G15+Equity!G24-OCI!G18 -> 0 | H12: =Equity!H15+Equity!H24-OCI!H18 -> 0 | I12: =Equity!I15+Equity!I24-OCI!I18 -> 0 | ... K12: =Equity!K15+Equity!K24-OCI!K18 -> 0
A13: Equity: OCI to NCI - OCI statement | B13: =Equity!B24-(OCI!B20-IS!B30) -> 0 | C13: =Equity!C24-(OCI!C20-IS!C30) -> 0 | D13: =Equity!D24-(OCI!D20-IS!D30) -> 0 | E13: =Equity!E24-(OCI!E20-IS!E30) -> 0 | F13: =Equity!F24-(OCI!F20-IS!F30) -> 0 | G13: =Equity!G24-(OCI!G20-IS!G30) -> 0 | H13: =Equity!H24-(OCI!H20-IS!H30) -> 0 | I13: =Equity!I24-(OCI!I20-IS!I30) -> 0 | ... K13: =Equity!K24-(OCI!K20-IS!K30) -> 0
A14: Equity: closing controlling - BS | B14: =Equity!B16-BS!B51 -> 0 | C14: =Equity!C16-BS!C51 -> 0 | D14: =Equity!D16-BS!D51 -> 0 | E14: =Equity!E16-BS!E51 -> 0 | F14: =Equity!F16-BS!F51 -> 0 | G14: =Equity!G16-BS!G51 -> 119512 | H14: =Equity!H16-BS!H51 -> 119512 | I14: =Equity!I16-BS!I51 -> 119512 | ... K14: =Equity!K16-BS!K51 -> 119512
A15: Equity: closing NCI - BS | B15: =Equity!B25-BS!B52 -> 0 | C15: =Equity!C25-BS!C52 -> 0 | D15: =Equity!D25-BS!D52 -> 0 | E15: =Equity!E25-BS!E52 -> 0 | F15: =Equity!F25-BS!F52 -> 0 | G15: =Equity!G25-BS!G52 -> 743 | H15: =Equity!H25-BS!H52 -> 743 | I15: =Equity!I25-BS!I52 -> 743 | ... K15: =Equity!K25-BS!K52 -> 743
A16: Equity: share repurchases - CF | B16: =Equity!B12-CF!B61 -> 0 | C16: =Equity!C12-CF!C61 -> 0 | D16: =Equity!D12-CF!D61 -> 0 | E16: =Equity!E12-CF!E61 -> 0 | F16: =Equity!F12-CF!F61 -> 0 | G16: =Equity!G12-CF!G61 -> 0 | H16: =Equity!H12-CF!H61 -> 0 | I16: =Equity!I12-CF!I61 -> 0 | ... K16: =Equity!K12-CF!K61 -> 0
A18: Subtotals vs the audited filing (history only)
A19: IS net sales vs filing | B19: =IS!B6-338792 -> 0 | C19: =IS!C6-398706 -> 0 | D19: =IS!D6-399879 -> 0 | E19: =IS!E6-408335 -> 0 | F19: =IS!F6-426952 -> 0
A20: IS gross profit vs filing | B20: =IS!B8-181089 -> 0 | C20: =IS!C8-205381 -> 0 | D20: =IS!D8-205510 -> 0 | E20: =IS!E8-214928 -> 0 | F20: =IS!F8-223487 -> 0
A21: IS operating income vs filing | B21: =IS!B14-32580 -> 0 | C21: =IS!C14-53696 -> 0 | D21: =IS!D14-35455 -> 0 | E21: =IS!E14-33149 -> 0 | F21: =IS!F14-34146 -> 0
A22: IS income before taxes vs filing | B22: =IS!B23-24854 -> 0 | C22: =IS!C23-45878 -> 0 | D22: =IS!D23-25324 -> 0 | E22: =IS!E23-21034 -> 0 | F22: =IS!F23-20143 -> 0
A23: IS consolidated net income vs filing | B23: =IS!B27-17382 -> 0 | C23: =IS!C27-48485 -> 0 | D23: =IS!D27-16922 -> 0 | E23: =IS!E27-14043 -> 0 | F23: =IS!F27-12946 -> 0
A24: IS controlling net income vs filing | B24: =IS!B31-15916 -> 0 | C24: =IS!C31-46910 -> 0 | D24: =IS!D31-15477 -> 0 | E24: =IS!E31-12544 -> 0 | F24: =IS!F31-11133 -> 0
A25: BS total current assets vs filing | B25: =BS!B13-53411 -> 0 | C25: =BS!C13-63470 -> 0 | D25: =BS!D13-58914 -> 0 | E25: =BS!E13-67180 -> 0 | F25: =BS!F13-64671 -> 0
A26: BS total assets vs filing | B26: =BS!B22-337640 -> 0 | C26: =BS!C22-347764 -> 0 | D26: =BS!D22-348102 -> 0 | E26: =BS!E22-416804 -> 0 | F26: =BS!F22-409805 -> 0
A27: BS total current liabilities vs filing | B27: =BS!B34-80760 -> 0 | C27: =BS!C34-89734 -> 0 | D27: =BS!D34-87192 -> 0 | E27: =BS!E34-85155 -> 0 | F27: =BS!F34-90573 -> 0
A28: BS total liabilities vs filing | B28: =BS!B41-236034 -> 0 | C28: =BS!C41-220162 -> 0 | D28: =BS!D41-236474 -> 0 | E28: =BS!E41-289106 -> 0 | F28: =BS!F41-289550 -> 0
A29: BS total equity vs filing | B29: =BS!B53-101606 -> 0 | C29: =BS!C53-127602 -> 0 | D29: =BS!D53-111628 -> 0 | E29: =BS!E53-127698 -> 0 | F29: =BS!F53-120255 -> 0
A30: CF operating vs filing | B30: =CF!B34-45776 -> 0 | C30: =CF!C34-38851 -> 0 | D30: =CF!D34-31411 -> 0 | E30: =CF!E34-39907 -> 0 | F30: =CF!F34-47753 -> 0
A31: CF investing vs filing | B31: =CF!B49--32459 -> 0 | C31: =CF!C49--9122 -> 0 | D31: =CF!D49--42440 -> 0 | E31: =CF!E49--36138 -> 0 | F31: =CF!F49--34652 -> 0
A32: CF financing vs filing | B32: =CF!B62--14116 -> 0 | C32: =CF!C62--25692 -> 0 | D32: =CF!D62-5904 -> 0 | E32: =CF!E62--2696 -> 0 | F32: =CF!F62--11908 -> 0
A33: OCI total vs filing | B33: =OCI!B18-4441 -> 0 | C33: =OCI!C18--10705 -> 0 | D33: =OCI!D18--14790 -> 0 | E33: =OCI!E18-13814 -> 0 | F33: =OCI!F18--11045 -> 0
A35: Sum of absolute differences | B35: =SUMPRODUCT(ABS(B6:B33)) -> 0 | C35: =SUMPRODUCT(ABS(C6:C33)) -> 0 | D35: =SUMPRODUCT(ABS(D6:D33)) -> 0 | E35: =SUMPRODUCT(ABS(E6:E33)) -> 0 | F35: =SUMPRODUCT(ABS(F6:F33)) -> 0 | G35: =SUMPRODUCT(ABS(G6:G33)) -> 128790 | H35: =SUMPRODUCT(ABS(H6:H33)) -> 128790 | I35: =SUMPRODUCT(ABS(I6:I33)) -> 128790 | ... K35: =SUMPRODUCT(ABS(K6:K33)) -> 128790
A36: Status | B36: =IF(ROUND(B35,0)=0,"OK","CHECK") -> OK | C36: =IF(ROUND(C35,0)=0,"OK","CHECK") -> OK | D36: =IF(ROUND(D35,0)=0,"OK","CHECK") -> OK | E36: =IF(ROUND(E35,0)=0,"OK","CHECK") -> OK | F36: =IF(ROUND(F35,0)=0,"OK","CHECK") -> OK | G36: =IF(ROUND(G35,0)=0,"OK","CHECK") -> CHECK | H36: =IF(ROUND(H35,0)=0,"OK","CHECK") -> CHECK | I36: =IF(ROUND(I35,0)=0,"OK","CHECK") -> CHECK | ... K36: =IF(ROUND(K35,0)=0,"OK","CHECK") -> CHECK
