Workbook

Sheet Notes
A1: Nominal GDP growth, local currency, 2016-2030 (Grupo Bimbo regions)
A3: Built | B3: 2026-10-24 by the AI for the team (logged in docs/context/ai-use-log.md)
A4: Levels | B4: S&P Capital IQ nominalGDPLCU, entered as values exactly as stored [sourced]; file and line in Data columns H-I
A5: Sources | B5: data/capitaliq/capiq-sales-drivers-{M1..M5,X1,E1..E5}_2026-10-24.md; ESP/PRT/FRA/ITA from BIMBOA/research/Informacion_BIMBO_macro.txt (its "Derived" growth rows, computed by ChatIQ, are not used)
A6: Growth | B6: Live formula in Data column J: level_t / level_t-1 - 1 [calc]. Growth_view links to Data; nothing is pasted as a value
A7: Duplicates | B7: PER, URY, VEN 2015-2025 appear in M5 and X1 with identical values; the M5 row is cited
A8: [unverified] | B8: UKR 2027 (gap vs real GDP + CPI); VEN all years (unusable); SVN 2025 (flag conflict). Shaded orange
A9: H-02 fix | B9: KAZ, KOR, MAR and UKR 2026: the stored level step is a likely series break, so 2026 growth = (1 + real GDP growth) x (1 + CPI) - 1 (Data columns L-M; CPI from IAS29_test) [calc]; CPI is a proxy for the GDP deflator [assumption]. The 2026 levels stay as stored, so 2027-2030 growth is unchanged. Shaded green. Audit fix 2026-10-26
A10: Unit notes | B10: HRV labelled knB but euro-scale, one unit throughout so growth is unaffected; PRY 2026 flagged ACTUAL (label wrong, value plausible); India on calendar years
A11: FX | B11: Local currency per USD, annual average, as stored in BIMBOA/research/Informacion_BIMBO_macro.txt [sourced]; USD = 1; VES and MKD not in source
A12: Regional_agg | B12: Same logic as Bimbo ex-FX growth: each country grows in local currency; countries are added at the prior-year exchange rate, so weight_t = GDP USD t-1 / region total t-1 and region growth_t = sum(weight x growth) [calc]. All consolidated countries included (team decision 2026-10-25). VEN excluded because Bimbo has not consolidated it since 1-Jun-2017; MKD excluded for lack of FX (toggle column C). Weights are GDP, not Bimbo sales (Bimbo discloses sales by region only)
A13: IAS29_test | B13: IAS 29 para 3(e): one indicator of hyperinflation is cumulative inflation over three years approaching or exceeding 100%. Computed with live formulas from the Capital IQ CPI annual averages in the same blocks [calc]. Annual-average CPI is a proxy; IAS 29 practice uses index levels

Sheet Data
A1: iso3 | B1: region | C1: year | D1: nominal_gdp_lcu | E1: unit | F1: flag | G1: as_of | H1: source_file | I1: source_line | J1: growth | K1: tag | L1: real_gdp_growth (H-02) | M1: real GDP source (H-02)
A2: MEX | B2: Mexico | C2: 2015 | D2: 19228.61 | E2: Mex$B | F2: As reported ACTUAL | G2: 10/15/2026 | H2: capiq-sales-drivers-X1_2026-10-24.md | I2: 26 | K2: [sourced] level only
A3: MEX | B3: Mexico | C3: 2016 | D3: 20758.79 | E3: Mex$B | F3: As reported ACTUAL | G3: 10/15/2026 | H3: capiq-sales-drivers-X1_2026-10-24.md | I3: 27 | J3: =IF(D2=0,"",D3/D2-1) -> 0.079578295 | K3: [calc]
A4: MEX | B4: Mexico | C4: 2017 | D4: 22536.21 | E4: Mex$B | F4: As reported ACTUAL | G4: 10/15/2026 | H4: capiq-sales-drivers-X1_2026-10-24.md | I4: 28 | J4: =IF(D3=0,"",D4/D3-1) -> 0.085622524 | K4: [calc]
A5: MEX | B5: Mexico | C5: 2018 | D5: 24176.67 | E5: Mex$B | F5: As reported ACTUAL | G5: 10/15/2026 | H5: capiq-sales-drivers-X1_2026-10-24.md | I5: 29 | J5: =IF(D4=0,"",D5/D4-1) -> 0.072792186 | K5: [calc]
A6: MEX | B6: Mexico | C6: 2019 | D6: 25121.82 | E6: Mex$B | F6: As reported ACTUAL | G6: 10/15/2026 | H6: capiq-sales-drivers-X1_2026-10-24.md | I6: 30 | J6: =IF(D5=0,"",D6/D5-1) -> 0.039093473 | K6: [calc]
A7: MEX | B7: Mexico | C7: 2020 | D7: 24086.76 | E7: Mex$B | F7: As reported ACTUAL | G7: 10/15/2026 | H7: capiq-sales-drivers-X1_2026-10-24.md | I7: 31 | J7: =IF(D6=0,"",D7/D6-1) -> -0.041201633 | K7: [calc]
A8: MEX | B8: Mexico | C8: 2021 | D8: 26690.03 | E8: Mex$B | F8: As reported ACTUAL | G8: 10/15/2026 | H8: capiq-sales-drivers-X1_2026-10-24.md | I8: 32 | J8: =IF(D7=0,"",D8/D7-1) -> 0.10807888 | K8: [calc]
A9: MEX | B9: Mexico | C9: 2022 | D9: 29525.51 | E9: Mex$B | F9: As reported ACTUAL | G9: 10/15/2026 | H9: capiq-sales-drivers-X1_2026-10-24.md | I9: 33 | J9: =IF(D8=0,"",D9/D8-1) -> 0.10623742 | K9: [calc]
A10: MEX | B10: Mexico | C10: 2023 | D10: 31871.09 | E10: Mex$B | F10: As reported ACTUAL | G10: 10/15/2026 | H10: capiq-sales-drivers-X1_2026-10-24.md | I10: 34 | J10: =IF(D9=0,"",D10/D9-1) -> 0.079442489 | K10: [calc]
A11: MEX | B11: Mexico | C11: 2024 | D11: 33582.9 | E11: Mex$B | F11: As reported ACTUAL | G11: 10/15/2026 | H11: capiq-sales-drivers-X1_2026-10-24.md | I11: 35 | J11: =IF(D10=0,"",D11/D10-1) -> 0.053710432 | K11: [calc]
A12: MEX | B12: Mexico | C12: 2025 | D12: 35301.59 | E12: Mex$B | F12: As reported ACTUAL | G12: 10/15/2026 | H12: capiq-sales-drivers-X1_2026-10-24.md | I12: 36 | J12: =IF(D11=0,"",D12/D11-1) -> 0.051177534 | K12: [calc]
A13: MEX | B13: Mexico | C13: 2026 | D13: 37481.45 | E13: Mex$B | F13: Standardized FORECAST | G13: 10/15/2026 | H13: capiq-sales-drivers-M1_2026-10-24.md | I13: 24 | J13: =IF(D12=0,"",D13/D12-1) -> 0.061749627 | K13: [calc]
A14: MEX | B14: Mexico | C14: 2027 | D14: 39990.58 | E14: Mex$B | F14: Standardized FORECAST | G14: 10/15/2026 | H14: capiq-sales-drivers-M1_2026-10-24.md | I14: 25 | J14: =IF(D13=0,"",D14/D13-1) -> 0.066943248 | K14: [calc]
... A17: MEX | B17: Mexico | C17: 2030 | D17: 47039.53 | E17: Mex$B | F17: Standardized FORECAST | G17: 10/15/2026 | H17: capiq-sales-drivers-M1_2026-10-24.md | I17: 28 | J17: =IF(D16=0,"",D17/D16-1) -> 0.04875605 | K17: [calc]
A18: USA | B18: North America | C18: 2015 | D18: 18295.02 | E18: $B | F18: As reported ACTUAL | G18: 10/07/2026 | H18: capiq-sales-drivers-X1_2026-10-24.md | I18: 48 | K18: [sourced] level only
A19: USA | B19: North America | C19: 2016 | D19: 18804.91 | E19: $B | F19: As reported ACTUAL | G19: 10/07/2026 | H19: capiq-sales-drivers-X1_2026-10-24.md | I19: 49 | J19: =IF(D18=0,"",D19/D18-1) -> 0.027870426 | K19: [calc]
A20: USA | B20: North America | C20: 2017 | D20: 19612.1 | E20: $B | F20: As reported ACTUAL | G20: 10/07/2026 | H20: capiq-sales-drivers-X1_2026-10-24.md | I20: 50 | J20: =IF(D19=0,"",D20/D19-1) -> 0.042924428 | K20: [calc]
A21: USA | B21: North America | C21: 2018 | D21: 20656.52 | E21: $B | F21: As reported ACTUAL | G21: 10/07/2026 | H21: capiq-sales-drivers-X1_2026-10-24.md | I21: 51 | J21: =IF(D20=0,"",D21/D20-1) -> 0.053253859 | K21: [calc]
A22: USA | B22: North America | C22: 2019 | D22: 21539.98 | E22: $B | F22: As reported ACTUAL | G22: 10/07/2026 | H22: capiq-sales-drivers-X1_2026-10-24.md | I22: 52 | J22: =IF(D21=0,"",D22/D21-1) -> 0.042769063 | K22: [calc]
A23: USA | B23: North America | C23: 2020 | D23: 21375.28 | E23: $B | F23: As reported ACTUAL | G23: 10/15/2026 | H23: capiq-sales-drivers-X1_2026-10-24.md | I23: 53 | J23: =IF(D22=0,"",D23/D22-1) -> -0.0076462467 | K23: [calc]
A24: USA | B24: North America | C24: 2021 | D24: 23745.85 | E24: $B | F24: As reported ACTUAL | G24: 10/15/2026 | H24: capiq-sales-drivers-X1_2026-10-24.md | I24: 54 | J24: =IF(D23=0,"",D24/D23-1) -> 0.11090241 | K24: [calc]
A25: USA | B25: North America | C25: 2022 | D25: 26059.71 | E25: $B | F25: As reported ACTUAL | G25: 10/15/2026 | H25: capiq-sales-drivers-X1_2026-10-24.md | I25: 55 | J25: =IF(D24=0,"",D25/D24-1) -> 0.097442711 | K25: [calc]
A26: USA | B26: North America | C26: 2023 | D26: 27825.89 | E26: $B | F26: As reported ACTUAL | G26: 10/15/2026 | H26: capiq-sales-drivers-X1_2026-10-24.md | I26: 56 | J26: =IF(D25=0,"",D26/D25-1) -> 0.067774354 | K26: [calc]
A27: USA | B27: North America | C27: 2024 | D27: 29380.99 | E27: $B | F27: As reported ACTUAL | G27: 10/15/2026 | H27: capiq-sales-drivers-X1_2026-10-24.md | I27: 57 | J27: =IF(D26=0,"",D27/D26-1) -> 0.055886802 | K27: [calc]
A28: USA | B28: North America | C28: 2025 | D28: 30861.29 | E28: $B | F28: As reported ACTUAL | G28: 10/15/2026 | H28: capiq-sales-drivers-X1_2026-10-24.md | I28: 58 | J28: =IF(D27=0,"",D28/D27-1) -> 0.050382918 | K28: [calc]
A29: USA | B29: North America | C29: 2026 | D29: 32710.81 | E29: $B | F29: Standardized FORECAST | G29: 10/15/2026 | H29: capiq-sales-drivers-M1_2026-10-24.md | I29: 39 | J29: =IF(D28=0,"",D29/D28-1) -> 0.059930094 | K29: [calc]
A30: USA | B30: North America | C30: 2027 | D30: 34488.98 | E30: $B | F30: Standardized FORECAST | G30: 10/15/2026 | H30: capiq-sales-drivers-M1_2026-10-24.md | I30: 40 | J30: =IF(D29=0,"",D30/D29-1) -> 0.054360317 | K30: [calc]
... A33: USA | B33: North America | C33: 2030 | D33: 39193.65 | E33: $B | F33: Standardized FORECAST | G33: 10/15/2026 | H33: capiq-sales-drivers-M1_2026-10-24.md | I33: 43 | J33: =IF(D32=0,"",D33/D32-1) -> 0.041287357 | K33: [calc]
A34: CAN | B34: North America | C34: 2015 | D34: 1990.44 | E34: C$B | F34: As reported ACTUAL | G34: 07/15/2026 | H34: capiq-sales-drivers-X1_2026-10-24.md | I34: 70 | K34: [sourced] level only
A35: CAN | B35: North America | C35: 2016 | D35: 2025.54 | E35: C$B | F35: As reported ACTUAL | G35: 07/15/2026 | H35: capiq-sales-drivers-X1_2026-10-24.md | I35: 71 | J35: =IF(D34=0,"",D35/D34-1) -> 0.017634292 | K35: [calc]
A36: CAN | B36: North America | C36: 2017 | D36: 2140.64 | E36: C$B | F36: As reported ACTUAL | G36: 07/15/2026 | H36: capiq-sales-drivers-X1_2026-10-24.md | I36: 72 | J36: =IF(D35=0,"",D36/D35-1) -> 0.056824353 | K36: [calc]
A37: CAN | B37: North America | C37: 2018 | D37: 2235.68 | E37: C$B | F37: As reported ACTUAL | G37: 07/15/2026 | H37: capiq-sales-drivers-X1_2026-10-24.md | I37: 73 | J37: =IF(D36=0,"",D37/D36-1) -> 0.044397937 | K37: [calc]
A38: CAN | B38: North America | C38: 2019 | D38: 2313.56 | E38: C$B | F38: As reported ACTUAL | G38: 07/15/2026 | H38: capiq-sales-drivers-X1_2026-10-24.md | I38: 74 | J38: =IF(D37=0,"",D38/D37-1) -> 0.034835039 | K38: [calc]
A39: CAN | B39: North America | C39: 2020 | D39: 2220.53 | E39: C$B | F39: As reported ACTUAL | G39: 07/15/2026 | H39: capiq-sales-drivers-X1_2026-10-24.md | I39: 75 | J39: =IF(D38=0,"",D39/D38-1) -> -0.040210757 | K39: [calc]
A40: CAN | B40: North America | C40: 2021 | D40: 2535.82 | E40: C$B | F40: As reported ACTUAL | G40: 07/15/2026 | H40: capiq-sales-drivers-X1_2026-10-24.md | I40: 76 | J40: =IF(D39=0,"",D40/D39-1) -> 0.14198862 | K40: [calc]
A41: CAN | B41: North America | C41: 2022 | D41: 2864.16 | E41: C$B | F41: As reported ACTUAL | G41: 07/15/2026 | H41: capiq-sales-drivers-X1_2026-10-24.md | I41: 77 | J41: =IF(D40=0,"",D41/D40-1) -> 0.1294808 | K41: [calc]
A42: CAN | B42: North America | C42: 2023 | D42: 2965.2 | E42: C$B | F42: As reported ACTUAL | G42: 07/15/2026 | H42: capiq-sales-drivers-X1_2026-10-24.md | I42: 78 | J42: =IF(D41=0,"",D42/D41-1) -> 0.035277359 | K42: [calc]
A43: CAN | B43: North America | C43: 2024 | D43: 3108.55 | E43: C$B | F43: As reported ACTUAL | G43: 07/15/2026 | H43: capiq-sales-drivers-X1_2026-10-24.md | I43: 79 | J43: =IF(D42=0,"",D43/D42-1) -> 0.048344125 | K43: [calc]
A44: CAN | B44: North America | C44: 2025 | D44: 3245.26 | E44: C$B | F44: As reported ACTUAL | G44: 07/15/2026 | H44: capiq-sales-drivers-X1_2026-10-24.md | I44: 80 | J44: =IF(D43=0,"",D44/D43-1) -> 0.043978704 | K44: [calc]
...

Sheet Growth_view
A1: iso3 | B1: region | C1: 2016 | D1: 2017 | E1: 2018 | F1: 2019 | G1: 2020 | H1: 2021 | I1: 2022 | J1: 2023 | K1: 2024 | L1: 2025 | M1: 2026 | N1: 2027 | O1: 2028 | P1: 2029 | Q1: 2030
A2: MEX | B2: Mexico | C2: =Data!J3 -> 0.079578295 | D2: =Data!J4 -> 0.085622524 | E2: =Data!J5 -> 0.072792186 | F2: =Data!J6 -> 0.039093473 | G2: =Data!J7 -> -0.041201633 | H2: =Data!J8 -> 0.10807888 | I2: =Data!J9 -> 0.10623742 | J2: =Data!J10 -> 0.079442489 | K2: =Data!J11 -> 0.053710432 | L2: =Data!J12 -> 0.051177534 | M2: =Data!J13 -> 0.061749627 | N2: =Data!J14 -> 0.066943248 | O2: =Data!J15 -> 0.060058894 | P2: =Data!J16 -> 0.058036859 | Q2: =Data!J17 -> 0.04875605
A3: USA | B3: North America | C3: =Data!J19 -> 0.027870426 | D3: =Data!J20 -> 0.042924428 | E3: =Data!J21 -> 0.053253859 | F3: =Data!J22 -> 0.042769063 | G3: =Data!J23 -> -0.0076462467 | H3: =Data!J24 -> 0.11090241 | I3: =Data!J25 -> 0.097442711 | J3: =Data!J26 -> 0.067774354 | K3: =Data!J27 -> 0.055886802 | L3: =Data!J28 -> 0.050382918 | M3: =Data!J29 -> 0.059930094 | N3: =Data!J30 -> 0.054360317 | O3: =Data!J31 -> 0.047543882 | P3: =Data!J32 -> 0.041819638 | Q3: =Data!J33 -> 0.041287357
A4: CAN | B4: North America | C4: =Data!J35 -> 0.017634292 | D4: =Data!J36 -> 0.056824353 | E4: =Data!J37 -> 0.044397937 | F4: =Data!J38 -> 0.034835039 | G4: =Data!J39 -> -0.040210757 | H4: =Data!J40 -> 0.14198862 | I4: =Data!J41 -> 0.1294808 | J4: =Data!J42 -> 0.035277359 | K4: =Data!J43 -> 0.048344125 | L4: =Data!J44 -> 0.043978704 | M4: =Data!J45 -> 0.05642383 | N4: =Data!J46 -> 0.06478589 | O4: =Data!J47 -> 0.047215709 | P4: =Data!J48 -> 0.036349939 | Q4: =Data!J49 -> 0.040860215
A5: ARG | B5: Latin America | C5: =Data!J51 -> 0.38183662 | D5: =Data!J52 -> 0.29557884 | E5: =Data!J53 -> 0.38316059 | F5: =Data!J54 -> 0.46210361 | G5: =Data!J55 -> 0.26214188 | H5: =Data!J56 -> 0.69861826 | I5: =Data!J57 -> 0.79168538 | J5: =Data!J58 -> 1.3420609 | K5: =Data!J59 -> 2.0130885 | L5: =Data!J60 -> 0.4549508 | M5: =Data!J61 -> 0.33527866 | N5: =Data!J62 -> 0.18138872 | O5: =Data!J63 -> 0.10103969 | P5: =Data!J64 -> 0.079943169 | Q5: =Data!J65 -> 0.077944282
A6: BRA | B6: Latin America | C6: =Data!J67 -> 0.045622011 | D6: =Data!J68 -> 0.050428036 | E6: =Data!J69 -> 0.063573194 | F6: =Data!J70 -> 0.054966063 | G6: =Data!J71 -> 0.029837071 | H6: =Data!J72 -> 0.18431192 | I6: =Data!J73 -> 0.11845577 | J6: =Data!J74 -> 0.085683276 | K6: =Data!J75 -> 0.076385272 | L6: =Data!J76 -> 0.081441518 | M6: =Data!J77 -> 0.07209993 | N6: =Data!J78 -> 0.056305109 | O6: =Data!J79 -> 0.052576671 | P6: =Data!J80 -> 0.063255502 | Q6: =Data!J81 -> 0.07117272
A7: CHL | B7: Latin America | C7: =Data!J83 -> 0.063926365 | D7: =Data!J84 -> 0.062514814 | E7: =Data!J85 -> 0.05643857 | F7: =Data!J86 -> 0.032307449 | G7: =Data!J87 -> 0.029455382 | H7: =Data!J88 -> 0.19000546 | I7: =Data!J89 -> 0.097637335 | J7: =Data!J90 -> 0.072827534 | K7: =Data!J91 -> 0.10131159 | L7: =Data!J92 -> 0.094309257 | M7: =Data!J93 -> 0.073239602 | N7: =Data!J94 -> 0.076216838 | O7: =Data!J95 -> 0.0593598 | P7: =Data!J96 -> 0.079495192 | Q7: =Data!J97 -> 0.080566504
A8: COL | B8: Latin America | C8: =Data!J99 -> 0.073432005 | D8: =Data!J100 -> 0.065630137 | E8: =Data!J101 -> 0.07313655 | F8: =Data!J102 -> 0.073173448 | G8: =Data!J103 -> -0.05810937 | H8: =Data!J104 -> 0.19445752 | I8: =Data!J105 -> 0.2334756 | J8: =Data!J106 -> 0.078935204 | K8: =Data!J107 -> 0.079460685 | L8: =Data!J108 -> 0.081333318 | M8: =Data!J109 -> 0.090814878 | N8: =Data!J110 -> 0.084407102 | O8: =Data!J111 -> 0.071371207 | P8: =Data!J112 -> 0.068264968 | Q8: =Data!J113 -> 0.070425287
A9: CRI | B9: Latin America | C9: =Data!J115 -> 0.062454428 | D9: =Data!J116 -> 0.071354483 | E9: =Data!J117 -> 0.051136964 | F9: =Data!J118 -> 0.053448931 | G9: =Data!J119 -> -0.03401975 | H9: =Data!J120 -> 0.10836836 | I9: =Data!J121 -> 0.12846919 | J9: =Data!J122 -> 0.036212681 | K9: =Data!J123 -> 0.046372375 | L9: =Data!J124 -> 0.04000729 | M9: =Data!J125 -> 0.0244027 | N9: =Data!J126 -> 0.049777247 | O9: =Data!J127 -> 0.051734185 | P9: =Data!J128 -> 0.051594139 | Q9: =Data!J129 -> 0.052014525
A10: ECU | B10: Latin America | C10: =Data!J131 -> 0.0047320235 | D10: =Data!J132 -> 0.069622197 | E10: =Data!J133 -> 0.028812099 | F10: =Data!J134 -> 0.0011164868 | G10: =Data!J135 -> -0.10901487 | H10: =Data!J136 -> 0.11797225 | I10: =Data!J137 -> 0.083504385 | J10: =Data!J138 -> 0.040127443 | K10: =Data!J139 -> 0.024919281 | L10: =Data!J140 -> 0.05266559 | M10: =Data!J141 -> 0.056169429 | N10: =Data!J142 -> 0.053327521 | O10: =Data!J143 -> 0.045868396 | P10: =Data!J144 -> 0.042471806 | Q10: =Data!J145 -> 0.042576074
A11: SLV | B11: Latin America | C11: =Data!J147 -> 0.031996587 | D11: =Data!J148 -> 0.032658123 | E11: =Data!J149 -> 0.041633307 | F11: =Data!J150 -> 0.033051499 | G11: =Data!J151 -> -0.072916667 | H11: =Data!J152 -> 0.16532905 | I11: =Data!J153 -> 0.097451791 | J11: =Data!J154 -> 0.053341701 | K11: =Data!J155 -> 0.039022937 | L11: =Data!J156 -> 0.052465596 | M11: =Data!J157 -> 0.045219286 | N11: =Data!J158 -> 0.043262966 | O11: =Data!J159 -> 0.039220585 | P11: =Data!J160 -> 0.038461538 | Q11: =Data!J161 -> 0.038657407
A12: GTM | B12: Latin America | C12: =Data!J163 -> 0.054577539 | D12: =Data!J164 -> 0.048824701 | E12: =Data!J165 -> 0.047216577 | F12: =Data!J166 -> 0.077262093 | G12: =Data!J167 -> 0.010354058 | H12: =Data!J168 -> 0.11424382 | I12: =Data!J169 -> 0.10786923 | J12: =Data!J170 -> 0.1026579 | K12: =Data!J171 -> 0.075325025 | L12: =Data!J172 -> 0.078120197 | M12: =Data!J173 -> 0.07308265 | N12: =Data!J174 -> 0.10540041 | O12: =Data!J175 -> 0.0981813 | P12: =Data!J176 -> 0.1002821 | Q12: =Data!J177 -> 0.099784135
A13: HND | B13: Latin America | C13: =Data!J179 -> 0.077126909 | D13: =Data!J180 -> 0.095741249 | E13: =Data!J181 -> 0.058667648 | F13: =Data!J182 -> 0.060057711 | G13: =Data!J183 -> -0.058688487 | H13: =Data!J184 -> 0.17749634 | I13: =Data!J185 -> 0.1384167 | J13: =Data!J186 -> 0.098402838 | K13: =Data!J187 -> 0.085032122 | L13: =Data!J188 -> 0.1206874 | M13: =Data!J189 -> 0.092054565 | N13: =Data!J190 -> 0.081229897 | O13: =Data!J191 -> 0.073479243 | P13: =Data!J192 -> 0.069209571 | Q13: =Data!J193 -> 0.067680401
A14: NIC | B14: Latin America | C14: =Data!J195 -> 0.093612493 | D14: =Data!J196 -> 0.089465103 | E14: =Data!J197 -> -0.0079414888 | F14: =Data!J198 -> 0.023406896 | G14: =Data!J199 -> 0.039086089 | H14: =Data!J200 -> 0.14346185 | I14: =Data!J201 -> 0.12232116 | J14: =Data!J202 -> 0.15687848 | K14: =Data!J203 -> 0.11171729 | L14: =Data!J204 -> 0.12900632 | M14: =Data!J205 -> 0.070651507 | N14: =Data!J206 -> 0.065966329 | O14: =Data!J207 -> 0.074794509 | P14: =Data!J208 -> 0.065915916 | Q14: =Data!J209 -> 0.0632953
A15: PAN | B15: Latin America | C15: =Data!J211 -> 0.070623036 | D15: =Data!J212 -> 0.07408047 | E15: =Data!J213 -> 0.082315113 | F15: =Data!J214 -> 0.036541889 | G15: =Data!J215 -> -0.18228719 | H15: =Data!J216 -> 0.18121276 | I15: =Data!J217 -> 0.1347181 | J15: =Data!J218 -> 0.095972803 | K15: =Data!J219 -> 0.032689096 | L15: =Data!J220 -> 0.047828096 | M15: =Data!J221 -> 0.065159868 | N15: =Data!J222 -> 0.054031674 | O15: =Data!J223 -> 0.04998527 | P15: =Data!J224 -> 0.050224467 | Q15: =Data!J225 -> 0.05004898
A16: PRY | B16: Latin America | C16: =Data!J227 -> 0.085791596 | D16: =Data!J228 -> 0.070706084 | E16: =Data!J229 -> 0.05230011 | F16: =Data!J230 -> 0.026455026 | G16: =Data!J231 -> 0.013647118 | H16: =Data!J232 -> 0.12767288 | I16: =Data!J233 -> 0.079951209 | J16: =Data!J234 -> 0.076256974 | K16: =Data!J235 -> 0.075655907 | L16: =Data!J236 -> 0.099308184 | M16: =Data!J237 -> 0.078933921 | N16: =Data!J238 -> 0.055760507 | O16: =Data!J239 -> 0.075622713 | P16: =Data!J240 -> 0.067276878 | Q16: =Data!J241 -> 0.065421714
A17: PER | B17: Latin America | C17: =Data!J243 -> 0.084403107 | D17: =Data!J244 -> 0.065980702 | E17: =Data!J245 -> 0.055317306 | F17: =Data!J246 -> 0.044263836 | G17: =Data!J247 -> -0.069627714 | H17: =Data!J248 -> 0.21563258 | I17: =Data!J249 -> 0.067413841 | J17: =Data!J250 -> 0.06901512 | K17: =Data!J251 -> 0.089467946 | L17: =Data!J252 -> 0.094372622 | M17: =Data!J253 -> 0.10654914 | N17: =Data!J254 -> 0.059237366 | O17: =Data!J255 -> 0.051995699 | P17: =Data!J256 -> 0.05032102 | Q17: =Data!J257 -> 0.05512973
A18: URY | B18: Latin America | C18: =Data!J259 -> 0.070182153 | D18: =Data!J260 -> 0.075194518 | E18: =Data!J261 -> 0.077027476 | F18: =Data!J262 -> 0.092612054 | G18: =Data!J263 -> 0.025769601 | H18: =Data!J264 -> 0.1756555 | I18: =Data!J265 -> 0.10871455 | J18: =Data!J266 -> 0.048457924 | K18: =Data!J267 -> 0.076496086 | L18: =Data!J268 -> 0.061952677 | M18: =Data!J269 -> 0.049119334 | N18: =Data!J270 -> 0.063581151 | O18: =Data!J271 -> 0.073304102 | P18: =Data!J272 -> 0.074442135 | Q18: =Data!J273 -> 0.073155204
A19: VEN | B19: Latin America | C19: =Data!J275 -> 2.5 | D19: =Data!J276 -> 6.1785714 | E19: =Data!J277 -> -1 | F19: =Data!J278 | G19: =Data!J279 -> 40.83871 | H19: =Data!J280 -> 15.444102 | I19: =Data!J281 -> 2.437922 | J19: =Data!J282 -> 1.9624816 | K19: =Data!J283 -> 1.0148052 | L19: =Data!J284 -> 2.8092597 | M19: =Data!J285 -> 3.7878125 | N19: =Data!J286 -> 0.82465683 | O19: =Data!J287 -> 0.38505682 | P19: =Data!J288 -> 0.25573277 | Q19: =Data!J289 -> 0.17196854
A20: GBR | B20: EAA | C20: =Data!J291 -> 0.039716525 | D20: =Data!J292 -> 0.048306433 | E20: =Data!J293 -> 0.036001541 | F20: =Data!J294 -> 0.039176346 | G20: =Data!J295 -> -0.058186027 | H20: =Data!J296 -> 0.094345907 | I20: =Data!J297 -> 0.11055576 | J20: =Data!J298 -> 0.067814078 | K20: =Data!J299 -> 0.050064162 | L20: =Data!J300 -> 0.048069674 | M20: =Data!J301 -> 0.039154697 | N20: =Data!J302 -> 0.035052785 | O20: =Data!J303 -> 0.03943262 | P20: =Data!J304 -> 0.041174207 | Q20: =Data!J305 -> 0.040762081
A21: CHE | B21: EAA | C21: =Data!J307 -> 0.01290408 | D21: =Data!J308 -> 0.01080767 | E21: =Data!J309 -> 0.041015176 | F21: =Data!J310 -> 0.010243242 | G21: =Data!J311 -> -0.029994534 | H21: =Data!J312 -> 0.082313165 | I21: =Data!J313 -> 0.066928724 | J21: =Data!J314 -> 0.021300476 | K21: =Data!J315 -> 0.028393617 | L21: =Data!J316 -> 0.023974075 | M21: =Data!J317 -> 0.019272434 | N21: =Data!J318 -> 0.025919249 | O21: =Data!J319 -> 0.027509899 | P21: =Data!J320 -> 0.025506487 | Q21: =Data!J321 -> 0.021093919
A22: ROU | B22: EAA | C22: =Data!J323 -> 0.055546979 | D22: =Data!J324 -> 0.13227766 | E22: =Data!J325 -> 0.11832742 | F22: =Data!J326 -> 0.10583899 | G22: =Data!J327 -> 0.0029529335 | H22: =Data!J328 -> 0.11694594 | I22: =Data!J329 -> 0.16835476 | J22: =Data!J330 -> 0.1519812 | K22: =Data!J331 -> 0.1130759 | L22: =Data!J332 -> 0.091885806 | M22: =Data!J333 -> 0.086386553 | N22: =Data!J334 -> 0.075806644 | O22: =Data!J335 -> 0.057013908 | P22: =Data!J336 -> 0.073798649 | Q22: =Data!J337 -> 0.071714828
A23: SRB | B23: EAA | C23: =Data!J339 -> 0.045649063 | D23: =Data!J340 -> 0.054316458 | E23: =Data!J341 -> 0.067422557 | F23: =Data!J342 -> 0.072097338 | G23: =Data!J343 -> 0.016741221 | H23: =Data!J344 -> 0.14084817 | I23: =Data!J345 -> 0.13444606 | J23: =Data!J346 -> 0.18200329 | K23: =Data!J347 -> 0.10550686 | L23: =Data!J348 -> 0.066107182 | M23: =Data!J349 -> 0.075674344 | N23: =Data!J350 -> 0.050056579 | O23: =Data!J351 -> 0.054625113 | P23: =Data!J352 -> 0.049093011 | Q23: =Data!J353 -> 0.0343062
A24: SVN | B24: EAA | C24: =Data!J355 -> 0.039490777 | D24: =Data!J356 -> 0.065483629 | E24: =Data!J357 -> 0.066385175 | F24: =Data!J358 -> 0.059392873 | G24: =Data!J359 -> -0.02948505 | H24: =Data!J360 -> 0.11317929 | I24: =Data!J361 -> 0.093599846 | J24: =Data!J362 -> 0.12688928 | K24: =Data!J363 -> 0.052401747 | L24: =Data!J364 -> 0.054682869 | M24: =Data!J365 -> 0.050442602 | N24: =Data!J366 -> 0.065676833 | O24: =Data!J367 -> 0.052089871 | P24: =Data!J368 -> 0.051419709 | Q24: =Data!J369 -> 0.051174401
A25: HRV | B25: EAA | C25: =Data!J371 -> 0.034805308 | D25: =Data!J372 -> 0.045406769 | E25: =Data!J373 -> 0.05007038 | F25: =Data!J374 -> 0.05151283 | G25: =Data!J375 -> -0.075942451 | H25: =Data!J376 -> 0.14978321 | I25: =Data!J377 -> 0.15889613 | J25: =Data!J378 -> 0.17127644 | K25: =Data!J379 -> 0.084859199 | L25: =Data!J380 -> 0.082295425 | M25: =Data!J381 -> 0.065497957 | N25: =Data!J382 -> 0.056121934 | O25: =Data!J383 -> 0.051323712 | P25: =Data!J384 -> 0.051909091 | Q25: =Data!J385 -> 0.047878316
A26: MNE | B26: EAA | C26: =Data!J387 -> 0.091412742 | D26: =Data!J388 -> 0.078680203 | E26: =Data!J389 -> 0.082352941 | F26: =Data!J390 -> 0.065217391 | G26: =Data!J391 -> -0.15510204 | H26: =Data!J392 -> 0.1884058 | I26: =Data!J393 -> 0.20731707 | J26: =Data!J394 -> 0.19023569 | K26: =Data!J395 -> 0.080622348 | L26: =Data!J396 -> 0.082460733 | M26: =Data!J397 -> 0.054413543 | N26: =Data!J398 -> 0.064220183 | O26: =Data!J399 -> 0.061422414 | P26: =Data!J400 -> 0.059898477 | Q26: =Data!J401 -> 0.058429119
A27: MKD | B27: EAA | C27: =Data!J403 -> 0.064120225 | D27: =Data!J404 -> 0.039207115 | E27: =Data!J405 -> 0.069194804 | F27: =Data!J406 -> 0.048117661 | G27: =Data!J407 -> -0.033781833 | H27: =Data!J408 -> 0.08988764 | I27: =Data!J409 -> 0.11877605 | J27: =Data!J410 -> 0.10639888 | K27: =Data!J411 -> 0.067758691 | L27: =Data!J412 -> 0.082761983 | M27: =Data!J413 -> 0.072565812 | N27: =Data!J414 -> 0.069531899 | O27: =Data!J415 -> 0.055140796 | P27: =Data!J416 -> 0.053873733 | Q27: =Data!J417 -> 0.051420117
A28: RUS | B28: EAA | C28: =Data!J419 -> 0.030434473 | D28: =Data!J420 -> 0.072732482 | E28: =Data!J421 -> 0.13085897 | F28: =Data!J422 -> 0.055329951 | G28: =Data!J423 -> -0.017792264 | H28: =Data!J424 -> 0.25143795 | I28: =Data!J425 -> 0.16532575 | J28: =Data!J426 -> 0.10996298 | K28: =Data!J427 -> 0.16098822 | L28: =Data!J428 -> 0.059018055 | M28: =Data!J429 -> 0.10087252 | N28: =Data!J430 -> 0.07246744 | O28: =Data!J431 -> 0.04676368 | P28: =Data!J432 -> 0.070421773 | Q28: =Data!J433 -> 0.074451036
A29: UKR | B29: EAA | C29: =Data!J435 -> 0.19955847 | D29: =Data!J436 -> 0.24979773 | E29: =Data!J437 -> 0.19423862 | F29: =Data!J438 -> 0.11709687 | G29: =Data!J439 -> 0.061558383 | H29: =Data!J440 -> 0.29104957 | I29: =Data!J441 -> -0.038845318 | J29: =Data!J442 -> 0.26509274 | K29: =Data!J443 -> 0.15606914 | L29: =Data!J444 -> 0.16558954 | M29: =Data!J445 -> 0.0962395 | N29: =Data!J446 -> 0.18650762 | O29: =Data!J447 -> 0.1972805 | P29: =Data!J448 -> 0.20549831 | Q29: =Data!J449 -> 0.18495488
A30: TUR | B30: EAA | C30: =Data!J451 -> 0.11721451 | D30: =Data!J452 -> 0.19830494 | E30: =Data!J453 -> 0.20781969 | F30: =Data!J454 -> 0.15646214 | G30: =Data!J455 -> 0.16802626 | H30: =Data!J456 -> 0.4457836 | I30: =Data!J457 -> 1.0616455 | J30: =Data!J458 -> 0.76769656 | K30: =Data!J459 -> 0.64907884 | L30: =Data!J460 -> 0.4155377 | M30: =Data!J461 -> 0.30665276 | N30: =Data!J462 -> 0.20545857 | O30: =Data!J463 -> 0.15906133 | P30: =Data!J464 -> 0.13635358 | Q30: =Data!J465 -> 0.1350944
A31: KAZ | B31: EAA | C31: =Data!J467 -> 0.14888467 | D31: =Data!J468 -> 0.15770766 | E31: =Data!J469 -> 0.13683038 | F31: =Data!J470 -> 0.12476783 | G31: =Data!J471 -> 0.016055771 | H31: =Data!J472 -> 0.18829077 | I31: =Data!J473 -> 0.23601614 | J31: =Data!J474 -> 0.1510788 | K31: =Data!J475 -> 0.14442983 | L31: =Data!J476 -> 0.16763972 | M31: =Data!J477 -> 0.15262336 | N31: =Data!J478 -> 0.12378759 | O31: =Data!J479 -> 0.12436113 | P31: =Data!J480 -> 0.11494272 | Q31: =Data!J481 -> 0.10755211
A32: CHN | B32: EAA | C32: =Data!J483 -> 0.083531017 | D32: =Data!J484 -> 0.11323002 | E32: =Data!J485 -> 0.10458932 | F32: =Data!J486 -> 0.074638404 | G32: =Data!J487 -> 0.028825923 | H32: =Data!J488 -> 0.1342736 | I32: =Data!J489 -> 0.051290868 | J32: =Data!J490 -> 0.048817557 | K32: =Data!J491 -> 0.04156353 | L32: =Data!J492 -> 0.039918663 | M32: =Data!J493 -> 0.05812819 | N32: =Data!J494 -> 0.056284419 | O32: =Data!J495 -> 0.055110723 | P32: =Data!J496 -> 0.05559696 | Q32: =Data!J497 -> 0.056332149
A33: IND | B33: EAA | C33: =Data!J499 -> 0.11754291 | D33: =Data!J500 -> 0.11115583 | E33: =Data!J501 -> 0.12358235 | F33: =Data!J502 -> 0.057435636 | G33: =Data!J503 -> -0.025866181 | H33: =Data!J504 -> 0.18635267 | I33: =Data!J505 -> 0.11774009 | J33: =Data!J506 -> 0.10745392 | K33: =Data!J507 -> 0.10105933 | L33: =Data!J508 -> 0.084341894 | M33: =Data!J509 -> 0.13607713 | N33: =Data!J510 -> 0.1289866 | O33: =Data!J511 -> 0.13175973 | P33: =Data!J512 -> 0.12188021 | Q33: =Data!J513 -> 0.11020998
A34: KOR | B34: EAA | C34: =Data!J515 -> 0.052993486 | D34: =Data!J516 -> 0.055209135 | E34: =Data!J517 -> 0.037606696 | F34: =Data!J518 -> 0.016751621 | G34: =Data!J519 -> 0.0087621717 | H34: =Data!J520 -> 0.080278071 | I34: =Data!J521 -> 0.046970842 | J34: =Data!J522 -> 0.034108334 | K34: =Data!J523 -> 0.065052875 | L34: =Data!J524 -> 0.043861633 | M34: =Data!J525 -> 0.05955636 | N34: =Data!J526 -> 0.048119645 | O34: =Data!J527 -> 0.039327691 | P34: =Data!J528 -> 0.035685373 | Q34: =Data!J529 -> 0.034515309
A35: ZAF | B35: EAA | C35: =Data!J531 -> 0.076628838 | D35: =Data!J532 -> 0.066947506 | E35: =Data!J533 -> 0.056122359 | F35: =Data!J534 -> 0.048855252 | G35: =Data!J535 -> -0.011101808 | H35: =Data!J536 -> 0.11578425 | I35: =Data!J537 -> 0.074069897 | J35: =Data!J538 -> 0.055664224 | K35: =Data!J539 -> 0.044727872 | L35: =Data!J540 -> 0.039352869 | M35: =Data!J541 -> 0.057182938 | N35: =Data!J542 -> 0.052561219 | O35: =Data!J543 -> 0.056710257 | P35: =Data!J544 -> 0.064822389 | Q35: =Data!J545 -> 0.068074121
A36: MAR | B36: EAA | C36: =Data!J547 -> 0.014961229 | D36: =Data!J548 -> 0.049942883 | E36: =Data!J549 -> 0.040334233 | F36: =Data!J550 -> 0.037314682 | G36: =Data!J551 -> -0.070460705 | H36: =Data!J552 -> 0.10766347 | I36: =Data!J553 -> 0.044635583 | J36: =Data!J554 -> 0.11405732 | K36: =Data!J555 -> 0.086784147 | L36: =Data!J556 -> 0.065422992 | M36: =Data!J557 -> 0.0531814 | N36: =Data!J558 -> 0.047821902 | O36: =Data!J559 -> 0.052349977 | P36: =Data!J560 -> 0.053499375 | Q36: =Data!J561 -> 0.074016561
A37: TUN | B37: EAA | C37: =Data!J563 -> 0.061135857 | D37: =Data!J564 -> 0.070521566 | E37: =Data!J565 -> 0.10763651 | F37: =Data!J566 -> 0.088326401 | G37: =Data!J567 -> -0.028218265 | H37: =Data!J568 -> 0.10075314 | I37: =Data!J569 -> 0.060057777 | J37: =Data!J570 -> 0.074225473 | K37: =Data!J571 -> 0.067160692 | L37: =Data!J572 -> 0.073756647 | M37: =Data!J573 -> 0.057620601 | N37: =Data!J574 -> 0.091995813 | O37: =Data!J575 -> 0.082278162 | P37: =Data!J576 -> 0.066654237 | Q37: =Data!J577 -> 0.048898794
A38: ESP | B38: EAA | C38: =Data!J579 -> 0.032986542 | D38: =Data!J580 -> 0.041897825 | E38: =Data!J581 -> 0.036119041 | F38: =Data!J582 -> 0.034175273 | G38: =Data!J583 -> -0.099305262 | H38: =Data!J584 -> 0.094101186 | I38: =Data!J585 -> 0.11363287 | J38: =Data!J586 -> 0.08752344 | K38: =Data!J587 -> 0.06837624 | L38: =Data!J588 -> 0.057187897 | M38: =Data!J589 -> 0.052638742 | N38: =Data!J590 -> 0.041400361 | O38: =Data!J591 -> 0.037314722 | P38: =Data!J592 -> 0.038537791 | Q38: =Data!J593 -> 0.039272275
A39: PRT | B39: EAA | C39: =Data!J595 -> 0.038965383 | D39: =Data!J596 -> 0.048985943 | E39: =Data!J597 -> 0.048539717 | F39: =Data!J598 -> 0.046292683 | G39: =Data!J599 -> -0.062753508 | H39: =Data!J600 -> 0.076903945 | I39: =Data!J601 -> 0.12688808 | J39: =Data!J602 -> 0.10817347 | K39: =Data!J603 -> 0.076937303 | L39: =Data!J604 -> 0.059728662 | M39: =Data!J605 -> 0.045407403 | N39: =Data!J606 -> 0.037389552 | O39: =Data!J607 -> 0.038612116 | P39: =Data!J608 -> 0.04379478 | Q39: =Data!J609 -> 0.039641626
A40: FRA | B40: EAA | C40: =Data!J611 -> 0.013818479 | D40: =Data!J612 -> 0.026821159 | E40: =Data!J613 -> 0.027787475 | F40: =Data!J614 -> 0.032627709 | G40: =Data!J615 -> -0.046842172 | H40: =Data!J616 -> 0.081879669 | I40: =Data!J617 -> 0.058171524 | J40: =Data!J618 -> 0.067758101 | K40: =Data!J619 -> 0.035785492 | L40: =Data!J620 -> 0.019017184 | M40: =Data!J621 -> 0.026117831 | N40: =Data!J622 -> 0.027932542 | O40: =Data!J623 -> 0.029915275 | P40: =Data!J624 -> 0.033828929 | Q40: =Data!J625 -> 0.033067299
...

Sheet IAS29_test
A1: CPI annual average [sourced]: Capital IQ consumerPriceInflation, % stored / 100. Source lines in column S
A2: iso3 | B2: region | C2: 2015 | D2: 2016 | E2: 2017 | F2: 2018 | G2: 2019 | H2: 2020 | I2: 2021 | J2: 2022 | K2: 2023 | L2: 2024 | M2: 2025 | N2: 2026 | O2: 2027 | P2: 2028 | Q2: 2029 | R2: 2030 | S2: source
A3: MEX | B3: Mexico | C3: 0.0272 | D3: 0.0282 | E3: 0.0604 | F3: 0.049 | G3: 0.0364 | H3: 0.034 | I3: 0.0569 | J3: 0.079 | K3: 0.0553 | L3: 0.0472 | M3: 0.0381 | N3: 0.0376 | O3: 0.039 | P3: 0.0372 | Q3: 0.0321 | R3: 0.0255 | S3: capiq-sales-drivers-M1_2026-10-24.md; capiq-sales-drivers-X1_2026-10-24.md L29-L47
A4: USA | B4: North America | C4: 0.0012 | D4: 0.0126 | E4: 0.0213 | F4: 0.0244 | G4: 0.0181 | H4: 0.0123 | I4: 0.047 | J4: 0.08 | K4: 0.0412 | L4: 0.0295 | M4: 0.0271 | N4: 0.0336 | O4: 0.0242 | P4: 0.0208 | Q4: 0.02 | R4: 0.0206 | S4: capiq-sales-drivers-M1_2026-10-24.md; capiq-sales-drivers-X1_2026-10-24.md L44-L69
A5: CAN | B5: North America | C5: 0.0113 | D5: 0.0143 | E5: 0.016 | F5: 0.0227 | G5: 0.0195 | H5: 0.0072 | I5: 0.034 | J5: 0.068 | K5: 0.0388 | L5: 0.0238 | M5: 0.0207 | N5: 0.0278 | O5: 0.0279 | P5: 0.0206 | Q5: 0.0182 | R5: 0.0186 | S5: capiq-sales-drivers-M1_2026-10-24.md; capiq-sales-drivers-X1_2026-10-24.md L59-L91
A6: ARG | B6: Latin America | C6: 0.1636 | D6: 0.3752 | E6: 0.2528 | F6: 0.3428 | G6: 0.5355 | H6: 0.4202 | I6: 0.4841 | J6: 0.7243 | K6: 1.3349 | L6: 2.1988 | M6: 0.4192 | N6: 0.327 | O6: 0.1779 | P6: 0.083 | Q6: 0.0667 | R6: 0.0709 | S6: capiq-sales-drivers-M2_2026-10-24.md; capiq-sales-drivers-X1_2026-10-24.md L32-L113
A7: BRA | B7: Latin America | C7: 0.0903 | D7: 0.0874 | E7: 0.0345 | F7: 0.0366 | G7: 0.0373 | H7: 0.0321 | I7: 0.083 | J7: 0.0928 | K7: 0.0459 | L7: 0.0437 | M7: 0.0502 | N7: 0.0459 | O7: 0.0487 | P7: 0.0351 | Q7: 0.0362 | R7: 0.0321 | S7: capiq-sales-drivers-M2_2026-10-24.md; capiq-sales-drivers-X1_2026-10-24.md L47-L135
A8: CHL | B8: Latin America | C8: 0.0435 | D8: 0.0378 | E8: 0.0218 | F8: 0.0244 | G8: 0.0256 | H8: 0.0305 | I8: 0.0452 | J8: 0.1164 | K8: 0.0758 | L8: 0.0427 | M8: 0.0421 | N8: 0.0375 | O8: 0.0366 | P8: 0.0289 | Q8: 0.0271 | R8: 0.0309 | S8: capiq-sales-drivers-M2_2026-10-24.md; capiq-sales-drivers-X1_2026-10-24.md L62-L157
A9: COL | B9: Latin America | C9: 0.0499 | D9: 0.0751 | E9: 0.0432 | F9: 0.0324 | G9: 0.0352 | H9: 0.0253 | I9: 0.035 | J9: 0.1018 | K9: 0.1174 | L9: 0.0661 | M9: 0.0514 | N9: 0.06 | O9: 0.0605 | P9: 0.0382 | Q9: 0.0344 | R9: 0.033 | S9: capiq-sales-drivers-M2_2026-10-24.md; capiq-sales-drivers-X1_2026-10-24.md L77-L179
A10: CRI | B10: Latin America | C10: 0.008 | D10: -0.0002 | E10: 0.0163 | F10: 0.0222 | G10: 0.021 | H10: 0.0072 | I10: 0.0173 | J10: 0.0827 | K10: 0.0053 | L10: -0.0041 | M10: -0.0007 | N10: -0.0056 | O10: 0.0344 | P10: 0.0195 | Q10: 0.0171 | R10: 0.0218 | S10: capiq-sales-drivers-M3_2026-10-24.md; capiq-sales-drivers-X1_2026-10-24.md L32-L201
A11: ECU | B11: Latin America | C11: 0.0397 | D11: 0.0173 | E11: 0.0042 | F11: -0.0022 | G11: 0.0027 | H11: -0.0034 | I11: 0.0013 | J11: 0.0347 | K11: 0.0222 | L11: 0.0155 | M11: 0.0071 | N11: 0.0237 | O11: 0.0269 | P11: 0.0218 | Q11: 0.0209 | R11: 0.0207 | S11: capiq-sales-drivers-M3_2026-10-24.md; capiq-sales-drivers-X1_2026-10-24.md L47-L223
A12: SLV | B12: Latin America | C12: -0.0073 | D12: 0.006 | E12: 0.0101 | F12: 0.0109 | G12: 0.0007 | H12: -0.0037 | I12: 0.0347 | J12: 0.072 | K12: 0.0405 | L12: 0.0085 | M12: 0.0026 | N12: 0.0242 | O12: 0.0262 | P12: 0.0246 | Q12: 0.0256 | R12: 0.0265 | S12: capiq-sales-drivers-M3_2026-10-24.md; capiq-sales-drivers-X1_2026-10-24.md L62-L245
A13: GTM | B13: Latin America | C13: 0.0239 | D13: 0.0445 | E13: 0.0442 | F13: 0.0375 | G13: 0.037 | H13: 0.0321 | I13: 0.0426 | J13: 0.0689 | K13: 0.0621 | L13: 0.0287 | M13: 0.0158 | N13: 0.031 | O13: 0.0354 | P13: 0.0355 | Q13: 0.0313 | R13: 0.0304 | S13: capiq-sales-drivers-M3_2026-10-24.md L77-L93
... A42: ITA | B42: EAA | C42: 0.0016 | D42: -0.0006 | E42: 0.0133 | F42: 0.0124 | G42: 0.0066 | H42: -0.0017 | I42: 0.0195 | J42: 0.0875 | K42: 0.0591 | L42: 0.0108 | M42: 0.0163 | N42: 0.0299 | O42: 0.0261 | P42: 0.0151 | Q42: 0.0177 | R42: 0.0183 | S42: Informacion_BIMBO_macro.txt L948-L963
A44: Cumulative 3-year inflation ending in each year [calc] = (1+CPI t-2)(1+CPI t-1)(1+CPI t) - 1; orange = 100% or more (IAS 29 para 3(e))
A45: iso3 | B45: region | E45: 2017 | F45: 2018 | G45: 2019 | H45: 2020 | I45: 2021 | J45: 2022 | K45: 2023 | L45: 2024 | M45: 2025 | N45: 2026 | O45: 2027 | P45: 2028 | Q45: 2029 | R45: 2030
A46: MEX | B46: Mexico | E46: =IF(COUNT(C3:E3)<3,"",(1+C3)*(1+D3)*(1+E3)-1) -> 0.11995953 | F46: =IF(COUNT(D3:F3)<3,"",(1+D3)*(1+E3)*(1+F3)-1) -> 0.14372814 | G46: =IF(COUNT(E3:G3)<3,"",(1+E3)*(1+F3)*(1+G3)-1) -> 0.15284949 | H46: =IF(COUNT(F3:H3)<3,"",(1+F3)*(1+G3)*(1+H3)-1) -> 0.12414784 | I46: =IF(COUNT(G3:I3)<3,"",(1+G3)*(1+H3)*(1+I3)-1) -> 0.13261378 | J46: =IF(COUNT(H3:J3)<3,"",(1+H3)*(1+I3)*(1+J3)-1) -> 0.17916853 | K46: =IF(COUNT(I3:K3)<3,"",(1+I3)*(1+J3)*(1+K3)-1) -> 0.20345895 | L46: =IF(COUNT(J3:L3)<3,"",(1+J3)*(1+K3)*(1+L3)-1) -> 0.19241386 | ... R46: =IF(COUNT(P3:R3)<3,"",(1+P3)*(1+Q3)*(1+R3)-1) -> 0.09779172
A47: USA | B47: North America | E47: =IF(COUNT(C4:E4)<3,"",(1+C4)*(1+D4)*(1+E4)-1) -> 0.035409382 | F47: =IF(COUNT(D4:F4)<3,"",(1+D4)*(1+E4)*(1+F4)-1) -> 0.059402088 | G47: =IF(COUNT(E4:G4)<3,"",(1+E4)*(1+F4)*(1+G4)-1) -> 0.065156297 | H47: =IF(COUNT(F4:H4)<3,"",(1+F4)*(1+G4)*(1+H4)-1) -> 0.055769822 | I47: =IF(COUNT(G4:I4)<3,"",(1+G4)*(1+H4)*(1+I4)-1) -> 0.079061894 | J47: =IF(COUNT(H4:J4)<3,"",(1+H4)*(1+I4)*(1+J4)-1) -> 0.14466835 | K47: =IF(COUNT(I4:K4)<3,"",(1+I4)*(1+J4)*(1+K4)-1) -> 0.17734731 | L47: =IF(COUNT(J4:L4)<3,"",(1+J4)*(1+K4)*(1+L4)-1) -> 0.15766863 | ... R47: =IF(COUNT(P4:R4)<3,"",(1+P4)*(1+Q4)*(1+R4)-1) -> 0.06266505
A48: CAN | B48: North America | E48: =IF(COUNT(C5:E5)<3,"",(1+C5)*(1+D5)*(1+E5)-1) -> 0.042173775 | F48: =IF(COUNT(D5:F5)<3,"",(1+D5)*(1+E5)*(1+F5)-1) -> 0.053921804 | G48: =IF(COUNT(E5:G5)<3,"",(1+E5)*(1+F5)*(1+G5)-1) -> 0.059324932 | H48: =IF(COUNT(F5:H5)<3,"",(1+F5)*(1+G5)*(1+H5)-1) -> 0.050149677 | I48: =IF(COUNT(G5:I5)<3,"",(1+G5)*(1+H5)*(1+I5)-1) -> 0.061752974 | J48: =IF(COUNT(H5:J5)<3,"",(1+H5)*(1+I5)*(1+J5)-1) -> 0.11226305 | K48: =IF(COUNT(I5:K5)<3,"",(1+I5)*(1+J5)*(1+K5)-1) -> 0.14715931 | L48: =IF(COUNT(J5:L5)<3,"",(1+J5)*(1+K5)*(1+L5)-1) -> 0.13584303 | ... R48: =IF(COUNT(P5:R5)<3,"",(1+P5)*(1+Q5)*(1+R5)-1) -> 0.058503574
A49: ARG | B49: Latin America | E49: =IF(COUNT(C6:E6)<3,"",(1+C6)*(1+D6)*(1+E6)-1) -> 1.0047089 | F49: =IF(COUNT(D6:F6)<3,"",(1+D6)*(1+E6)*(1+F6)-1) -> 1.3134437 | G49: =IF(COUNT(E6:G6)<3,"",(1+E6)*(1+F6)*(1+G6)-1) -> 1.58311 | H49: =IF(COUNT(F6:H6)<3,"",(1+F6)*(1+G6)*(1+H6)-1) -> 1.9282669 | I49: =IF(COUNT(G6:I6)<3,"",(1+G6)*(1+H6)*(1+I6)-1) -> 2.2364022 | J49: =IF(COUNT(H6:J6)<3,"",(1+H6)*(1+I6)*(1+J6)-1) -> 2.6343396 | K49: =IF(COUNT(I6:K6)<3,"",(1+I6)*(1+J6)*(1+K6)-1) -> 4.9750876 | L49: =IF(COUNT(J6:L6)<3,"",(1+J6)*(1+K6)*(1+L6)-1) -> 11.878587 | ... R49: =IF(COUNT(P6:R6)<3,"",(1+P6)*(1+Q6)*(1+R6)-1) -> 0.23714234
A50: BRA | B50: Latin America | E50: =IF(COUNT(C7:E7)<3,"",(1+C7)*(1+D7)*(1+E7)-1) -> 0.22649515 | F50: =IF(COUNT(D7:F7)<3,"",(1+D7)*(1+E7)*(1+F7)-1) -> 0.1660872 | G50: =IF(COUNT(E7:G7)<3,"",(1+E7)*(1+F7)*(1+G7)-1) -> 0.11236183 | H50: =IF(COUNT(F7:H7)<3,"",(1+F7)*(1+G7)*(1+H7)-1) -> 0.10978119 | I50: =IF(COUNT(G7:I7)<3,"",(1+G7)*(1+H7)*(1+I7)-1) -> 0.15945691 | J50: =IF(COUNT(H7:J7)<3,"",(1+H7)*(1+I7)*(1+J7)-1) -> 0.22149283 | K50: =IF(COUNT(I7:K7)<3,"",(1+I7)*(1+J7)*(1+K7)-1) -> 0.23782516 | L50: =IF(COUNT(J7:L7)<3,"",(1+J7)*(1+K7)*(1+L7)-1) -> 0.19290685 | ... R50: =IF(COUNT(P7:R7)<3,"",(1+P7)*(1+Q7)*(1+R7)-1) -> 0.10700014
A51: CHL | B51: Latin America | E51: =IF(COUNT(C8:E8)<3,"",(1+C8)*(1+D8)*(1+E8)-1) -> 0.10655249 | F51: =IF(COUNT(D8:F8)<3,"",(1+D8)*(1+E8)*(1+F8)-1) -> 0.086298387 | G51: =IF(COUNT(E8:G8)<3,"",(1+E8)*(1+F8)*(1+G8)-1) -> 0.073528257 | H51: =IF(COUNT(F8:H8)<3,"",(1+F8)*(1+G8)*(1+H8)-1) -> 0.082668692 | I51: =IF(COUNT(G8:I8)<3,"",(1+G8)*(1+H8)*(1+I8)-1) -> 0.10465181 | J51: =IF(COUNT(H8:J8)<3,"",(1+H8)*(1+I8)*(1+J8)-1) -> 0.20245055 | K51: =IF(COUNT(I8:K8)<3,"",(1+I8)*(1+J8)*(1+K8)-1) -> 0.25530937 | L51: =IF(COUNT(J8:L8)<3,"",(1+J8)*(1+K8)*(1+L8)-1) -> 0.25230681 | ... R51: =IF(COUNT(P8:R8)<3,"",(1+P8)*(1+Q8)*(1+R8)-1) -> 0.089437791
A52: COL | B52: Latin America | E52: =IF(COUNT(C9:E9)<3,"",(1+C9)*(1+D9)*(1+E9)-1) -> 0.17750938 | F52: =IF(COUNT(D9:F9)<3,"",(1+D9)*(1+E9)*(1+F9)-1) -> 0.15788236 | G52: =IF(COUNT(E9:G9)<3,"",(1+E9)*(1+F9)*(1+G9)-1) -> 0.11491007 | H52: =IF(COUNT(F9:H9)<3,"",(1+F9)*(1+G9)*(1+H9)-1) -> 0.095779614 | I52: =IF(COUNT(G9:I9)<3,"",(1+G9)*(1+H9)*(1+I9)-1) -> 0.09853923 | J52: =IF(COUNT(H9:J9)<3,"",(1+H9)*(1+I9)*(1+J9)-1) -> 0.16921418 | K52: =IF(COUNT(I9:K9)<3,"",(1+I9)*(1+J9)*(1+K9)-1) -> 0.27424162 | L52: =IF(COUNT(J9:L9)<3,"",(1+J9)*(1+K9)*(1+L9)-1) -> 0.31253042 | ... R52: =IF(COUNT(P9:R9)<3,"",(1+P9)*(1+Q9)*(1+R9)-1) -> 0.10935324
A53: CRI | B53: Latin America | E53: =IF(COUNT(C10:E10)<3,"",(1+C10)*(1+D10)*(1+E10)-1) -> 0.024225514 | F53: =IF(COUNT(D10:F10)<3,"",(1+D10)*(1+E10)*(1+F10)-1) -> 0.038654088 | G53: =IF(COUNT(E10:G10)<3,"",(1+E10)*(1+F10)*(1+G10)-1) -> 0.060677959 | H53: =IF(COUNT(F10:H10)<3,"",(1+F10)*(1+G10)*(1+H10)-1) -> 0.051180597 | I53: =IF(COUNT(G10:I10)<3,"",(1+G10)*(1+H10)*(1+I10)-1) -> 0.046141676 | J53: =IF(COUNT(H10:J10)<3,"",(1+H10)*(1+I10)*(1+J10)-1) -> 0.10936101 | K53: =IF(COUNT(I10:K10)<3,"",(1+I10)*(1+J10)*(1+K10)-1) -> 0.10726829 | L53: =IF(COUNT(J10:L10)<3,"",(1+J10)*(1+K10)*(1+L10)-1) -> 0.083975713 | ... R53: =IF(COUNT(P10:R10)<3,"",(1+P10)*(1+Q10)*(1+R10)-1) -> 0.059538599
A54: ECU | B54: Latin America | E54: =IF(COUNT(C11:E11)<3,"",(1+C11)*(1+D11)*(1+E11)-1) -> 0.062129095 | F54: =IF(COUNT(D11:F11)<3,"",(1+D11)*(1+E11)*(1+F11)-1) -> 0.0193252 | G54: =IF(COUNT(E11:G11)<3,"",(1+E11)*(1+F11)*(1+G11)-1) -> 0.0046961351 | H54: =IF(COUNT(F11:H11)<3,"",(1+F11)*(1+G11)*(1+H11)-1) -> -0.0029076198 | I54: =IF(COUNT(G11:I11)<3,"",(1+G11)*(1+H11)*(1+I11)-1) -> 0.00058989807 | J54: =IF(COUNT(H11:J11)<3,"",(1+H11)*(1+I11)*(1+J11)-1) -> 0.032522557 | K54: =IF(COUNT(I11:K11)<3,"",(1+I11)*(1+J11)*(1+K11)-1) -> 0.059045311 | L54: =IF(COUNT(J11:L11)<3,"",(1+J11)*(1+K11)*(1+L11)-1) -> 0.07406423 | ... R54: =IF(COUNT(P11:R11)<3,"",(1+P11)*(1+Q11)*(1+R11)-1) -> 0.064748941
A55: SLV | B55: Latin America | E55: =IF(COUNT(C12:E12)<3,"",(1+C12)*(1+D12)*(1+E12)-1) -> 0.0087426276 | F55: =IF(COUNT(D12:F12)<3,"",(1+D12)*(1+E12)*(1+F12)-1) -> 0.027236751 | G55: =IF(COUNT(E12:G12)<3,"",(1+E12)*(1+F12)*(1+G12)-1) -> 0.021824867 | H55: =IF(COUNT(F12:H12)<3,"",(1+F12)*(1+G12)*(1+H12)-1) -> 0.0078646818 | I55: =IF(COUNT(G12:I12)<3,"",(1+G12)*(1+H12)*(1+I12)-1) -> 0.03159322 | J55: =IF(COUNT(H12:J12)<3,"",(1+H12)*(1+I12)*(1+J12)-1) -> 0.10509437 | K55: =IF(COUNT(I12:K12)<3,"",(1+I12)*(1+J12)*(1+K12)-1) -> 0.15412094 | L55: =IF(COUNT(J12:L12)<3,"",(1+J12)*(1+K12)*(1+L12)-1) -> 0.12489704 | ... R55: =IF(COUNT(P12:R12)<3,"",(1+P12)*(1+Q12)*(1+R12)-1) -> 0.078676749
A56: GTM | B56: Latin America | E56: =IF(COUNT(C13:E13)<3,"",(1+C13)*(1+D13)*(1+E13)-1) -> 0.11673384 | F56: =IF(COUNT(D13:F13)<3,"",(1+D13)*(1+E13)*(1+F13)-1) -> 0.13156691 | G56: =IF(COUNT(E13:G13)<3,"",(1+E13)*(1+F13)*(1+G13)-1) -> 0.12344173 | H56: =IF(COUNT(F13:H13)<3,"",(1+F13)*(1+G13)*(1+H13)-1) -> 0.11042349 | I56: =IF(COUNT(G13:I13)<3,"",(1+G13)*(1+H13)*(1+I13)-1) -> 0.11588196 | J56: =IF(COUNT(H13:J13)<3,"",(1+H13)*(1+I13)*(1+J13)-1) -> 0.15020851 | K56: =IF(COUNT(I13:K13)<3,"",(1+I13)*(1+J13)*(1+K13)-1) -> 0.18364156 | L56: =IF(COUNT(J13:L13)<3,"",(1+J13)*(1+K13)*(1+L13)-1) -> 0.16786119 | ... R56: =IF(COUNT(P13:R13)<3,"",(1+P13)*(1+Q13)*(1+R13)-1) -> 0.10037565
A57: HND | B57: Latin America | E57: =IF(COUNT(C14:E14)<3,"",(1+C14)*(1+D14)*(1+E14)-1) -> 0.10130414 | F57: =IF(COUNT(D14:F14)<3,"",(1+D14)*(1+E14)*(1+F14)-1) -> 0.11400821 | G57: =IF(COUNT(E14:G14)<3,"",(1+E14)*(1+F14)*(1+G14)-1) -> 0.13190262 | H57: =IF(COUNT(F14:H14)<3,"",(1+F14)*(1+G14)*(1+H14)-1) -> 0.12689275 | I57: =IF(COUNT(G14:I14)<3,"",(1+G14)*(1+H14)*(1+I14)-1) -> 0.12829664 | J57: =IF(COUNT(H14:J14)<3,"",(1+H14)*(1+I14)*(1+J14)-1) -> 0.17932242 | K57: =IF(COUNT(I14:K14)<3,"",(1+I14)*(1+J14)*(1+K14)-1) -> 0.21568116 | L57: =IF(COUNT(J14:L14)<3,"",(1+J14)*(1+K14)*(1+L14)-1) -> 0.21719378 | ... R57: =IF(COUNT(P14:R14)<3,"",(1+P14)*(1+Q14)*(1+R14)-1) -> 0.12247912
... A85: ITA | B85: EAA | E85: =IF(COUNT(C42:E42)<3,"",(1+C42)*(1+D42)*(1+E42)-1) -> 0.014312327 | F85: =IF(COUNT(D42:F42)<3,"",(1+D42)*(1+E42)*(1+F42)-1) -> 0.025249401 | G85: =IF(COUNT(E42:G42)<3,"",(1+E42)*(1+F42)*(1+G42)-1) -> 0.032635628 | H85: =IF(COUNT(F42:H42)<3,"",(1+F42)*(1+G42)*(1+H42)-1) -> 0.017349401 | I85: =IF(COUNT(G42:I42)<3,"",(1+G42)*(1+H42)*(1+I42)-1) -> 0.024484111 | J85: =IF(COUNT(H42:J42)<3,"",(1+H42)*(1+I42)*(1+J42)-1) -> 0.10682145 | K85: =IF(COUNT(I42:K42)<3,"",(1+I42)*(1+J42)*(1+K42)-1) -> 0.17423079 | L85: =IF(COUNT(J42:L42)<3,"",(1+J42)*(1+K42)*(1+L42)-1) -> 0.16421038 | ... R85: =IF(COUNT(P42:R42)<3,"",(1+P42)*(1+Q42)*(1+R42)-1) -> 0.051972401

Sheet FX
A1: Local currency per USD, annual average [sourced]: BIMBOA/research/Informacion_BIMBO_macro.txt (2015-2025 Banxico FIX for MXN, and CAD/GBP/EUR from 2019, else Capital IQ; 2026-2030 Capital IQ forecast). USD = 1 by definition
A2: currency | B2: 2015 | C2: 2016 | D2: 2017 | E2: 2018 | F2: 2019 | G2: 2020 | H2: 2021 | I2: 2022 | J2: 2023 | K2: 2024 | L2: 2025 | M2: 2026 | N2: 2027 | O2: 2028 | P2: 2029 | Q2: 2030 | R2: source lines
A3: ARS | B3: 9.23 | C3: 14.76 | D3: 16.56 | E3: 28.09 | F3: 48.25 | G3: 70.64 | H3: 95.09 | I3: 130.71 | J3: 296.52 | K3: 916.32 | L3: 1243.79 | M3: 1472.34 | N3: 1695.69 | O3: 1851.17 | P3: 1907.4 | Q3: 1974.33 | R3: L1028 (2015-2025), L1131 (2026-2030)
A4: BRL | B4: 3.33 | C4: 3.49 | D4: 3.19 | E4: 3.65 | F4: 3.94 | G4: 5.15 | H4: 5.39 | I4: 5.16 | J4: 5 | K4: 5.39 | L4: 5.59 | M4: 5.14 | N4: 5.18 | O4: 5.3 | P4: 5.42 | Q4: 5.54 | R4: L1027 (2015-2025), L1130 (2026-2030)
A5: CAD | B5: 1.28 | C5: 1.33 | D5: 1.3 | E5: 1.3 | F5: 1.3269 | G5: 1.3413 | H5: 1.2534 | I5: 1.3011 | J5: 1.3494 | K5: 1.3698 | L5: 1.3975 | M5: 1.39 | N5: 1.36 | O5: 1.33 | P5: 1.29 | Q5: 1.26 | R5: L1026 (2015-2025), L1129 (2026-2030)
A6: CHF | B6: 0.96 | C6: 0.99 | D6: 0.98 | E6: 0.98 | F6: 0.99 | G6: 0.94 | H6: 0.91 | I6: 0.95 | J6: 0.9 | K6: 0.88 | L6: 0.83 | M6: 0.8 | N6: 0.81 | O6: 0.81 | P6: 0.8 | Q6: 0.79 | R6: L1039 (2015-2025), L1142 (2026-2030)
A7: CLP | B7: 650 | C7: 680 | D7: 650 | E7: 640 | F7: 700 | G7: 790 | H7: 760 | I7: 870 | J7: 840 | K7: 940 | L7: 950 | M7: 917 | N7: 931.8 | O7: 901.75 | P7: 906.75 | Q7: 914.72 | R7: L1029 (2015-2025), L1132 (2026-2030)
A8: CNY | B8: 6.28 | C8: 6.64 | D8: 6.76 | E8: 6.62 | F8: 6.91 | G8: 6.9 | H8: 6.45 | I8: 6.73 | J8: 7.08 | K8: 7.2 | L8: 7.19 | M8: 6.79 | N8: 6.66 | O8: 6.62 | P8: 6.59 | Q8: 6.59 | R8: L1045 (2015-2025), L1148 (2026-2030)
A9: COP | B9: 2740 | C9: 3050 | D9: 2950 | E9: 2960 | F9: 3280 | G9: 3690 | H9: 3740 | I9: 4250 | J9: 4330 | K9: 4070 | L9: 4050 | M9: 3484.23 | N9: 3445.24 | O9: 3657.07 | P9: 3715.25 | Q9: 3714.47 | R9: L1030 (2015-2025), L1133 (2026-2030)
A10: CRC | B10: 534.57 | C10: 544.74 | D10: 567.51 | E10: 576.97 | F10: 584.01 | G10: 581.67 | H10: 617.56 | I10: 643.65 | J10: 540.7 | K10: 511.97 | L10: 500.58 | M10: 459.37 | N10: 465.17 | O10: 476.92 | P10: 486.67 | Q10: 500.07 | R10: L1036 (2015-2025), L1139 (2026-2030)
A11: EUR | B11: 0.9 | C11: 0.9 | D11: 0.89 | E11: 0.85 | F11: 0.8934 | G11: 0.8773 | H11: 0.8458 | I11: 0.9515 | J11: 0.9249 | K11: 0.9241 | L11: 0.8863 | M11: 0.87 | N11: 0.89 | O11: 0.89 | P11: 0.86 | Q11: 0.84 | R11: L1052 (2015-2025), L1155 (2026-2030)
A12: GBP | B12: 0.65 | C12: 0.74 | D12: 0.78 | E12: 0.75 | F12: 0.7844 | G12: 0.7798 | H12: 0.7269 | I12: 0.8118 | J12: 0.8041 | K12: 0.7824 | L12: 0.7589 | M12: 0.75 | N12: 0.75 | O12: 0.75 | P12: 0.75 | Q12: 0.75 | R12: L1038 (2015-2025), L1141 (2026-2030)
A13: GTQ | B13: 7.65 | C13: 7.6 | D13: 7.35 | E13: 7.52 | F13: 7.7 | G13: 7.72 | H13: 7.74 | I13: 7.75 | J13: 7.83 | K13: 7.76 | L13: 7.68 | M13: 7.64 | N13: 7.71 | O13: 7.76 | P13: 7.83 | Q13: 7.9 | R13: L1034 (2015-2025), L1137 (2026-2030)
... A18: MAD | B18: 9.76 | C18: 9.81 | D18: 9.69 | E18: 9.39 | F18: 9.62 | G18: 9.49 | H18: 8.99 | I18: 10.16 | J18: 10.13 | K18: 9.94 | L18: 9.35 | M18: 9.32 | N18: 9.62 | O18: 9.75 | P18: 9.65 | Q18: 9.69 | R18: L1050 (2015-2025), L1153 (2026-2030)
A19: MKD | R19: not in source: no FX
A20: MXN | B20: 15.881 | C20: 18.689 | D20: 18.907 | E20: 19.237 | F20: 19.257 | G20: 21.498 | H20: 20.282 | I20: 20.12 | J20: 17.734 | K20: 18.326 | L20: 19.2 | M20: 17.54 | N20: 18.21 | O20: 18.67 | P20: 19.03 | Q20: 19.24 | R20: L1025 (2015-2025), L1128 (2026-2030)
A21: NIO | B21: 27.26 | C21: 28.62 | D21: 30.05 | E21: 31.55 | F21: 33.12 | G21: 34.34 | H21: 35.17 | I21: 35.87 | J21: 36.44 | K21: 36.62 | L21: 36.62 | M21: 36.62 | N21: 36.67 | O21: 38.53 | P21: 40.17 | Q21: 41.89 | R21: L1037 (2015-2025), L1140 (2026-2030)
A22: PEN | B22: 3.18 | C22: 3.38 | D22: 3.26 | E22: 3.29 | F22: 3.34 | G22: 3.5 | H22: 3.88 | I22: 3.83 | J22: 3.74 | K22: 3.75 | L22: 3.57 | M22: 3.41 | N22: 3.42 | O22: 3.44 | P22: 3.45 | Q22: 3.45 | R22: L1031 (2015-2025), L1134 (2026-2030)
A23: PYG | B23: 5200 | C23: 5670 | D23: 5620 | E23: 5730 | F23: 6240 | G23: 6770 | H23: 6770 | I23: 6980 | J23: 7290 | K23: 7560 | L23: 7540 | M23: 6134.11 | N23: 5972.76 | O23: 6224.53 | P23: 6445.97 | Q23: 6660.27 | R23: L1033 (2015-2025), L1136 (2026-2030)
A24: RON | B24: 4.01 | C24: 4.06 | D24: 4.05 | E24: 3.94 | F24: 4.24 | G24: 4.24 | H24: 4.16 | I24: 4.69 | J24: 4.57 | K24: 4.6 | L24: 4.47 | M24: 4.52 | N24: 4.75 | O24: 4.73 | P24: 4.58 | Q24: 4.49 | R24: L1040 (2015-2025), L1143 (2026-2030)
A25: RSD | B25: 108.81 | C25: 111.28 | D25: 107.76 | E25: 100.18 | F25: 105.25 | G25: 103.16 | H25: 99.4 | I25: 111.66 | J25: 108.4 | K25: 108.21 | L25: 103.97 | M25: 102.61 | N25: 102.82 | O25: 100.67 | P25: 99.92 | Q25: 99.68 | R25: L1041 (2015-2025), L1144 (2026-2030)
A26: RUB | B26: 61.11 | C26: 67.03 | D26: 58.31 | E26: 62.74 | F26: 64.72 | G26: 72.21 | H26: 73.66 | I26: 68.57 | J26: 85.29 | K26: 92.6 | L26: 83.55 | M26: 79.93 | N26: 87.56 | O26: 95.88 | P26: 100.67 | Q26: 100.45 | R26: L1043 (2015-2025), L1146 (2026-2030)
A27: TND | B27: 1.96 | C27: 2.15 | D27: 2.42 | E27: 2.65 | F27: 2.93 | G27: 2.81 | H27: 2.79 | I27: 3.1 | J27: 3.11 | K27: 3.11 | L27: 3 | M27: 2.95 | N27: 3.15 | O27: 3.29 | P27: 3.38 | Q27: 3.45 | R27: L1051 (2015-2025), L1154 (2026-2030)
A28: TRY | B28: 2.72 | C28: 3.02 | D28: 3.65 | E28: 4.83 | F28: 5.68 | G28: 7.02 | H28: 8.86 | I28: 16.57 | J28: 23.79 | K28: 32.83 | L28: 39.49 | M28: 46.74 | N28: 54.83 | O28: 60.56 | P28: 64.5 | Q28: 68.7 | R28: L1042 (2015-2025), L1145 (2026-2030)
A29: UAH | B29: 21.84 | C29: 25.55 | D29: 26.6 | E29: 27.2 | F29: 25.83 | G29: 26.96 | H29: 27.28 | I29: 32.3 | J29: 36.57 | K29: 40.16 | L29: 41.69 | M29: 44.25 | N29: 46.55 | O29: 46.98 | P29: 46.43 | Q29: 43.9 | R29: L1044 (2015-2025), L1147 (2026-2030)
A30: USD | B30: 1 | C30: 1 | D30: 1 | E30: 1 | F30: 1 | G30: 1 | H30: 1 | I30: 1 | J30: 1 | K30: 1 | L30: 1 | M30: 1 | N30: 1 | O30: 1 | P30: 1 | Q30: 1
A31: UYU | B31: 27.33 | C31: 30.16 | D31: 28.68 | E31: 30.73 | F31: 35.25 | G31: 42.01 | H31: 43.56 | I31: 41.18 | J31: 38.83 | K31: 40.21 | L31: 41.09 | M31: 40.09 | N31: 42.63 | O31: 44.28 | P31: 45.82 | Q31: 47.29 | R31: L1032 (2015-2025), L1135 (2026-2030)
A32: VES | R32: not in source: no FX
A33: ZAR | B33: 12.76 | C33: 14.71 | D33: 13.33 | E33: 13.24 | F33: 14.45 | G33: 16.47 | H33: 14.78 | I33: 16.36 | J33: 18.45 | K33: 18.33 | L33: 17.89 | M33: 16.39 | N33: 16.61 | O33: 16.77 | P33: 17.05 | Q33: 17.37 | R33: L1049 (2015-2025), L1152 (2026-2030)

Sheet Regional_agg
A1: Regional nominal GDP growth, local currency, constant prior-year FX (same logic as Bimbo ex-FX growth) [calc]. include = 1/0 (team can toggle). GDP USD bn = level (x1000 when stored in trillions: CHL, COL, PRY, KOR) / FX
A2: iso3 | B2: region | C2: include | D2: note | E2: GDP USD bn 2015 | F2: GDP USD bn 2016 | G2: GDP USD bn 2017 | H2: GDP USD bn 2018 | I2: GDP USD bn 2019 | J2: GDP USD bn 2020 | K2: GDP USD bn 2021 | L2: GDP USD bn 2022 | M2: GDP USD bn 2023 | N2: GDP USD bn 2024 | O2: GDP USD bn 2025 | P2: GDP USD bn 2026 | Q2: GDP USD bn 2027 | R2: GDP USD bn 2028 | S2: GDP USD bn 2029 | T2: GDP USD bn 2030
A3: MEX | B3: Mexico | C3: 1 | E3: =IF(N(FX!B20)=0,"",Data!D2/FX!B20) -> 1210.7934 | F3: =IF(N(FX!C20)=0,"",Data!D3/FX!C20) -> 1110.7491 | G3: =IF(N(FX!D20)=0,"",Data!D4/FX!D20) -> 1191.9506 | H3: =IF(N(FX!E20)=0,"",Data!D5/FX!E20) -> 1256.7796 | I3: =IF(N(FX!F20)=0,"",Data!D6/FX!F20) -> 1304.5552 | J3: =IF(N(FX!G20)=0,"",Data!D7/FX!G20) -> 1120.4186 | K3: =IF(N(FX!H20)=0,"",Data!D8/FX!H20) -> 1315.9467 | L3: =IF(N(FX!I20)=0,"",Data!D9/FX!I20) -> 1467.4707 | M3: =IF(N(FX!J20)=0,"",Data!D10/FX!J20) -> 1797.1744 | N3: =IF(N(FX!K20)=0,"",Data!D11/FX!K20) -> 1832.5276 | O3: =IF(N(FX!L20)=0,"",Data!D12/FX!L20) -> 1838.6245 | P3: =IF(N(FX!M20)=0,"",Data!D13/FX!M20) -> 2136.9128 | Q3: =IF(N(FX!N20)=0,"",Data!D14/FX!N20) -> 2196.078 | R3: =IF(N(FX!O20)=0,"",Data!D15/FX!O20) -> 2270.6144 | S3: =IF(N(FX!P20)=0,"",Data!D16/FX!P20) -> 2356.9464 | T3: =IF(N(FX!Q20)=0,"",Data!D17/FX!Q20) -> 2444.882
A4: USA | B4: North America | C4: 1 | E4: =IF(N(FX!B30)=0,"",Data!D18/FX!B30) -> 18295.02 | F4: =IF(N(FX!C30)=0,"",Data!D19/FX!C30) -> 18804.91 | G4: =IF(N(FX!D30)=0,"",Data!D20/FX!D30) -> 19612.1 | H4: =IF(N(FX!E30)=0,"",Data!D21/FX!E30) -> 20656.52 | I4: =IF(N(FX!F30)=0,"",Data!D22/FX!F30) -> 21539.98 | J4: =IF(N(FX!G30)=0,"",Data!D23/FX!G30) -> 21375.28 | K4: =IF(N(FX!H30)=0,"",Data!D24/FX!H30) -> 23745.85 | L4: =IF(N(FX!I30)=0,"",Data!D25/FX!I30) -> 26059.71 | M4: =IF(N(FX!J30)=0,"",Data!D26/FX!J30) -> 27825.89 | N4: =IF(N(FX!K30)=0,"",Data!D27/FX!K30) -> 29380.99 | O4: =IF(N(FX!L30)=0,"",Data!D28/FX!L30) -> 30861.29 | P4: =IF(N(FX!M30)=0,"",Data!D29/FX!M30) -> 32710.81 | Q4: =IF(N(FX!N30)=0,"",Data!D30/FX!N30) -> 34488.98 | R4: =IF(N(FX!O30)=0,"",Data!D31/FX!O30) -> 36128.72 | S4: =IF(N(FX!P30)=0,"",Data!D32/FX!P30) -> 37639.61 | T4: =IF(N(FX!Q30)=0,"",Data!D33/FX!Q30) -> 39193.65
A5: CAN | B5: North America | C5: 1 | E5: =IF(N(FX!B5)=0,"",Data!D34/FX!B5) -> 1555.0312 | F5: =IF(N(FX!C5)=0,"",Data!D35/FX!C5) -> 1522.9624 | G5: =IF(N(FX!D5)=0,"",Data!D36/FX!D5) -> 1646.6462 | H5: =IF(N(FX!E5)=0,"",Data!D37/FX!E5) -> 1719.7538 | I5: =IF(N(FX!F5)=0,"",Data!D38/FX!F5) -> 1743.5828 | J5: =IF(N(FX!G5)=0,"",Data!D39/FX!G5) -> 1655.5059 | K5: =IF(N(FX!H5)=0,"",Data!D40/FX!H5) -> 2023.153 | L5: =IF(N(FX!I5)=0,"",Data!D41/FX!I5) -> 2201.3373 | M5: =IF(N(FX!J5)=0,"",Data!D42/FX!J5) -> 2197.4211 | N5: =IF(N(FX!K5)=0,"",Data!D43/FX!K5) -> 2269.3459 | O5: =IF(N(FX!L5)=0,"",Data!D44/FX!L5) -> 2322.1896 | P5: =IF(N(FX!M5)=0,"",Data!D45/FX!M5) -> 2466.4532 | Q5: =IF(N(FX!N5)=0,"",Data!D46/FX!N5) -> 2684.1765 | R5: =IF(N(FX!O5)=0,"",Data!D47/FX!O5) -> 2874.3158 | S5: =IF(N(FX!P5)=0,"",Data!D48/FX!P5) -> 3071.1628 | T5: =IF(N(FX!Q5)=0,"",Data!D49/FX!Q5) -> 3272.7619
A6: ARG | B6: Latin America | C6: 1 | E6: =IF(N(FX!B3)=0,"",Data!D50/FX!B3) -> 645.12568 | F6: =IF(N(FX!C3)=0,"",Data!D51/FX!C3) -> 557.46341 | G6: =IF(N(FX!D3)=0,"",Data!D52/FX!D3) -> 643.7337 | H6: =IF(N(FX!E3)=0,"",Data!D53/FX!E3) -> 524.91314 | I6: =IF(N(FX!F3)=0,"",Data!D54/FX!F3) -> 446.80705 | J6: =IF(N(FX!G3)=0,"",Data!D55/FX!G3) -> 385.18984 | K6: =IF(N(FX!H3)=0,"",Data!D56/FX!H3) -> 486.05616 | L6: =IF(N(FX!I3)=0,"",Data!D57/FX!I3) -> 633.54028 | M6: =IF(N(FX!J3)=0,"",Data!D58/FX!J3) -> 654.07453 | N6: =IF(N(FX!K3)=0,"",Data!D59/FX!K3) -> 637.74338 | O6: =IF(N(FX!L3)=0,"",Data!D60/FX!L3) -> 683.5879 | P6: =IF(N(FX!M3)=0,"",Data!D61/FX!M3) -> 771.09028 | Q6: =IF(N(FX!N3)=0,"",Data!D62/FX!N3) -> 790.96943 | R6: =IF(N(FX!O3)=0,"",Data!D63/FX!O3) -> 797.74268 | S6: =IF(N(FX!P3)=0,"",Data!D64/FX!P3) -> 836.11931 | T6: =IF(N(FX!Q3)=0,"",Data!D65/FX!Q3) -> 870.7362
A7: BRA | B7: Latin America | C7: 1 | E7: =IF(N(FX!B4)=0,"",Data!D66/FX!B4) -> 1800.5375 | F7: =IF(N(FX!C4)=0,"",Data!D67/FX!C4) -> 1796.3696 | G7: =IF(N(FX!D4)=0,"",Data!D68/FX!D4) -> 2064.4138 | H7: =IF(N(FX!E4)=0,"",Data!D69/FX!E4) -> 1918.9425 | I7: =IF(N(FX!F4)=0,"",Data!D70/FX!F4) -> 1875.4137 | J7: =IF(N(FX!G4)=0,"",Data!D71/FX!G4) -> 1477.5922 | K7: =IF(N(FX!H4)=0,"",Data!D72/FX!H4) -> 1672.0111 | L7: =IF(N(FX!I4)=0,"",Data!D73/FX!I4) -> 1953.4264 | M7: =IF(N(FX!J4)=0,"",Data!D74/FX!J4) -> 2188.668 | N7: =IF(N(FX!K4)=0,"",Data!D75/FX!K4) -> 2185.3896 | O7: =IF(N(FX!L4)=0,"",Data!D76/FX!L4) -> 2278.814 | P7: =IF(N(FX!M4)=0,"",Data!D77/FX!M4) -> 2657.0078 | Q7: =IF(N(FX!N4)=0,"",Data!D78/FX!N4) -> 2784.9382 | R7: =IF(N(FX!O4)=0,"",Data!D79/FX!O4) -> 2864.9906 | S7: =IF(N(FX!P4)=0,"",Data!D80/FX!P4) -> 2978.7731 | T7: =IF(N(FX!Q4)=0,"",Data!D81/FX!Q4) -> 3121.6661
A8: CHL | B8: Latin America | C8: 1 | E8: =IF(N(FX!B7)=0,"",Data!D82*1000/FX!B7) -> 244.03077 | F8: =IF(N(FX!C7)=0,"",Data!D83*1000/FX!C7) -> 248.17647 | G8: =IF(N(FX!D7)=0,"",Data!D84*1000/FX!D7) -> 275.86154 | H8: =IF(N(FX!E7)=0,"",Data!D85*1000/FX!E7) -> 295.98438 | I8: =IF(N(FX!F7)=0,"",Data!D86*1000/FX!F7) -> 279.35714 | J8: =IF(N(FX!G7)=0,"",Data!D87*1000/FX!G7) -> 254.82278 | K8: =IF(N(FX!H7)=0,"",Data!D88*1000/FX!H7) -> 315.21053 | L8: =IF(N(FX!I7)=0,"",Data!D89*1000/FX!I7) -> 302.24138 | M8: =IF(N(FX!J7)=0,"",Data!D90*1000/FX!J7) -> 335.83333 | N8: =IF(N(FX!K7)=0,"",Data!D91*1000/FX!K7) -> 330.51064 | O8: =IF(N(FX!L7)=0,"",Data!D92*1000/FX!L7) -> 357.87368 | P8: =IF(N(FX!M7)=0,"",Data!D93*1000/FX!M7) -> 397.90622 | Q8: =IF(N(FX!N7)=0,"",Data!D94*1000/FX!N7) -> 421.43164 | R8: =IF(N(FX!O7)=0,"",Data!D95*1000/FX!O7) -> 461.3252 | S8: =IF(N(FX!P7)=0,"",Data!D96*1000/FX!P7) -> 495.25227 | T8: =IF(N(FX!Q7)=0,"",Data!D97*1000/FX!Q7) -> 530.4902
A9: COL | B9: Latin America | C9: 1 | E9: =IF(N(FX!B9)=0,"",Data!D98*1000/FX!B9) -> 293.68248 | F9: =IF(N(FX!C9)=0,"",Data!D99*1000/FX!C9) -> 283.20656 | G9: =IF(N(FX!D9)=0,"",Data!D100*1000/FX!D9) -> 312.02373 | H9: =IF(N(FX!E9)=0,"",Data!D101*1000/FX!E9) -> 333.71284 | I9: =IF(N(FX!F9)=0,"",Data!D102*1000/FX!F9) -> 323.19207 | J9: =IF(N(FX!G9)=0,"",Data!D103*1000/FX!G9) -> 270.58808 | K9: =IF(N(FX!H9)=0,"",Data!D104*1000/FX!H9) -> 318.88503 | L9: =IF(N(FX!I9)=0,"",Data!D105*1000/FX!I9) -> 346.13647 | M9: =IF(N(FX!J9)=0,"",Data!D106*1000/FX!J9) -> 366.55889 | N9: =IF(N(FX!K9)=0,"",Data!D107*1000/FX!K9) -> 420.96314 | O9: =IF(N(FX!L9)=0,"",Data!D108*1000/FX!L9) -> 457.44938 | P9: =IF(N(FX!M9)=0,"",Data!D109*1000/FX!M9) -> 580.01911 | Q9: =IF(N(FX!N9)=0,"",Data!D110*1000/FX!N9) -> 636.09502 | R9: =IF(N(FX!O9)=0,"",Data!D111*1000/FX!O9) -> 642.01943 | S9: =IF(N(FX!P9)=0,"",Data!D112*1000/FX!P9) -> 675.10666 | T9: =IF(N(FX!Q9)=0,"",Data!D113*1000/FX!Q9) -> 722.80298
A10: CRI | B10: Latin America | C10: 1 | E10: =IF(N(FX!B10)=0,"",Data!D114/FX!B10) -> 56.441476 | F10: =IF(N(FX!C10)=0,"",Data!D115/FX!C10) -> 58.846955 | G10: =IF(N(FX!D10)=0,"",Data!D116/FX!D10) -> 60.516379 | H10: =IF(N(FX!E10)=0,"",Data!D117/FX!E10) -> 62.568036 | I10: =IF(N(FX!F10)=0,"",Data!D118/FX!F10) -> 65.117686 | J10: =IF(N(FX!G10)=0,"",Data!D119/FX!G10) -> 63.155449 | K10: =IF(N(FX!H10)=0,"",Data!D120/FX!H10) -> 65.931424 | L10: =IF(N(FX!I10)=0,"",Data!D121/FX!I10) -> 71.385753 | M10: =IF(N(FX!J10)=0,"",Data!D122/FX!J10) -> 88.054966 | N10: =IF(N(FX!K10)=0,"",Data!D123/FX!K10) -> 97.308768 | O10: =IF(N(FX!L10)=0,"",Data!D124/FX!L10) -> 103.50453 | P10: =IF(N(FX!M10)=0,"",Data!D125/FX!M10) -> 115.54229 | Q10: =IF(N(FX!N10)=0,"",Data!D126/FX!N10) -> 119.78131 | R10: =IF(N(FX!O10)=0,"",Data!D127/FX!O10) -> 122.87434 | S10: =IF(N(FX!P10)=0,"",Data!D128/FX!P10) -> 126.62525 | T10: =IF(N(FX!Q10)=0,"",Data!D129/FX!Q10) -> 129.64203
A11: ECU | B11: Latin America | C11: 1 | E11: =IF(N(FX!B30)=0,"",Data!D130/FX!B30) -> 97.21 | F11: =IF(N(FX!C30)=0,"",Data!D131/FX!C30) -> 97.67 | G11: =IF(N(FX!D30)=0,"",Data!D132/FX!D30) -> 104.47 | H11: =IF(N(FX!E30)=0,"",Data!D133/FX!E30) -> 107.48 | I11: =IF(N(FX!F30)=0,"",Data!D134/FX!F30) -> 107.6 | J11: =IF(N(FX!G30)=0,"",Data!D135/FX!G30) -> 95.87 | K11: =IF(N(FX!H30)=0,"",Data!D136/FX!H30) -> 107.18 | L11: =IF(N(FX!I30)=0,"",Data!D137/FX!I30) -> 116.13 | M11: =IF(N(FX!J30)=0,"",Data!D138/FX!J30) -> 120.79 | N11: =IF(N(FX!K30)=0,"",Data!D139/FX!K30) -> 123.8 | O11: =IF(N(FX!L30)=0,"",Data!D140/FX!L30) -> 130.32 | P11: =IF(N(FX!M30)=0,"",Data!D141/FX!M30) -> 137.64 | Q11: =IF(N(FX!N30)=0,"",Data!D142/FX!N30) -> 144.98 | R11: =IF(N(FX!O30)=0,"",Data!D143/FX!O30) -> 151.63 | S11: =IF(N(FX!P30)=0,"",Data!D144/FX!P30) -> 158.07 | T11: =IF(N(FX!Q30)=0,"",Data!D145/FX!Q30) -> 164.8
